Workbook

Sheet 원가
A1: 원 가 계 산 서
A3: 공사명: | C3: 화성 청원지구 전기공사_(지구내) | E3: 공사기간: 32 개월
A4: 비 목 | C4: 구 분 | D4: 금 액 | E4: 구 성 비 | I4: 요율 | J4: 수량 | K4: 금액 | L4: 이윤 | M4: 끝자리 맞추기
B5: 재 료 비 | C5: 직 접 재 료 비 | J5: 1 | K5: =D5*J5 -> 0
C6: 간 접 재 료 비 | K6: =D6*J6 -> 0
C7: ( 소 계 ) | K7: =D7*J7 -> 0
A8: 순 | B8: 노 무 비 | C8: 직 접 노 무 비 | J8: 1 | K8: =D8*J8 -> 0
C9: 간 접 노 무 비 | E9: (직접 노무비) * 16.7 % | I9: 16.7 | J9: 1 | K9: =D9*J9 -> 0
C10: ( 소 계 ) | K10: =D10*J10 -> 0
C11: 기 계 경 비 | J11: 1 | K11: =D11*J11 -> 0
C12: 산 재 보 험 료 | E12: (노무비) * 3.56 % | I12: 3.56 | J12: 1 | K12: =D12*J12 -> 0
A13: 공 | C13: 고 용 보 험 료 | E13: (노무비) * 1.01 % | I13: 1.01 | J13: 1 | K13: =D13*J13 -> 0
B14: 경 | C14: 퇴 직 금 공 제 | E14: (직접 노무비) * 2.3 % | I14: 2.3 | J14: 1 | K14: =D14*J14 -> 0
C15: 안 전 관 리 비 | E15: (재료+직노) * 2.07 % | I15: 2.07 | J15: 1 | K15: =D15*J15 -> 0
C16: 기 타 경 비 | E16: (재료+노무) * 5.3 % | H16: =D7+D10 -> 0 | I16: 5.3 | J16: 1 | K16: =D16*J16 -> 0
C17: 건 강 보 험 료 | E17: (직접 노무비) * 3.595 % | I17: 3.595 | J17: 1 | K17: =D17*J17 -> 0
A18: 사 | C18: 연 금 보 험 료 | E18: (직접 노무비) * 4.75 % | I18: 4.75 | J18: 1 | K18: =D18*J18 -> 0
C19: 노인장기요양보험 | E19: (건강 보험료) * 13.14 % | I19: 13.14 | J19: 1 | K19: =D19*J19 -> 0
C20: 석면분담금 | E20: (노무비) * 0.006 % | I20: 0.006 | J20: 1 | K20: =D20*J20 -> 0
C21: 임금채권부담금 | E21: (노무비) * 0.09 % | I21: 0.09 | J21: 1 | K21: =D21*J21 -> 0
B22: 비 | K22: =D22*J22 -> 0
A23: 비 | K23: =D23*J23 -> 0
K24: =D24*J24 -> 0
C25: ( 소 계 ) | K25: =D25*J25 -> 0
B26: ( 순 공 사 비 계 ) | K26: =D26*J26 -> 0
A27: 일 반 관 리 비 | E27: (재료+노무+경비) * 6.5 % | H27: =D7+D10+D25 -> 0 | I27: 6.5 | J27: 1 | K27: =D27*J27 -> 0
A28: 이 윤 | E28: (노무+경비+일반관리비) * 15 % | I28: 15 | J28: 1 | K28: =D28*J28 -> 0 | L28: =TRUNC((D10+D25+D27)*I28/100) -> 0 | M28: 100000
A29: ( 총 원 가 ) | K29: =D29*J29 -> 0
A30: 부 가 가 치 세 | I30: 10 | J30: 1 | K30: =D30*J30 -> 0
A31: 한 전 수 탁 비 | J31: 1 | K31: =D31*J31 -> 0
K32: =D32*J32 -> 0
K33: =D33*J33 -> 0
K34: =D34*J34 -> 0
A35: ( 총 계 ) | K35: =SUM(K5:K34) -> 0

Sheet 총괄표
A1: 총줄수-> | B1: 81 | C1: 2.0 | D1: [ 화성 청원지구 전기공사 ] | AA1: 연속견적가로형식
A2: 번호 | B2: 공종코드 | C2: … | D2: 공 종 명 | E2: 규격 | F2: 단위 | G2: 수량 | H2: 재료비 | J2: 노무비 | M2: 경비 | P2: 계 | Q2: 비고
H3: 단가 | I3: 금액 | J3: 수량 | K3: 단가 | L3: 금액 | M3: 단가 | N3: 금액 | O3: 단가
B4: 공종줄 | D4: [화성 청원지구 전기공사]
B5: 001 | D5: 1. 전기공사 (지구내) | F5: 식 | G5: 1 | H5: =총괄표!I55 -> 0 | I5: =G5*H5 -> 0 | K5: =총괄표!L55 -> 0 | L5: =G5*K5 -> 0 | M5: =총괄표!N55 -> 0 | N5: =G5*M5 -> 0 | P5: =SUM(I5,L5,N5) -> 0
I7: =G7*H7 -> 0 | L7: =G7*K7 -> 0 | N7: =G7*M7 -> 0 | P7: =SUM(I7,L7,N7) -> 0
I8: =G8*H8 -> 0 | L8: =G8*K8 -> 0 | N8: =G8*M8 -> 0 | P8: =SUM(I8,L8,N8) -> 0
I9: =G9*H9 -> 0 | L9: =G9*K9 -> 0 | N9: =G9*M9 -> 0 | P9: =SUM(I9,L9,N9) -> 0
I10: =G10*H10 -> 0 | L10: =G10*K10 -> 0 | N10: =G10*M10 -> 0 | P10: =SUM(I10,L10,N10) -> 0
I11: =G11*H11 -> 0 | L11: =G11*K11 -> 0 | N11: =G11*M11 -> 0 | P11: =SUM(I11,L11,N11) -> 0
I12: =G12*H12 -> 0 | L12: =G12*K12 -> 0 | N12: =G12*M12 -> 0 | P12: =SUM(I12,L12,N12) -> 0
I13: =G13*H13 -> 0 | L13: =G13*K13 -> 0 | N13: =G13*M13 -> 0 | P13: =SUM(I13,L13,N13) -> 0
I14: =G14*H14 -> 0 | L14: =G14*K14 -> 0 | N14: =G14*M14 -> 0 | P14: =SUM(I14,L14,N14) -> 0
I15: =G15*H15 -> 0 | L15: =G15*K15 -> 0 | N15: =G15*M15 -> 0 | P15: =SUM(I15,L15,N15) -> 0
I16: =G16*H16 -> 0 | L16: =G16*K16 -> 0 | N16: =G16*M16 -> 0 | P16: =SUM(I16,L16,N16) -> 0
I17: =G17*H17 -> 0 | L17: =G17*K17 -> 0 | N17: =G17*M17 -> 0 | P17: =SUM(I17,L17,N17) -> 0
I18: =G18*H18 -> 0 | L18: =G18*K18 -> 0 | N18: =G18*M18 -> 0 | P18: =SUM(I18,L18,N18) -> 0
... I28: =G28*H28 -> 0 | L28: =G28*K28 -> 0 | N28: =G28*M28 -> 0 | P28: =SUM(I28,L28,N28) -> 0
C29: Total | D29: ( 합 계 ) | I29: =TRUNC(SUM(I4:I28)) -> 0 | L29: =TRUNC(SUM(L4:L28)) -> 0 | N29: =TRUNC(SUM(N4:N28)) -> 0 | P29: =TRUNC(SUM(P4:P28)) -> 0
B30: 공종줄 | D30: 1.전기공사 (지구내)
B31: 00101 | D31: 1-1.가로등설비공사 | F31: 식 | G31: 1 | H31: =내역서!I55 -> 0 | I31: =G31*H31 -> 0 | K31: =내역서!L55 -> 0 | L31: =G31*K31 -> 0 | M31: =내역서!N55 -> 0 | N31: =G31*M31 -> 0 | P31: =SUM(I31,L31,N31) -> 0
B32: 00102 | D32: 1-2.공원등설비공사 | F32: 식 | G32: 1 | H32: =내역서!I107 -> 0 | I32: =G32*H32 -> 0 | K32: =내역서!L107 -> 0 | L32: =G32*K32 -> 0 | M32: =내역서!N107 -> 0 | N32: =G32*M32 -> 0 | P32: =SUM(I32,L32,N32) -> 0
B33: 00103 | D33: 1-3.신호등설비공사 | F33: 식 | G33: 1 | H33: =내역서!I133 -> 0 | I33: =G33*H33 -> 0 | K33: =내역서!L133 -> 0 | L33: =G33*K33 -> 0 | M33: =내역서!N133 -> 0 | N33: =G33*M33 -> 0 | P33: =SUM(I33,L33,N33) -> 0
B34: 00104 | D34: 1-4.공원 통신설비 공사 | F34: 식 | G34: 1 | H34: =내역서!I185 -> 0 | I34: =G34*H34 -> 0 | K34: =내역서!L185 -> 0 | L34: =G34*K34 -> 0 | M34: =내역서!N185 -> 0 | N34: =G34*M34 -> 0 | P34: =SUM(I34,L34,N34) -> 0
B35: 00105 | D35: 1-5.불법주정차단속시스템 | F35: 식 | G35: 1 | H35: =내역서!I211 -> 0 | I35: =G35*H35 -> 0 | K35: =내역서!L211 -> 0 | L35: =G35*K35 -> 0 | M35: =내역서!N211 -> 0 | N35: =G35*M35 -> 0 | P35: =SUM(I35,L35,N35) -> 0
I36: =G36*H36 -> 0 | L36: =G36*K36 -> 0 | N36: =G36*M36 -> 0 | P36: =SUM(I36,L36,N36) -> 0
I37: =G37*H37 -> 0 | L37: =G37*K37 -> 0 | N37: =G37*M37 -> 0 | P37: =SUM(I37,L37,N37) -> 0
I38: =G38*H38 -> 0 | L38: =G38*K38 -> 0 | N38: =G38*M38 -> 0 | P38: =SUM(I38,L38,N38) -> 0
I39: =G39*H39 -> 0 | L39: =G39*K39 -> 0 | N39: =G39*M39 -> 0 | P39: =SUM(I39,L39,N39) -> 0
I40: =G40*H40 -> 0 | L40: =G40*K40 -> 0 | N40: =G40*M40 -> 0 | P40: =SUM(I40,L40,N40) -> 0
I41: =G41*H41 -> 0 | L41: =G41*K41 -> 0 | N41: =G41*M41 -> 0 | P41: =SUM(I41,L41,N41) -> 0
I42: =G42*H42 -> 0 | L42: =G42*K42 -> 0 | N42: =G42*M42 -> 0 | P42: =SUM(I42,L42,N42) -> 0
I43: =G43*H43 -> 0 | L43: =G43*K43 -> 0 | N43: =G43*M43 -> 0 | P43: =SUM(I43,L43,N43) -> 0
I44: =G44*H44 -> 0 | L44: =G44*K44 -> 0 | N44: =G44*M44 -> 0 | P44: =SUM(I44,L44,N44) -> 0
I45: =G45*H45 -> 0 | L45: =G45*K45 -> 0 | N45: =G45*M45 -> 0 | P45: =SUM(I45,L45,N45) -> 0
I46: =G46*H46 -> 0 | L46: =G46*K46 -> 0 | N46: =G46*M46 -> 0 | P46: =SUM(I46,L46,N46) -> 0
I47: =G47*H47 -> 0 | L47: =G47*K47 -> 0 | N47: =G47*M47 -> 0 | P47: =SUM(I47,L47,N47) -> 0
... I54: =G54*H54 -> 0 | L54: =G54*K54 -> 0 | N54: =G54*M54 -> 0 | P54: =SUM(I54,L54,N54) -> 0
B55: 001 | C55: Total | D55: ( 합 계 ) | I55: =TRUNC(SUM(I30:I54)) -> 0 | L55: =TRUNC(SUM(L30:L54)) -> 0 | N55: =TRUNC(SUM(N30:N54)) -> 0 | P55: =TRUNC(SUM(P30:P54)) -> 0
B56: 공종줄 | D56: 2.전기공사 (지구외)
...

Sheet 내역서
A1: 총줄수-> | B1: 341 | C1: 2.0 | D1: [ 화성 청원지구 전기공사 ] | W1: 노임 계산 정보 | AA1: 부속재 및 손료
A2: 번호 | B2: 공종코드 | C2: 코드 | D2: 명 칭 | E2: 규 격 | F2: 단위 | G2: 수량 | H2: 재료비 | J2: 노무비 | M2: 경비 | P2: 계 | Q2: 비고 | W2: 노임계 | X2: 전체(%) | Y2: 공종별(%) | Z2: 노임 소수 | AA2: CD배관재 | AB2: 일반배관재 | AC2: 소모재 | AD2: 자재계 | AE2: 노임계
H3: 단가 | I3: 금액 | J3: 수량 | K3: 단가 | L3: 금액 | M3: 단가 | N3: 금액 | O3: 단가 | AD3: =IF(#REF! =0, "1",#REF!) -> #REF! | AE3: =IF(#REF! =0, "1",#REF!) -> #REF!
B4: 공종줄 | D4: 1.전기공사 (지구내)::1-1.가로등설비공사
A5: 5975D077002 | B5: 00101 | C5: E59753077002 | D5: 파상형 폴리에틸렌 전선관 | E5: 40㎜(가로등,신호,구내) | F5: m | G5: 2061 | Q5: 제 11호 | AB5: =G5*H5 -> 0 | AC5: =G5*H5 -> 0
A6: 5975D077003 | B6: 00101 | C6: ECI31100030S | D6: 파상형 폴리에틸렌 전선관 | E6: 50㎜(가로등,신호,구내) | F6: m | G6: 105 | Q6: 제 12호 | AB6: =G6*H6 -> 0 | AC6: =G6*H6 -> 0
A7: E145A927203 | B7: 00101 | C7: EE1450927203 | D7: 접지용비닐절연전선(F-GV)_지중 | E7: 6㎟ | F7: m | G7: 35 | Q7: 제 19호 | AC7: =G7*H7 -> 0
A8: E145A927204 | B8: 00101 | C8: EE1450927204 | D8: 접지용비닐절연전선(F-GV) | E8: 10㎟ | F8: m | G8: 2157 | Q8: 제 20호 | AC8: =G8*H8 -> 0
A9: E145A927205 | B9: 00101 | C9: EE1450927205 | D9: 접지용비닐절연전선(F-GV) | E9: 16㎟ | F9: m | G9: 39 | Q9: 제 21호 | AC9: =G9*H9 -> 0
A10: E145A287521 | B10: 00101 | C10: EE1450287521 | D10: 폴리에틸렌 난연케이블 | E10: 0.6/1kv F-CV 2C×2.5㎟ | F10: m | G10: 780 | Q10: 제 22호 | AC10: =G10*H10 -> 0
A11: GG450287521 | B11: 00101 | C11: 2612162921683904 | D11: 폴리에틸렌 난연케이블(옥외) | E11: 0.6/1kv F-CV 2C×10㎟ | F11: m | G11: 487 | AC11: =G11*H11 -> 0
A12: GG450287523 | B12: 00101 | C12: 2612162921683906 | D12: 폴리에틸렌 난연케이블(옥외) | E12: 0.6/1kv F-CV 2C×25㎟ | F12: m | G12: 105 | AC12: =G12*H12 -> 0
A13: GG450287551 | B13: 00101 | C13: 2612162921683946 | D13: 폴리에틸렌 난연케이블(옥외) | E13: 0.6/1kv F-CV 4C×10㎟ | F13: m | G13: 1565 | AC13: =G13*H13 -> 0
A14: GG450287553 | B14: 00101 | C14: 2612162921683948 | D14: 폴리에틸렌 난연케이블(옥외) | E14: 0.6/1kv F-CV 4C×25㎟ | F14: m | G14: 105 | AC14: =G14*H14 -> 0
A15: 5975A427102 | B15: 00101 | C15: E59750427102 | D15: 접지봉 | E15: 14Φ×1000 mm | F15: 개 | G15: 14 | Q15: 제 27호
A16: E975A427014 | B16: 00101 | C16: EE9750427014 | D16: 접지크램프(IEC 90) | E16: 16sq | F16: 개 | G16: 16 | Q16: 제 28호
A17: 56959000004 | B17: 00101 | C17: EMM300041326 | D17: 케이블표지시트 | E17: 0.23x400 | F17: m | G17: 2005 | Q17: 제 29호
A18: E940A267007 | B18: 00101 | C18: EE9400267007 | D18: 압착단자 | E18: R형동선 나압착 25 ㎟ | F18: 개 | G18: 24 | Q18: 제 31호
A19: 56950010201 | B19: 00101 | C19: EBP110110000 | D19: 가로등 건주 기계화 시공 | E19: 일반 5m-7m | F19: 식 | G19: 2 | Q19: 제 6호
A20: 56950010203 | B20: 00101 | C20: EBP110130000 | D20: 가로등 건주 기계화 시공 | E20: 일반 10m-12m | F20: 식 | G20: 43 | Q20: 제 7호
A21: 56930220040 | B21: 00101 | C21: ABB103100000 | D21: 터파기(기계90%,인력10%) | E21: 보통토사 | F21: ㎥ | G21: 794.591 | Q21: 제 1호
A22: 56930220053 | B22: 00101 | C22: ABB104100000 | D22: 되메우기(기계90%,인력10%) | E22: 보통토사 | F22: ㎥ | G22: 767.46 | Q22: 제 2호
A23: 56930220102 | B23: 00101 | C23: ABC112700000 | D23: 인력잔토처리 | E23: 현장처리 | F23: ㎥ | G23: 27.131 | Q23: 제 3호
A24: 56959000005 | B24: 00101 | C24: EMM408901996 | D24: 전주용입상관 | E24: Φ130*2t*2m | F24: EA | G24: 4 | Q24: 제 35호
A25: MM408901997 | B25: 00101 | C25: 391190ZZ701Z0100 | D25: 반경관취부밴드 | F25: EA | G25: 12
A26: 56959000010 | B26: 00101 | C26: EMM666919040 | D26: 케이블 포설(가로등) | E26: 10㎟/2C*1열 | F26: m | G26: 473 | Q26: 제 40호 | AC26: =G26*H26 -> 0
A27: 56959000012 | B27: 00101 | C27: EMM666919042 | D27: 케이블 포설(가로등) | E27: 25㎟/2C*1열 | F27: m | G27: 114 | Q27: 제 42호 | AC27: =G27*H27 -> 0
A28: GM42C520962 | B28: 00101 | C28: EGM422520962 | D28: 케이블 포설(가로등) | E28: 10㎟/4C*1열 | F28: m | G28: 1520 | Q28: 제 45호 | AC28: =G28*H28 -> 0
A29: GM90A002029 | B29: 00101 | C29: EGM900002029 | D29: 케이블 포설(가로등) | E29: 25㎟/4C*1열 | F29: m | G29: 102 | Q29: 제 46호 | AC29: =G29*H29 -> 0
A30: 56959000014 | B30: 00101 | C30: EMM868935935 | D30: LED 가로등기구 | E30: 100W급 | F30: 개 | G30: 43 | Q30: 제 47호
A31: 56959000015 | B31: 00101 | C31: EMM992900263 | D31: LED 공원등기구 | E31: 50W급(A타입) | F31: 개 | G31: 2 | Q31: 제 48호
A32: 56959000017 | B32: 00101 | C32: EMM992900278 | D32: 가로등기초(직각)기성품 | E32: 500X850X675X700 | F32: 개 | G32: 2 | Q32: 제 50호
A33: 56959000018 | B33: 00101 | C33: EMM811566471 | D33: 가로등기초 | E33: 500x775x1050x1100(E) | F33: 개 | G33: 43 | Q33: 제 51호
A34: 56959000019 | B34: 00101 | C34: EMM811377544 | D34: 가로등 제어반 | E34: 6회로 | F34: 개 | G34: 2 | Q34: 제 52호
A35: MM811377553 | B35: 00101 | C35: 391115ZZ701Z0008 | D35: 가로등주 | E35: 원형테퍼 강관주 10m -1등용 | F35: 개 | G35: 43
A36: 56959000021 | B36: 00101 | C36: EMM811561481 | D36: 가로등 표찰 | E36: STS | F36: 개 | G36: 45 | Q36: 제 54호
A37: 56959000022 | B37: 00101 | C37: EMM992900295 | D37: 공원등주 | E37: 5m-1.0m 1등용(A타입) | F37: 개 | G37: 2 | Q37: 제 55호
A38: 56959000025 | B38: 00101 | C38: EMM811561499 | D38: 방수형 접속함 | E38: 1등용,ELB부 | F38: 개 | G38: 45 | Q38: 제 58호
A39: MM811561501 | B39: 00101 | C39: 391115ZZ701Z0023 | D39: 방수형 접속함 | E39: 격등용 | F39: 개 | G39: 34
A40: MM811567758 | B40: 00101 | C40: 391115ZZ701Z0024 | D40: 백호우 | E40: 0.4㎥ | F40: hr | G40: 21
...
