Workbook

Sheet 원가
A1: 원 가 계 산 서
A3: 공사명: | C3: 화성 청원지구 전기공사_(지구내) | E3: 공사기간: 32 개월
A4: 비 목 | C4: 구 분 | D4: 금 액 | E4: 구 성 비 | I4: 요율 | J4: 수량 | K4: 금액 | L4: 이윤 | M4: 끝자리 맞추기
B5: 재 료 비 | C5: 직 접 재 료 비 | D5: =옵션!$B$2 -> 0 | J5: 1 | K5: =D5*J5 -> 0
C6: 간 접 재 료 비 | K6: =D6*J6 -> 0
C7: ( 소 계 ) | D7: =SUM(D5:D6) -> 0 | K7: =D7*J7 -> 0
A8: 순 | B8: 노 무 비 | C8: 직 접 노 무 비 | D8: =옵션!$C$2 -> 0 | J8: 1 | K8: =D8*J8 -> 0
C9: 간 접 노 무 비 | D9: =TRUNC(D8*I9/100) -> 0 | E9: (직접 노무비) * 16.7 % | I9: 16.7 | J9: 1 | K9: =D9*J9 -> 0
C10: ( 소 계 ) | D10: =SUM(D8:D9) -> 0 | K10: =D10*J10 -> 0
C11: 기 계 경 비 | D11: =옵션!$D$2 -> 0 | J11: 1 | K11: =D11*J11 -> 0
C12: 산 재 보 험 료 | D12: =TRUNC(D10*I12/100) -> 0 | E12: (노무비) * 3.56 % | I12: 3.56 | J12: 1 | K12: =D12*J12 -> 0
A13: 공 | C13: 고 용 보 험 료 | D13: =TRUNC(D10*I13/100) -> 0 | E13: (노무비) * 1.01 % | I13: 1.01 | J13: 1 | K13: =D13*J13 -> 0
B14: 경 | C14: 퇴 직 금 공 제 | D14: =TRUNC(D8*I14/100) -> 0 | E14: (직접 노무비) * 2.3 % | I14: 2.3 | J14: 1 | K14: =D14*J14 -> 0
C15: 안 전 관 리 비 | D15: =TRUNC((D7+D8)*I15/100) -> 0 | E15: (재료+직노) * 2.07 % | I15: 2.07 | J15: 1 | K15: =D15*J15 -> 0
C16: 기 타 경 비 | D16: =TRUNC((D7+D10)*I16/100) -> 0 | E16: (재료+노무) * 5.3 % | H16: =D7+D10 -> 0 | I16: 5.3 | J16: 1 | K16: =D16*J16 -> 0
C17: 건 강 보 험 료 | D17: =TRUNC(D8*I17/100) -> 0 | E17: (직접 노무비) * 3.595 % | I17: 3.595 | J17: 1 | K17: =D17*J17 -> 0
A18: 사 | C18: 연 금 보 험 료 | D18: =TRUNC(D8*I18/100) -> 0 | E18: (직접 노무비) * 4.75 % | I18: 4.75 | J18: 1 | K18: =D18*J18 -> 0
C19: 노인장기요양보험 | D19: =TRUNC(D17*I19/100) -> 0 | E19: (건강 보험료) * 13.14 % | I19: 13.14 | J19: 1 | K19: =D19*J19 -> 0
C20: 석면분담금 | D20: =TRUNC(D10*I20/100) -> 0 | E20: (노무비) * 0.006 % | I20: 0.006 | J20: 1 | K20: =D20*J20 -> 0
C21: 임금채권부담금 | D21: =TRUNC(D10*I21/100) -> 0 | E21: (노무비) * 0.09 % | I21: 0.09 | J21: 1 | K21: =D21*J21 -> 0
B22: 비 | K22: =D22*J22 -> 0
A23: 비 | K23: =D23*J23 -> 0
K24: =D24*J24 -> 0
C25: ( 소 계 ) | D25: =SUM(D11:D24) -> 0 | K25: =D25*J25 -> 0
B26: ( 순 공 사 비 계 ) | D26: =D7+D10+D25 -> 0 | K26: =D26*J26 -> 0
A27: 일 반 관 리 비 | D27: =TRUNC((D7+D10+D25)*I27/100) -> 0 | E27: (재료+노무+경비) * 6.5 % | H27: =D7+D10+D25 -> 0 | I27: 6.5 | J27: 1 | K27: =D27*J27 -> 0
A28: 이 윤 | D28: =L28-((SUM(K5:K27)+L28-TRUNC((SUM(K5:K27)+L28)/M28)*M28)) -> 0 | E28: (노무+경비+일반관리비) * 15 % | I28: 15 | J28: 1 | K28: =D28*J28 -> 0 | L28: =TRUNC((D10+D25+D27)*I28/100) -> 0 | M28: 100000
A29: ( 총 원 가 ) | D29: =SUM(K5:K28) -> 0 | K29: =D29*J29 -> 0
A30: 부 가 가 치 세 | D30: =TRUNC(D29*I30/100) -> 0 | I30: 10 | J30: 1 | K30: =D30*J30 -> 0
A31: 한 전 수 탁 비 | D31: ='한전인입공사비 (지구내)'!H25 -> 5131000 | J31: 1 | K31: =D31*J31 -> 5131000
K32: =D32*J32 -> 0
K33: =D33*J33 -> 0
K34: =D34*J34 -> 0
A35: ( 총 계 ) | D35: =K35 -> 5131000 | K35: =SUM(K5:K34) -> 5131000

Sheet 총괄표
A1: 총줄수-> | B1: 81 | C1: 2.0 | D1: [ 화성 청원지구 전기공사 ] | AA1: 연속견적가로형식
A2: 번호 | B2: 공종코드 | C2: … | D2: 공 종 명 | E2: 규격 | F2: 단위 | G2: 수량 | H2: 재료비 | J2: 노무비 | M2: 경비 | P2: 계 | Q2: 비고
H3: 단가 | I3: 금액 | J3: 수량 | K3: 단가 | L3: 금액 | M3: 단가 | N3: 금액 | O3: 단가
B4: 공종줄 | D4: [화성 청원지구 전기공사]
B5: 001 | D5: 1. 전기공사 (지구내) | F5: 식 | G5: 1 | H5: =총괄표!I55 -> 0 | I5: =G5*H5 -> 0 | K5: =총괄표!L55 -> 0 | L5: =G5*K5 -> 0 | M5: =총괄표!N55 -> 0 | N5: =G5*M5 -> 0 | P5: =SUM(I5,L5,N5) -> 0
I7: =G7*H7 -> 0 | L7: =G7*K7 -> 0 | N7: =G7*M7 -> 0 | P7: =SUM(I7,L7,N7) -> 0
I8: =G8*H8 -> 0 | L8: =G8*K8 -> 0 | N8: =G8*M8 -> 0 | P8: =SUM(I8,L8,N8) -> 0
I9: =G9*H9 -> 0 | L9: =G9*K9 -> 0 | N9: =G9*M9 -> 0 | P9: =SUM(I9,L9,N9) -> 0
I10: =G10*H10 -> 0 | L10: =G10*K10 -> 0 | N10: =G10*M10 -> 0 | P10: =SUM(I10,L10,N10) -> 0
I11: =G11*H11 -> 0 | L11: =G11*K11 -> 0 | N11: =G11*M11 -> 0 | P11: =SUM(I11,L11,N11) -> 0
I12: =G12*H12 -> 0 | L12: =G12*K12 -> 0 | N12: =G12*M12 -> 0 | P12: =SUM(I12,L12,N12) -> 0
I13: =G13*H13 -> 0 | L13: =G13*K13 -> 0 | N13: =G13*M13 -> 0 | P13: =SUM(I13,L13,N13) -> 0
I14: =G14*H14 -> 0 | L14: =G14*K14 -> 0 | N14: =G14*M14 -> 0 | P14: =SUM(I14,L14,N14) -> 0
I15: =G15*H15 -> 0 | L15: =G15*K15 -> 0 | N15: =G15*M15 -> 0 | P15: =SUM(I15,L15,N15) -> 0
I16: =G16*H16 -> 0 | L16: =G16*K16 -> 0 | N16: =G16*M16 -> 0 | P16: =SUM(I16,L16,N16) -> 0
I17: =G17*H17 -> 0 | L17: =G17*K17 -> 0 | N17: =G17*M17 -> 0 | P17: =SUM(I17,L17,N17) -> 0
I18: =G18*H18 -> 0 | L18: =G18*K18 -> 0 | N18: =G18*M18 -> 0 | P18: =SUM(I18,L18,N18) -> 0
... I28: =G28*H28 -> 0 | L28: =G28*K28 -> 0 | N28: =G28*M28 -> 0 | P28: =SUM(I28,L28,N28) -> 0
C29: Total | D29: ( 합 계 ) | I29: =TRUNC(SUM(I4:I28)) -> 0 | L29: =TRUNC(SUM(L4:L28)) -> 0 | N29: =TRUNC(SUM(N4:N28)) -> 0 | P29: =TRUNC(SUM(P4:P28)) -> 0
B30: 공종줄 | D30: 1.전기공사 (지구내)
B31: 00101 | D31: 1-1.가로등설비공사 | F31: 식 | G31: 1 | H31: =내역서!I55 -> 0 | I31: =G31*H31 -> 0 | K31: =내역서!L55 -> 0 | L31: =G31*K31 -> 0 | M31: =내역서!N55 -> 0 | N31: =G31*M31 -> 0 | P31: =SUM(I31,L31,N31) -> 0
B32: 00102 | D32: 1-2.공원등설비공사 | F32: 식 | G32: 1 | H32: =내역서!I107 -> 0 | I32: =G32*H32 -> 0 | K32: =내역서!L107 -> 0 | L32: =G32*K32 -> 0 | M32: =내역서!N107 -> 0 | N32: =G32*M32 -> 0 | P32: =SUM(I32,L32,N32) -> 0
B33: 00103 | D33: 1-3.신호등설비공사 | F33: 식 | G33: 1 | H33: =내역서!I133 -> 0 | I33: =G33*H33 -> 0 | K33: =내역서!L133 -> 0 | L33: =G33*K33 -> 0 | M33: =내역서!N133 -> 0 | N33: =G33*M33 -> 0 | P33: =SUM(I33,L33,N33) -> 0
B34: 00104 | D34: 1-4.공원 통신설비 공사 | F34: 식 | G34: 1 | H34: =내역서!I185 -> 0 | I34: =G34*H34 -> 0 | K34: =내역서!L185 -> 0 | L34: =G34*K34 -> 0 | M34: =내역서!N185 -> 0 | N34: =G34*M34 -> 0 | P34: =SUM(I34,L34,N34) -> 0
B35: 00105 | D35: 1-5.불법주정차단속시스템 | F35: 식 | G35: 1 | H35: =내역서!I211 -> 0 | I35: =G35*H35 -> 0 | K35: =내역서!L211 -> 0 | L35: =G35*K35 -> 0 | M35: =내역서!N211 -> 0 | N35: =G35*M35 -> 0 | P35: =SUM(I35,L35,N35) -> 0
I36: =G36*H36 -> 0 | L36: =G36*K36 -> 0 | N36: =G36*M36 -> 0 | P36: =SUM(I36,L36,N36) -> 0
I37: =G37*H37 -> 0 | L37: =G37*K37 -> 0 | N37: =G37*M37 -> 0 | P37: =SUM(I37,L37,N37) -> 0
I38: =G38*H38 -> 0 | L38: =G38*K38 -> 0 | N38: =G38*M38 -> 0 | P38: =SUM(I38,L38,N38) -> 0
I39: =G39*H39 -> 0 | L39: =G39*K39 -> 0 | N39: =G39*M39 -> 0 | P39: =SUM(I39,L39,N39) -> 0
I40: =G40*H40 -> 0 | L40: =G40*K40 -> 0 | N40: =G40*M40 -> 0 | P40: =SUM(I40,L40,N40) -> 0
I41: =G41*H41 -> 0 | L41: =G41*K41 -> 0 | N41: =G41*M41 -> 0 | P41: =SUM(I41,L41,N41) -> 0
I42: =G42*H42 -> 0 | L42: =G42*K42 -> 0 | N42: =G42*M42 -> 0 | P42: =SUM(I42,L42,N42) -> 0
I43: =G43*H43 -> 0 | L43: =G43*K43 -> 0 | N43: =G43*M43 -> 0 | P43: =SUM(I43,L43,N43) -> 0
I44: =G44*H44 -> 0 | L44: =G44*K44 -> 0 | N44: =G44*M44 -> 0 | P44: =SUM(I44,L44,N44) -> 0
I45: =G45*H45 -> 0 | L45: =G45*K45 -> 0 | N45: =G45*M45 -> 0 | P45: =SUM(I45,L45,N45) -> 0
I46: =G46*H46 -> 0 | L46: =G46*K46 -> 0 | N46: =G46*M46 -> 0 | P46: =SUM(I46,L46,N46) -> 0
I47: =G47*H47 -> 0 | L47: =G47*K47 -> 0 | N47: =G47*M47 -> 0 | P47: =SUM(I47,L47,N47) -> 0
... I54: =G54*H54 -> 0 | L54: =G54*K54 -> 0 | N54: =G54*M54 -> 0 | P54: =SUM(I54,L54,N54) -> 0
B55: 001 | C55: Total | D55: ( 합 계 ) | I55: =TRUNC(SUM(I30:I54)) -> 0 | L55: =TRUNC(SUM(L30:L54)) -> 0 | N55: =TRUNC(SUM(N30:N54)) -> 0 | P55: =TRUNC(SUM(P30:P54)) -> 0
B56: 공종줄 | D56: 2.전기공사 (지구외)
...

Sheet 내역서
A1: 총줄수-> | B1: 341 | C1: 2.0 | D1: [ 화성 청원지구 전기공사 ] | W1: 노임 계산 정보 | AA1: 부속재 및 손료
A2: 번호 | B2: 공종코드 | C2: 코드 | D2: 명 칭 | E2: 규 격 | F2: 단위 | G2: 수량 | H2: 재료비 | J2: 노무비 | M2: 경비 | P2: 계 | Q2: 비고 | W2: 노임계 | X2: 전체(%) | Y2: 공종별(%) | Z2: 노임 소수 | AA2: CD배관재 | AB2: 일반배관재 | AC2: 소모재 | AD2: 자재계 | AE2: 노임계
H3: 단가 | I3: 금액 | J3: 수량 | K3: 단가 | L3: 금액 | M3: 단가 | N3: 금액 | O3: 단가 | AD3: =IF(옵션!$C$11 =0, "1", 옵션!$C$11) -> 1 | AE3: =IF(옵션!$C$12 =0, "1", 옵션!$C$12) -> 1
B4: 공종줄 | D4: 1.전기공사 (지구내)::1-1.가로등설비공사
A5: 5975D077002 | B5: 00101 | C5: E59753077002 | D5: 파상형 폴리에틸렌 전선관 | E5: 40㎜(가로등,신호,구내) | F5: m | G5: 2061 | Q5: 제 11호 | AB5: =G5*H5 -> 0 | AC5: =G5*H5 -> 0
A6: 5975D077003 | B6: 00101 | C6: ECI31100030S | D6: 파상형 폴리에틸렌 전선관 | E6: 50㎜(가로등,신호,구내) | F6: m | G6: 105 | Q6: 제 12호 | AB6: =G6*H6 -> 0 | AC6: =G6*H6 -> 0
A7: E145A927203 | B7: 00101 | C7: EE1450927203 | D7: 접지용비닐절연전선(F-GV)_지중 | E7: 6㎟ | F7: m | G7: 35 | Q7: 제 19호 | AC7: =G7*H7 -> 0
A8: E145A927204 | B8: 00101 | C8: EE1450927204 | D8: 접지용비닐절연전선(F-GV) | E8: 10㎟ | F8: m | G8: 2157 | Q8: 제 20호 | AC8: =G8*H8 -> 0
A9: E145A927205 | B9: 00101 | C9: EE1450927205 | D9: 접지용비닐절연전선(F-GV) | E9: 16㎟ | F9: m | G9: 39 | Q9: 제 21호 | AC9: =G9*H9 -> 0
A10: E145A287521 | B10: 00101 | C10: EE1450287521 | D10: 폴리에틸렌 난연케이블 | E10: 0.6/1kv F-CV 2C×2.5㎟ | F10: m | G10: 780 | Q10: 제 22호 | AC10: =G10*H10 -> 0
A11: GG450287521 | B11: 00101 | C11: 2612162921683904 | D11: 폴리에틸렌 난연케이블(옥외) | E11: 0.6/1kv F-CV 2C×10㎟ | F11: m | G11: 487 | AC11: =G11*H11 -> 0
A12: GG450287523 | B12: 00101 | C12: 2612162921683906 | D12: 폴리에틸렌 난연케이블(옥외) | E12: 0.6/1kv F-CV 2C×25㎟ | F12: m | G12: 105 | AC12: =G12*H12 -> 0
A13: GG450287551 | B13: 00101 | C13: 2612162921683946 | D13: 폴리에틸렌 난연케이블(옥외) | E13: 0.6/1kv F-CV 4C×10㎟ | F13: m | G13: 1565 | AC13: =G13*H13 -> 0
A14: GG450287553 | B14: 00101 | C14: 2612162921683948 | D14: 폴리에틸렌 난연케이블(옥외) | E14: 0.6/1kv F-CV 4C×25㎟ | F14: m | G14: 105 | AC14: =G14*H14 -> 0
A15: 5975A427102 | B15: 00101 | C15: E59750427102 | D15: 접지봉 | E15: 14Φ×1000 mm | F15: 개 | G15: 14 | Q15: 제 27호
A16: E975A427014 | B16: 00101 | C16: EE9750427014 | D16: 접지크램프(IEC 90) | E16: 16sq | F16: 개 | G16: 16 | Q16: 제 28호
A17: 56959000004 | B17: 00101 | C17: EMM300041326 | D17: 케이블표지시트 | E17: 0.23x400 | F17: m | G17: 2005 | Q17: 제 29호
A18: E940A267007 | B18: 00101 | C18: EE9400267007 | D18: 압착단자 | E18: R형동선 나압착 25 ㎟ | F18: 개 | G18: 24 | Q18: 제 31호
A19: 56950010201 | B19: 00101 | C19: EBP110110000 | D19: 가로등 건주 기계화 시공 | E19: 일반 5m-7m | F19: 식 | G19: 2 | Q19: 제 6호
A20: 56950010203 | B20: 00101 | C20: EBP110130000 | D20: 가로등 건주 기계화 시공 | E20: 일반 10m-12m | F20: 식 | G20: 43 | Q20: 제 7호
A21: 56930220040 | B21: 00101 | C21: ABB103100000 | D21: 터파기(기계90%,인력10%) | E21: 보통토사 | F21: ㎥ | G21: 794.591 | Q21: 제 1호
A22: 56930220053 | B22: 00101 | C22: ABB104100000 | D22: 되메우기(기계90%,인력10%) | E22: 보통토사 | F22: ㎥ | G22: 767.46 | Q22: 제 2호
A23: 56930220102 | B23: 00101 | C23: ABC112700000 | D23: 인력잔토처리 | E23: 현장처리 | F23: ㎥ | G23: 27.131 | Q23: 제 3호
A24: 56959000005 | B24: 00101 | C24: EMM408901996 | D24: 전주용입상관 | E24: Φ130*2t*2m | F24: EA | G24: 4 | Q24: 제 35호
A25: MM408901997 | B25: 00101 | C25: 391190ZZ701Z0100 | D25: 반경관취부밴드 | F25: EA | G25: 12
A26: 56959000010 | B26: 00101 | C26: EMM666919040 | D26: 케이블 포설(가로등) | E26: 10㎟/2C*1열 | F26: m | G26: 473 | Q26: 제 40호 | AC26: =G26*H26 -> 0
A27: 56959000012 | B27: 00101 | C27: EMM666919042 | D27: 케이블 포설(가로등) | E27: 25㎟/2C*1열 | F27: m | G27: 114 | Q27: 제 42호 | AC27: =G27*H27 -> 0
A28: GM42C520962 | B28: 00101 | C28: EGM422520962 | D28: 케이블 포설(가로등) | E28: 10㎟/4C*1열 | F28: m | G28: 1520 | Q28: 제 45호 | AC28: =G28*H28 -> 0
A29: GM90A002029 | B29: 00101 | C29: EGM900002029 | D29: 케이블 포설(가로등) | E29: 25㎟/4C*1열 | F29: m | G29: 102 | Q29: 제 46호 | AC29: =G29*H29 -> 0
A30: 56959000014 | B30: 00101 | C30: EMM868935935 | D30: LED 가로등기구 | E30: 100W급 | F30: 개 | G30: 43 | Q30: 제 47호
A31: 56959000015 | B31: 00101 | C31: EMM992900263 | D31: LED 공원등기구 | E31: 50W급(A타입) | F31: 개 | G31: 2 | Q31: 제 48호
A32: 56959000017 | B32: 00101 | C32: EMM992900278 | D32: 가로등기초(직각)기성품 | E32: 500X850X675X700 | F32: 개 | G32: 2 | Q32: 제 50호
A33: 56959000018 | B33: 00101 | C33: EMM811566471 | D33: 가로등기초 | E33: 500x775x1050x1100(E) | F33: 개 | G33: 43 | Q33: 제 51호
A34: 56959000019 | B34: 00101 | C34: EMM811377544 | D34: 가로등 제어반 | E34: 6회로 | F34: 개 | G34: 2 | Q34: 제 52호
A35: MM811377553 | B35: 00101 | C35: 391115ZZ701Z0008 | D35: 가로등주 | E35: 원형테퍼 강관주 10m -1등용 | F35: 개 | G35: 43
A36: 56959000021 | B36: 00101 | C36: EMM811561481 | D36: 가로등 표찰 | E36: STS | F36: 개 | G36: 45 | Q36: 제 54호
A37: 56959000022 | B37: 00101 | C37: EMM992900295 | D37: 공원등주 | E37: 5m-1.0m 1등용(A타입) | F37: 개 | G37: 2 | Q37: 제 55호
A38: 56959000025 | B38: 00101 | C38: EMM811561499 | D38: 방수형 접속함 | E38: 1등용,ELB부 | F38: 개 | G38: 45 | Q38: 제 58호
A39: MM811561501 | B39: 00101 | C39: 391115ZZ701Z0023 | D39: 방수형 접속함 | E39: 격등용 | F39: 개 | G39: 34
A40: MM811567758 | B40: 00101 | C40: 391115ZZ701Z0024 | D40: 백호우 | E40: 0.4㎥ | F40: hr | G40: 21
...

Sheet 한전인입공사비 (지구내)
A1: ■ 한전인입 공사비
A3: 1. 공사비 산출근거 (한국전력공사 전기공급 약관 별표4 표준공사비 단가표)
A4: 1) 기본공사비 (부가가치세 불포함)
A5: 구 분 | H5: 금 액 | L5: 비 고
H6: 가공공급 | J6: 지중공급
A7: 저 압 | C7: 매 1계약에 대하여 계약전력 5kW까지 | H7: 306000 | J7: 588000
C8: 계약전력 5kW 초과분의 매 1kW에 대하여 | H8: 121000 | J8: 141000
A9: 고압 또는 특별고압 | C9: 신증설 계약전력 매 1kW에 대하여 | H9: 24000 | J9: 50000
A10: 2) 거리공사비 (부가가치세 불포함)
A11: 구 분 | H11: 가공공급 | J11: 지중공급 | L11: 비 고
H12: 단상 | I12: 삼상
A13: 신설거리 공사비 | C13: 기본거리를 초과하는 신설거리 매 1m에 대하여 | G13: 저압 | H13: 48000 | I13: 53000 | J13: 75000
G14: 특별고압 | H14: 53000 | J14: 137000
A15: 첨가거리 공사비 | C15: 기본거리를 초과하는 첨가거리 매 1m에 대하여 | G15: 저압 | H15: 7000 | J15: -
G16: 특별고압 | H16: 12000 | J16: -
A17: 기본거리 : 가공배전선로 (200M), 지중배전선로 (50M)
A18: ■ 한전인입 및 사용전공사비 적용
A19: 구 분 | C19: 개 요 | H19: 소 계 | J19: 비 고
A20: 한전 인입공사비 | C20: 특고압수전 | H20: =K54 -> 0
A21: 한전 인입공사비 | C21: 저압수전 | H21: =K45 -> 4290000
A22: 사용전 검사비 | H22: ='사용전검사비 (지구내)'!K23 -> 841000
A24: 계 | H24: =SUM(H20:H23) -> 5131000 | J24: 부가가치세포함
A25: 적용 | H25: =TRUNC(H24,-3) -> 5131000 | J25: 천단위이하 절사
A26: ■ 한전인입 공사비
A27: 구 분 | B27: 예상수전점 까지의거리 | C27: 시설용량 (kW) | D27: 기본공사비 | J27: 거리공사비 | K27: 소 계 | L27: 비 고
D28: 수전 개소 | E28: 계약전력 5kW까지 | F28: 계약전력 5kW초과분의 매 1kW에 대하여 | I28: 계 | J28: 기본거리 50m (지중), 200m (가공)
A30: [가로등 저압]
A31: 가로등-1 | B31: 50 | C31: 3 | D31: 1 | E31: =$H$7*D31 -> 306000 | F31: =IF(C31>5*D31,C31-5*D31,0) -> 0 | G31: =IF(F31=0,0,$J$8) -> 0 | H31: =F31*G31 -> 0 | I31: =E31+H31 -> 306000 | J31: =IF(L31="가공",IF(B31<200,"0",IF(B31>=200,(B31-200)*$H$14)),IF(L31="지중",IF(B31<50,"0",IF(B31>=50,(B31-50)*$J$13)))) -> 0 | K31: =I31+J31 -> 306000 | L31: 가공
A32: 가로등-2 | B32: 50 | C32: 3 | D32: 1 | E32: =$H$7*D32 -> 306000 | F32: =IF(C32>5*D32,C32-5*D32,0) -> 0 | G32: =IF(F32=0,0,$J$8) -> 0 | H32: =F32*G32 -> 0 | I32: =E32+H32 -> 306000 | J32: =IF(L32="가공",IF(B32<200,"0",IF(B32>=200,(B32-200)*$H$14)),IF(L32="지중",IF(B32<50,"0",IF(B32>=50,(B32-50)*$J$13)))) -> 0 | K32: =I32+J32 -> 306000 | L32: 가공
A33: 공원등-1 | B33: 50 | C33: 3 | D33: 1 | E33: =$H$7*D33 -> 306000 | F33: =IF(C33>5*D33,C33-5*D33,0) -> 0 | G33: =IF(F33=0,0,$J$8) -> 0 | H33: =F33*G33 -> 0 | I33: =E33+H33 -> 306000 | J33: =IF(L33="가공",IF(B33<200,"0",IF(B33>=200,(B33-200)*$H$14)),IF(L33="지중",IF(B33<50,"0",IF(B33>=50,(B33-50)*$J$13)))) -> 0 | K33: =I33+J33 -> 306000 | L33: 가공
A34: 공원등-2 | B34: 50 | C34: 3 | D34: 1 | E34: =$H$7*D34 -> 306000 | F34: =IF(C34>5*D34,C34-5*D34,0) -> 0 | G34: =IF(F34=0,0,$J$8) -> 0 | H34: =F34*G34 -> 0 | I34: =E34+H34 -> 306000 | J34: =IF(L34="가공",IF(B34<200,"0",IF(B34>=200,(B34-200)*$H$14)),IF(L34="지중",IF(B34<50,"0",IF(B34>=50,(B34-50)*$J$13)))) -> 0 | K34: =I34+J34 -> 306000 | L34: 가공
A36: [신호등 저압]
A37: 신호등 | B37: 50 | C37: 1 | D37: 2 | E37: =$H$7*D37 -> 612000 | F37: =IF(C37>5*D37,C37-5*D37,0) -> 0 | G37: =IF(F37=0,0,$J$8) -> 0 | H37: =F37*G37 -> 0 | I37: =E37+H37 -> 612000 | J37: =IF(L37="가공",IF(B37<200,"0",IF(B37>=200,(B37-200)*$H$14)),IF(L37="지중",IF(B37<50,"0",IF(B37>=50,(B37-50)*$J$13)))) -> 0 | K37: =I37+J37 -> 612000 | L37: 가공
A39: [오수처리 및 비점처리 저압]
A40: 오수처리 | B40: 50 | C40: 10 | D40: 1 | E40: =$H$7*D40 -> 306000 | F40: =IF(C40>5*D40,C40-5*D40,0) -> 5 | G40: =IF(F40=0,0,$J$8) -> 141000 | H40: =F40*G40 -> 705000 | I40: =E40+H40 -> 1011000 | J40: =IF(L40="가공",IF(B40<200,"0",IF(B40>=200,(B40-200)*$H$14)),IF(L40="지중",IF(B40<50,"0",IF(B40>=50,(B40-50)*$J$13)))) -> 0 | K40: =I40+J40 -> 1011000 | L40: 가공
A41: 비점처리시설 | B41: 50 | C41: 10 | D41: 1 | E41: =$H$7*D41 -> 306000 | F41: =IF(C41>5*D41,C41-5*D41,0) -> 5 | G41: =IF(F41=0,0,$J$8) -> 141000 | H41: =F41*G41 -> 705000 | I41: =E41+H41 -> 1011000 | J41: =IF(L41="가공",IF(B41<200,"0",IF(B41>=200,(B41-200)*$H$14)),IF(L41="지중",IF(B41<50,"0",IF(B41>=50,(B41-50)*$J$13)))) -> 0 | K41: =I41+J41 -> 1011000 | L41: 가공
A43: 소 계 | K43: =ROUNDUP(SUM(K31:K42)/100000,0)*100000 -> 3900000
A44: VAT | K44: =K43*0.1 -> 390000 | L44: 10%
A45: 계 | K45: =SUM(K43:K44) -> 4290000
K57: =K45+'사용전검사비 (지구내)'!K23 -> 5131000

Sheet 사용전검사비 (지구내)
A1: ■ 사용전검사비
A3: 1. 공사비 산출근거 (한국전기안전공사)
A4: [수용설비 설치공사, 단위 : 원/VAT별도]
A5: 구 분 | C5: 기본료 | E5: 용 량 별 금 액 | I5: 비 고
A6: 저압 | C6: 94000 | H6: 391 | I6: 구내배전설비 검사시는 기본료에 kw당 요금의 2배합산 적용
A7: 고압 300kw 까지 | C7: 298000 | H7: 660
A8: 고압 300kw 초과 | C8: 559000 | E8: 1,000kw 미만 | H8: 315
A9: 고압 1000kw 이상 | C9: 678000 | E9: 1,000kw까지 | H9: 268
E10: 1,001~100,000kw까지 | H10: 152
E11: 100,000kw초과 | H11: 32
A13: 2. 사용전 검사비 적용 | O13: =ROUNDDOWN(N13,-3) -> 0
O14: =ROUNDDOWN(N14,-3) -> 0
A15: 구 분 | B15: 계약 전압 | D15: 시설용량 (kW) | E15: 기본공사비 | H15: KW 당 요금 | K15: 소 계 | L15: 비 고 | O15: =ROUNDDOWN(N15,-3) -> 0
O16: =ROUNDDOWN(N16,-3) -> 0
A17: 가로등 | B17: 가로등,공원등, 저압(4개소) | D17: ='한전인입공사비 (지구내)'!C31+'한전인입공사비 (지구내)'!C32+'한전인입공사비 (지구내)'!C33+'한전인입공사비 (지구내)'!C34 -> 12 | E17: =C6*4 -> 376000 | H17: =D17*$H$6 -> 4692 | K17: =H17+E17 -> 380692
A18: 신호등 | B18: 신호등, 저압(1개소) | D18: ='한전인입공사비 (지구내)'!C37*1 -> 1 | E18: =C6*'한전인입공사비 (지구내)'!D37 -> 188000 | H18: =D18*$H$6 -> 391 | K18: =H18+E18 -> 188391
A19: 관계시설 | B19: 저류지 및 하수처리, 저압(2개소) | D19: ='한전인입공사비 (지구내)'!C40+'한전인입공사비 (지구내)'!C41 -> 20 | E19: =C6*2 -> 188000 | H19: =D19*$H$6 -> 7820 | K19: =H19+E19 -> 195820
A21: 소 계 | K21: =SUM(K17:K20) -> 764903 | N21: =K21-900000 -> -135097
A22: VAT | B22: 0.1 | K22: =K21*0.1 -> 76490.3
A23: 계 | E23: =$J$7 -> 0 | H23: =$J$7 -> 0 | K23: =TRUNC(SUM(K21:K22),-3) -> 841000 | N23: =K23-1000000 -> -159000 | O23: =SUM(O13:O22) -> 0

Sheet 일대목차
A1: 총줄수-> | B1: 81 | C1: [ 화성 청원지구 전기공사 ] - 일위대가목차
A2: 번호 | B2: … | C2: 코드 | D2: 명 칭 | E2: 규 격 | F2: 단위 | G2: 수량 | H2: 재료비 | J2: 노무비 | M2: 경비 | O2: 계 | P2: 계 | Q2: 비고
H3: 단가 | I3: 금액 | J3: 수량 | K3: 단가 | L3: 금액 | M3: 단가 | N3: 금액 | O3: 단가
A4: 56930220040 | B4: ABB103100000 | C4: 제 1호 | D4: 터파기(기계90%,인력10%) | E4: 보통토사 | F4: ㎥ | H4: =일위대가!I7 -> 501 | I4: =H4 -> 501 | K4: =일위대가!L7 -> 4659 | L4: =K4 -> 4659 | M4: =일위대가!N7 -> 483 | N4: =M4 -> 483 | P4: =I4+L4+N4 -> 5643
A5: 56930220053 | B5: ABB104100000 | C5: 제 2호 | D5: 되메우기(기계90%,인력10%) | E5: 보통토사 | F5: ㎥ | H5: =일위대가!I12 -> 449 | I5: =H5 -> 449 | K5: =일위대가!L12 -> 2939 | L5: =K5 -> 2939 | M5: =일위대가!N12 -> 483 | N5: =M5 -> 483 | P5: =I5+L5+N5 -> 3871
A6: 56930220102 | B6: ABC112700000 | C6: 제 3호 | D6: 인력잔토처리 | E6: 현장처리 | F6: ㎥ | H6: =일위대가!I17 -> 1032 | I6: =H6 -> 1032 | K6: =일위대가!L17 -> 34413 | L6: =K6 -> 34413 | M6: =일위대가!N17 -> 0 | N6: =M6 -> 0 | P6: =I6+L6+N6 -> 35445
A7: 56930310010 | B7: ADF202100000 | C7: 제 4호 | D7: 레미콘타설 | E7: 무근(미할증) | F7: ㎥ | H7: =일위대가!I23 -> 1759 | I7: =H7 -> 1759 | K7: =일위대가!L23 -> 58635 | L7: =K7 -> 58635 | M7: =일위대가!N23 -> 0 | N7: =M7 -> 0 | P7: =I7+L7+N7 -> 60394
A8: 56930370040 | B8: ADA220110000 | C8: 제 5호 | D8: 합판거푸집 | E8: 4회 | F8: ㎡ | H8: =일위대가!I32 -> 24425 | I8: =H8 -> 24425 | K8: =일위대가!L32 -> 35498 | L8: =K8 -> 35498 | M8: =일위대가!N32 -> 0 | N8: =M8 -> 0 | P8: =I8+L8+N8 -> 59923
A9: 56950010201 | B9: EBP110110000 | C9: 제 6호 | D9: 가로등 건주 기계화 시공 | E9: 일반 5m-7m | F9: 식 | H9: =일위대가!I38 -> 11653 | I9: =H9 -> 11653 | K9: =일위대가!L38 -> 117311 | L9: =K9 -> 117311 | M9: =일위대가!N38 -> 31713 | N9: =M9 -> 31713 | P9: =I9+L9+N9 -> 160677
A10: 56950010203 | B10: EBP110130000 | C10: 제 7호 | D10: 가로등 건주 기계화 시공 | E10: 일반 10m-12m | F10: 식 | H10: =일위대가!I44 -> 14212 | I10: =H10 -> 14212 | K10: =일위대가!L44 -> 153319 | L10: =K10 -> 153319 | M10: =일위대가!N44 -> 37479 | N10: =M10 -> 37479 | P10: =I10+L10+N10 -> 205010
A11: 56930210010 | B11: ABB111100000 | C11: 제 9호 | D11: 인력터파기 | E11: 보통토사0-1m | F11: ㎥ | H11: =일위대가!I49 -> 1032 | I11: =H11 -> 1032 | K11: =일위대가!L49 -> 34413 | L11: =K11 -> 34413 | M11: =일위대가!N49 -> 0 | N11: =M11 -> 0 | P11: =I11+L11+N11 -> 35445
A12: 56930210021 | B12: ABD100001000 | C12: 제 10호 | D12: 인력되메우기 | E12: 보통토사0-1m | F12: ㎥ | H12: =일위대가!I54 -> 516 | I12: =H12 -> 516 | K12: =일위대가!L54 -> 17206 | L12: =K12 -> 17206 | M12: =일위대가!N54 -> 0 | N12: =M12 -> 0 | P12: =I12+L12+N12 -> 17722
A13: 5975D077002 | B13: E59753077002 | C13: 제 11호 | D13: 파상형 폴리에틸렌 전선관 | E13: 40㎜(가로등,신호,구내) | F13: M | H13: =일위대가!I64 -> 945 | I13: =H13 -> 945 | K13: =일위대가!L64 -> 9002 | L13: =K13 -> 9002 | M13: =일위대가!N64 -> 0 | N13: =M13 -> 0 | P13: =I13+L13+N13 -> 9947
A14: 5975D077003 | B14: ECI31100030S | C14: 제 12호 | D14: 파상형 폴리에틸렌 전선관 | E14: 50㎜(가로등,신호,구내) | F14: M | H14: =일위대가!I74 -> 1170 | I14: =H14 -> 1170 | K14: =일위대가!L74 -> 9002 | L14: =K14 -> 9002 | M14: =일위대가!N74 -> 0 | N14: =M14 -> 0 | P14: =I14+L14+N14 -> 10172
A15: 5975D077004 | B15: E59753077004 | C15: 제 13호 | D15: 파상형 폴리에틸렌 전선관 | E15: 65㎜(가로등,신호,구내) | F15: M | H15: =일위대가!I84 -> 1825 | I15: =H15 -> 1825 | K15: =일위대가!L84 -> 11280 | L15: =K15 -> 11280 | M15: =일위대가!N84 -> 0 | N15: =M15 -> 0 | P15: =I15+L15+N15 -> 13105
A16: 5975D077005 | B16: ECI31100040S | C16: 제 14호 | D16: 파상형 폴리에틸렌 전선관 | E16: 80㎜(가로등,신호,구내) | F16: M | H16: =일위대가!I94 -> 2296 | I16: =H16 -> 2296 | K16: =일위대가!L94 -> 11280 | L16: =K16 -> 11280 | M16: =일위대가!N94 -> 0 | N16: =M16 -> 0 | P16: =I16+L16+N16 -> 13576
A17: 5975D077006 | B17: ECI31100050S | C17: 제 15호 | D17: 파상형 폴리에틸렌 전선관 | E17: 100㎜(가로등,신호,구내) | F17: M | H17: =일위대가!I104 -> 3128 | I17: =H17 -> 3128 | K17: =일위대가!L104 -> 16761 | L17: =K17 -> 16761 | M17: =일위대가!N104 -> 0 | N17: =M17 -> 0 | P17: =I17+L17+N17 -> 19889
A18: 5975D178002 | B18: E59753178002 | C18: 제 16호 | D18: 파상형 폴리에틸렌 전선관 | E18: 40㎜ | F18: M | H18: =일위대가!I114 -> 855 | I18: =H18 -> 855 | K18: =일위대가!L114 -> 6001 | L18: =K18 -> 6001 | M18: =일위대가!N114 -> 0 | N18: =M18 -> 0 | P18: =I18+L18+N18 -> 6856
A19: 5975D178003 | B19: E59753178003 | C19: 제 17호 | D19: 파상형 폴리에틸렌 전선관 | E19: 50㎜ | F19: M | H19: =일위대가!I124 -> 1080 | I19: =H19 -> 1080 | K19: =일위대가!L124 -> 6001 | L19: =K19 -> 6001 | M19: =일위대가!N124 -> 0 | N19: =M19 -> 0 | P19: =I19+L19+N19 -> 7081
A20: 56959000002 | B20: EMM300000108 | C20: 제 18호 | D20: 광케블내외관일체형전선관 | E20: COD 36-4 공 | F20: M | H20: =일위대가!I134 -> 34596 | I20: =H20 -> 34596 | K20: =일위대가!L134 -> 10206 | L20: =K20 -> 10206 | M20: =일위대가!N134 -> 0 | N20: =M20 -> 0 | P20: =I20+L20+N20 -> 44802
A21: E145A927203 | B21: EE1450927203 | C21: 제 19호 | D21: 접지용비닐절연전선(F-GV)_지중 | E21: 6㎟ | F21: M | H21: =일위대가!I142 -> 1879 | I21: =H21 -> 1879 | K21: =일위대가!L142 -> 2463 | L21: =K21 -> 2463 | M21: =일위대가!N142 -> 0 | N21: =M21 -> 0 | P21: =I21+L21+N21 -> 4342
A22: E145A927204 | B22: EE1450927204 | C22: 제 20호 | D22: 접지용비닐절연전선(F-GV) | E22: 10㎟ | F22: M | H22: =일위대가!I150 -> 3116 | I22: =H22 -> 3116 | K22: =일위대가!L150 -> 2463 | L22: =K22 -> 2463 | M22: =일위대가!N150 -> 0 | N22: =M22 -> 0 | P22: =I22+L22+N22 -> 5579
A23: E145A927205 | B23: EE1450927205 | C23: 제 21호 | D23: 접지용비닐절연전선(F-GV) | E23: 16㎟ | F23: M | H23: =일위대가!I158 -> 4094 | I23: =H23 -> 4094 | K23: =일위대가!L158 -> 2873 | L23: =K23 -> 2873 | M23: =일위대가!N158 -> 0 | N23: =M23 -> 0 | P23: =I23+L23+N23 -> 6967
A24: E145A287521 | B24: EE1450287521 | C24: 제 22호 | D24: 폴리에틸렌 난연케이블 | E24: 0.6/1kv F-CV 2C×2.5㎟ | F24: M | H24: =일위대가!I166 -> 2116 | I24: =H24 -> 2116 | K24: =일위대가!L166 -> 4258 | L24: =K24 -> 4258 | M24: =일위대가!N166 -> 0 | N24: =M24 -> 0 | P24: =I24+L24+N24 -> 6374
A25: E145A287540 | B25: EE1450287540 | C25: 제 23호 | D25: 폴리에틸렌 난연케이블 | E25: 0.6/1kv F-CV 3C×6㎟ | F25: M | H25: =일위대가!I174 -> 5289 | I25: =H25 -> 5289 | K25: =일위대가!L174 -> 7908 | L25: =K25 -> 7908 | M25: =일위대가!N174 -> 0 | N25: =M25 -> 0 | P25: =I25+L25+N25 -> 13197
A26: E145A358087 | B26: EE1450358087 | C26: 제 24호 | D26: 난연제어케이블 | E26: F-CVV 5Cx2.5㎟ | F26: M | H26: =일위대가!I182 -> 3832 | I26: =H26 -> 3832 | K26: =일위대가!L182 -> 9732 | L26: =K26 -> 9732 | M26: =일위대가!N182 -> 0 | N26: =M26 -> 0 | P26: =I26+L26+N26 -> 13564
A27: 56959000003 | B27: EMM525000002 | C27: 제 25호 | D27: 광케이블(옥외용) | E27: SM 9/125, 4c | F27: M | H27: =일위대가!I191 -> 1211 | I27: =H27 -> 1211 | K27: =일위대가!L191 -> 5376 | L27: =K27 -> 5376 | M27: =일위대가!N191 -> 0 | N27: =M27 -> 0 | P27: =I27+L27+N27 -> 6587
A28: 6310A147401 | B28: E63100147401 | C28: 제 26호 | D28: 신호 제어기 | E28: 경보제어기, 전자회로 | F28: 대 | H28: =일위대가!I198 -> 202876 | I28: =H28 -> 202876 | K28: =일위대가!L198 -> 95868 | L28: =K28 -> 95868 | M28: =일위대가!N198 -> 0 | N28: =M28 -> 0 | P28: =I28+L28+N28 -> 298744
A29: 5975A427102 | B29: E59750427102 | C29: 제 27호 | D29: 접지봉 | E29: 14Φ×1000 mm | F29: 개 | H29: =일위대가!I205 -> 7096 | I29: =H29 -> 7096 | K29: =일위대가!L205 -> 43869 | L29: =K29 -> 43869 | M29: =일위대가!N205 -> 0 | N29: =M29 -> 0 | P29: =I29+L29+N29 -> 50965
A30: E975A427014 | B30: EE9750427014 | C30: 제 28호 | D30: 접지크램프(IEC 90) | E30: 16sq | F30: 개 | H30: =일위대가!I211 -> 721 | I30: =H30 -> 721 | K30: =일위대가!L211 -> 7389 | L30: =K30 -> 7389 | M30: =일위대가!N211 -> 0 | N30: =M30 -> 0 | P30: =I30+L30+N30 -> 8110
A31: 56959000004 | B31: EMM300041326 | C31: 제 29호 | D31: 케이블표지시트 | E31: 0.23x400 | F31: m | H31: =일위대가!I218 -> 187 | I31: =H31 -> 187 | K31: =일위대가!L218 -> 237 | L31: =K31 -> 237 | M31: =일위대가!N218 -> 0 | N31: =M31 -> 0 | P31: =I31+L31+N31 -> 424
A32: E940A267006 | B32: EE9400267006 | C32: 제 30호 | D32: 압착단자 | E32: R형동선 나압착 16 ㎟ | F32: 개 | H32: =일위대가!I224 -> 1086 | I32: =H32 -> 1086 | K32: =일위대가!L224 -> 29563 | L32: =K32 -> 29563 | M32: =일위대가!N224 -> 0 | N32: =M32 -> 0 | P32: =I32+L32+N32 -> 30649
A33: E940A267007 | B33: EE9400267007 | C33: 제 31호 | D33: 압착단자 | E33: R형동선 나압착 25 ㎟ | F33: 개 | H33: =일위대가!I230 -> 1343 | I33: =H33 -> 1343 | K33: =일위대가!L230 -> 36133 | L33: =K33 -> 36133 | M33: =일위대가!N230 -> 0 | N33: =M33 -> 0 | P33: =I33+L33+N33 -> 37476
A34: E940A267008 | B34: EE9400267008 | C34: 제 32호 | D34: 압착단자 | E34: R형동선 나압착 35 ㎟ | F34: 개 | H34: =일위대가!I236 -> 1498 | I34: =H34 -> 1498 | K34: =일위대가!L236 -> 39418 | L34: =K34 -> 39418 | M34: =일위대가!N236 -> 0 | N34: =M34 -> 0 | P34: =I34+L34+N34 -> 40916
A35: 5630A217281 | B35: E56300217281 | C35: 제 33호 | D35: 핸드홀 | E35: 수공1호 | F35: 조 | H35: =일위대가!I245 -> 121913 | I35: =H35 -> 121913 | K35: =일위대가!L245 -> 397128 | L35: =K35 -> 397128 | M35: =일위대가!N245 -> 0 | N35: =M35 -> 0 | P35: =I35+L35+N35 -> 519041
A36: 5680A447433 | B36: E56800447433 | C36: 제 34호 | D36: 핸드홀카바 | E36: 통신용 | F36: 기 | H36: =일위대가!I252 -> 380691 | I36: =H36 -> 380691 | K36: =일위대가!L252 -> 356382 | L36: =K36 -> 356382 | M36: =일위대가!N252 -> 0 | N36: =M36 -> 0 | P36: =I36+L36+N36 -> 737073
A37: 56959000005 | B37: EMM408901996 | C37: 제 35호 | D37: 전주용입상관 | E37: Φ130*2t*2m | F37: EA | H37: =일위대가!I259 -> 38396 | I37: =H37 -> 38396 | K37: =일위대가!L259 -> 110220 | L37: =K37 -> 110220 | M37: =일위대가!N259 -> 0 | N37: =M37 -> 0 | P37: =I37+L37+N37 -> 148616
A38: 56959000006 | B38: EMM474327364 | C38: 제 36호 | D38: 보행철주 기초앙카 | E38: Φ125×1.4m | F38: 본 | H38: =일위대가!I265 -> 38940 | I38: =H38 -> 38940 | K38: =일위대가!L265 -> 131364 | L38: =K38 -> 131364 | M38: =일위대가!N265 -> 0 | N38: =M38 -> 0 | P38: =I38+L38+N38 -> 170304
A39: 56959000007 | B39: EMM389225351 | C39: 제 37호 | D39: 신호등용 맨홀(주철뚜껑) | E39: 600x600x600,경찰청규격 | F39: 개 | H39: =일위대가!I272 -> 354509 | I39: =H39 -> 354509 | K39: =일위대가!L272 -> 150304 | L39: =K39 -> 150304 | M39: =일위대가!N272 -> 0 | N39: =M39 -> 0 | P39: =I39+L39+N39 -> 504813
A40: 56959000008 | B40: EMM579245673 | C40: 제 38호 | D40: 신호 제어기 설치 | E40: 교통신호제어기, 3거리 | F40: 대 | H40: =일위대가!I282 -> 21063 | I40: =H40 -> 21063 | K40: =일위대가!L282 -> 702133 | L40: =K40 -> 702133 | M40: =일위대가!N282 -> 0 | N40: =M40 -> 0 | P40: =I40+L40+N40 -> 723196
...

Sheet 일위대가
A1: 총줄수-> | B1: 497 | D1: [ 화성 청원지구 전기공사 ] - 일위대가표 | W1: 노임 계산 정보 | AA1: 부속재 및 손료
A2: 번호 | B2: 목차코드 | C2: 코드 | D2: 명 칭 | E2: 규 격 | F2: 단위 | G2: 수량 | H2: 재료비 | J2: 노무비 | M2: 경비 | P2: 계 | Q2: 비고 | W2: 노임계 | X2: 전체(%) | Y2: 공종별(%) | Z2: 노임 소수 | AA2: CD배관재 | AB2: 일반배관재 | AC2: 소모재 | AD2: 자재계 | AE2: 노임계
H3: 단가 | I3: 금액 | J3: 수량 | K3: 단가 | L3: 금액 | M3: 단가 | N3: 금액 | O3: 단가 | AD3: 1 | AE3: 1
A4: 56930220040 | B4: 일목줄 | C4: ABB103100000 | D4: [제 1호] 터파기(기계90%,인력10%) 보통토사 [㎥]
A5: 56930210010 | B5: 제 1호 | C5: ABB111100000 | D5: 인력터파기 | E5: 보통토사0-1m | F5: ㎥ | G5: 0.1 | H5: =일대목차!H11 -> 1032 | I5: =IF(G5*H5<>0, TRUNC(G5*H5,1),"") -> 103.2 | J5: 0.1 | K5: =일대목차!K11 -> 34413 | L5: =IF(G5*K5<>0, TRUNC(G5*K5,1),"") -> 3441.3 | M5: =일대목차!M11 -> 0 | N5: =IF(G5*M5<>0, TRUNC(G5*M5,1),"") | P5: =IF(SUM(I5,L5,N5)<>0,TRUNC(SUM(I5,L5,N5),1),"") -> 3544.5 | Q5: 제 9호 | R5: ILD
A6: CA565826042 | B6: 제 1호 | C6: ECA565826042 | D6: 기계터파기 | E6: 보통토사(0.6㎥) | F6: ㎥ | G6: 0.9 | H6: =합산자재!H112 -> 442 | I6: =IF(G6*H6<>0, TRUNC(G6*H6,1),"") -> 397.8 | J6: 0.9 | K6: =합산자재!I112 -> 1354 | L6: =IF(G6*K6<>0, TRUNC(G6*K6,1),"") -> 1218.6 | M6: =합산자재!J112 -> 537 | N6: =IF(G6*M6<>0, TRUNC(G6*M6,1),"") -> 483.3 | P6: =IF(SUM(I6,L6,N6)<>0,TRUNC(SUM(I6,L6,N6),1),"") -> 2099.7 | Q6: 182-하 | R6: ild | Z6: 노임계
B7: 합계줄 | D7: ( 합 계 ) | I7: =TRUNC(SUM(I4:I6)) -> 501 | L7: =TRUNC(SUM(L4:L6)) -> 4659 | N7: =TRUNC(SUM(N4:N6)) -> 483 | P7: =IF(SUM(I7,L7,N7)<>0,TRUNC(SUM(I7,L7,N7),1),"") -> 5643 | AE7: =TRUNC(SUM(AE4:AE6)) -> 0
I8: =IF(G8*H8<>0, TRUNC(G8*H8,1),"") | L8: =IF(G8*K8<>0, TRUNC(G8*K8,1),"") | N8: =IF(G8*M8<>0, TRUNC(G8*M8,1),"") | P8: =IF(SUM(I8,L8,N8)<>0,TRUNC(SUM(I8,L8,N8),1),"")
A9: 56930220053 | B9: 일목줄 | C9: ABB104100000 | D9: [제 2호] 되메우기(기계90%,인력10%) 보통토사 [㎥]
A10: 56930210021 | B10: 제 2호 | C10: ABD100001000 | D10: 인력되메우기 | E10: 보통토사0-1m | F10: ㎥ | G10: 0.1 | H10: =일대목차!H12 -> 516 | I10: =IF(G10*H10<>0, TRUNC(G10*H10,1),"") -> 51.6 | J10: 0.1 | K10: =일대목차!K12 -> 17206 | L10: =IF(G10*K10<>0, TRUNC(G10*K10,1),"") -> 1720.6 | M10: =일대목차!M12 -> 0 | N10: =IF(G10*M10<>0, TRUNC(G10*M10,1),"") | P10: =IF(SUM(I10,L10,N10)<>0,TRUNC(SUM(I10,L10,N10),1),"") -> 1772.2 | Q10: 제 10호 | R10: ILD | Z10: 노임계
A11: CA565826051 | B11: 제 2호 | C11: ECA565826051 | D11: 기계되메우기 | E11: 보통토사(0.6㎥) | F11: ㎥ | G11: 0.9 | H11: =합산자재!H113 -> 442 | I11: =IF(G11*H11<>0, TRUNC(G11*H11,1),"") -> 397.8 | J11: 0.9 | K11: =합산자재!I113 -> 1354 | L11: =IF(G11*K11<>0, TRUNC(G11*K11,1),"") -> 1218.6 | M11: =합산자재!J113 -> 537 | N11: =IF(G11*M11<>0, TRUNC(G11*M11,1),"") -> 483.3 | P11: =IF(SUM(I11,L11,N11)<>0,TRUNC(SUM(I11,L11,N11),1),"") -> 2099.7 | Q11: 182-하 | R11: ild
B12: 합계줄 | D12: ( 합 계 ) | I12: =TRUNC(SUM(I9:I11)) -> 449 | L12: =TRUNC(SUM(L9:L11)) -> 2939 | N12: =TRUNC(SUM(N9:N11)) -> 483 | P12: =IF(SUM(I12,L12,N12)<>0,TRUNC(SUM(I12,L12,N12),1),"") -> 3871 | AE12: =TRUNC(SUM(AE9:AE11)) -> 0
I13: =IF(G13*H13<>0, TRUNC(G13*H13,1),"") | L13: =IF(G13*K13<>0, TRUNC(G13*K13,1),"") | N13: =IF(G13*M13<>0, TRUNC(G13*M13,1),"") | P13: =IF(SUM(I13,L13,N13)<>0,TRUNC(SUM(I13,L13,N13),1),"")
A14: 56930220102 | B14: 일목줄 | C14: ABC112700000 | D14: [제 3호] 인력잔토처리 현장처리 [㎥]
A15: 56900017041 | B15: 제 3호 | C15: L001010101000002 | D15: 노 무 비 | E15: 보통인부 | F15: 인 | G15: =일위노임!G6 -> 0.2 | H15: =합산자재!H124 -> 0 | I15: =IF(G15*H15<>0, TRUNC(G15*H15,1),"") | J15: 0.2 | K15: =합산자재!I124 -> 172068 | L15: =IF(G15*K15<>0, TRUNC(G15*K15,1),"") -> 34413.6 | M15: =합산자재!J124 -> 0 | N15: =IF(G15*M15<>0, TRUNC(G15*M15,1),"") | P15: =IF(SUM(I15,L15,N15)<>0,TRUNC(SUM(I15,L15,N15),1),"") -> 34413.6 | Z15: 노임계 | AE15: =L15 -> 34413.6
A16: A0300000000 | B16: 제 3호 | C16: RENT000000000006 | D16: [ 공 구 손 료 ] | E16: 노무비의 3 % | F16: 식 | G16: 1 | H16: =IF(TRUNC((AD17+AC17)/$AE$3,1)*$AE$3-AD17 <0, AC17, TRUNC((AD17+AC17)/$AE$3,1)*$AE$3-AD17) -> 1032.3 | I16: =H16 -> 1032.3 | J16: 1 | L16: =IF(G16*K16<>0, TRUNC(G16*K16,1),"") | N16: =IF(G16*M16<>0, TRUNC(G16*M16,1),"") | P16: =IF(SUM(I16,L16,N16)<>0,TRUNC(SUM(I16,L16,N16),1),"") -> 1032.3
B17: 합계줄 | D17: ( 합 계 ) | I17: =TRUNC(SUM(I14:I16)) -> 1032 | L17: =TRUNC(SUM(L14:L16)) -> 34413 | N17: =TRUNC(SUM(N14:N16)) -> 0 | P17: =IF(SUM(I17,L17,N17)<>0,TRUNC(SUM(I17,L17,N17),1),"") -> 35445 | AC17: =TRUNC(AE17*옵션!$B$36/100,1) -> 1032.3 | AD17: =TRUNC(SUM(L14:L15)) -> 34413 | AE17: =TRUNC(SUM(AE14:AE16)) -> 34413
I18: =IF(G18*H18<>0, TRUNC(G18*H18,1),"") | L18: =IF(G18*K18<>0, TRUNC(G18*K18,1),"") | N18: =IF(G18*M18<>0, TRUNC(G18*M18,1),"") | P18: =IF(SUM(I18,L18,N18)<>0,TRUNC(SUM(I18,L18,N18),1),"")
A19: 56930310010 | B19: 일목줄 | C19: ADF202100000 | D19: [제 4호] 레미콘타설 무근(미할증) [㎥] | Z19: 노임계
A20: 56900017041 | B20: 제 4호 | C20: L001010101000002 | D20: 노 무 비 | E20: 보통인부 | F20: 인 | G20: =일위노임!G10 -> 0.15 | H20: =합산자재!H124 -> 0 | I20: =IF(G20*H20<>0, TRUNC(G20*H20,1),"") | J20: 0.15 | K20: =합산자재!I124 -> 172068 | L20: =IF(G20*K20<>0, TRUNC(G20*K20,1),"") -> 25810.2 | M20: =합산자재!J124 -> 0 | N20: =IF(G20*M20<>0, TRUNC(G20*M20,1),"") | P20: =IF(SUM(I20,L20,N20)<>0,TRUNC(SUM(I20,L20,N20),1),"") -> 25810.2 | AE20: =L20 -> 25810.2
A21: 56900017108 | B21: 제 4호 | C21: L001010101000013 | D21: 노 무 비 | E21: 콘크리트공 | F21: 인 | G21: =일위노임!G11 -> 0.12 | H21: =합산자재!H129 -> 0 | I21: =IF(G21*H21<>0, TRUNC(G21*H21,1),"") | J21: 0.12 | K21: =합산자재!I129 -> 273540 | L21: =IF(G21*K21<>0, TRUNC(G21*K21,1),"") -> 32824.8 | M21: =합산자재!J129 -> 0 | N21: =IF(G21*M21<>0, TRUNC(G21*M21,1),"") | P21: =IF(SUM(I21,L21,N21)<>0,TRUNC(SUM(I21,L21,N21),1),"") -> 32824.8 | AE21: =L21 -> 32824.8
A22: A0300000000 | B22: 제 4호 | C22: RENT000000000006 | D22: [ 공 구 손 료 ] | E22: 노무비의 3 % | F22: 식 | G22: 1 | H22: =IF(TRUNC((AD23+AC23)/$AE$3,1)*$AE$3-AD23 <0, AC23, TRUNC((AD23+AC23)/$AE$3,1)*$AE$3-AD23) -> 1759 | I22: =H22 -> 1759 | J22: 1 | L22: =IF(G22*K22<>0, TRUNC(G22*K22,1),"") | N22: =IF(G22*M22<>0, TRUNC(G22*M22,1),"") | P22: =IF(SUM(I22,L22,N22)<>0,TRUNC(SUM(I22,L22,N22),1),"") -> 1759 | Z22: 노임계
B23: 합계줄 | D23: ( 합 계 ) | I23: =TRUNC(SUM(I19:I22)) -> 1759 | L23: =TRUNC(SUM(L19:L22)) -> 58635 | N23: =TRUNC(SUM(N19:N22)) -> 0 | P23: =IF(SUM(I23,L23,N23)<>0,TRUNC(SUM(I23,L23,N23),1),"") -> 60394 | AC23: =TRUNC(AE23*옵션!$B$36/100,1) -> 1759 | AD23: =TRUNC(SUM(L19:L21)) -> 58635 | AE23: =TRUNC(SUM(AE19:AE22)) -> 58635
I24: =IF(G24*H24<>0, TRUNC(G24*H24,1),"") | L24: =IF(G24*K24<>0, TRUNC(G24*K24,1),"") | N24: =IF(G24*M24<>0, TRUNC(G24*M24,1),"") | P24: =IF(SUM(I24,L24,N24)<>0,TRUNC(SUM(I24,L24,N24),1),"")
A25: 56930370040 | B25: 일목줄 | C25: ADA220110000 | D25: [제 5호] 합판거푸집 4회 [㎡] | Z25: 노임계
A26: 55300057061 | B26: 제 5호 | C26: 1112200120142458 | D26: 내수합판 | E26: 1급, 12×1220×2440mm | F26: ㎡ | G26: 0.3914 | H26: =합산자재!H37 -> 10900 | I26: =IF(G26*H26<>0, TRUNC(G26*H26,1),"") -> 4266.2 | J26: 0.3914 | K26: =합산자재!I37 -> 0 | L26: =IF(G26*K26<>0, TRUNC(G26*K26,1),"") | M26: =합산자재!J37 -> 0 | N26: =IF(G26*M26<>0, TRUNC(G26*M26,1),"") | P26: =IF(SUM(I26,L26,N26)<>0,TRUNC(SUM(I26,L26,N26),1),"") -> 4266.2
A27: 55100027011 | B27: 제 5호 | C27: 3010369820141038 | D27: 각재(角材) | E27: 외송(㎥) | F27: ㎥ | G27: 0.0144 | H27: =합산자재!H36 -> 1326000 | I27: =IF(G27*H27<>0, TRUNC(G27*H27,1),"") -> 19094.4 | J27: 0.0144 | K27: =합산자재!I36 -> 0 | L27: =IF(G27*K27<>0, TRUNC(G27*K27,1),"") | M27: =합산자재!J36 -> 0 | N27: =IF(G27*M27<>0, TRUNC(G27*M27,1),"") | P27: =IF(SUM(I27,L27,N27)<>0,TRUNC(SUM(I27,L27,N27),1),"") -> 19094.4
A28: MM882214702 | B28: 제 5호 | C28: 391115ZZ701Z0033 | D28: 소모자재(박리재 등) | E28: 주자재비의 9% | F28: 식 | G28: 1 | H28: =합산자재!H88 -> 0 | I28: =IF(G28*H28<>0, TRUNC(G28*H28,1),"") | J28: 1 | K28: =합산자재!I88 -> 0 | L28: =IF(G28*K28<>0, TRUNC(G28*K28,1),"") | M28: =합산자재!J88 -> 0 | N28: =IF(G28*M28<>0, TRUNC(G28*M28,1),"") | P28: =IF(SUM(I28,L28,N28)<>0,TRUNC(SUM(I28,L28,N28),1),"") | Z28: 노임계
A29: 56900017041 | B29: 제 5호 | C29: L001010101000002 | D29: 노 무 비 | E29: 보통인부 | F29: 인 | G29: =일위노임!G15 -> 0.03 | H29: =합산자재!H124 -> 0 | I29: =IF(G29*H29<>0, TRUNC(G29*H29,1),"") | J29: 0.03 | K29: =합산자재!I124 -> 172068 | L29: =IF(G29*K29<>0, TRUNC(G29*K29,1),"") -> 5162 | M29: =합산자재!J124 -> 0 | N29: =IF(G29*M29<>0, TRUNC(G29*M29,1),"") | P29: =IF(SUM(I29,L29,N29)<>0,TRUNC(SUM(I29,L29,N29),1),"") -> 5162 | AE29: =L29 -> 5162
A30: 56900017137 | B30: 제 5호 | C30: L001010101000007 | D30: 노 무 비 | E30: 형틀목공 | F30: 인 | G30: =일위노임!G16 -> 0.11 | H30: =합산자재!H127 -> 0 | I30: =IF(G30*H30<>0, TRUNC(G30*H30,1),"") | J30: 0.11 | K30: =합산자재!I127 -> 275790 | L30: =IF(G30*K30<>0, TRUNC(G30*K30,1),"") -> 30336.9 | M30: =합산자재!J127 -> 0 | N30: =IF(G30*M30<>0, TRUNC(G30*M30,1),"") | P30: =IF(SUM(I30,L30,N30)<>0,TRUNC(SUM(I30,L30,N30),1),"") -> 30336.9 | AE30: =L30 -> 30336.9
A31: A0300000000 | B31: 제 5호 | C31: RENT000000000006 | D31: [ 공 구 손 료 ] | E31: 노무비의 3 % | F31: 식 | G31: 1 | H31: =IF(TRUNC((AD32+AC32)/$AE$3,1)*$AE$3-AD32 <0, AC32, TRUNC((AD32+AC32)/$AE$3,1)*$AE$3-AD32) -> 1064.9 | I31: =H31 -> 1064.9 | J31: 1 | L31: =IF(G31*K31<>0, TRUNC(G31*K31,1),"") | N31: =IF(G31*M31<>0, TRUNC(G31*M31,1),"") | P31: =IF(SUM(I31,L31,N31)<>0,TRUNC(SUM(I31,L31,N31),1),"") -> 1064.9
B32: 합계줄 | D32: ( 합 계 ) | I32: =TRUNC(SUM(I25:I31)) -> 24425 | L32: =TRUNC(SUM(L25:L31)) -> 35498 | N32: =TRUNC(SUM(N25:N31)) -> 0 | P32: =IF(SUM(I32,L32,N32)<>0,TRUNC(SUM(I32,L32,N32),1),"") -> 59923 | Z32: 노임계 | AC32: =TRUNC(AE32*옵션!$B$36/100,1) -> 1064.9 | AD32: =TRUNC(SUM(L25:L30)) -> 35498 | AE32: =TRUNC(SUM(AE25:AE31)) -> 35498
I33: =IF(G33*H33<>0, TRUNC(G33*H33,1),"") | L33: =IF(G33*K33<>0, TRUNC(G33*K33,1),"") | N33: =IF(G33*M33<>0, TRUNC(G33*M33,1),"") | P33: =IF(SUM(I33,L33,N33)<>0,TRUNC(SUM(I33,L33,N33),1),"")
A34: 56950010201 | B34: 일목줄 | C34: EBP110110000 | D34: [제 6호] 가로등 건주 기계화 시공 일반 5m-7m [식]
A35: CA565826045 | B35: 제 6호 | C35: ECA565826045 | D35: 크레인 | E35: 타이어 30 Ton | F35: 분 | G35: 33 | H35: =합산자재!H114 -> 276 | I35: =IF(G35*H35<>0, TRUNC(G35*H35,1),"") -> 9108 | J35: 33 | K35: =합산자재!I114 -> 984 | L35: =IF(G35*K35<>0, TRUNC(G35*K35,1),"") -> 32472 | M35: =합산자재!J114 -> 961 | N35: =IF(G35*M35<>0, TRUNC(G35*M35,1),"") -> 31713 | P35: =IF(SUM(I35,L35,N35)<>0,TRUNC(SUM(I35,L35,N35),1),"") -> 73293 | Q35: 184-하 | R35: ild
A36: 56900017016 | B36: 제 6호 | C36: L001010101000075 | D36: 노 무 비 | E36: 내선전공 | F36: 인 | G36: =일위노임!G19 -> 0.31 | H36: =합산자재!H115 -> 0 | I36: =IF(G36*H36<>0, TRUNC(G36*H36,1),"") | J36: 0.31 | K36: =합산자재!I115 -> 273676 | L36: =IF(G36*K36<>0, TRUNC(G36*K36,1),"") -> 84839.5 | M36: =합산자재!J115 -> 0 | N36: =IF(G36*M36<>0, TRUNC(G36*M36,1),"") | P36: =IF(SUM(I36,L36,N36)<>0,TRUNC(SUM(I36,L36,N36),1),"") -> 84839.5 | AE36: =L36 -> 84839.5
A37: A0300000000 | B37: 제 6호 | C37: RENT000000000006 | D37: [ 공 구 손 료 ] | E37: 노무비의 3 % | F37: 식 | G37: 1 | H37: =IF(TRUNC((AD38+AC38)/$AE$3,1)*$AE$3-AD38 <0, AC38, TRUNC((AD38+AC38)/$AE$3,1)*$AE$3-AD38) -> 2545.1 | I37: =H37 -> 2545.1 | J37: 1 | L37: =IF(G37*K37<>0, TRUNC(G37*K37,1),"") | N37: =IF(G37*M37<>0, TRUNC(G37*M37,1),"") | P37: =IF(SUM(I37,L37,N37)<>0,TRUNC(SUM(I37,L37,N37),1),"") -> 2545.1 | Z37: 노임계
B38: 합계줄 | D38: ( 합 계 ) | I38: =TRUNC(SUM(I34:I37)) -> 11653 | L38: =TRUNC(SUM(L34:L37)) -> 117311 | N38: =TRUNC(SUM(N34:N37)) -> 31713 | P38: =IF(SUM(I38,L38,N38)<>0,TRUNC(SUM(I38,L38,N38),1),"") -> 160677 | AC38: =TRUNC(AE38*옵션!$B$36/100,1) -> 2545.1 | AD38: =TRUNC(SUM(L34:L36)) -> 117311 | AE38: =TRUNC(SUM(AE34:AE37)) -> 84839
I39: =IF(G39*H39<>0, TRUNC(G39*H39,1),"") | L39: =IF(G39*K39<>0, TRUNC(G39*K39,1),"") | N39: =IF(G39*M39<>0, TRUNC(G39*M39,1),"") | P39: =IF(SUM(I39,L39,N39)<>0,TRUNC(SUM(I39,L39,N39),1),"")
A40: 56950010203 | B40: 일목줄 | C40: EBP110130000 | D40: [제 7호] 가로등 건주 기계화 시공 일반 10m-12m [식]
...

Sheet 일위노임
A1: 총줄수-> | B1: 289 | D1: [ 화성 청원지구 전기공사 ] - 일위노임 산출근거(202601-노임) | AA1: 내선전공 | AB1: 저압케이블전공 | AC1: 특고압케이블전공 | AD1: 배전전공 | AE1: 통신케이블공 | AF1: 통신설비공 | AG1: 통신외선공 | AH1: 통신관련산업기사 | AI1: 광케이블설치사 | AJ1: 보통인부 | AK1: 특별인부 | AL1: 비계공 | AM1: 형틀목공 | AN1: 줄눈공 | AO1: 콘크리트공 | AP1: H/W시험사 | AQ1: 작업반장
A2: 번호 | B2: 공종코드 | C2: 코드 | D2: 명 칭 | E2: 규 격 | F2: 단위 | G2: 수량 | K2: 코드 | L2: 공량산출 | P2: 단 위 단 가 산 출 | S2: 품셈근거 | T2: 비고
G3: 결정수량 | H3: 할증 | I3: 산출수량 | J3: 재할% | L3: 명칭 | M3: 품셈 | N3: 할증% | O3: 공량 | P3: 단가 | Q3: 단위단가 | R3: 단위계
B4: 공종줄 | D4: [ 제 3호 ] 인력잔토처리 현장처리 [㎥]
B5: 800 | C5: 391115ZZ701Z0059 | D5: 품셈 산출근거 | E5: 인력잔토처리 현장처리 | F5: 식 | G5: 1 | H5: =IF(I5<>0,G5-I5,"") -> 0 | I5: 1 | K5: 56900017041 | L5: 보통인부 | M5: 0.2 | N5: 100 | O5: =IF(I5*M5=0,"",I5*M5*(N5/100)) -> 0.2 | S5: 토목3-1-3-1 | AJ5: =O5 -> 0.2
B6: 800 | C6: L001010101000002 | D6: 노 무 비 | E6: 보통인부 | F6: 인 | G6: =IF(H6*I6/100+0.000005 <1, TRUNC(H6*I6/100+0.000005, 옵션!$E$13), TRUNC(H6*I6/100+0.000005, 옵션!$E$13)) -> 0.2 | H6: =옵션!$B$13 -> 100 | I6: =SUM(AJ5:AJ5) -> 0.2 | O6: =IF(I6*M6=0,"",I6*M6*(N6/100)) | AJ6: =SUM(AJ5:AJ5) -> 0.2
B7: 공종줄 | D7: [ 제 4호 ] 레미콘타설 무근(미할증) [㎥]
B8: 800 | C8: 391115ZZ701Z0057 | D8: 품셈 산출근거 | E8: 레미콘타설 무근(미할증) | F8: 식 | G8: 1 | H8: =IF(I8<>0,G8-I8,"") -> 0 | I8: 1 | K8: 56900017108 | L8: 콘크리트공 | M8: 0.12 | N8: 100 | O8: =IF(I8*M8=0,"",I8*M8*(N8/100)) -> 0.12 | S8: 토목6-1-1-1 | AO8: =O8 -> 0.12
B9: 800 | C9: 391115ZZ701Z0057 | G9: 1 | H9: =IF(I9<>0,G9-I9,"") -> 0 | I9: 1 | K9: 56900017041 | L9: 보통인부 | M9: 0.15 | N9: 100 | O9: =IF(I9*M9=0,"",I9*M9*(N9/100)) -> 0.15 | S9: 토목6-1-1-1 | AJ9: =O9 -> 0.15
B10: 800 | C10: L001010101000002 | D10: 노 무 비 | E10: 보통인부 | F10: 인 | G10: =IF(H10*I10/100+0.000005 <1, TRUNC(H10*I10/100+0.000005, 옵션!$E$13), TRUNC(H10*I10/100+0.000005, 옵션!$E$13)) -> 0.15 | H10: =옵션!$B$13 -> 100 | I10: =SUM(AJ8:AJ9) -> 0.15 | O10: =IF(I10*M10=0,"",I10*M10*(N10/100)) | AJ10: =SUM(AJ8:AJ9) -> 0.15 | AO10: =SUM(AO8:AO9) -> 0.12
B11: 800 | C11: L001010101000013 | D11: 노 무 비 | E11: 콘크리트공 | F11: 인 | G11: =IF(H11*I11/100+0.000005 <1, TRUNC(H11*I11/100+0.000005, 옵션!$E$13), TRUNC(H11*I11/100+0.000005, 옵션!$E$13)) -> 0.12 | H11: =옵션!$B$13 -> 100 | I11: =SUM(AO8:AO9) -> 0.12 | O11: =IF(I11*M11=0,"",I11*M11*(N11/100))
B12: 공종줄 | D12: [ 제 5호 ] 합판거푸집 4회 [㎡]
B13: 800 | C13: 391115ZZ701Z0061 | D13: 품셈 산출근거 | E13: 합판거푸집 4회(보통) | F13: 식 | G13: 1 | H13: =IF(I13<>0,G13-I13,"") -> 0 | I13: 1 | K13: 56900017137 | L13: 형틀목공 | M13: 0.11 | N13: 100 | O13: =IF(I13*M13=0,"",I13*M13*(N13/100)) -> 0.11 | AM13: =O13 -> 0.11
B14: 800 | C14: 391115ZZ701Z0061 | G14: 1 | H14: =IF(I14<>0,G14-I14,"") -> 0 | I14: 1 | K14: 56900017041 | L14: 보통인부 | M14: 0.03 | N14: 100 | O14: =IF(I14*M14=0,"",I14*M14*(N14/100)) -> 0.03 | AJ14: =O14 -> 0.03
B15: 800 | C15: L001010101000002 | D15: 노 무 비 | E15: 보통인부 | F15: 인 | G15: =IF(H15*I15/100+0.000005 <1, TRUNC(H15*I15/100+0.000005, 옵션!$E$13), TRUNC(H15*I15/100+0.000005, 옵션!$E$13)) -> 0.03 | H15: =옵션!$B$13 -> 100 | I15: =SUM(AJ13:AJ14) -> 0.03 | O15: =IF(I15*M15=0,"",I15*M15*(N15/100)) | AJ15: =SUM(AJ13:AJ14) -> 0.03 | AM15: =SUM(AM13:AM14) -> 0.11
B16: 800 | C16: L001010101000007 | D16: 노 무 비 | E16: 형틀목공 | F16: 인 | G16: =IF(H16*I16/100+0.000005 <1, TRUNC(H16*I16/100+0.000005, 옵션!$E$13), TRUNC(H16*I16/100+0.000005, 옵션!$E$13)) -> 0.11 | H16: =옵션!$B$13 -> 100 | I16: =SUM(AM13:AM14) -> 0.11 | O16: =IF(I16*M16=0,"",I16*M16*(N16/100))
B17: 공종줄 | D17: [ 제 6호 ] 가로등 건주 기계화 시공 일반 5m-7m [식]
B18: 800 | C18: 391115ZZ701Z0056 | D18: 품셈 산출근거 | E18: 건주 기계화 일반 5m-7m | F18: 식 | G18: 1 | H18: =IF(I18<>0,G18-I18,"") -> 0 | I18: 1 | K18: 56900017016 | L18: 내선전공 | M18: 0.31 | N18: 100 | O18: =IF(I18*M18=0,"",I18*M18*(N18/100)) -> 0.31 | S18: 전기5-27-나 | AA18: =O18 -> 0.31
B19: 800 | C19: L001010101000075 | D19: 노 무 비 | E19: 내선전공 | F19: 인 | G19: =IF(H19*I19/100+0.000005 <1, TRUNC(H19*I19/100+0.000005, 옵션!$E$13), TRUNC(H19*I19/100+0.000005, 옵션!$E$13)) -> 0.31 | H19: =옵션!$B$13 -> 100 | I19: =SUM(AA18:AA18) -> 0.31 | O19: =IF(I19*M19=0,"",I19*M19*(N19/100)) | AA19: =SUM(AA18:AA18) -> 0.31
B20: 공종줄 | D20: [ 제 7호 ] 가로등 건주 기계화 시공 일반 10m-12m [식]
B21: 800 | C21: 391115ZZ701Z0055 | D21: 품셈 산출근거 | E21: 건주 기계화 일반 10m-12m | F21: 식 | G21: 1 | H21: =IF(I21<>0,G21-I21,"") -> 0 | I21: 1 | K21: 56900017016 | L21: 내선전공 | M21: 0.42 | N21: 100 | O21: =IF(I21*M21=0,"",I21*M21*(N21/100)) -> 0.42 | S21: 전기5-27-나 | AA21: =O21 -> 0.42
B22: 800 | C22: L001010101000075 | D22: 노 무 비 | E22: 내선전공 | F22: 인 | G22: =IF(H22*I22/100+0.000005 <1, TRUNC(H22*I22/100+0.000005, 옵션!$E$13), TRUNC(H22*I22/100+0.000005, 옵션!$E$13)) -> 0.42 | H22: =옵션!$B$13 -> 100 | I22: =SUM(AA21:AA21) -> 0.42 | O22: =IF(I22*M22=0,"",I22*M22*(N22/100)) | AA22: =SUM(AA21:AA21) -> 0.42
B23: 공종줄 | D23: [ 제 9호 ] 인력터파기 보통토사0-1m [㎥]
B24: 800 | C24: 391115ZZ701Z0060 | D24: 품셈 산출근거 | E24: 인력터파기 보통토사 0-1M | F24: 식 | G24: 1 | H24: =IF(I24<>0,G24-I24,"") -> 0 | I24: 1 | K24: 56900017041 | L24: 보통인부 | M24: 0.2 | N24: 100 | O24: =IF(I24*M24=0,"",I24*M24*(N24/100)) -> 0.2 | S24: 토목3-1-3-1 | AJ24: =O24 -> 0.2
B25: 800 | C25: L001010101000002 | D25: 노 무 비 | E25: 보통인부 | F25: 인 | G25: =IF(H25*I25/100+0.000005 <1, TRUNC(H25*I25/100+0.000005, 옵션!$E$13), TRUNC(H25*I25/100+0.000005, 옵션!$E$13)) -> 0.2 | H25: =옵션!$B$13 -> 100 | I25: =SUM(AJ24:AJ24) -> 0.2 | O25: =IF(I25*M25=0,"",I25*M25*(N25/100)) | AJ25: =SUM(AJ24:AJ24) -> 0.2
B26: 공종줄 | D26: [ 제 10호 ] 인력되메우기 보통토사0-1m [㎥]
B27: 800 | C27: 391115ZZ701Z0058 | D27: 품셈 산출근거 | E27: 인력되메우기 보통토사 0-1M | F27: 식 | G27: 1 | H27: =IF(I27<>0,G27-I27,"") -> 0 | I27: 1 | K27: 56900017041 | L27: 보통인부 | M27: 0.1 | N27: 100 | O27: =IF(I27*M27=0,"",I27*M27*(N27/100)) -> 0.1 | S27: 토목3-1-3-1 | AJ27: =O27 -> 0.1
B28: 800 | C28: L001010101000002 | D28: 노 무 비 | E28: 보통인부 | F28: 인 | G28: =IF(H28*I28/100+0.000005 <1, TRUNC(H28*I28/100+0.000005, 옵션!$E$13), TRUNC(H28*I28/100+0.000005, 옵션!$E$13)) -> 0.1 | H28: =옵션!$B$13 -> 100 | I28: =SUM(AJ27:AJ27) -> 0.1 | O28: =IF(I28*M28=0,"",I28*M28*(N28/100)) | AJ28: =SUM(AJ27:AJ27) -> 0.1
B29: 공종줄 | D29: [ 제 11호 ] 파상형 폴리에틸렌 전선관 40㎜(가로등,신호,구내) [M.]
B30: 800 | C30: 3913170610035632 | D30: 파상형 폴리에틸렌 전선관 | E30: 40㎜(가로등,신호,구내) | F30: m | G30: 1 | H30: =IF(I30<>0,G30-I30,"") -> 0 | I30: 1 | K30: 56900017031 | L30: 배전전공 | M30: 0.007 | N30: 150 | O30: =IF(I30*M30=0,"",I30*M30*(N30/100)) -> 0.0105 | S30: 전기4-31 | AD30: =O30 -> 0.0105
B31: 800 | C31: 3913170610035632 | G31: 1 | H31: =IF(I31<>0,G31-I31,"") -> 0 | I31: 1 | K31: 56900017041 | L31: 보통인부 | M31: 0.018 | N31: 150 | O31: =IF(I31*M31=0,"",I31*M31*(N31/100)) -> 0.027 | S31: 전기4-31 | AJ31: =O31 -> 0.027
B32: 800 | C32: L001010101000081 | D32: 노 무 비 | E32: 배전전공 | F32: 인 | G32: =IF(H32*I32/100+0.000005 <1, TRUNC(H32*I32/100+0.000005, 옵션!$E$13), TRUNC(H32*I32/100+0.000005, 옵션!$E$13)) -> 0.0105 | H32: =옵션!$B$13 -> 100 | I32: =SUM(AD30:AD31) -> 0.0105 | O32: =IF(I32*M32=0,"",I32*M32*(N32/100)) | AD32: =SUM(AD30:AD31) -> 0.0105 | AJ32: =SUM(AJ30:AJ31) -> 0.027
B33: 800 | C33: L001010101000002 | D33: 노 무 비 | E33: 보통인부 | F33: 인 | G33: =IF(H33*I33/100+0.000005 <1, TRUNC(H33*I33/100+0.000005, 옵션!$E$13), TRUNC(H33*I33/100+0.000005, 옵션!$E$13)) -> 0.027 | H33: =옵션!$B$13 -> 100 | I33: =SUM(AJ30:AJ31) -> 0.027 | O33: =IF(I33*M33=0,"",I33*M33*(N33/100))
B34: 공종줄 | D34: [ 제 12호 ] 파상형 폴리에틸렌 전선관 50㎜(가로등,신호,구내) [M.]
B35: 800 | C35: 3913170610035633 | D35: 파상형 폴리에틸렌 전선관 | E35: 50㎜(가로등,신호,구내) | F35: m | G35: 1 | H35: =IF(I35<>0,G35-I35,"") -> 0 | I35: 1 | K35: 56900017031 | L35: 배전전공 | M35: 0.007 | N35: 150 | O35: =IF(I35*M35=0,"",I35*M35*(N35/100)) -> 0.0105 | S35: 전기4-31 | AD35: =O35 -> 0.0105
B36: 800 | C36: 3913170610035633 | G36: 1 | H36: =IF(I36<>0,G36-I36,"") -> 0 | I36: 1 | K36: 56900017041 | L36: 보통인부 | M36: 0.018 | N36: 150 | O36: =IF(I36*M36=0,"",I36*M36*(N36/100)) -> 0.027 | S36: 전기4-31 | AJ36: =O36 -> 0.027
B37: 800 | C37: L001010101000081 | D37: 노 무 비 | E37: 배전전공 | F37: 인 | G37: =IF(H37*I37/100+0.000005 <1, TRUNC(H37*I37/100+0.000005, 옵션!$E$13), TRUNC(H37*I37/100+0.000005, 옵션!$E$13)) -> 0.0105 | H37: =옵션!$B$13 -> 100 | I37: =SUM(AD35:AD36) -> 0.0105 | O37: =IF(I37*M37=0,"",I37*M37*(N37/100)) | AD37: =SUM(AD35:AD36) -> 0.0105 | AJ37: =SUM(AJ35:AJ36) -> 0.027
B38: 800 | C38: L001010101000002 | D38: 노 무 비 | E38: 보통인부 | F38: 인 | G38: =IF(H38*I38/100+0.000005 <1, TRUNC(H38*I38/100+0.000005, 옵션!$E$13), TRUNC(H38*I38/100+0.000005, 옵션!$E$13)) -> 0.027 | H38: =옵션!$B$13 -> 100 | I38: =SUM(AJ35:AJ36) -> 0.027 | O38: =IF(I38*M38=0,"",I38*M38*(N38/100))
B39: 공종줄 | D39: [ 제 13호 ] 파상형 폴리에틸렌 전선관 65㎜(가로등,신호,구내) [M.]
B40: 800 | C40: 3913170610035634 | D40: 파상형 폴리에틸렌 전선관 | E40: 65㎜(가로등,신호,구내) | F40: m | G40: 1 | H40: =IF(I40<>0,G40-I40,"") -> 0 | I40: 1 | K40: 56900017031 | L40: 배전전공 | M40: 0.009 | N40: 150 | O40: =IF(I40*M40=0,"",I40*M40*(N40/100)) -> 0.0135 | S40: 전기4-31 | AD40: =O40 -> 0.0135
...

Sheet 단가조사
A1: 총줄수-> | B1: 153 | D1: [ 화성 청원지구 전기공사 ] - 단가조사서(1/6단가:2026년02월)
A2: 번호 | B2: 공종코드 | C2: 코드 | D2: 명 칭 | E2: 규 격 | F2: 단위 | G2: 적용단가 | H2: 시설단가 | J2: 거래가격 | L2: 물가정보 | N2: 물가자료 | P2: 조사단가1 | R2: 조사단가2 | T2: 비고
H3: 단가 | I3: 코드 | J3: 단가 | K3: PAGE | L3: 단가 | M3: PAGE | N3: 단가 | O3: PAGE | P3: 단가 | Q3: PAGE | R3: 단가 | S3: PAGE
C4: 3913170610035632 | D4: 파상형 폴리에틸렌 전선관 | E4: 40㎜(가로등,신호,구내) | F4: m | G4: =MIN(H4,J4,L4,N4,P4) -> 563 | J4: 563 | K4: 1025 | L4: 607 | M4: 1-1203
C5: 3913170610035633 | D5: 파상형 폴리에틸렌 전선관 | E5: 50㎜(가로등,신호,구내) | F5: m | G5: =MIN(H5,J5,L5,N5,P5) -> 750 | J5: 750 | K5: 1025 | L5: 860 | M5: 1-1203
C6: 3913170610035634 | D6: 파상형 폴리에틸렌 전선관 | E6: 65㎜(가로등,신호,구내) | F6: m | G6: =MIN(H6,J6,L6,N6,P6) -> 1239 | J6: 1250 | K6: 1025 | L6: 1239 | M6: 1-1203
C7: 3913170610035635 | D7: 파상형 폴리에틸렌 전선관 | E7: 80㎜(가로등,신호,구내) | F7: m | G7: =MIN(H7,J7,L7,N7,P7) -> 1632 | J7: 1719 | K7: 1025 | L7: 1632 | M7: 1-1203
C8: 3913170610035636 | D8: 파상형 폴리에틸렌 전선관 | E8: 100㎜(가로등,신호,구내) | F8: m | G8: =MIN(H8,J8,L8,N8,P8) -> 2188 | J8: 2188 | K8: 1025 | L8: 2214 | M8: 1-1203
C9: 3913170610045632 | D9: 파상형 폴리에틸렌 전선관 | E9: 40㎜ | F9: m | G9: =MIN(H9,J9,L9,N9,P9) -> 563 | J9: 563 | K9: 1025 | L9: 607 | M9: 1-1203
C10: 3913170610045633 | D10: 파상형 폴리에틸렌 전선관 | E10: 50㎜ | F10: m | G10: =MIN(H10,J10,L10,N10,P10) -> 750 | J10: 750 | K10: 1025 | L10: 860 | M10: 1-1203
C11: 3913170620175668 | D11: 광케블내외관일체형전선관 | E11: COD 36-4 공 | F11: m | G11: =MIN(H11,J11,L11,N11,P11) -> 27000 | J11: 27000 | K11: 1024 | L11: 27000 | M11: 1-1200
C12: 2612152420683697 | D12: 접지용비닐절연전선(F-GV)_지중 | E12: 6㎟ | F12: m | G12: =MIN(H12,J12,L12,N12,P12) -> 1612 | J12: 1658 | K12: 994 | L12: 1612 | M12: 1-1165
C13: 2612152420683698 | D13: 접지용비닐절연전선(F-GV) | E13: 10㎟ | F13: m | G13: =MIN(H13,J13,L13,N13,P13) -> 2717 | L13: 2717 | M13: 1-1165
C14: 2612152420683699 | D14: 접지용비닐절연전선(F-GV) | E14: 16㎟ | F14: m | G14: =MIN(H14,J14,L14,N14,P14) -> 3579 | J14: 3579 | K14: 994 | L14: 3710 | M14: 1-1165
C15: 2612162920683902 | D15: 폴리에틸렌 난연케이블 | E15: 0.6/1kv F-CV 2C×2.5㎟ | F15: m | G15: =MIN(H15,J15,L15,N15,P15) -> 1859 | J15: 2002 | K15: 993 | L15: 1859 | M15: 1-1168
C16: 2612162921683903 | D16: 폴리에틸렌 난연케이블(옥외) | E16: 0.6/1kv F-CV 2C×6㎟ | F16: m | G16: =MIN(H16,J16,L16,N16,P16) -> 2907 | J16: 3561 | K16: 993 | L16: 2907 | M16: 1-1164
C17: 2612162921683904 | D17: 폴리에틸렌 난연케이블(옥외) | E17: 0.6/1kv F-CV 2C×10㎟ | F17: m | G17: =MIN(H17,J17,L17,N17,P17) -> 4423 | J17: 5417 | K17: 993 | L17: 4423 | M17: 1-1164
C18: 2612162921683905 | D18: 폴리에틸렌 난연케이블(옥외) | E18: 0.6/1kv F-CV 2C×16㎟ | F18: m | G18: =MIN(H18,J18,L18,N18,P18) -> 6915 | J18: 7689 | K18: 993 | L18: 6915 | M18: 1-1164
C19: 2612162921683906 | D19: 폴리에틸렌 난연케이블(옥외) | E19: 0.6/1kv F-CV 2C×25㎟ | F19: m | G19: =MIN(H19,J19,L19,N19,P19) -> 10580 | J19: 11765 | K19: 993 | L19: 10580 | M19: 1-1164
C20: 2612162921683907 | D20: 폴리에틸렌 난연케이블(옥외) | E20: 0.6/1kv F-CV 2C×35㎟ | F20: m | G20: =MIN(H20,J20,L20,N20,P20) -> 14046 | J20: 15619 | K20: 993 | L20: 14046 | M20: 1-1164
C21: 2612162920683923 | D21: 폴리에틸렌 난연케이블 | E21: 0.6/1kv F-CV 3C×6㎟ | F21: m | G21: =MIN(H21,J21,L21,N21,P21) -> 4722 | J21: 5086 | K21: 993 | L21: 4722 | M21: 1-1168
C22: 2612162921683945 | D22: 폴리에틸렌 난연케이블(옥외) | E22: 0.6/1kv F-CV 4C×6㎟ | F22: m | G22: =MIN(H22,J22,L22,N22,P22) -> 5058 | J22: 6193 | K22: 993 | L22: 5058 | M22: 1-1164
C23: 2612162921683946 | D23: 폴리에틸렌 난연케이블(옥외) | E23: 0.6/1kv F-CV 4C×10㎟ | F23: m | G23: =MIN(H23,J23,L23,N23,P23) -> 8027 | J23: 9830 | K23: 993 | L23: 8027 | M23: 1-1164
C24: 2612162921683948 | D24: 폴리에틸렌 난연케이블(옥외) | E24: 0.6/1kv F-CV 4C×25㎟ | F24: m | G24: =MIN(H24,J24,L24,N24,P24) -> 19933 | J24: 22165 | K24: 993 | L24: 19933 | M24: 1-1164
C25: 2612160320684239 | D25: 난연제어케이블 | E25: F-CVV 5Cx2.5㎟ | F25: m | G25: =MIN(H25,J25,L25,N25,P25) -> 3309 | J25: 3309 | K25: 995 | L25: 4340 | M25: 1-1171
C26: 2612163720177109 | D26: 광케이블(옥외용) | E26: SM 9/125, 4c | F26: m | G26: =MIN(H26,J26,L26,N26,P26) -> 1000 | L26: 1457 | M26: 1170 | N26: 1000 | O26: 1081
C27: 4616150420191801 | D27: 신호 제어기 | E27: 경보제어기, 전자회로 | F27: 대 | G27: =MIN(H27,J27,L27,N27,P27) -> 200000 | L27: 250000 | M27: 1301 | N27: 200000 | O27: 1240
C28: 3912161310034844 | D28: 접지봉 | E28: 14Φ×1000 mm | F28: 개 | G28: =MIN(H28,J28,L28,N28,P28) -> 5780 | L28: 6500 | M28: 1-1271 | N28: 5780 | O28: 1198
C29: 3912161320937692 | D29: 접지크램프(IEC 90) | E29: 16sq | F29: 개 | G29: =MIN(H29,J29,L29,N29,P29) -> 500 | L29: 600 | M29: 1272 | N29: 500 | O29: 1198
C30: 3912218220173434 | D30: 케이블표지시트 | E30: 0.23x400 | F30: m | G30: =MIN(H30,J30,L30,N30,P30) -> 180 | N30: 180 | O30: 747
C31: 3912143221650911 | D31: 압착단자 | E31: R형동선 나압착 16 ㎟ | F31: 개 | G31: =MIN(H31,J31,L31,N31,P31) -> 200 | J31: 200 | K31: 1019 | L31: 528 | M31: 1-1231
C32: 3912143221650912 | D32: 압착단자 | E32: R형동선 나압착 25 ㎟ | F32: 개 | G32: =MIN(H32,J32,L32,N32,P32) -> 260 | J32: 260 | K32: 1019 | L32: 647 | M32: 1-1231
C33: 3912143221650913 | D33: 압착단자 | E33: R형동선 나압착 35 ㎟ | F33: 개 | G33: =MIN(H33,J33,L33,N33,P33) -> 316 | J33: 316 | K33: 1019 | L33: 822 | M33: 1-1231
C34: 3012169821869021 | D34: 핸드홀 | E34: 수공1호 | F34: 조 | G34: =MIN(H34,J34,L34,N34,P34) -> 110000 | L34: 110000 | M34: 1-208
C35: 3012169821869024 | D35: 핸드홀카바 | E35: 통신용 | F35: 기 | G35: =MIN(H35,J35,L35,N35,P35) -> 370000 | L35: 370000 | M35: 206
C36: 3010369820141038 | D36: 각재(角材) | E36: 외송(㎥) | F36: ㎥ | G36: =MIN(H36,J36,L36,N36,P36) -> 1326000 | L36: 1326000
C37: 1112200120142458 | D37: 내수합판 | E37: 1급, 12×1220×2440mm | F37: ㎡ | G37: =MIN(H37,J37,L37,N37,P37) -> 10900 | L37: 10900 | M37: 1-587
C38: 391115ZZ801Z2008 | D38: 레미콘 | E38: 25-210-8 | F38: ㎥ | G38: =MIN(H38,J38,L38,N38,P38) -> 101280 | N38: 101280 | O38: 71
C39: 391189ZZ701Z0100 | D39: 전주용입상관 | E39: Φ130*2t*2m | F39: EA | G39: =MIN(H39,J39,L39,N39,P39) -> 35090 | L39: 35090 | M39: 1165
C40: 391190ZZ701Z0100 | D40: 반경관취부밴드 | F40: EA | G40: =MIN(H40,J40,L40,N40,P40) -> 2424 | L40: 2424 | M40: 1164
...

Sheet 이후출력안함

Sheet 옵션
B1: 재료비 | C1: 노무비 | D1: 경비 | F1: 계
A2: 총 급 액 | B2: =총괄표!I29 -> 0 | C2: =총괄표!L29 -> 0 | D2: =총괄표!N29 -> 0 | F2: =SUM(B2,C2,D2) -> 0
A3: 관급 자재비 | F3: =SUM(B3,C3,D3) -> 0 | H3: 금액조정이 안되나요?
H6: 이지테크에서 변환할 때 2번 옵션을 지정하여 다시 해보세요
H9: 시트를 삭제할 때 에러가 뜨면 1번 옵션으로 하면 됩니다.
B10: 적용율(%) | C10: 끝자리 | D10: 적용율(%)/100 | E10: 일위대가소수
A11: 전체자재 적용율(%)(공종/일위대가) | B11: 100 | C11: 1 | D11: =$B$11/100 -> 1
A12: 전체노임 적용율(%)(공종) | B12: 100 | C12: 1 | D12: =$B$12/100 -> 1 | E12: 2 | H12: 2번 옵션으로 변환했을 때에는 결과값이 다를 수 있습니다.
A13: 전체노임 적용율(%)(일위대가) | B13: 100 | C13: 1 | D13: =$B$13/100 -> 1 | E13: 5
A20: *(그룹별 자재 단가 추가 할증)* | B20: 적용율(%) | D20: 적용율(%)/100
A21: Cable(CAB) 할증(%) | B21: =B11 -> 100 | D21: =$B$21/100 -> 1
A22: Wire (WIR) 할증(%) | B22: =B11 -> 100 | D22: =$B$22/100 -> 1
A23: Pipe (PIP) 할증(%) | B23: =B11 -> 100 | D23: =$B$23/100 -> 1
A24: 제 4그룹 할증(%) | B24: =B11 -> 100 | D24: =$B$24/100 -> 1
A25: 제 5그룹 할증(%) | B25: =B11 -> 100 | D25: =$B$25/100 -> 1
A30: *(그룹별 노임 추가 할증)* | B30: 적용율(%) | C30: 자동부속재(전기) | D30: 자동부속재(통신)
A31: 배관부속재(%) | B31: 15 | C31: 15 | D31: 20
A32: CD관부속재(%) | B32: 40 | C32: 40 | D32: 40
A33: 소모잡자재(%) | B33: 2 | H33: 본 파일은 이지테크에서 2번 옵션으로 만들었습니다.
A34: 방폭할증(%)
A35: 고소할증(%) | B35: 2
A36: 공구손료(%) | B36: 3
A40: *(공종별 노임 적용율(%))* | B40: 적용율(%) | C40: 소수자릿수
A41: 1-1.가로등설비공사 | B41: 100 | C41: 3
A42: 1-2.공원등설비공사 | B42: 100 | C42: 3
A43: 1-3.신호등설비공사 | B43: 100 | C43: 3
A44: 1-4.공원 통신설비 공사 | B44: 100 | C44: 3
A45: 1-5.불법주정차단속시스템 | B45: 100 | C45: 3
A46: 2-1.가로등설비공사 | B46: 100 | C46: 3
A47: 2-2.신호등설비공사 | B47: 100 | C47: 3
A48: 2-3.불법주정차단속시스템 | B48: 100 | C48: 3

Sheet 사용설명
B1: ** 반드시 다음 사항을 숙지하신 다음 수정 작업을 하십시오 **
A2: 1. | B2: 속성이 숫자인 셀을 삭제할 때는 반드시 'Delete' 키를 사용하십시오.
B3: **주의:'Space Bar' 로 지웠을 때는 '#Value' Error가 발생됩니다.
A4: 2. | B4: 일위대가(을지)는 소수점 처리 때문에 셀 속성을 '일반'으로 하였습니다.(소수점 능동 처리)
B5: **참고: (수량*단가)의 결과는 소수 한자리, 금액을 취합한 소계는 1원 이하 절사입니다.
A6: 3. | B6: 내역서에서는 수량에만 셀 속성을 '일반'으로 하였습니다.(소수점 능동 처리)
A7: 4. | B7: 단가수정은 '단가조사서'시트 에서 하십시오.
B8: a)표지와 원가 -> 총괄표 -> 내역서 ->일위대가와 합산자재 ->단가조사서 를 참조하고
B9: 있으므로 단가조사서의 결정단가를 수정하면 전체 금액이 갱신됩니다.
B10: **주의: 금액란은 공식이 걸려있으므로 조심하여 수정하십시오.
B11: b)전체 자재를 일정 요율(%)로 변경할 때는 옵션시트의 자재 적용율을 조정하면 됩니다.
A12: 5. | B12: 노임 단가는 '단가조사서'시트에서 품셈은 '노임근거'시트에서 수정하십시오.
B13: a)전체 노임을 일정 요율(%)로 변경할 때는 '옵션시트'의 전체노임 적용율을 조정하면 됩니다.
B14: b)공종별로 노임을 수정하려면 '옵션시트'의 공종별 노임 적용율을 조정하면 됩니다.
B15: c)케이블 및 전선 자재 단가를 추가로 조정하려면 그룹별 자재 적용율을 조정하면 됩니다.
B16: 그룹은 견적 프로그램에서 엑셀파일이 만들어질때 지정됩니다.
A17: 6. | B17: 겉표지의 모든 정보는 표지를 참조하였습니다.(정보 수정은 표지에서만 하시면 됩니다.)
A18: 7. | B18: 필수 :본 프로그램의 총 금액을 확인한 후 사용하십시오.
A19: 8. | B19: 본 파일의 내용을 인쇄할 경우, 미리보기를 통하여 페이지 절선을 확인 후 인쇄하십시오.
A20: 9. | B20: 관급자재 Sheet가 해당이 없을 경우엔 삭제하십시오.
A21: 10. | B21: 페이지 절선이 맞지 않으면 다음을 참고하십시오.
B33: a. 해당시트의 셀 전체를 선택합니다.
B34: b. 행높이를 적절히 가감하면 페이지 절선을 맞출 수 있습니다.

Sheet 겉표지
A1: =표지!A1 -> 見 積 書 | Z1: 견적가로형식-1
C18: 件 名: | D18: =표지!C13 -> 화성 청원지구 전기공사
C20: 提 出 處: | D20: =표지!C4 -> 貴下
C22: 提 出 日: | D22: =표지!C6 -> 2026년 4월 1일
D36: =표지!I3 -> 대 한 민 국 주 식 회 사
D37: =표지!I4
D38: =표지!I5 -> ㅇ ㅇ 시 ㅇ ㅇ 구 ㅇ ㅇ 동
D39: =표지!I6
D40: =표지!I7 -> 대표이사 홍 길 동
D41: =표지!I8
D42: =표지!I9 -> 대표전화 (02) 0 0 0 - 0 0 0 0
D43: =표지!I10
D44: =표지!I11 -> 팩 스 (02) 0 0 0 - 0 0 0 0
D45: =표지!I12
D46: =표지!I13

Sheet 표지
A1: 見 積 書
I3: 대 한 민 국 주 식 회 사
B4: 제 출 처: | C4: 貴下
I5: ㅇ ㅇ 시 ㅇ ㅇ 구 ㅇ ㅇ 동
B6: 제 출 일: | C6: 2026년 4월 1일
I7: 대표이사 홍 길 동
B8: 아래와 같이 見積書를 제출합니다.
I9: 대표전화 (02) 0 0 0 - 0 0 0 0
I11: 팩 스 (02) 0 0 0 - 0 0 0 0
B13: 공 사 명: | C13: 화성 청원지구 전기공사
B15: 공사금액: | C15: ="一金"&NUMBERSTRING(F40,2)&"원整("&DOLLAR(F40,0)&")" -> 一金零원整(₩0)
B17: 내 용 | D17: 단위 | E17: 수량 | F17: 금 액 | H17: 비 고 | M17: 요율 | N17: 금액 | O17: 이윤 | P17: 끝자리맞추기
B18: 재 료 비 | D18: 식 | E18: 1 | F18: =옵션!$B$2 -> 0 | N18: =E18*F18 -> 0
B19: 노 무 비 | D19: 식 | E19: 1 | F19: =옵션!$C$2 -> 0 | N19: =E19*F19 -> 0
B20: 간 접 노 무 비 | D20: 식 | E20: 1 | F20: =TRUNC((F19)*M20/100) -> 0 | H20: (직접 노무비) * 15.2 % | M20: 15.2 | N20: =E20*F20 -> 0
B21: ( 소 계 ) | F21: =SUM(F18:F20) -> 0 | N21: =E21*F21 -> 0
B22: 기 계 경 비 | D22: 식 | E22: 1 | F22: =옵션!$D$2 -> 0 | N22: =E22*F22 -> 0
B23: 산 재 보 험 료 | D23: 식 | E23: 1 | F23: =TRUNC((F19+F20)*M23/100) -> 0 | H23: (노무비) * 3.56 % | M23: 3.56 | N23: =E23*F23 -> 0
B24: 고 용 보 험 료 | D24: 식 | E24: 1 | F24: =TRUNC((F19+F20)*M24/100) -> 0 | H24: (노무비) * 1.01 % | M24: 1.01 | N24: =E24*F24 -> 0
B25: 건 강 보 험 료 | D25: 식 | E25: 1 | F25: =TRUNC((F19)*M25/100) -> 0 | H25: (직접 노무비) * 3.595 % | M25: 3.595 | N25: =E25*F25 -> 0
B26: 연 금 보 험 료 | D26: 식 | E26: 1 | F26: =TRUNC((F19)*M26/100) -> 0 | H26: (직접 노무비) * 4.75 % | M26: 4.75 | N26: =E26*F26 -> 0
B27: 퇴 직 금 공 제 | D27: 식 | E27: 1 | F27: =TRUNC((F19)*M27/100) -> 0 | H27: (직접 노무비) * 2.3 % | M27: 2.3 | N27: =E27*F27 -> 0
B28: 안 전 관 리 비 | D28: 식 | E28: 1 | F28: =TRUNC((F18+F19+0/1.1)*M28/100) -> 0 | H28: (재료+직노+관급재/1.1) * 3.11 % | M28: 3.11 | N28: =E28*F28 -> 0
B29: 기 타 경 비 | D29: 식 | E29: 1 | F29: =TRUNC((F21)*M29/100) -> 0 | H29: (재료+노무) * 4.7 % | M29: 4.7 | N29: =E29*F29 -> 0
B30: 노인장기요양보험 | D30: 식 | E30: 1 | F30: =TRUNC((F25)*M30/100) -> 0 | H30: (건강 보험료) * 13.14 % | M30: 13.14 | N30: =E30*F30 -> 0
B31: ( 소 계 ) | F31: =SUM(F22:F30) -> 0 | N31: =E31*F31 -> 0
B32: 일 반 관 리 비 | D32: 식 | E32: 1 | F32: =TRUNC((F21+F31)*M32/100) -> 0 | H32: (재료+노무+경비) * 8 % | M32: 8 | N32: =E32*F32 -> 0
B33: 이 윤 | D33: 식 | E33: 1 | F33: =O33-((SUM(N18:N32)+O33-TRUNC((SUM(N18:N32)+O33)/P33)*P33)) -> 0 | H33: (노무+경비+일반관리비) * 15 % | M33: 15 | N33: =E33*F33 -> 0 | O33: =TRUNC((F19+F20+F31+F32)*M33/100) -> 0 | P33: 100000
B34: ( 총 원 가 ) | F34: =SUM(N18:N33) -> 0 | N34: =E34*F34 -> 0
B35: 부 가 가 치 세 | D35: 식 | E35: 1 | F35: =TRUNC((F34)*M35/100) -> 0 | M35: 10 | N35: =E35*F35 -> 0
N36: =E36*F36 -> 0
N37: =E37*F37 -> 0
N38: =E38*F38 -> 0
N39: =E39*F39 -> 0
B40: ( 총 계 ) | F40: =N40 -> 0 | N40: =SUM(N18:N39) -> 0
B41: 1. 부가가치세 별도
B42: 2. 한전불입금 별도

Sheet 합산자재
A1: 총줄수-> | B1: 133 | C1: [ 화성 청원지구 전기공사 ] - 합산자재목록
A2: 번호 | B2: … | C2: 코드 | D2: 명 칭 | E2: 규 격 | F2: 단위 | G2: 수량 | H2: 재료비 | I2: 노무비 | J2: 경비 | K2: 지급비 | L2: 계 | M2: 비고
C4: 3913170610035632 | D4: 파상형 폴리에틸렌 전선관 | E4: 40㎜(가로등,신호,구내) | F4: m | G4: 4049.96 | H4: =TRUNC(단가조사!G4*옵션!$D$11) -> 563 | L4: =SUM(H4,I4,J4) -> 563
C5: 3913170610035633 | D5: 파상형 폴리에틸렌 전선관 | E5: 50㎜(가로등,신호,구내) | F5: m | G5: 306.94 | H5: =TRUNC(단가조사!G5*옵션!$D$11) -> 750 | L5: =SUM(H5,I5,J5) -> 750
C6: 3913170610035634 | D6: 파상형 폴리에틸렌 전선관 | E6: 65㎜(가로등,신호,구내) | F6: m | G6: 11.33 | H6: =TRUNC(단가조사!G6*옵션!$D$11) -> 1239 | L6: =SUM(H6,I6,J6) -> 1239
C7: 3913170610035635 | D7: 파상형 폴리에틸렌 전선관 | E7: 80㎜(가로등,신호,구내) | F7: m | G7: 28.84 | H7: =TRUNC(단가조사!G7*옵션!$D$11) -> 1632 | L7: =SUM(H7,I7,J7) -> 1632
C8: 3913170610035636 | D8: 파상형 폴리에틸렌 전선관 | E8: 100㎜(가로등,신호,구내) | F8: m | G8: 179.22 | H8: =TRUNC(단가조사!G8*옵션!$D$11) -> 2188 | L8: =SUM(H8,I8,J8) -> 2188
C9: 3913170610045632 | D9: 파상형 폴리에틸렌 전선관 | E9: 40㎜ | F9: m | G9: 140.08 | H9: =TRUNC(단가조사!G9*옵션!$D$11) -> 563 | L9: =SUM(H9,I9,J9) -> 563
C10: 3913170610045633 | D10: 파상형 폴리에틸렌 전선관 | E10: 50㎜ | F10: m | G10: 140.08 | H10: =TRUNC(단가조사!G10*옵션!$D$11) -> 750 | L10: =SUM(H10,I10,J10) -> 750
