Workbook

Sheet 내역서
A1: 내 역 서
A2: 2026년 상반기 충청남도교육청 건설공사 일위대가(토목, 조경)
A3: 품 명 | B3: 규 격 | C3: 단위 | D3: 수량 | E3: 재 료 비 | G3: 노 무 비 | I3: 경 비 | K3: 합 계 | M3: 비 고
E4: 단 가 | F4: 금 액 | G4: 단 가 | H4: 금 액 | I4: 단 가 | J4: 금 액 | K4: 단 가 | L4: 금 액
A5: (☞ 사각지대 충돌방지장치)------- | E5: =TRUNC(단가대비표!O194,0) -> 0 | F5: =TRUNC(E5*D5, 0) -> 0 | G5: =TRUNC(단가대비표!P194,0) -> 0 | H5: =TRUNC(G5*D5, 0) -> 0 | I5: =TRUNC(단가대비표!V194,0) -> 0 | J5: =TRUNC(I5*D5, 0) -> 0 | K5: =TRUNC(E5+G5+I5, 0) -> 0 | L5: =TRUNC(F5+H5+J5, 0) -> 0
A6: 사각지대 충돌방지장치 설치 및 해체 | C6: 개당 | D6: 1 | E6: =TRUNC(일위대가목록!E4,0) -> 0 | F6: =TRUNC(E6*D6, 0) -> 0 | G6: =TRUNC(일위대가목록!F4,0) -> 127366 | H6: =TRUNC(G6*D6, 0) -> 127366 | I6: =TRUNC(일위대가목록!G4,0) -> 1273 | J6: =TRUNC(I6*D6, 0) -> 1273 | K6: =TRUNC(E6+G6+I6, 0) -> 128639 | L6: =TRUNC(F6+H6+J6, 0) -> 128639 | M6: 호표 1
A7: (☞ 박스형 간이흙막이 설치 및 해체)------- | E7: =TRUNC(단가대비표!O311,0) -> 0 | F7: =TRUNC(E7*D7, 0) -> 0 | G7: =TRUNC(단가대비표!P311,0) -> 0 | H7: =TRUNC(G7*D7, 0) -> 0 | I7: =TRUNC(단가대비표!V311,0) -> 0 | J7: =TRUNC(I7*D7, 0) -> 0 | K7: =TRUNC(E7+G7+I7, 0) -> 0 | L7: =TRUNC(F7+H7+J7, 0) -> 0
A8: 박스형 간이흙막이 설치 및 해체 | B8: H=3.0M 이하, 개당 길이=3.0M 이하, 폭=2.0M 이하 | C8: 개 | D8: 1 | E8: =TRUNC(일위대가목록!E5,0) -> 4286 | F8: =TRUNC(E8*D8, 0) -> 4286 | G8: =TRUNC(일위대가목록!F5,0) -> 61706 | H8: =TRUNC(G8*D8, 0) -> 61706 | I8: =TRUNC(일위대가목록!G5,0) -> 6186 | J8: =TRUNC(I8*D8, 0) -> 6186 | K8: =TRUNC(E8+G8+I8, 0) -> 72178 | L8: =TRUNC(F8+H8+J8, 0) -> 72178 | M8: 호표 2
A9: 박스형 간이흙막이 설치 및 해체 | B9: H=4.0M 이하, 개당 길이=3.0M 이하, 폭=2.0M 이하 | C9: 개 | D9: 1 | E9: =TRUNC(일위대가목록!E6,0) -> 7254 | F9: =TRUNC(E9*D9, 0) -> 7254 | G9: =TRUNC(일위대가목록!F6,0) -> 91657 | H9: =TRUNC(G9*D9, 0) -> 91657 | I9: =TRUNC(일위대가목록!G6,0) -> 10469 | J9: =TRUNC(I9*D9, 0) -> 10469 | K9: =TRUNC(E9+G9+I9, 0) -> 109380 | L9: =TRUNC(F9+H9+J9, 0) -> 109380 | M9: 호표 3
A10: (☞ 조립식 간이흙막이 설치 및 해체)------- | E10: =TRUNC(단가대비표!O312,0) -> 0 | F10: =TRUNC(E10*D10, 0) -> 0 | G10: =TRUNC(단가대비표!P312,0) -> 0 | H10: =TRUNC(G10*D10, 0) -> 0 | I10: =TRUNC(단가대비표!V312,0) -> 0 | J10: =TRUNC(I10*D10, 0) -> 0 | K10: =TRUNC(E10+G10+I10, 0) -> 0 | L10: =TRUNC(F10+H10+J10, 0) -> 0
A11: 조립식 간이흙막이 설치 및 해체 | B11: H=3.0M 이하 | C11: M | D11: 1 | E11: =TRUNC(일위대가목록!E7,0) -> 7584 | F11: =TRUNC(E11*D11, 0) -> 7584 | G11: =TRUNC(일위대가목록!F7,0) -> 77905 | H11: =TRUNC(G11*D11, 0) -> 77905 | I11: =TRUNC(일위대가목록!G7,0) -> 10945 | J11: =TRUNC(I11*D11, 0) -> 10945 | K11: =TRUNC(E11+G11+I11, 0) -> 96434 | L11: =TRUNC(F11+H11+J11, 0) -> 96434 | M11: 호표 4
A12: 조립식 간이흙막이 설치 및 해체 | B12: H=4.0M 이하 | C12: M | D12: 1 | E12: =TRUNC(일위대가목록!E8,0) -> 14839 | F12: =TRUNC(E12*D12, 0) -> 14839 | G12: =TRUNC(일위대가목록!F8,0) -> 125321 | H12: =TRUNC(G12*D12, 0) -> 125321 | I12: =TRUNC(일위대가목록!G8,0) -> 21415 | J12: =TRUNC(I12*D12, 0) -> 21415 | K12: =TRUNC(E12+G12+I12, 0) -> 161575 | L12: =TRUNC(F12+H12+J12, 0) -> 161575 | M12: 호표 5
A13: 조립식 간이흙막이 설치 및 해체 | B13: H=5.0M 이하 | C13: M | D13: 1 | E13: =TRUNC(일위대가목록!E9,0) -> 24402 | F13: =TRUNC(E13*D13, 0) -> 24402 | G13: =TRUNC(일위대가목록!F9,0) -> 189930 | H13: =TRUNC(G13*D13, 0) -> 189930 | I13: =TRUNC(일위대가목록!G9,0) -> 35216 | J13: =TRUNC(I13*D13, 0) -> 35216 | K13: =TRUNC(E13+G13+I13, 0) -> 249548 | L13: =TRUNC(F13+H13+J13, 0) -> 249548 | M13: 호표 6
A14: 조립식 간이흙막이 설치 및 해체 | B14: H=6.0M 이하 | C14: M | D14: 1 | E14: =TRUNC(일위대가목록!E10,0) -> 36273 | F14: =TRUNC(E14*D14, 0) -> 36273 | G14: =TRUNC(일위대가목록!F10,0) -> 276256 | H14: =TRUNC(G14*D14, 0) -> 276256 | I14: =TRUNC(일위대가목록!G10,0) -> 52349 | J14: =TRUNC(I14*D14, 0) -> 52349 | K14: =TRUNC(E14+G14+I14, 0) -> 364878 | L14: =TRUNC(F14+H14+J14, 0) -> 364878 | M14: 호표 7
A15: (☞ 비탈면 보양)---------- | E15: =TRUNC(단가대비표!O314,0) -> 0 | F15: =TRUNC(E15*D15, 0) -> 0 | G15: =TRUNC(단가대비표!P314,0) -> 0 | H15: =TRUNC(G15*D15, 0) -> 0 | I15: =TRUNC(단가대비표!V314,0) -> 0 | J15: =TRUNC(I15*D15, 0) -> 0 | K15: =TRUNC(E15+G15+I15, 0) -> 0 | L15: =TRUNC(F15+H15+J15, 0) -> 0
A16: 비탈면 보양 | B16: 보양재(천막 등) | C16: M2 | D16: 1 | E16: =TRUNC(일위대가목록!E11,0) -> 0 | F16: =TRUNC(E16*D16, 0) -> 0 | G16: =TRUNC(일위대가목록!F11,0) -> 6243 | H16: =TRUNC(G16*D16, 0) -> 6243 | I16: =TRUNC(일위대가목록!G11,0) -> 0 | J16: =TRUNC(I16*D16, 0) -> 0 | K16: =TRUNC(E16+G16+I16, 0) -> 6243 | L16: =TRUNC(F16+H16+J16, 0) -> 6243 | M16: 호표 8
A17: (☞ 인력굴착(토사))---------- | E17: =TRUNC(단가대비표!O195,0) -> 0 | F17: =TRUNC(E17*D17, 0) -> 0 | G17: =TRUNC(단가대비표!P195,0) -> 0 | H17: =TRUNC(G17*D17, 0) -> 0 | I17: =TRUNC(단가대비표!V195,0) -> 0 | J17: =TRUNC(I17*D17, 0) -> 0 | K17: =TRUNC(E17+G17+I17, 0) -> 0 | L17: =TRUNC(F17+H17+J17, 0) -> 0
A18: 인력굴착(토사) / 보통토사 | B18: H=1m 이하(구조물터파기, 흙깍기) | C18: M3 | D18: 1 | E18: =TRUNC(일위대가목록!E12,0) -> 0 | F18: =TRUNC(E18*D18, 0) -> 0 | G18: =TRUNC(일위대가목록!F12,0) -> 63314 | H18: =TRUNC(G18*D18, 0) -> 63314 | I18: =TRUNC(일위대가목록!G12,0) -> 0 | J18: =TRUNC(I18*D18, 0) -> 0 | K18: =TRUNC(E18+G18+I18, 0) -> 63314 | L18: =TRUNC(F18+H18+J18, 0) -> 63314 | M18: 호표 9
A19: 인력굴착(토사) / 경질토사 | B19: H=1m 이하(구조물터파기, 흙깍기) | C19: M3 | D19: 1 | E19: =TRUNC(일위대가목록!E13,0) -> 0 | F19: =TRUNC(E19*D19, 0) -> 0 | G19: =TRUNC(일위대가목록!F13,0) -> 83665 | H19: =TRUNC(G19*D19, 0) -> 83665 | I19: =TRUNC(일위대가목록!G13,0) -> 0 | J19: =TRUNC(I19*D19, 0) -> 0 | K19: =TRUNC(E19+G19+I19, 0) -> 83665 | L19: =TRUNC(F19+H19+J19, 0) -> 83665 | M19: 호표 10
A20: 인력굴착(토사) / 고사점토 및 자갈섞인토사 | B20: H=1m 이하(구조물터파기, 흙깍기) | C20: M3 | D20: 1 | E20: =TRUNC(일위대가목록!E14,0) -> 0 | F20: =TRUNC(E20*D20, 0) -> 0 | G20: =TRUNC(일위대가목록!F14,0) -> 101754 | H20: =TRUNC(G20*D20, 0) -> 101754 | I20: =TRUNC(일위대가목록!G14,0) -> 0 | J20: =TRUNC(I20*D20, 0) -> 0 | K20: =TRUNC(E20+G20+I20, 0) -> 101754 | L20: =TRUNC(F20+H20+J20, 0) -> 101754 | M20: 호표 11
A21: 인력굴착(토사) / 호박돌섞인토사 | B21: H=1m 이하(구조물터파기, 흙깍기) | C21: M3 | D21: 1 | E21: =TRUNC(일위대가목록!E15,0) -> 0 | F21: =TRUNC(E21*D21, 0) -> 0 | G21: =TRUNC(일위대가목록!F15,0) -> 187681 | H21: =TRUNC(G21*D21, 0) -> 187681 | I21: =TRUNC(일위대가목록!G15,0) -> 0 | J21: =TRUNC(I21*D21, 0) -> 0 | K21: =TRUNC(E21+G21+I21, 0) -> 187681 | L21: =TRUNC(F21+H21+J21, 0) -> 187681 | M21: 호표 12
A22: 잔토처리 | B22: 인력 (현장 내 소운반 깔고 고르기) | C22: M3 | D22: 1 | E22: =TRUNC(일위대가목록!E16,0) -> 0 | F22: =TRUNC(E22*D22, 0) -> 0 | G22: =TRUNC(일위대가목록!F16,0) -> 34413 | H22: =TRUNC(G22*D22, 0) -> 34413 | I22: =TRUNC(일위대가목록!G16,0) -> 0 | J22: =TRUNC(I22*D22, 0) -> 0 | K22: =TRUNC(E22+G22+I22, 0) -> 34413 | L22: =TRUNC(F22+H22+J22, 0) -> 34413 | M22: 호표 13
A23: 인력굴착 / 풍화암 | B23: 10m3 미만, 소형브레이커 | C23: M3 | D23: 1 | E23: =TRUNC(일위대가목록!E17,0) -> 5651 | F23: =TRUNC(E23*D23, 0) -> 5651 | G23: =TRUNC(일위대가목록!F17,0) -> 118597 | H23: =TRUNC(G23*D23, 0) -> 118597 | I23: =TRUNC(일위대가목록!G17,0) -> 1669 | J23: =TRUNC(I23*D23, 0) -> 1669 | K23: =TRUNC(E23+G23+I23, 0) -> 125917 | L23: =TRUNC(F23+H23+J23, 0) -> 125917 | M23: 호표 14
A24: (☞ 인력굴착(암반)----- | E24: =TRUNC(단가대비표!O196,0) -> 0 | F24: =TRUNC(E24*D24, 0) -> 0 | G24: =TRUNC(단가대비표!P196,0) -> 0 | H24: =TRUNC(G24*D24, 0) -> 0 | I24: =TRUNC(단가대비표!V196,0) -> 0 | J24: =TRUNC(I24*D24, 0) -> 0 | K24: =TRUNC(E24+G24+I24, 0) -> 0 | L24: =TRUNC(F24+H24+J24, 0) -> 0
A25: 인력굴착 / 연 암 | B25: 10m3 미만, 소형브레이커 | C25: M3 | D25: 1 | E25: =TRUNC(일위대가목록!E18,0) -> 8700 | F25: =TRUNC(E25*D25, 0) -> 8700 | G25: =TRUNC(일위대가목록!F18,0) -> 155609 | H25: =TRUNC(G25*D25, 0) -> 155609 | I25: =TRUNC(일위대가목록!G18,0) -> 2505 | J25: =TRUNC(I25*D25, 0) -> 2505 | K25: =TRUNC(E25+G25+I25, 0) -> 166814 | L25: =TRUNC(F25+H25+J25, 0) -> 166814 | M25: 호표 15
A26: 인력굴착 / 보통암 | B26: 10m3 미만, 소형브레이커 | C26: M3 | D26: 1 | E26: =TRUNC(일위대가목록!E19,0) -> 11072 | F26: =TRUNC(E26*D26, 0) -> 11072 | G26: =TRUNC(일위대가목록!F19,0) -> 214249 | H26: =TRUNC(G26*D26, 0) -> 214249 | I26: =TRUNC(일위대가목록!G19,0) -> 3280 | J26: =TRUNC(I26*D26, 0) -> 3280 | K26: =TRUNC(E26+G26+I26, 0) -> 228601 | L26: =TRUNC(F26+H26+J26, 0) -> 228601 | M26: 호표 16
A27: 인력굴착 / 경 암 | B27: 10m3 미만, 소형브레이커 | C27: M3 | D27: 1 | E27: =TRUNC(일위대가목록!E20,0) -> 17770 | F27: =TRUNC(E27*D27, 0) -> 17770 | G27: =TRUNC(일위대가목록!F20,0) -> 348219 | H27: =TRUNC(G27*D27, 0) -> 348219 | I27: =TRUNC(일위대가목록!G20,0) -> 5277 | J27: =TRUNC(I27*D27, 0) -> 5277 | K27: =TRUNC(E27+G27+I27, 0) -> 371266 | L27: =TRUNC(F27+H27+J27, 0) -> 371266 | M27: 호표 17
A28: (☞ 흙깍기(기계))---------- | E28: =TRUNC(단가대비표!O197,0) -> 0 | F28: =TRUNC(E28*D28, 0) -> 0 | G28: =TRUNC(단가대비표!P197,0) -> 0 | H28: =TRUNC(G28*D28, 0) -> 0 | I28: =TRUNC(단가대비표!V197,0) -> 0 | J28: =TRUNC(I28*D28, 0) -> 0 | K28: =TRUNC(E28+G28+I28, 0) -> 0 | L28: =TRUNC(F28+H28+J28, 0) -> 0
A29: 흙깎기/보통토사 | B29: 소규모 | C29: M3 | D29: 1 | E29: =TRUNC(일위대가목록!E21,0) -> 818 | F29: =TRUNC(E29*D29, 0) -> 818 | G29: =TRUNC(일위대가목록!F21,0) -> 1522 | H29: =TRUNC(G29*D29, 0) -> 1522 | I29: =TRUNC(일위대가목록!G21,0) -> 764 | J29: =TRUNC(I29*D29, 0) -> 764 | K29: =TRUNC(E29+G29+I29, 0) -> 3104 | L29: =TRUNC(F29+H29+J29, 0) -> 3104 | M29: 호표 18
A30: 흙깎기/혼합토사 | B30: 소규모 | C30: M3 | D30: 1 | E30: =TRUNC(일위대가목록!E22,0) -> 1104 | F30: =TRUNC(E30*D30, 0) -> 1104 | G30: =TRUNC(일위대가목록!F22,0) -> 2053 | H30: =TRUNC(G30*D30, 0) -> 2053 | I30: =TRUNC(일위대가목록!G22,0) -> 1114 | J30: =TRUNC(I30*D30, 0) -> 1114 | K30: =TRUNC(E30+G30+I30, 0) -> 4271 | L30: =TRUNC(F30+H30+J30, 0) -> 4271 | M30: 호표 19
A31: 흙깎기/보통토사 | B31: 중규모 | C31: M3 | D31: 1 | E31: =TRUNC(일위대가목록!E23,0) -> 553 | F31: =TRUNC(E31*D31, 0) -> 553 | G31: =TRUNC(일위대가목록!F23,0) -> 843 | H31: =TRUNC(G31*D31, 0) -> 843 | I31: =TRUNC(일위대가목록!G23,0) -> 513 | J31: =TRUNC(I31*D31, 0) -> 513 | K31: =TRUNC(E31+G31+I31, 0) -> 1909 | L31: =TRUNC(F31+H31+J31, 0) -> 1909 | M31: 호표 20
A32: 흙깎기/혼합토사 | B32: 중규모 | C32: M3 | D32: 1 | E32: =TRUNC(일위대가목록!E24,0) -> 793 | F32: =TRUNC(E32*D32, 0) -> 793 | G32: =TRUNC(일위대가목록!F24,0) -> 1209 | H32: =TRUNC(G32*D32, 0) -> 1209 | I32: =TRUNC(일위대가목록!G24,0) -> 790 | J32: =TRUNC(I32*D32, 0) -> 790 | K32: =TRUNC(E32+G32+I32, 0) -> 2792 | L32: =TRUNC(F32+H32+J32, 0) -> 2792 | M32: 호표 21
A33: 흙깎기/보통토사 | B33: 대규모 | C33: M3 | D33: 1 | E33: =TRUNC(일위대가목록!E25,0) -> 553 | F33: =TRUNC(E33*D33, 0) -> 553 | G33: =TRUNC(일위대가목록!F25,0) -> 507 | H33: =TRUNC(G33*D33, 0) -> 507 | I33: =TRUNC(일위대가목록!G25,0) -> 410 | J33: =TRUNC(I33*D33, 0) -> 410 | K33: =TRUNC(E33+G33+I33, 0) -> 1470 | L33: =TRUNC(F33+H33+J33, 0) -> 1470 | M33: 호표 22
A34: 흙깎기/혼합토사 | B34: 대규모 | C34: M3 | D34: 1 | E34: =TRUNC(일위대가목록!E26,0) -> 804 | F34: =TRUNC(E34*D34, 0) -> 804 | G34: =TRUNC(일위대가목록!F26,0) -> 737 | H34: =TRUNC(G34*D34, 0) -> 737 | I34: =TRUNC(일위대가목록!G26,0) -> 639 | J34: =TRUNC(I34*D34, 0) -> 639 | K34: =TRUNC(E34+G34+I34, 0) -> 2180 | L34: =TRUNC(F34+H34+J34, 0) -> 2180 | M34: 호표 23
A35: 흙깎기/굴착기 | B35: 풍화암 | C35: M3 | D35: 1 | E35: =TRUNC(일위대가목록!E27,0) -> 4051 | F35: =TRUNC(E35*D35, 0) -> 4051 | G35: =TRUNC(일위대가목록!F27,0) -> 7259 | H35: =TRUNC(G35*D35, 0) -> 7259 | I35: =TRUNC(일위대가목록!G27,0) -> 5972 | J35: =TRUNC(I35*D35, 0) -> 5972 | K35: =TRUNC(E35+G35+I35, 0) -> 17282 | L35: =TRUNC(F35+H35+J35, 0) -> 17282 | M35: 호표 24
A36: 흙깎기/굴착기 | B36: 연암 | C36: M3 | D36: 1 | E36: =TRUNC(일위대가목록!E28,0) -> 5462 | F36: =TRUNC(E36*D36, 0) -> 5462 | G36: =TRUNC(일위대가목록!F28,0) -> 9443 | H36: =TRUNC(G36*D36, 0) -> 9443 | I36: =TRUNC(일위대가목록!G28,0) -> 7769 | J36: =TRUNC(I36*D36, 0) -> 7769 | K36: =TRUNC(E36+G36+I36, 0) -> 22674 | L36: =TRUNC(F36+H36+J36, 0) -> 22674 | M36: 호표 25
A37: 흙깎기/굴착기 | B37: 보통암 | C37: M3 | D37: 1 | E37: =TRUNC(일위대가목록!E29,0) -> 10080 | F37: =TRUNC(E37*D37, 0) -> 10080 | G37: =TRUNC(일위대가목록!F29,0) -> 15758 | H37: =TRUNC(G37*D37, 0) -> 15758 | I37: =TRUNC(일위대가목록!G29,0) -> 12965 | J37: =TRUNC(I37*D37, 0) -> 12965 | K37: =TRUNC(E37+G37+I37, 0) -> 38803 | L37: =TRUNC(F37+H37+J37, 0) -> 38803 | M37: 호표 26
A38: 흙깎기/굴착기 | B38: 경암 | C38: M3 | D38: 1 | E38: =TRUNC(일위대가목록!E30,0) -> 12851 | F38: =TRUNC(E38*D38, 0) -> 12851 | G38: =TRUNC(일위대가목록!F30,0) -> 18886 | H38: =TRUNC(G38*D38, 0) -> 18886 | I38: =TRUNC(일위대가목록!G30,0) -> 15539 | J38: =TRUNC(I38*D38, 0) -> 15539 | K38: =TRUNC(E38+G38+I38, 0) -> 47276 | L38: =TRUNC(F38+H38+J38, 0) -> 47276 | M38: 호표 27
A39: (☞ 터파기(기계))---------- | E39: =TRUNC(단가대비표!O198,0) -> 0 | F39: =TRUNC(E39*D39, 0) -> 0 | G39: =TRUNC(단가대비표!P198,0) -> 0 | H39: =TRUNC(G39*D39, 0) -> 0 | I39: =TRUNC(단가대비표!V198,0) -> 0 | J39: =TRUNC(I39*D39, 0) -> 0 | K39: =TRUNC(E39+G39+I39, 0) -> 0 | L39: =TRUNC(F39+H39+J39, 0) -> 0
A40: 기계터파기/보통토사/5M이하(육상) | B40: TypeⅠ(일반) | C40: M3 | D40: 1 | E40: =TRUNC(일위대가목록!E31,0) -> 453 | F40: =TRUNC(E40*D40, 0) -> 453 | G40: =TRUNC(일위대가목록!F31,0) -> 843 | H40: =TRUNC(G40*D40, 0) -> 843 | I40: =TRUNC(일위대가목록!G31,0) -> 423 | J40: =TRUNC(I40*D40, 0) -> 423 | K40: =TRUNC(E40+G40+I40, 0) -> 1719 | L40: =TRUNC(F40+H40+J40, 0) -> 1719 | M40: 호표 28
...

Sheet 일위대가목록
B1: 일 위 대 가 목 록
B2: 2026년 상반기 충청남도교육청 건설공사 일위대가(토목, 조경)
A3: 코 드 | B3: 품 명 | C3: 규 격 | D3: 단위 | E3: 재 료 비 | F3: 노 무 비 | G3: 경 비 | H3: 합 계 | I3: 번 호 | J3: 비 고 | K3: 노임계수 | L3: 할증 | M3: 품셈개요 | N3: 장비일위
A4: 5045818DECA91619EE86466C5BBC0B | B4: 사각지대 충돌방지장치 설치 및 해체 | D4: 개당 | E4: =일위대가!F8 -> 0 | F4: =일위대가!H8 -> 127366 | G4: =일위대가!J8 -> 1273 | H4: =E4+F4+G4 -> 128639 | I4: 호표 1 | M4: 공통 2-9-12
A5: 5045818DECA91619EE86088A54191A | B5: 박스형 간이흙막이 설치 및 해체 | C5: H=3.0M 이하, 개당 길이=3.0M 이하, 폭=2.0M 이하 | D5: 개 | E5: =일위대가!F14 -> 4286 | F5: =일위대가!H14 -> 61706 | G5: =일위대가!J14 -> 6186 | H5: =E5+F5+G5 -> 72178 | I5: 호표 2 | M5: 공통 2-10-4
A6: 5045818DECA91619EE8608B758F7D2 | B6: 박스형 간이흙막이 설치 및 해체 | C6: H=4.0M 이하, 개당 길이=3.0M 이하, 폭=2.0M 이하 | D6: 개 | E6: =일위대가!F20 -> 7254 | F6: =일위대가!H20 -> 91657 | G6: =일위대가!J20 -> 10469 | H6: =E6+F6+G6 -> 109380 | I6: 호표 3 | M6: 공통 2-10-4
A7: 5045818DECA91619EE86191453A5A3 | B7: 조립식 간이흙막이 설치 및 해체 | C7: H=3.0M 이하 | D7: M | E7: =일위대가!F26 -> 7584 | F7: =일위대가!H26 -> 77905 | G7: =일위대가!J26 -> 10945 | H7: =E7+F7+G7 -> 96434 | I7: 호표 4 | M7: 공통 2-10-5
A8: 5045818DECA91619EE8619265A4F85 | B8: 조립식 간이흙막이 설치 및 해체 | C8: H=4.0M 이하 | D8: M | E8: =일위대가!F32 -> 14839 | F8: =일위대가!H32 -> 125321 | G8: =일위대가!J32 -> 21415 | H8: =E8+F8+G8 -> 161575 | I8: 호표 5 | M8: 공통 2-10-5
A9: 5045818DECA91619EE8619265B55D0 | B9: 조립식 간이흙막이 설치 및 해체 | C9: H=5.0M 이하 | D9: M | E9: =일위대가!F38 -> 24402 | F9: =일위대가!H38 -> 189930 | G9: =일위대가!J38 -> 35216 | H9: =E9+F9+G9 -> 249548 | I9: 호표 6 | M9: 공통 2-10-5
A10: 5045818DECA91619EE861926588171 | B10: 조립식 간이흙막이 설치 및 해체 | C10: H=6.0M 이하 | D10: M | E10: =일위대가!F44 -> 36273 | F10: =일위대가!H44 -> 276256 | G10: =일위대가!J44 -> 52349 | H10: =E10+F10+G10 -> 364878 | I10: 호표 7 | M10: 공통 2-10-5
A11: 5045818DECA9C719807643395AAFFA | B11: 비탈면 보양 | C11: 보양재(천막 등) | D11: M2 | E11: =일위대가!F49 -> 0 | F11: =일위대가!H49 -> 6243 | G11: =일위대가!J49 -> 0 | H11: =E11+F11+G11 -> 6243 | I11: 호표 8 | M11: 공통 2-10-6
A12: 5045D1864FC2EC19280E22735F2D9E | B12: 인력굴착(토사) / 보통토사 | C12: H=1m 이하(구조물터파기, 흙깍기) | D12: M3 | E12: =일위대가!F53 -> 0 | F12: =일위대가!H53 -> 63314 | G12: =일위대가!J53 -> 0 | H12: =E12+F12+G12 -> 63314 | I12: 호표 9 | M12: 공통 3-2-1
A13: 5045D1864FC2EC19280E2261565648 | B13: 인력굴착(토사) / 경질토사 | C13: H=1m 이하(구조물터파기, 흙깍기) | D13: M3 | E13: =일위대가!F57 -> 0 | F13: =일위대가!H57 -> 83665 | G13: =일위대가!J57 -> 0 | H13: =E13+F13+G13 -> 83665 | I13: 호표 10 | M13: 공통 3-2-1
A14: 5045D1864FC2EC19280E2257519AD2 | B14: 인력굴착(토사) / 고사점토 및 자갈섞인토사 | C14: H=1m 이하(구조물터파기, 흙깍기) | D14: M3 | E14: =일위대가!F61 -> 0 | F14: =일위대가!H61 -> 101754 | G14: =일위대가!J61 -> 0 | H14: =E14+F14+G14 -> 101754 | I14: 호표 11 | M14: 공통 3-2-1
A15: 5045D1864FC2EC19280E22465B4F85 | B15: 인력굴착(토사) / 호박돌섞인토사 | C15: H=1m 이하(구조물터파기, 흙깍기) | D15: M3 | E15: =일위대가!F65 -> 0 | F15: =일위대가!H65 -> 187681 | G15: =일위대가!J65 -> 0 | H15: =E15+F15+G15 -> 187681 | I15: 호표 12 | M15: 공통 3-2-1
A16: 5045D1864FC2EC19282AF9545D306C | B16: 잔토처리 | C16: 인력 (현장 내 소운반 깔고 고르기) | D16: M3 | E16: =일위대가!F69 -> 0 | F16: =일위대가!H69 -> 34413 | G16: =일위대가!J69 -> 0 | H16: =E16+F16+G16 -> 34413 | I16: 호표 13 | M16: 공통 3-2-1 [비고]
A17: 5045D1864FFE3619F43278E951E883 | B17: 인력굴착 / 풍화암 | C17: 10m3 미만, 소형브레이커 | D17: M3 | E17: =일위대가!F77 -> 5651 | F17: =일위대가!H77 -> 118597 | G17: =일위대가!J77 -> 1669 | H17: =E17+F17+G17 -> 125917 | I17: 호표 14 | M17: 공통 3-2-2
A18: 5045D1864FFE3619F43278D85AF6CB | B18: 인력굴착 / 연 암 | C18: 10m3 미만, 소형브레이커 | D18: M3 | E18: =일위대가!F85 -> 8700 | F18: =일위대가!H85 -> 155609 | G18: =일위대가!J85 -> 2505 | H18: =E18+F18+G18 -> 166814 | I18: 호표 15 | M18: 공통 3-2-2
A19: 5045D1864FFE3619F43278CE530C9B | B19: 인력굴착 / 보통암 | C19: 10m3 미만, 소형브레이커 | D19: M3 | E19: =일위대가!F93 -> 11072 | F19: =일위대가!H93 -> 214249 | G19: =일위대가!J93 -> 3280 | H19: =E19+F19+G19 -> 228601 | I19: 호표 16 | M19: 공통 3-2-2
A20: 5045D1864FFE3619F43278BD5C1BEB | B20: 인력굴착 / 경 암 | C20: 10m3 미만, 소형브레이커 | D20: M3 | E20: =일위대가!F101 -> 17770 | F20: =일위대가!H101 -> 348219 | G20: =일위대가!J101 -> 5277 | H20: =E20+F20+G20 -> 371266 | I20: 호표 17 | M20: 공통 3-2-2
A21: 5045D186585AED19C1DF5367529FE9 | B21: 흙깎기/보통토사 | C21: 소규모 | D21: M3 | E21: =일위대가!F105 -> 818 | F21: =일위대가!H105 -> 1522 | G21: =일위대가!J105 -> 764 | H21: =E21+F21+G21 -> 3104 | I21: 호표 18 | M21: 공통 3-2-3,가
A22: 5045D186585AED19C1DF537159093B | B22: 흙깎기/혼합토사 | C22: 소규모 | D22: M3 | E22: =일위대가!F110 -> 1104 | F22: =일위대가!H110 -> 2053 | G22: =일위대가!J110 -> 1114 | H22: =E22+F22+G22 -> 4271 | I22: 호표 19 | M22: 공통 3-2-3,나
A23: 5045D186585AED19C1CEEC4D5A5D47 | B23: 흙깎기/보통토사 | C23: 중규모 | D23: M3 | E23: =일위대가!F114 -> 553 | F23: =일위대가!H114 -> 843 | G23: =일위대가!J114 -> 513 | H23: =E23+F23+G23 -> 1909 | I23: 호표 20 | M23: 공통 3-2-3,가
A24: 5045D186585AED19C1CEEC5E514F1E | B24: 흙깎기/혼합토사 | C24: 중규모 | D24: M3 | E24: =일위대가!F119 -> 793 | F24: =일위대가!H119 -> 1209 | G24: =일위대가!J119 -> 790 | H24: =E24+F24+G24 -> 2792 | I24: 호표 21 | M24: 공통 3-2-3,나
A25: 5045D186585AED19C1FA28BE58F9DD | B25: 흙깎기/보통토사 | C25: 대규모 | D25: M3 | E25: =일위대가!F123 -> 553 | F25: =일위대가!H123 -> 507 | G25: =일위대가!J123 -> 410 | H25: =E25+F25+G25 -> 1470 | I25: 호표 22 | M25: 공통 3-2-3,가
A26: 5045D186585AED19C1FA28AC51EE6D | B26: 흙깎기/혼합토사 | C26: 대규모 | D26: M3 | E26: =일위대가!F128 -> 804 | F26: =일위대가!H128 -> 737 | G26: =일위대가!J128 -> 639 | H26: =E26+F26+G26 -> 2180 | I26: 호표 23 | M26: 공통 3-2-3,나
A27: 5045D186586B42197AB2C0C253A0F9 | B27: 흙깎기/굴착기 | C27: 풍화암 | D27: M3 | E27: =일위대가!F134 -> 4051 | F27: =일위대가!H134 -> 7259 | G27: =일위대가!J134 -> 5972 | H27: =E27+F27+G27 -> 17282 | I27: 호표 24 | M27: 공통 3-2-3,다
A28: 5045D186586B42197AB2C0FF57DEFB | B28: 흙깎기/굴착기 | C28: 연암 | D28: M3 | E28: =일위대가!F140 -> 5462 | F28: =일위대가!H140 -> 9443 | G28: =일위대가!J140 -> 7769 | H28: =E28+F28+G28 -> 22674 | I28: 호표 25 | M28: 공통 3-2-3,다
A29: 5045D186586B42197AB2C0ED5034DA | B29: 흙깎기/굴착기 | C29: 보통암 | D29: M3 | E29: =일위대가!F146 -> 10080 | F29: =일위대가!H146 -> 15758 | G29: =일위대가!J146 -> 12965 | H29: =E29+F29+G29 -> 38803 | I29: 호표 26 | M29: 공통 3-2-3,다
A30: 5045D186586B42197AB2C0965ED54E | B30: 흙깎기/굴착기 | C30: 경암 | D30: M3 | E30: =일위대가!F152 -> 12851 | F30: =일위대가!H152 -> 18886 | G30: =일위대가!J152 -> 15539 | H30: =E30+F30+G30 -> 47276 | I30: 호표 27 | M30: 공통 3-2-3,다
A31: 5045D1864FC2B019E1A2314C5424AB | B31: 기계터파기/보통토사/5M이하(육상) | C31: TypeⅠ(일반) | D31: M3 | E31: =일위대가!F156 -> 453 | F31: =일위대가!H156 -> 843 | G31: =일위대가!J156 -> 423 | H31: =E31+F31+G31 -> 1719 | I31: 호표 28 | M31: 공통 3-2-4,가
A32: 5045D1864FC2B019E1A2314C54277F | B32: 기계터파기/보통토사/5M이하(육상) | C32: TypeⅡ(지장물, 가시설등) | D32: M3 | E32: =일위대가!F160 -> 602 | F32: =일위대가!H160 -> 1121 | G32: =일위대가!J160 -> 562 | H32: =E32+F32+G32 -> 2285 | I32: 호표 29 | M32: 공통 3-2-4,가
A33: 5045D1864FC2B019E1A2314C542659 | B33: 기계터파기/보통토사/5M이하(육상) | C33: TypeⅢ(측구 터파기등) | D33: M3 | E33: =일위대가!F164 -> 698 | F33: =일위대가!H164 -> 2484 | G33: =일위대가!J164 -> 986 | H33: =E33+F33+G33 -> 4168 | I33: 호표 30 | M33: 공통 3-2-4,가
A34: 5045D1864FC2B019E1A2314C5421D7 | B34: 기계터파기/보통토사/5M이하(용수) | C34: TypeⅠ(일반) | D34: M3 | E34: =일위대가!F168 -> 602 | F34: =일위대가!H168 -> 1121 | G34: =일위대가!J168 -> 562 | H34: =E34+F34+G34 -> 2285 | I34: 호표 31 | M34: 공통 3-2-4,가
A35: 5045D1864FC2B019E1A2314C542030 | B35: 기계터파기/보통토사/5M이하(용수) | C35: TypeⅡ(지장물, 가시설등) | D35: M3 | E35: =일위대가!F172 -> 806 | F35: =일위대가!H172 -> 1499 | G35: =일위대가!J172 -> 752 | H35: =E35+F35+G35 -> 3057 | I35: 호표 32 | M35: 공통 3-2-4,가
A36: 5045D1864FC2B019E1A2314C542384 | B36: 기계터파기/보통토사/5M이하(용수) | C36: TypeⅢ(측구 터파기등) | D36: M3 | E36: =일위대가!F176 -> 931 | F36: =일위대가!H176 -> 3311 | G36: =일위대가!J176 -> 1314 | H36: =E36+F36+G36 -> 5556 | I36: 호표 33 | M36: 공통 3-2-4,가
A37: 5045D1864FC2B019E1A2314C5150CC | B37: 기계터파기/보통토사/5M초과(육상) | C37: TypeⅠ(일반) | D37: M3 | E37: =일위대가!F180 -> 498 | F37: =일위대가!H180 -> 926 | G37: =일위대가!J180 -> 465 | H37: =E37+F37+G37 -> 1889 | I37: 호표 34 | M37: 공통 3-2-4,가
A38: 5045D1864FC2B019E1A2314C515381 | B38: 기계터파기/보통토사/5M초과(육상) | C38: TypeⅡ(지장물, 가시설등) | D38: M3 | E38: =일위대가!F184 -> 663 | F38: =일위대가!H184 -> 1233 | G38: =일위대가!J184 -> 619 | H38: =E38+F38+G38 -> 2515 | I38: 호표 35 | M38: 공통 3-2-4,가
A39: 5045D1864FC2B019E1A2314C5152FA | B39: 기계터파기/보통토사/5M초과(육상) | C39: TypeⅢ(측구 터파기등) | D39: M3 | E39: =일위대가!F188 -> 768 | F39: =일위대가!H188 -> 2732 | G39: =일위대가!J188 -> 1084 | H39: =E39+F39+G39 -> 4584 | I39: 호표 36 | M39: 공통 3-2-4,가
A40: 5045D1864FC2B019E1A2314C51554E | B40: 기계터파기/보통토사/5M초과(용수) | C40: TypeⅠ(일반) | D40: M3 | E40: =일위대가!F192 -> 663 | F40: =일위대가!H192 -> 1233 | G40: =일위대가!J192 -> 619 | H40: =E40+F40+G40 -> 2515 | I40: 호표 37 | M40: 공통 3-2-4,가
...

Sheet 일위대가
A1: 2026년 상반기 충청남도교육청 건설공사 일위대가(토목, 조경)
A2: 품 명 | B2: 규 격 | C2: 단위 | D2: 수량 | E2: 재 료 비 | G2: 노 무 비 | I2: 경 비 | K2: 합 계 | M2: 비 고 | N2: 일위대가 | O2: 품목코드 | P2: 일위 | Q2: 단산 | R2: 자재 | S2: 손료적용 | T2: 손료저장 | U2: 적용율 | V2: JUK1 | W2: JUK2 | X2: JUK3 | Y2: JUK4 | Z2: JUK5 | AA2: JUK6 | AB2: JUK7 | AC2: JUK8 | AD2: JUK9 | AE2: JUK10 | AF2: JUK11 | AG2: JUK12 | AH2: JUK13 | AI2: JUK14 | AJ2: JUK15 | AK2: JUK16 | AL2: JUK17 | AM2: JUK18 | AN2: JUK19 | AO2: JUK20 | AP2: 할증적용 | AQ2: 할증저장 | AR2: 할증율 | AS2: HAL1 | AT2: HAL2 | AU2: HAL3 | AV2: 자재구분 | AW2: 일위대가+자재 | AX2: 장비일위 | AY2: 설정 | AZ2: 할증체크
E3: 단 가 | F3: 금 액 | G3: 단 가 | H3: 금 액 | I3: 단 가 | J3: 금 액 | K3: 단 가 | L3: 금 액
A4: 사각지대 충돌방지장치 설치 및 해체 개당 공통 2-9-12 ( 호표 1 ) | N4: 5045818DECA91619EE86466C5BBC0B
A5: 중급기술자 | B5: 정보통신 | C5: 인 | D5: 0.25 | E5: =단가대비표!O192 -> 0 | F5: =TRUNC(E5*D5,1) -> 0 | G5: =단가대비표!P192 -> 283343 | H5: =TRUNC(G5*D5,1) -> 70835.7 | I5: =단가대비표!V192 -> 0 | J5: =TRUNC(I5*D5,1) -> 0 | K5: =TRUNC(E5+G5+I5,1) -> 283343 | L5: =TRUNC(F5+H5+J5,1) -> 70835.7 | N5: 5045818DECA91619EE86466C5BBC0B | O5: 50B5818C1C385D19E433E26852D8A50E7567BE | P5: F | Q5: F | R5: T | V5: 1 | AW5: 5045818DECA91619EE86466C5BBC0B50B5818C1C385D19E433E26852D8A50E7567BE
A6: 특별인부 | B6: 일반공사 직종 | C6: 인 | D6: 0.25 | E6: =단가대비표!O165 -> 0 | F6: =TRUNC(E6*D6,1) -> 0 | G6: =단가대비표!P165 -> 226122 | H6: =TRUNC(G6*D6,1) -> 56530.5 | I6: =단가대비표!V165 -> 0 | J6: =TRUNC(I6*D6,1) -> 0 | K6: =TRUNC(E6+G6+I6,1) -> 226122 | L6: =TRUNC(F6+H6+J6,1) -> 56530.5 | N6: 5045818DECA91619EE86466C5BBC0B | O6: 50B5818C1C385D19DBC67C675F9ED6AF0EFAAF | P6: F | Q6: F | R6: T | V6: 1 | AW6: 5045818DECA91619EE86466C5BBC0B50B5818C1C385D19DBC67C675F9ED6AF0EFAAF
A7: 공구손료 및 경장비의 기계경비 | B7: 인력품의 1% | C7: 식 | D7: 1 | E7: 0 | F7: =TRUNC(E7*D7,1) -> 0 | G7: 0 | H7: =TRUNC(G7*D7,1) -> 0 | I7: =TRUNC(SUMIF(V5:V7, RIGHTB(O7, 1), H5:H7)*U7, 2) -> 1273.66 | J7: =TRUNC(I7*D7,1) -> 1273.6 | K7: =TRUNC(E7+G7+I7,1) -> 1273.6 | L7: =TRUNC(F7+H7+J7,1) -> 1273.6 | N7: 5045818DECA91619EE86466C5BBC0B | O7: 51769183174AB519D74B12C15769001 | P7: F | Q7: F | R7: F | S7: 1 | T7: 2 | U7: 0.01 | AW7: 5045818DECA91619EE86466C5BBC0B51769183174AB519D74B12C15769001
A8: [ 합 계 ] | F8: =TRUNC(SUMIF(N5:N7, N4, F5:F7),0) -> 0 | H8: =TRUNC(SUMIF(N5:N7, N4, H5:H7),0) -> 127366 | J8: =TRUNC(SUMIF(N5:N7, N4, J5:J7),0) -> 1273 | L8: =F8+H8+J8 -> 128639 | N8: TOTAL | O8: TOTAL
A10: 박스형 간이흙막이 설치 및 해체 H=3.0M 이하, 개당 길이=3.0M 이하, 폭=2.0M 이하 개 공통 2-10-4 ( 호표 2 ) | N10: 5045818DECA91619EE86088A54191A
A11: 특별인부 | B11: 일반공사 직종 | C11: 인 | D11: 0.17 | E11: =단가대비표!O165 -> 0 | F11: =TRUNC(E11*D11,1) -> 0 | G11: =단가대비표!P165 -> 226122 | H11: =TRUNC(G11*D11,1) -> 38440.7 | I11: =단가대비표!V165 -> 0 | J11: =TRUNC(I11*D11,1) -> 0 | K11: =TRUNC(E11+G11+I11,1) -> 226122 | L11: =TRUNC(F11+H11+J11,1) -> 38440.7 | N11: 5045818DECA91619EE86088A54191A | O11: 50B5818C1C385D19DBC67C675F9ED6AF0EFAAF | P11: F | Q11: F | R11: T | AW11: 5045818DECA91619EE86088A54191A50B5818C1C385D19DBC67C675F9ED6AF0EFAAF
A12: 보통인부 | B12: 일반공사 직종 | C12: 인 | D12: 0.06 | E12: =단가대비표!O164 -> 0 | F12: =TRUNC(E12*D12,1) -> 0 | G12: =단가대비표!P164 -> 172068 | H12: =TRUNC(G12*D12,1) -> 10324 | I12: =단가대비표!V164 -> 0 | J12: =TRUNC(I12*D12,1) -> 0 | K12: =TRUNC(E12+G12+I12,1) -> 172068 | L12: =TRUNC(F12+H12+J12,1) -> 10324 | N12: 5045818DECA91619EE86088A54191A | O12: 50B5818C1C385D19DBC67C675F9ED6AF0EFAAE | P12: F | Q12: F | R12: T | AW12: 5045818DECA91619EE86088A54191A50B5818C1C385D19DBC67C675F9ED6AF0EFAAE
A13: 트럭탑재형 크레인 | B13: 10ton | C13: HR | D13: 0.26 | E13: =일위대가목록!E308 -> 16488 | F13: =TRUNC(E13*D13,1) -> 4286.8 | G13: =일위대가목록!F308 -> 49778 | H13: =TRUNC(G13*D13,1) -> 12942.2 | I13: =일위대가목록!G308 -> 23795 | J13: =TRUNC(I13*D13,1) -> 6186.7 | K13: =TRUNC(E13+G13+I13,1) -> 90061 | L13: =TRUNC(F13+H13+J13,1) -> 23415.7 | M13: 호표 305 | N13: 5045818DECA91619EE86088A54191A | O13: 577F118D8878DD199FF2D86D5B20720393AEBD59 | P13: T | Q13: F | R13: F | AW13: 5045818DECA91619EE86088A54191A577F118D8878DD199FF2D86D5B20720393AEBD59
A14: [ 합 계 ] | F14: =TRUNC(SUMIF(N11:N13, N10, F11:F13),0) -> 4286 | H14: =TRUNC(SUMIF(N11:N13, N10, H11:H13),0) -> 61706 | J14: =TRUNC(SUMIF(N11:N13, N10, J11:J13),0) -> 6186 | L14: =F14+H14+J14 -> 72178 | N14: TOTAL | O14: TOTAL
A16: 박스형 간이흙막이 설치 및 해체 H=4.0M 이하, 개당 길이=3.0M 이하, 폭=2.0M 이하 개 공통 2-10-4 ( 호표 3 ) | N16: 5045818DECA91619EE8608B758F7D2
A17: 특별인부 | B17: 일반공사 직종 | C17: 인 | D17: 0.24 | E17: =단가대비표!O165 -> 0 | F17: =TRUNC(E17*D17,1) -> 0 | G17: =단가대비표!P165 -> 226122 | H17: =TRUNC(G17*D17,1) -> 54269.2 | I17: =단가대비표!V165 -> 0 | J17: =TRUNC(I17*D17,1) -> 0 | K17: =TRUNC(E17+G17+I17,1) -> 226122 | L17: =TRUNC(F17+H17+J17,1) -> 54269.2 | N17: 5045818DECA91619EE8608B758F7D2 | O17: 50B5818C1C385D19DBC67C675F9ED6AF0EFAAF | P17: F | Q17: F | R17: T | AW17: 5045818DECA91619EE8608B758F7D250B5818C1C385D19DBC67C675F9ED6AF0EFAAF
A18: 보통인부 | B18: 일반공사 직종 | C18: 인 | D18: 0.09 | E18: =단가대비표!O164 -> 0 | F18: =TRUNC(E18*D18,1) -> 0 | G18: =단가대비표!P164 -> 172068 | H18: =TRUNC(G18*D18,1) -> 15486.1 | I18: =단가대비표!V164 -> 0 | J18: =TRUNC(I18*D18,1) -> 0 | K18: =TRUNC(E18+G18+I18,1) -> 172068 | L18: =TRUNC(F18+H18+J18,1) -> 15486.1 | N18: 5045818DECA91619EE8608B758F7D2 | O18: 50B5818C1C385D19DBC67C675F9ED6AF0EFAAE | P18: F | Q18: F | R18: T | AW18: 5045818DECA91619EE8608B758F7D250B5818C1C385D19DBC67C675F9ED6AF0EFAAE
A19: 트럭탑재형 크레인 | B19: 10ton | C19: HR | D19: 0.44 | E19: =일위대가목록!E308 -> 16488 | F19: =TRUNC(E19*D19,1) -> 7254.7 | G19: =일위대가목록!F308 -> 49778 | H19: =TRUNC(G19*D19,1) -> 21902.3 | I19: =일위대가목록!G308 -> 23795 | J19: =TRUNC(I19*D19,1) -> 10469.8 | K19: =TRUNC(E19+G19+I19,1) -> 90061 | L19: =TRUNC(F19+H19+J19,1) -> 39626.8 | M19: 호표 305 | N19: 5045818DECA91619EE8608B758F7D2 | O19: 577F118D8878DD199FF2D86D5B20720393AEBD59 | P19: T | Q19: F | R19: F | AW19: 5045818DECA91619EE8608B758F7D2577F118D8878DD199FF2D86D5B20720393AEBD59
A20: [ 합 계 ] | F20: =TRUNC(SUMIF(N17:N19, N16, F17:F19),0) -> 7254 | H20: =TRUNC(SUMIF(N17:N19, N16, H17:H19),0) -> 91657 | J20: =TRUNC(SUMIF(N17:N19, N16, J17:J19),0) -> 10469 | L20: =F20+H20+J20 -> 109380 | N20: TOTAL | O20: TOTAL
A22: 조립식 간이흙막이 설치 및 해체 H=3.0M 이하 M 공통 2-10-5 ( 호표 4 ) | N22: 5045818DECA91619EE86191453A5A3
A23: 특별인부 | B23: 일반공사 직종 | C23: 인 | D23: 0.19 | E23: =단가대비표!O165 -> 0 | F23: =TRUNC(E23*D23,1) -> 0 | G23: =단가대비표!P165 -> 226122 | H23: =TRUNC(G23*D23,1) -> 42963.1 | I23: =단가대비표!V165 -> 0 | J23: =TRUNC(I23*D23,1) -> 0 | K23: =TRUNC(E23+G23+I23,1) -> 226122 | L23: =TRUNC(F23+H23+J23,1) -> 42963.1 | N23: 5045818DECA91619EE86191453A5A3 | O23: 50B5818C1C385D19DBC67C675F9ED6AF0EFAAF | P23: F | Q23: F | R23: T | AW23: 5045818DECA91619EE86191453A5A350B5818C1C385D19DBC67C675F9ED6AF0EFAAF
A24: 보통인부 | B24: 일반공사 직종 | C24: 인 | D24: 0.07 | E24: =단가대비표!O164 -> 0 | F24: =TRUNC(E24*D24,1) -> 0 | G24: =단가대비표!P164 -> 172068 | H24: =TRUNC(G24*D24,1) -> 12044.7 | I24: =단가대비표!V164 -> 0 | J24: =TRUNC(I24*D24,1) -> 0 | K24: =TRUNC(E24+G24+I24,1) -> 172068 | L24: =TRUNC(F24+H24+J24,1) -> 12044.7 | N24: 5045818DECA91619EE86191453A5A3 | O24: 50B5818C1C385D19DBC67C675F9ED6AF0EFAAE | P24: F | Q24: F | R24: T | AW24: 5045818DECA91619EE86191453A5A350B5818C1C385D19DBC67C675F9ED6AF0EFAAE
A25: 트럭탑재형 크레인 | B25: 10ton | C25: HR | D25: 0.46 | E25: =일위대가목록!E308 -> 16488 | F25: =TRUNC(E25*D25,1) -> 7584.4 | G25: =일위대가목록!F308 -> 49778 | H25: =TRUNC(G25*D25,1) -> 22897.8 | I25: =일위대가목록!G308 -> 23795 | J25: =TRUNC(I25*D25,1) -> 10945.7 | K25: =TRUNC(E25+G25+I25,1) -> 90061 | L25: =TRUNC(F25+H25+J25,1) -> 41427.9 | M25: 호표 305 | N25: 5045818DECA91619EE86191453A5A3 | O25: 577F118D8878DD199FF2D86D5B20720393AEBD59 | P25: T | Q25: F | R25: F | AW25: 5045818DECA91619EE86191453A5A3577F118D8878DD199FF2D86D5B20720393AEBD59
A26: [ 합 계 ] | F26: =TRUNC(SUMIF(N23:N25, N22, F23:F25),0) -> 7584 | H26: =TRUNC(SUMIF(N23:N25, N22, H23:H25),0) -> 77905 | J26: =TRUNC(SUMIF(N23:N25, N22, J23:J25),0) -> 10945 | L26: =F26+H26+J26 -> 96434 | N26: TOTAL | O26: TOTAL
A28: 조립식 간이흙막이 설치 및 해체 H=4.0M 이하 M 공통 2-10-5 ( 호표 5 ) | N28: 5045818DECA91619EE8619265A4F85
A29: 특별인부 | B29: 일반공사 직종 | C29: 인 | D29: 0.28 | E29: =단가대비표!O165 -> 0 | F29: =TRUNC(E29*D29,1) -> 0 | G29: =단가대비표!P165 -> 226122 | H29: =TRUNC(G29*D29,1) -> 63314.1 | I29: =단가대비표!V165 -> 0 | J29: =TRUNC(I29*D29,1) -> 0 | K29: =TRUNC(E29+G29+I29,1) -> 226122 | L29: =TRUNC(F29+H29+J29,1) -> 63314.1 | N29: 5045818DECA91619EE8619265A4F85 | O29: 50B5818C1C385D19DBC67C675F9ED6AF0EFAAF | P29: F | Q29: F | R29: T | AW29: 5045818DECA91619EE8619265A4F8550B5818C1C385D19DBC67C675F9ED6AF0EFAAF
A30: 보통인부 | B30: 일반공사 직종 | C30: 인 | D30: 0.1 | E30: =단가대비표!O164 -> 0 | F30: =TRUNC(E30*D30,1) -> 0 | G30: =단가대비표!P164 -> 172068 | H30: =TRUNC(G30*D30,1) -> 17206.8 | I30: =단가대비표!V164 -> 0 | J30: =TRUNC(I30*D30,1) -> 0 | K30: =TRUNC(E30+G30+I30,1) -> 172068 | L30: =TRUNC(F30+H30+J30,1) -> 17206.8 | N30: 5045818DECA91619EE8619265A4F85 | O30: 50B5818C1C385D19DBC67C675F9ED6AF0EFAAE | P30: F | Q30: F | R30: T | AW30: 5045818DECA91619EE8619265A4F8550B5818C1C385D19DBC67C675F9ED6AF0EFAAE
A31: 트럭탑재형 크레인 | B31: 10ton | C31: HR | D31: 0.9 | E31: =일위대가목록!E308 -> 16488 | F31: =TRUNC(E31*D31,1) -> 14839.2 | G31: =일위대가목록!F308 -> 49778 | H31: =TRUNC(G31*D31,1) -> 44800.2 | I31: =일위대가목록!G308 -> 23795 | J31: =TRUNC(I31*D31,1) -> 21415.5 | K31: =TRUNC(E31+G31+I31,1) -> 90061 | L31: =TRUNC(F31+H31+J31,1) -> 81054.9 | M31: 호표 305 | N31: 5045818DECA91619EE8619265A4F85 | O31: 577F118D8878DD199FF2D86D5B20720393AEBD59 | P31: T | Q31: F | R31: F | AW31: 5045818DECA91619EE8619265A4F85577F118D8878DD199FF2D86D5B20720393AEBD59
A32: [ 합 계 ] | F32: =TRUNC(SUMIF(N29:N31, N28, F29:F31),0) -> 14839 | H32: =TRUNC(SUMIF(N29:N31, N28, H29:H31),0) -> 125321 | J32: =TRUNC(SUMIF(N29:N31, N28, J29:J31),0) -> 21415 | L32: =F32+H32+J32 -> 161575 | N32: TOTAL | O32: TOTAL
A34: 조립식 간이흙막이 설치 및 해체 H=5.0M 이하 M 공통 2-10-5 ( 호표 6 ) | N34: 5045818DECA91619EE8619265B55D0
A35: 특별인부 | B35: 일반공사 직종 | C35: 인 | D35: 0.4 | E35: =단가대비표!O165 -> 0 | F35: =TRUNC(E35*D35,1) -> 0 | G35: =단가대비표!P165 -> 226122 | H35: =TRUNC(G35*D35,1) -> 90448.8 | I35: =단가대비표!V165 -> 0 | J35: =TRUNC(I35*D35,1) -> 0 | K35: =TRUNC(E35+G35+I35,1) -> 226122 | L35: =TRUNC(F35+H35+J35,1) -> 90448.8 | N35: 5045818DECA91619EE8619265B55D0 | O35: 50B5818C1C385D19DBC67C675F9ED6AF0EFAAF | P35: F | Q35: F | R35: T | AW35: 5045818DECA91619EE8619265B55D050B5818C1C385D19DBC67C675F9ED6AF0EFAAF
A36: 보통인부 | B36: 일반공사 직종 | C36: 인 | D36: 0.15 | E36: =단가대비표!O164 -> 0 | F36: =TRUNC(E36*D36,1) -> 0 | G36: =단가대비표!P164 -> 172068 | H36: =TRUNC(G36*D36,1) -> 25810.2 | I36: =단가대비표!V164 -> 0 | J36: =TRUNC(I36*D36,1) -> 0 | K36: =TRUNC(E36+G36+I36,1) -> 172068 | L36: =TRUNC(F36+H36+J36,1) -> 25810.2 | N36: 5045818DECA91619EE8619265B55D0 | O36: 50B5818C1C385D19DBC67C675F9ED6AF0EFAAE | P36: F | Q36: F | R36: T | AW36: 5045818DECA91619EE8619265B55D050B5818C1C385D19DBC67C675F9ED6AF0EFAAE
A37: 트럭탑재형 크레인 | B37: 10ton | C37: HR | D37: 1.48 | E37: =일위대가목록!E308 -> 16488 | F37: =TRUNC(E37*D37,1) -> 24402.2 | G37: =일위대가목록!F308 -> 49778 | H37: =TRUNC(G37*D37,1) -> 73671.4 | I37: =일위대가목록!G308 -> 23795 | J37: =TRUNC(I37*D37,1) -> 35216.6 | K37: =TRUNC(E37+G37+I37,1) -> 90061 | L37: =TRUNC(F37+H37+J37,1) -> 133290.2 | M37: 호표 305 | N37: 5045818DECA91619EE8619265B55D0 | O37: 577F118D8878DD199FF2D86D5B20720393AEBD59 | P37: T | Q37: F | R37: F | AW37: 5045818DECA91619EE8619265B55D0577F118D8878DD199FF2D86D5B20720393AEBD59
A38: [ 합 계 ] | F38: =TRUNC(SUMIF(N35:N37, N34, F35:F37),0) -> 24402 | H38: =TRUNC(SUMIF(N35:N37, N34, H35:H37),0) -> 189930 | J38: =TRUNC(SUMIF(N35:N37, N34, J35:J37),0) -> 35216 | L38: =F38+H38+J38 -> 249548 | N38: TOTAL | O38: TOTAL
A40: 조립식 간이흙막이 설치 및 해체 H=6.0M 이하 M 공통 2-10-5 ( 호표 7 ) | N40: 5045818DECA91619EE861926588171
A41: 특별인부 | B41: 일반공사 직종 | C41: 인 | D41: 0.57 | E41: =단가대비표!O165 -> 0 | F41: =TRUNC(E41*D41,1) -> 0 | G41: =단가대비표!P165 -> 226122 | H41: =TRUNC(G41*D41,1) -> 128889.5 | I41: =단가대비표!V165 -> 0 | J41: =TRUNC(I41*D41,1) -> 0 | K41: =TRUNC(E41+G41+I41,1) -> 226122 | L41: =TRUNC(F41+H41+J41,1) -> 128889.5 | N41: 5045818DECA91619EE861926588171 | O41: 50B5818C1C385D19DBC67C675F9ED6AF0EFAAF | P41: F | Q41: F | R41: T | AW41: 5045818DECA91619EE86192658817150B5818C1C385D19DBC67C675F9ED6AF0EFAAF
A42: 보통인부 | B42: 일반공사 직종 | C42: 인 | D42: 0.22 | E42: =단가대비표!O164 -> 0 | F42: =TRUNC(E42*D42,1) -> 0 | G42: =단가대비표!P164 -> 172068 | H42: =TRUNC(G42*D42,1) -> 37854.9 | I42: =단가대비표!V164 -> 0 | J42: =TRUNC(I42*D42,1) -> 0 | K42: =TRUNC(E42+G42+I42,1) -> 172068 | L42: =TRUNC(F42+H42+J42,1) -> 37854.9 | N42: 5045818DECA91619EE861926588171 | O42: 50B5818C1C385D19DBC67C675F9ED6AF0EFAAE | P42: F | Q42: F | R42: T | AW42: 5045818DECA91619EE86192658817150B5818C1C385D19DBC67C675F9ED6AF0EFAAE
A43: 트럭탑재형 크레인 | B43: 10ton | C43: HR | D43: 2.2 | E43: =일위대가목록!E308 -> 16488 | F43: =TRUNC(E43*D43,1) -> 36273.6 | G43: =일위대가목록!F308 -> 49778 | H43: =TRUNC(G43*D43,1) -> 109511.6 | I43: =일위대가목록!G308 -> 23795 | J43: =TRUNC(I43*D43,1) -> 52349 | K43: =TRUNC(E43+G43+I43,1) -> 90061 | L43: =TRUNC(F43+H43+J43,1) -> 198134.2 | M43: 호표 305 | N43: 5045818DECA91619EE861926588171 | O43: 577F118D8878DD199FF2D86D5B20720393AEBD59 | P43: T | Q43: F | R43: F | AW43: 5045818DECA91619EE861926588171577F118D8878DD199FF2D86D5B20720393AEBD59
A44: [ 합 계 ] | F44: =TRUNC(SUMIF(N41:N43, N40, F41:F43),0) -> 36273 | H44: =TRUNC(SUMIF(N41:N43, N40, H41:H43),0) -> 276256 | J44: =TRUNC(SUMIF(N41:N43, N40, J41:J43),0) -> 52349 | L44: =F44+H44+J44 -> 364878 | N44: TOTAL | O44: TOTAL
A46: 비탈면 보양 보양재(천막 등) M2 공통 2-10-6 ( 호표 8 ) | N46: 5045818DECA9C719807643395AAFFA
A47: 특별인부 | B47: 일반공사 직종 | C47: 인 | D47: 0.02 | E47: =단가대비표!O165 -> 0 | F47: =TRUNC(E47*D47,1) -> 0 | G47: =단가대비표!P165 -> 226122 | H47: =TRUNC(G47*D47,1) -> 4522.4 | I47: =단가대비표!V165 -> 0 | J47: =TRUNC(I47*D47,1) -> 0 | K47: =TRUNC(E47+G47+I47,1) -> 226122 | L47: =TRUNC(F47+H47+J47,1) -> 4522.4 | N47: 5045818DECA9C719807643395AAFFA | O47: 50B5818C1C385D19DBC67C675F9ED6AF0EFAAF | P47: F | Q47: F | R47: T | AW47: 5045818DECA9C719807643395AAFFA50B5818C1C385D19DBC67C675F9ED6AF0EFAAF
...

Sheet 단가산출목록
B1: 단 가 산 출 목 록
B2: 2026년 상반기 충청남도교육청 건설공사 일위대가(토목, 조경)
A3: 코 드 | B3: 품 명 | C3: 규 격 | D3: 단위 | E3: 재 료 비 | F3: 노 무 비 | G3: 경 비 | H3: 합 계 | I3: 번 호 | J3: 비 고 | K3: START | L3: 품셈개요
A4: 5045518AF62192199C10530B563414 | B4: 콘크리트포장 절단 | C4: 포장두께 20cm 이하 | D4: M | E4: =단가산출서!B41 -> 1002 | F4: =단가산출서!C41 -> 1529 | G4: =단가산출서!D41 -> 38 | H4: =단가산출서!E41 -> 2569 | I4: 산근 1 | K4: 5045518AF62192199C10530B563414 | L4: 유지관리 토목 2-1-2
A5: 5045518AF62192199C1053265490FC | B5: 아스팔트포장 절단 | C5: 포장두께 20cm 이하 | D5: M | E5: =단가산출서!B80 -> 878 | F5: =단가산출서!C80 -> 1376 | G5: =단가산출서!D80 -> 35 | H5: =단가산출서!E80 -> 2289 | I5: 산근 2 | K5: 5045518AF62192199C1053265490FC | L5: 유지관리 토목 2-1-2
A6: 5045518A832A4F19D43D6A80587011 | B6: 절삭 후 아스팔트 덧씌우기(밀링깊이 70mm) | C6: A-TYPE (연속구간) | D6: M2 | E6: =단가산출서!B161 -> 463 | F6: =단가산출서!C161 -> 1405 | G6: =단가산출서!D161 -> 852 | H6: =단가산출서!E161 -> 2720 | I6: 산근 3 | K6: 5045518A832A4F19D43D6A80587011 | L6: 유지관리 토목 2-1-3
A7: 5045518A832A4F19D43D6ACE554DBF | B7: 절삭 후 아스팔트 덧씌우기(밀링깊이 70mm) | C7: B-TYPE (불연속구간/장비운반 불필요) | D7: M2 | E7: =단가산출서!B242 -> 665 | F7: =단가산출서!C242 -> 1928 | G7: =단가산출서!D242 -> 1236 | H7: =단가산출서!E242 -> 3829 | I7: 산근 4 | K7: 5045518A832A4F19D43D6ACE554DBF | L7: 유지관리 토목 2-1-3
A8: 5045518A832A4F19D43D582057462D | B8: 절삭 후 아스팔트 덧씌우기(밀링깊이 70mm) | C8: C-TYPE (불연속구간/장비운반 필요) | D8: M2 | E8: =단가산출서!B323 -> 865 | F8: =단가산출서!C323 -> 3118 | G8: =단가산출서!D323 -> 1517 | H8: =단가산출서!E323 -> 5500 | I8: 산근 5 | K8: 5045518A832A4F19D43D582057462D | L8: 유지관리 토목 2-1-3
A9: 5045518A832A4F19D43D580558C37A | B9: 절삭 후 아스팔트 덧씌우기(밀링깊이 100mm) | C9: A-TYPE (연속구간) | D9: M2 | E9: =단가산출서!B404 -> 891 | F9: =단가산출서!C404 -> 2703 | G9: =단가산출서!D404 -> 1640 | H9: =단가산출서!E404 -> 5234 | I9: 산근 6 | K9: 5045518A832A4F19D43D580558C37A | L9: 유지관리 토목 2-1-4
A10: 5045518A832A4F19D43D58785940BF | B10: 절삭 후 아스팔트 덧씌우기(밀링깊이 100mm) | C10: B-TYPE (불연속구간/장비운반 불필요) | D10: M2 | E10: =단가산출서!B485 -> 1258 | F10: =단가산출서!C485 -> 3642 | G10: =단가산출서!D485 -> 2336 | H10: =단가산출서!E485 -> 7236 | I10: 산근 7 | K10: 5045518A832A4F19D43D58785940BF | L10: 유지관리 토목 2-1-4
A11: 5045518A832A4F19D43D4FD653E2D5 | B11: 절삭 후 콘크리트 덧씌우기(밀링깊이 t=100mm) | C11: (1일 2500m2) | D11: M2 | E11: =단가산출서!B535 -> 348 | F11: =단가산출서!C535 -> 1666 | G11: =단가산출서!D535 -> 777 | H11: =단가산출서!E535 -> 2791 | I11: 산근 8 | K11: 5045518A832A4F19D43D4FD653E2D5 | L11: 유지관리 토목 2-1-5
A12: 5045518A832A4F19D43D4FE05946DB | B12: 절삭 후 콘크리트 덧씌우기(밀링깊이 t=150mm) | C12: (1일 1600m2) | D12: M2 | E12: =단가산출서!B585 -> 544 | F12: =단가산출서!C585 -> 2603 | G12: =단가산출서!D585 -> 1214 | H12: =단가산출서!E585 -> 4361 | I12: 산근 9 | K12: 5045518A832A4F19D43D4FE05946DB | L12: 유지관리 토목 2-1-5
A13: 5045518A832A4F19D43D3D38549529 | B13: 아스팔트 덧씌우기 | C13: 소규모 포장(단지내 소로,주택가 도로 등) | D13: M2 | E13: =단가산출서!B651 -> 345 | F13: =단가산출서!C651 -> 2301 | G13: =단가산출서!D651 -> 507 | H13: =단가산출서!E651 -> 3153 | I13: 산근 10 | K13: 5045518A832A4F19D43D3D38549529 | L13: 유지관리 토목 2-1-6
A14: 5045518A832A4F19D43D3D3855BB2B | B14: 개질아스팔트 덧씌우기 | C14: 소규모 포장(단지내 소로,주택가 도로 등) | D14: M2 | E14: =단가산출서!B711 -> 391 | F14: =단가산출서!C711 -> 2557 | G14: =단가산출서!D711 -> 536 | H14: =단가산출서!E711 -> 3484 | I14: 산근 11 | K14: 5045518A832A4F19D43D3D3855BB2B | L14: 유지관리 토목 2-1-6
A15: 5045518A832A4F19D43D3D38564030 | B15: 투배수성 덧씌우기 | C15: 소규모 포장(단지내 소로,주택가 도로 등) | D15: M2 | E15: =단가산출서!B771 -> 439 | F15: =단가산출서!C771 -> 2877 | G15: =단가산출서!D771 -> 603 | H15: =단가산출서!E771 -> 3919 | I15: 산근 12 | K15: 5045518A832A4F19D43D3D38564030 | L15: 유지관리 토목 2-1-6
A16: 5045518A832A4F19D43D3D0C5FC729 | B16: 아스팔트 절삭 | C16: 밀링깊이 70MM이하(소규모 포장) | D16: M2 | E16: =단가산출서!B819 -> 356 | F16: =단가산출서!C819 -> 1036 | G16: =단가산출서!D819 -> 640 | H16: =단가산출서!E819 -> 2032 | I16: 산근 13 | K16: 5045518A832A4F19D43D3D0C5FC729 | L16: 유지관리 토목 2-1-6
A17: 5045518AF65EE619E334BDAA5AE495 | B17: 일체형 맨홀추락방지망 설치 | C17: 아스팔트구간 | D17: 개소 | E17: =단가산출서!B873 -> 43791 | F17: =단가산출서!C873 -> 427216 | G17: =단가산출서!D873 -> 44497 | H17: =단가산출서!E873 -> 515504 | I17: 산근 14 | K17: 5045518AF65EE619E334BDAA5AE495 | L17: 유지관리 토목 2-1-12
A18: 5045518AF65EE619E334BDD75E45C2 | B18: 일체형 맨홀추락방지망 설치 | C18: 보도구간 | D18: 개소 | E18: =단가산출서!B903 -> 5338 | F18: =단가산출서!C903 -> 167878 | G18: =단가산출서!D903 -> 10065 | H18: =단가산출서!E903 -> 183281 | I18: 산근 15 | K18: 5045518AF65EE619E334BDD75E45C2 | L18: 유지관리 토목 2-1-13
A19: 5045518AF65EE619E334BDC557BB99 | B19: 부착형 맨홀추락방지망 설치 | D19: 개소 | E19: =단가산출서!B931 -> 3558 | F19: =단가산출서!C931 -> 85211 | G19: =단가산출서!D931 -> 6949 | H19: =단가산출서!E931 -> 95718 | I19: 산근 16 | K19: 5045518AF65EE619E334BDC557BB99 | L19: 유지관리 토목 2-1-13
A20: 5045518AF65EE619E32A576E54EB8D | B20: 차선도색 제거 | D20: M2 | E20: =단가산출서!B962 -> 3454 | F20: =단가산출서!C962 -> 35956 | G20: =단가산출서!D962 -> 2350 | H20: =단가산출서!E962 -> 41760 | I20: 산근 17 | K20: 5045518AF65EE619E32A576E54EB8D | L20: 유지관리 토목 2-1-16
A21: 50448187514A2619B115E20758CD3D | B21: 보도용 블록 인력철거 | C21: A-TYPE: 공원, 단지내 보도 | D21: M2 | E21: =단가산출서!B986 -> 118 | F21: =단가산출서!C986 -> 3580 | G21: =단가산출서!D986 -> 144 | H21: =단가산출서!E986 -> 3842 | I21: 산근 18 | K21: 50448187514A2619B115E20758CD3D | L21: 유지관리 토목 2-1-27
A22: 50448187514A2619B115E20758CEC4 | B22: 보도용 블록 인력철거 | C22: B-TYPE: 차도인접, 주택가보도 | D22: M2 | E22: =단가산출서!B1010 -> 164 | F22: =단가산출서!C1010 -> 4295 | G22: =단가산출서!D1010 -> 200 | H22: =단가산출서!E1010 -> 4659 | I22: 산근 19 | K22: 50448187514A2619B115E20758CEC4 | L22: 유지관리 토목 2-1-27
A23: 50448187514A2619B115D19056D4EC | B23: 보도용 블록 장비사용 철거 | C23: A-TYPE: 공원, 단지내 보도 | D23: M2 | E23: =단가산출서!B1040 -> 285 | F23: =단가산출서!C1040 -> 2192 | G23: =단가산출서!D1040 -> 320 | H23: =단가산출서!E1040 -> 2797 | I23: 산근 20 | K23: 50448187514A2619B115D19056D4EC | L23: 유지관리 토목 2-1-28
A24: 50448187514A2619B115D19056D7A0 | B24: 보도용 블록 장비사용 철거 | C24: B-TYPE: 차도인접, 주택가보도 | D24: M2 | E24: =단가산출서!B1070 -> 233 | F24: =단가산출서!C1070 -> 2860 | G24: =단가산출서!D1070 -> 354 | H24: =단가산출서!E1070 -> 3447 | I24: 산근 21 | K24: 50448187514A2619B115D19056D7A0 | L24: 유지관리 토목 2-1-28
A25: 5045518ACA61F219F892327850A00E | B25: 보도용 블록 재설치(소형) / A-TYPE | C25: 블록 정밀절단 / 0 .1㎡이하, 두께 8cm | D25: M2 | E25: =단가산출서!B1116 -> 714 | F25: =단가산출서!C1116 -> 10679 | G25: =단가산출서!D1116 -> 1069 | H25: =단가산출서!E1116 -> 12462 | I25: 산근 22 | K25: 5045518ACA61F219F892327850A00E | L25: 유지관리 토목 2-1-29
A26: 5045518ACA61F219F89232785147F8 | B26: 보도용 블록 재설치(소형) / 유도,점자 / A-TYPE | C26: 블록 정밀절단 / 0 .1㎡이하, 두께 8cm | D26: M2 | E26: =단가산출서!B1160 -> 793 | F26: =단가산출서!C1160 -> 11865 | G26: =단가산출서!D1160 -> 1188 | H26: =단가산출서!E1160 -> 13846 | I26: 산근 23 | K26: 5045518ACA61F219F89232785147F8 | L26: 유지관리 토목 2-1-29
A27: 5045518ACA61F219F892324C5CF918 | B27: 보도용 블록 재설치(소형) / A-TYPE | C27: 0 .1㎡이하, 두께 8cm | D27: M2 | E27: =단가산출서!B1204 -> 714 | F27: =단가산출서!C1204 -> 9809 | G27: =단가산출서!D1204 -> 865 | H27: =단가산출서!E1204 -> 11388 | I27: 산근 24 | K27: 5045518ACA61F219F892324C5CF918 | L27: 유지관리 토목 2-1-29
A28: 5045518ACA61F219F892324C5D80EA | B28: 보도용 블록 재설치(소형) / 유도,점자 / A-TYPE | C28: 0 .1㎡이하, 두께 8cm | D28: M2 | E28: =단가산출서!B1248 -> 793 | F28: =단가산출서!C1248 -> 10899 | G28: =단가산출서!D1248 -> 961 | H28: =단가산출서!E1248 -> 12653 | I28: 산근 25 | K28: 5045518ACA61F219F892324C5D80EA | L28: 유지관리 토목 2-1-29
A29: 5045518ACA61F219F8920532520766 | B29: 보도용 블록 재설치(소형) / B-TYPE | C29: 블록 정밀절단 / 0 .1㎡이하, 두께 8cm | D29: M2 | E29: =단가산출서!B1292 -> 674 | F29: =단가산출서!C1292 -> 12951 | G29: =단가산출서!D1292 -> 1259 | H29: =단가산출서!E1292 -> 14884 | I29: 산근 26 | K29: 5045518ACA61F219F8920532520766 | L29: 유지관리 토목 2-1-29
A30: 5045518ACA61F219F8920532532E70 | B30: 보도용 블록 재설치(소형) / 유도,점자 / B-TYPE | C30: 블록 정밀절단 / 0 .1㎡이하, 두께 8cm | D30: M2 | E30: =단가산출서!B1336 -> 749 | F30: =단가산출서!C1336 -> 14390 | G30: =단가산출서!D1336 -> 1398 | H30: =단가산출서!E1336 -> 16537 | I30: 산근 27 | K30: 5045518ACA61F219F8920532532E70 | L30: 유지관리 토목 2-1-29
A31: 5045518ACA61F219F89205065DBAAD | B31: 보도용 블록 재설치(소형) / B-TYPE | C31: 0 .1㎡이하, 두께 8cm | D31: M2 | E31: =단가산출서!B1380 -> 674 | F31: =단가산출서!C1380 -> 11695 | G31: =단가산출서!D1380 -> 1038 | H31: =단가산출서!E1380 -> 13407 | I31: 산근 28 | K31: 5045518ACA61F219F89205065DBAAD | L31: 유지관리 토목 2-1-29
A32: 5045518ACA61F219F89205065C9383 | B32: 보도용 블록 재설치(소형) / 유도,점자 / B-TYPE | C32: 0 .1㎡이하, 두께 8cm | D32: M2 | E32: =단가산출서!B1424 -> 749 | F32: =단가산출서!C1424 -> 12994 | G32: =단가산출서!D1424 -> 1154 | H32: =단가산출서!E1424 -> 14897 | I32: 산근 29 | K32: 5045518ACA61F219F89205065C9383 | L32: 유지관리 토목 2-1-29
A33: 5045518ACA61E0198FFF907B504344 | B33: 보도용 블록 소규모보수 | C33: 시공면적: 10M2 이하 | D33: M2 | E33: =단가산출서!B1469 -> 2597 | F33: =단가산출서!C1469 -> 29441 | G33: =단가산출서!D1469 -> 3022 | H33: =단가산출서!E1469 -> 35060 | I33: 산근 30 | K33: 5045518ACA61E0198FFF907B504344 | L33: 유지관리 토목 2-1-31
A34: 5045518ACA61E0198FFF907B516A6D | B34: 보도용 유도,점자블록 소규모보수 | C34: 시공면적: 10M2 이하 | D34: M2 | E34: =단가산출서!B1514 -> 2886 | F34: =단가산출서!C1514 -> 32713 | G34: =단가산출서!D1514 -> 3358 | H34: =단가산출서!E1514 -> 38957 | I34: 산근 31 | K34: 5045518ACA61E0198FFF907B516A6D | L34: 유지관리 토목 2-1-31
A35: 5045518ACA61E0198FFF904F5C9C6E | B35: 보도용 블록 소규모보수 | C35: 시공면적: 30M2 이하 | D35: M2 | E35: =단가산출서!B1559 -> 1986 | F35: =단가산출서!C1559 -> 22514 | G35: =단가산출서!D1559 -> 2311 | H35: =단가산출서!E1559 -> 26811 | I35: 산근 32 | K35: 5045518ACA61E0198FFF904F5C9C6E | L35: 유지관리 토목 2-1-31
A36: 5045518ACA61E0198FFF904F5DA340 | B36: 보도용 유도,점자블록 소규모보수 | C36: 시공면적: 30M2 이하 | D36: M2 | E36: =단가산출서!B1604 -> 2207 | F36: =단가산출서!C1604 -> 25015 | G36: =단가산출서!D1604 -> 2568 | H36: =단가산출서!E1604 -> 29790 | I36: 산근 33 | K36: 5045518ACA61E0198FFF904F5DA340 | L36: 유지관리 토목 2-1-31
A37: 5045518ACA61E0198FFF9058536ECD | B37: 보도용 블록 소규모보수 | C37: 시공면적: 60M2 이하 | D37: M2 | E37: =단가산출서!B1649 -> 1777 | F37: =단가산출서!C1649 -> 20144 | G37: =단가산출서!D1649 -> 2068 | H37: =단가산출서!E1649 -> 23989 | I37: 산근 34 | K37: 5045518ACA61E0198FFF9058536ECD | L37: 유지관리 토목 2-1-31
A38: 5045518ACA61E0198FFF90585248CA | B38: 보도용 유도,점자블록 소규모보수 | C38: 시공면적: 60M2 이하 | D38: M2 | E38: =단가산출서!B1694 -> 1974 | F38: =단가산출서!C1694 -> 22383 | G38: =단가산출서!D1694 -> 2298 | H38: =단가산출서!E1694 -> 26655 | I38: 산근 35 | K38: 5045518ACA61E0198FFF90585248CA | L38: 유지관리 토목 2-1-31
A39: 5045518ACA61E0198FFF902C5FA8C6 | B39: 보도용 블록 소규모보수 | C39: 시공면적: 110M2 이하 | D39: M2 | E39: =단가산출서!B1739 -> 1688 | F39: =단가산출서!C1739 -> 19137 | G39: =단가산출서!D1739 -> 1964 | H39: =단가산출서!E1739 -> 22789 | I39: 산근 36 | K39: 5045518ACA61E0198FFF902C5FA8C6 | L39: 유지관리 토목 2-1-31
A40: 5045518ACA61E0198FFF902C5E813C | B40: 보도용 유도,점자블록 소규모보수 | C40: 시공면적: 110M2 이하 | D40: M2 | E40: =단가산출서!B1784 -> 1875 | F40: =단가산출서!C1784 -> 21264 | G40: =단가산출서!D1784 -> 2183 | H40: =단가산출서!E1784 -> 25322 | I40: 산근 37 | K40: 5045518ACA61E0198FFF902C5E813C | L40: 유지관리 토목 2-1-31
...

Sheet 단가산출서
A1: 단 가 산 출 서
A2: 2026년 상반기 충청남도교육청 건설공사 일위대가(토목, 조경)
A3: 산 출 내 역 | B3: 재 료 비 | C3: 노 무 비 | D3: 경 비 | E3: 합 계 | F3: 비 고 | G3: START | H3: 코드 | I3: 품명 | J3: 규격 | K3: 단위 | L3: 수량 | M3: 변수 | N3: 값 | O3: 소계 | P3: 소계 | Q3: 소계 | R3: 소계 | S3: 소계 | T3: 총계
A4: 콘크리트포장 절단 포장두께 20cm 이하 M 유지관리 토목 2-1-2 ( 산근 1 ) | G4: 5045518AF62192199C10530B563414 | I4: 콘크리트포장 절단 | J4: 포장두께 20cm 이하 | K4: M
G5: 5045518AF62192199C10530B563414 | H5: C | L5: 1
B6: 0 | C6: 0 | D6: 0 | E6: 0 | G6: 5045518AF62192199C10530B563414 | H6: C!
A7: Q1 1일시공량(M/일) =450 | B7: 0 | C7: 0 | D7: 0 | E7: 0 | G7: 5045518AF62192199C10530B563414 | H7: C! | I7: q1'1일시공량(M/일)' =450
A8: Q 시간당 작업량(M/HR) =Q1/8= 56.25 | B8: 0 | C8: 0 | D8: 0 | E8: 0 | G8: 5045518AF62192199C10530B563414 | H8: C! | I8: Q '시간당 작업량(M/HR)' =q1/8=?
B9: 0 | C9: 0 | D9: 0 | E9: 0 | G9: 5045518AF62192199C10530B563414 | H9: C!
A10: ◈배치인원 | B10: 0 | C10: 0 | D10: 0 | E10: 0 | G10: 5045518AF62192199C10530B563414 | H10: C! | I10: '◈배치인원'
B11: 0 | C11: 0 | D11: 0 | E11: 0 | G11: 5045518AF62192199C10530B563414 | H11: C!
A12: 1.인력 | B12: 0 | C12: 0 | D12: 0 | E12: 0 | G12: 5045518AF62192199C10530B563414 | H12: C! | I12: '1.인력'
A13: 특별인부 1인/8HR*작업시간 | B13: 0 | C13: 0 | D13: 0 | E13: 0 | G13: 5045518AF62192199C10530B563414 | H13: C! | I13: '특별인부 1인/8HR*작업시간'
A14: 노무비: 226122*1/8/56.25 = 502.4 | B14: 0 | C14: 502.4 | D14: 0 | E14: 502.4 | G14: 5045518AF62192199C10530B563414 | H14: C! | I14: '노무비:' ~L001010101000003.L~*1/8/{Q} =?LA+
A15: 보통인부 1인/8HR*작업시간 | B15: 0 | C15: 0 | D15: 0 | E15: 0 | G15: 5045518AF62192199C10530B563414 | H15: C! | I15: '보통인부 1인/8HR*작업시간'
A16: 노무비: 172068*1/8/56.25 = 382.3 | B16: 0 | C16: 382.3 | D16: 0 | E16: 382.3 | G16: 5045518AF62192199C10530B563414 | H16: C! | I16: '노무비:' ~L001010101000002.L~*1/8/{Q} =?LA+
A17: 소 계 | B17: 0 | C17: 884.7 | D17: 0 | E17: 884.7 | G17: 5045518AF62192199C10530B563414 | H17: C! | I17: >'소 계'
B18: 0 | C18: 0 | D18: 0 | E18: 0 | G18: 5045518AF62192199C10530B563414 | H18: C!
A19: ◈사용기계 | B19: 0 | C19: 0 | D19: 0 | E19: 0 | G19: 5045518AF62192199C10530B563414 | H19: C! | I19: '◈사용기계 '
B20: 0 | C20: 0 | D20: 0 | E20: 0 | G20: 5045518AF62192199C10530B563414 | H20: C!
A21: 2.커터(콘크리트 및 아스팔트) 320~400MM 1대 | B21: 0 | C21: 0 | D21: 0 | E21: 0 | G21: 5045518AF62192199C10530B563414 | H21: C! | I21: '2.커터(콘크리트 및 아스팔트) 320~400mm 1대'
A22: 재료비: 9898 / 56.25 = 175.9 | B22: 175.9 | C22: 0 | D22: 0 | E22: 175.9 | G22: 5045518AF62192199C10530B563414 | H22: C! | I22: '재료비:' ~00004430040000000.M~ / {Q} =?MA+
A23: 노무비: 36248 / 56.25 = 644.4 | B23: 0 | C23: 644.4 | D23: 0 | E23: 644.4 | G23: 5045518AF62192199C10530B563414 | H23: C! | I23: '노무비:' ~00004430040000000.L~ / {Q} =?LA+
A24: 경 비: 2064 / 56.25 = 36.6 | B24: 0 | C24: 0 | D24: 36.6 | E24: 36.6 | G24: 5045518AF62192199C10530B563414 | H24: C! | I24: '경 비:' ~00004430040000000.E~ / {Q} =?EQ+
A25: 소 계 | B25: 175.9 | C25: 644.4 | D25: 36.6 | E25: 856.9 | G25: 5045518AF62192199C10530B563414 | H25: C! | I25: >'소 계'
B26: 0 | C26: 0 | D26: 0 | E26: 0 | G26: 5045518AF62192199C10530B563414 | H26: C!
A27: 3.동력분무기 4.85kW 0.5대 | B27: 0 | C27: 0 | D27: 0 | E27: 0 | G27: 5045518AF62192199C10530B563414 | H27: C! | I27: '3.동력분무기 4.85kW 0.5대 '
A28: 재료비: 2297 *0.5 / 56.25 = 20.4 | B28: 20.4 | C28: 0 | D28: 0 | E28: 20.4 | G28: 5045518AF62192199C10530B563414 | H28: C! | I28: '재료비:' ~00007210048500000.M~ *0.5 / {Q} =?MA+
A29: 노무비: 0 *0.5 / 56.25 = 0 | B29: 0 | C29: 0 | D29: 0 | E29: 0 | G29: 5045518AF62192199C10530B563414 | H29: C! | I29: '노무비:' ~00007210048500000.L~ *0.5 / {Q} =?LA+
A30: 경 비: 258 *0.5 / 56.25 = 2.2 | B30: 0 | C30: 0 | D30: 2.2 | E30: 2.2 | G30: 5045518AF62192199C10530B563414 | H30: C! | I30: '경 비:' ~00007210048500000.E~ *0.5 / {Q} =?EQ+
A31: 소 계 | B31: 20.4 | C31: 0 | D31: 2.2 | E31: 22.6 | G31: 5045518AF62192199C10530B563414 | H31: C! | I31: >'소 계'
B32: 0 | C32: 0 | D32: 0 | E32: 0 | G32: 5045518AF62192199C10530B563414 | H32: C!
A33: ③ 블레이드 및 물 소비량은 별도 계상한다. | B33: 0 | C33: 0 | D33: 0 | E33: 0 | G33: 5045518AF62192199C10530B563414 | H33: C! | I33: '③ 블레이드 및 물 소비량은 별도 계상한다.'
A34: ※2020년 표준품셈 토목부분 1-7-1 준용 | B34: 0 | C34: 0 | D34: 0 | E34: 0 | G34: 5045518AF62192199C10530B563414 | H34: C! | I34: '※2020년 표준품셈 토목부분 1-7-1 준용'
A35: 4.자재 | B35: 0 | C35: 0 | D35: 0 | E35: 0 | G35: 5045518AF62192199C10530B563414 | H35: C! | I35: '4.자재'
A36: 블레이드(다이어몬드14인치T=3.2MM)100M당0.3개소모 | B36: 0 | C36: 0 | D36: 0 | E36: 0 | G36: 5045518AF62192199C10530B563414 | H36: C! | I36: '블레이드(다이어몬드14인치T=3.2MM)100M당0.3개소모 '
A37: 재료비: 260000 * 0.0031 = 806 | B37: 806 | C37: 0 | D37: 0 | E37: 806 | G37: 5045518AF62192199C10530B563414 | H37: C! | I37: '재료비:' ~20111614200Z8261.M~ * 0.0031 =?MA+
A38: 용수100M당 3.0M3소요 | B38: 0 | C38: 0 | D38: 0 | E38: 0 | G38: 5045518AF62192199C10530B563414 | H38: C! | I38: '용수100M당 3.0M3소요'
A39: 재료비: 0 * 0.03 = 0 | B39: 0 | C39: 0 | D39: 0 | E39: 0 | G39: 5045518AF62192199C10530B563414 | H39: C! | I39: '재료비:' ~E001010102002512.M~ * 0.03 =?MA+
A40: 소 계 | B40: 806 | C40: 0 | D40: 0 | E40: 806 | G40: 5045518AF62192199C10530B563414 | H40: C! | I40: >'소 계'
...

Sheet 단가대비표
A1: 단 가 대 비 표
A2: 2026년 상반기 충청남도교육청 건설공사 일위대가(토목, 조경)
A3: 코 드 | B3: 품 명 | C3: 규격 | D3: 단위 | E3: 재 료 비 | P3: 노 무 비 | Q3: 경 비 | W3: 번 호 | X3: 비 고 | Y3: 품목구분 | Z3: 노임구분 | AA3: 소수점처리 | AB3: 자재구분
E4: 조달청가격 | F4: PAGE | G4: 거래가격 | H4: PAGE | I4: 유통물가 | J4: PAGE | K4: 조사가격1 | L4: PAGE | M4: 조사가격2 | N4: PAGE | O4: 적용단가 | Q4: 조달청가격 | R4: 거래가격 | S4: 유통물가 | T4: 조사가격1 | U4: 조사가격2 | V4: 적용단가
A5: 577F118D8878F81948753DBF54A39208010373 | B5: 불도저(무한궤도) | C5: 19ton | D5: 대 | E5: 0 | G5: 0 | I5: 0 | K5: 0 | M5: 0 | O5: 0 | P5: 0 | Q5: 0 | R5: 0 | S5: 0 | T5: 0 | U5: 198150 | V5: =SMALL(Q5:U5,COUNTIF(Q5:U5,0)+1) -> 198150 | W5: 자재 1 | X5: 천원
A6: 577F118D8878F81948753DBF54A1EFB7BEB532 | B6: 불도저(무한궤도) | C6: 32ton | D6: 대 | E6: 0 | G6: 0 | I6: 0 | K6: 0 | M6: 0 | O6: 0 | P6: 0 | Q6: 0 | R6: 0 | S6: 0 | T6: 0 | U6: 263682 | V6: =SMALL(Q6:U6,COUNTIF(Q6:U6,0)+1) -> 263682 | W6: 자재 2 | X6: 천원
A7: 577F118D8878F81975B30CD1525C25E8BFC9E2 | B7: 굴착기(무한궤도) | C7: 0.2㎥ | D7: 대 | E7: 0 | G7: 0 | I7: 0 | K7: 0 | M7: 0 | O7: 0 | P7: 0 | Q7: 0 | R7: 0 | S7: 0 | T7: 0 | U7: 66538 | V7: =SMALL(Q7:U7,COUNTIF(Q7:U7,0)+1) -> 66538 | W7: 자재 3 | X7: 천원
A8: 577F118D8878F81975B30CD1525A770CB8653E | B8: 굴착기(무한궤도) | C8: 0.4㎥ | D8: 대 | E8: 0 | G8: 0 | I8: 0 | K8: 0 | M8: 0 | O8: 0 | P8: 0 | Q8: 0 | R8: 0 | S8: 0 | T8: 0 | U8: 84000 | V8: =SMALL(Q8:U8,COUNTIF(Q8:U8,0)+1) -> 84000 | W8: 자재 4 | X8: 천원
A9: 577F118D8878F81975B30CD152584A182F9E16 | B9: 굴착기(무한궤도) | C9: 0.6㎥ | D9: 대 | E9: 0 | G9: 0 | I9: 0 | K9: 0 | M9: 0 | O9: 0 | P9: 0 | Q9: 0 | R9: 0 | S9: 0 | T9: 0 | U9: 112342 | V9: =SMALL(Q9:U9,COUNTIF(Q9:U9,0)+1) -> 112342 | W9: 자재 5 | X9: 천원
A10: 577F118D8878F81975B30CD152595109C0EDBB | B10: 굴착기(무한궤도) | C10: 0.7㎥ | D10: 대 | E10: 0 | G10: 0 | I10: 0 | K10: 0 | M10: 0 | O10: 0 | P10: 0 | Q10: 0 | R10: 0 | S10: 0 | T10: 0 | U10: 117766 | V10: =SMALL(Q10:U10,COUNTIF(Q10:U10,0)+1) -> 117766 | W10: 자재 6 | X10: 천원
A11: 577F118D8878F81975B30CD152569CBC073D53 | B11: 굴착기(무한궤도) | C11: 0.8㎥ | D11: 대 | E11: 0 | G11: 0 | I11: 0 | K11: 0 | M11: 0 | O11: 0 | P11: 0 | Q11: 0 | R11: 0 | S11: 0 | T11: 0 | U11: 129586 | V11: =SMALL(Q11:U11,COUNTIF(Q11:U11,0)+1) -> 129586 | W11: 자재 7 | X11: 천원
A12: 577F118D8878F81975B30CD15365C43313EDD8 | B12: 굴착기(무한궤도) | C12: 1.0㎥ | D12: 대 | E12: 0 | G12: 0 | I12: 0 | K12: 0 | M12: 0 | O12: 0 | P12: 0 | Q12: 0 | R12: 0 | S12: 0 | T12: 0 | U12: 142069 | V12: =SMALL(Q12:U12,COUNTIF(Q12:U12,0)+1) -> 142069 | W12: 자재 8 | X12: 천원
A13: 577F118D8878F81975A2B893566CC7E9D8CEE0 | B13: 굴착기(타이어) | C13: 0.18㎥ | D13: 대 | E13: 0 | G13: 0 | I13: 0 | K13: 0 | M13: 0 | O13: 0 | P13: 0 | Q13: 0 | R13: 0 | S13: 0 | T13: 0 | U13: 69333 | V13: =SMALL(Q13:U13,COUNTIF(Q13:U13,0)+1) -> 69333 | W13: 자재 9 | X13: 천원
A14: 577F118D8878F81975A2B893566B299D6732AD | B14: 굴착기(타이어) | C14: 0.6㎥ | D14: 대 | E14: 0 | G14: 0 | I14: 0 | K14: 0 | M14: 0 | O14: 0 | P14: 0 | Q14: 0 | R14: 0 | S14: 0 | T14: 0 | U14: 119000 | V14: =SMALL(Q14:U14,COUNTIF(Q14:U14,0)+1) -> 119000 | W14: 자재 10 | X14: 천원
A15: 577F118D8878F81975A2B893566580B9A5CDBE | B15: 굴착기(타이어) | C15: 0.8㎥ | D15: 대 | E15: 0 | G15: 0 | I15: 0 | K15: 0 | M15: 0 | O15: 0 | P15: 0 | Q15: 0 | R15: 0 | S15: 0 | T15: 0 | U15: 141171 | V15: =SMALL(Q15:U15,COUNTIF(Q15:U15,0)+1) -> 141171 | W15: 자재 11 | X15: 천원
A16: 577F118D8878F81975A2B893577321BFE0FFE1 | B16: 굴착기(타이어) | C16: 1.0㎥ | D16: 대 | E16: 0 | G16: 0 | I16: 0 | K16: 0 | M16: 0 | O16: 0 | P16: 0 | Q16: 0 | R16: 0 | S16: 0 | T16: 0 | U16: 144360 | V16: =SMALL(Q16:U16,COUNTIF(Q16:U16,0)+1) -> 144360 | W16: 자재 12 | X16: 천원
... A21: 577F118D8878F8197587D2D65F98F7C102AEEF | B21: 대형 브레이커 | C21: 1.0㎥용 | D21: 대 | E21: 0 | G21: 0 | I21: 0 | K21: 0 | M21: 0 | O21: 0 | P21: 0 | Q21: 0 | R21: 0 | S21: 0 | T21: 0 | U21: 28692 | V21: =SMALL(Q21:U21,COUNTIF(Q21:U21,0)+1) -> 28692 | W21: 자재 17 | X21: 천원
A22: 577F118D8878F8197587C0765C21E3646B5F3E | B22: 대형 브레이커용 치즐 | C22: 0.4㎥용 | D22: 본 | E22: 0 | G22: 0 | I22: 0 | K22: 0 | M22: 0 | O22: 0 | P22: 0 | Q22: 0 | R22: 0 | S22: 0 | T22: 0 | U22: 204000 | V22: =SMALL(Q22:U22,COUNTIF(Q22:U22,0)+1) -> 204000 | W22: 자재 18
A23: 577F118D8878F8197587C0765C21E0AF9D5FCB | B23: 대형 브레이커용 치즐 | C23: 0.7㎥용 | D23: 본 | E23: 0 | G23: 0 | I23: 0 | K23: 0 | M23: 0 | O23: 0 | P23: 0 | Q23: 0 | R23: 0 | S23: 0 | T23: 0 | U23: 216000 | V23: =SMALL(Q23:U23,COUNTIF(Q23:U23,0)+1) -> 216000 | W23: 자재 19
A24: 577F118D8878F81975E85D275478DB9E59FF78 | B24: 압쇄기(펄버라이저) | C24: 1.0㎥용 | D24: 대 | E24: 0 | G24: 0 | I24: 0 | K24: 0 | M24: 0 | O24: 0 | P24: 0 | Q24: 0 | R24: 0 | S24: 0 | T24: 0 | U24: 28567 | V24: =SMALL(Q24:U24,COUNTIF(Q24:U24,0)+1) -> 28567 | W24: 자재 20 | X24: 천원
A25: 577F118D8878F8196B445B6250BA9825B9D048 | B25: 로더(타이어) | C25: 0.25㎥ | D25: 대 | E25: 0 | G25: 0 | I25: 0 | K25: 0 | M25: 0 | O25: 0 | P25: 0 | Q25: 0 | R25: 0 | S25: 0 | T25: 0 | U25: 30197 | V25: =SMALL(Q25:U25,COUNTIF(Q25:U25,0)+1) -> 30197 | W25: 자재 21 | X25: 천원
A26: 577F118D8878F8196B445B6250BD55C8A94FE4 | B26: 로더(타이어) | C26: 0.57㎥ | D26: 대 | E26: 0 | G26: 0 | I26: 0 | K26: 0 | M26: 0 | O26: 0 | P26: 0 | Q26: 0 | R26: 0 | S26: 0 | T26: 0 | U26: 35999 | V26: =SMALL(Q26:U26,COUNTIF(Q26:U26,0)+1) -> 35999 | W26: 자재 22 | X26: 천원
A27: 577F118D8878F8196B445B6250B1A43FC00768 | B27: 로더(타이어) | C27: 0.95㎥ | D27: 대 | E27: 0 | G27: 0 | I27: 0 | K27: 0 | M27: 0 | O27: 0 | P27: 0 | Q27: 0 | R27: 0 | S27: 0 | T27: 0 | U27: 46576 | V27: =SMALL(Q27:U27,COUNTIF(Q27:U27,0)+1) -> 46576 | W27: 자재 23 | X27: 천원
A28: 577F118D8878F81902C605E553105FB22A9BEC | B28: 모터그레이더 | C28: 3.6(일반용) | D28: 대 | E28: 0 | G28: 0 | I28: 0 | K28: 0 | M28: 0 | O28: 0 | P28: 0 | Q28: 0 | R28: 0 | S28: 0 | T28: 0 | U28: 310687 | V28: =SMALL(Q28:U28,COUNTIF(Q28:U28,0)+1) -> 310687 | W28: 자재 24 | X28: 천원
A29: 577F118D8878F8193E0EA90A592BDB1745A78A | B29: 덤프트럭 | C29: 2.5ton | D29: 대 | E29: 0 | G29: 0 | I29: 0 | K29: 0 | M29: 0 | O29: 0 | P29: 0 | Q29: 0 | R29: 0 | S29: 0 | T29: 0 | U29: 21982 | V29: =SMALL(Q29:U29,COUNTIF(Q29:U29,0)+1) -> 21982 | W29: 자재 25 | X29: 천원
A30: 577F118D8878F8193E0EA90A592D89F34C0B8E | B30: 덤프트럭 | C30: 4.5ton | D30: 대 | E30: 0 | G30: 0 | I30: 0 | K30: 0 | M30: 0 | O30: 0 | P30: 0 | Q30: 0 | R30: 0 | S30: 0 | T30: 0 | U30: 25662 | V30: =SMALL(Q30:U30,COUNTIF(Q30:U30,0)+1) -> 25662 | W30: 자재 26 | X30: 천원
A31: 577F118D8878F8193E0EA90A592FB9BC5A56F5 | B31: 덤프트럭 | C31: 6ton | D31: 대 | E31: 0 | G31: 0 | I31: 0 | K31: 0 | M31: 0 | O31: 0 | P31: 0 | Q31: 0 | R31: 0 | S31: 0 | T31: 0 | U31: 28043 | V31: =SMALL(Q31:U31,COUNTIF(Q31:U31,0)+1) -> 28043 | W31: 자재 27 | X31: 천원
A32: 577F118D8878F8193E0EA90A5921DBBEE15454 | B32: 덤프트럭 | C32: 8ton | D32: 대 | E32: 0 | G32: 0 | I32: 0 | K32: 0 | M32: 0 | O32: 0 | P32: 0 | Q32: 0 | R32: 0 | S32: 0 | T32: 0 | U32: 37391 | V32: =SMALL(Q32:U32,COUNTIF(Q32:U32,0)+1) -> 37391 | W32: 자재 28 | X32: 천원
A33: 577F118D8878F8193E0EA90A580202542E1CFC | B33: 덤프트럭 | C33: 10.5ton | D33: 대 | E33: 0 | G33: 0 | I33: 0 | K33: 0 | M33: 0 | O33: 0 | P33: 0 | Q33: 0 | R33: 0 | S33: 0 | T33: 0 | U33: 52810 | V33: =SMALL(Q33:U33,COUNTIF(Q33:U33,0)+1) -> 52810 | W33: 자재 29 | X33: 천원
A34: 577F118D8878F8193E0EA90A580789EF4B1AD6 | B34: 덤프트럭 | C34: 15ton | D34: 대 | E34: 0 | G34: 0 | I34: 0 | K34: 0 | M34: 0 | O34: 0 | P34: 0 | Q34: 0 | R34: 0 | S34: 0 | T34: 0 | U34: 90653 | V34: =SMALL(Q34:U34,COUNTIF(Q34:U34,0)+1) -> 90653 | W34: 자재 30 | X34: 천원
A35: 577F118D8878F8193E0EA90A5BD6A55F84BA05 | B35: 덤프트럭 | C35: 20ton | D35: 대 | E35: 0 | G35: 0 | I35: 0 | K35: 0 | M35: 0 | O35: 0 | P35: 0 | Q35: 0 | R35: 0 | S35: 0 | T35: 0 | U35: 127336 | V35: =SMALL(Q35:U35,COUNTIF(Q35:U35,0)+1) -> 127336 | W35: 자재 31 | X35: 천원
... A52: 577F118D8878EF1995A831A95F9818A7774402 | B52: 래머 | C52: 80kg | D52: 대 | E52: 0 | G52: 0 | I52: 0 | K52: 0 | M52: 0 | O52: 0 | P52: 0 | Q52: 0 | R52: 0 | S52: 0 | T52: 0 | U52: 1418 | V52: =SMALL(Q52:U52,COUNTIF(Q52:U52,0)+1) -> 1418 | W52: 자재 48 | X52: 천원
A53: 577F118D8878EF198B31E8BB5192377784825B | B53: 관로조사용 CCTV | C53: 자주식 측시.직시 | D53: 대 | E53: 0 | G53: 0 | H53: 1340 | I53: 0 | K53: 0 | M53: 0 | O53: 0 | P53: 0 | Q53: 0 | R53: 26436 | S53: 0 | T53: 0 | U53: 0 | V53: =SMALL(Q53:U53,COUNTIF(Q53:U53,0)+1) -> 26436 | W53: 자재 49 | X53: 천원 | Y53: C
A54: 577F118D8878EF198B045ABD5EEB630C9AE64F | B54: 플레이트 콤팩터 | C54: 1.5ton | D54: 대 | E54: 0 | G54: 0 | I54: 0 | K54: 0 | M54: 0 | O54: 0 | P54: 0 | Q54: 0 | R54: 0 | S54: 0 | T54: 0 | U54: 1673 | V54: =SMALL(Q54:U54,COUNTIF(Q54:U54,0)+1) -> 1673 | W54: 자재 50 | X54: 천원
A55: 577F118D8878DD199FF292BE5B793CEB156ECC | B55: 크레인(무한궤도) | C55: 10ton(0.29㎥) | D55: 대 | E55: 0 | G55: 0 | I55: 0 | K55: 0 | M55: 0 | O55: 0 | P55: 0 | Q55: 0 | R55: 0 | S55: 0 | T55: 0 | U55: 78059 | V55: =SMALL(Q55:U55,COUNTIF(Q55:U55,0)+1) -> 78059 | W55: 자재 51 | X55: 천원
A56: 577F118D8878DD199FF292BE5B7AC37C9F5D41 | B56: 크레인(무한궤도) | C56: 20ton(0.57㎥) | D56: 대 | E56: 0 | G56: 0 | I56: 0 | K56: 0 | M56: 0 | O56: 0 | P56: 0 | Q56: 0 | R56: 0 | S56: 0 | T56: 0 | U56: 164175 | V56: =SMALL(Q56:U56,COUNTIF(Q56:U56,0)+1) -> 164175 | W56: 자재 52 | X56: 천원
A57: 577F118D8878DD199FF292BE5B7AC6316CB6CA | B57: 크레인(무한궤도) | C57: 25ton(0.76㎥) | D57: 대 | E57: 0 | G57: 0 | I57: 0 | K57: 0 | M57: 0 | O57: 0 | P57: 0 | Q57: 0 | R57: 0 | S57: 0 | T57: 0 | U57: 189905 | V57: =SMALL(Q57:U57,COUNTIF(Q57:U57,0)+1) -> 189905 | W57: 자재 53 | X57: 천원
A58: 577F118D8878DD199FF292BE5B7BEA06C93B95 | B58: 크레인(무한궤도) | C58: 30ton(1.15㎥) | D58: 대 | E58: 0 | G58: 0 | I58: 0 | K58: 0 | M58: 0 | O58: 0 | P58: 0 | Q58: 0 | R58: 0 | S58: 0 | T58: 0 | U58: 246262 | V58: =SMALL(Q58:U58,COUNTIF(Q58:U58,0)+1) -> 246262 | W58: 자재 54 | X58: 천원
A59: 577F118D8878DD199FF292BE5B7D97DBDEC82D | B59: 크레인(무한궤도) | C59: 50ton(1.91㎥) | D59: 대 | E59: 0 | G59: 0 | I59: 0 | K59: 0 | M59: 0 | O59: 0 | P59: 0 | Q59: 0 | R59: 0 | S59: 0 | T59: 0 | U59: 442274 | V59: =SMALL(Q59:U59,COUNTIF(Q59:U59,0)+1) -> 442274 | W59: 자재 55 | X59: 천원
