Workbook
Name ____H66766: #REF!
Name __H66766: #REF!
Name _0: [1]직재!#REF!
Name _1: [2]I一般比!#REF!
Name _1._PANEL_BD.__LP___1: #REF!
Name _2: #N/A
Name _24_24: #REF!
Name _3: #N/A
Name _5: '[3]설직재-1'!#REF!
Name _7: '[3]설직재-1'!#REF!
Name _A1: #REF!
Name _b2: #REF!
Name _D1: #REF!
Name _D2: #REF!
Name _DOG1: #REF!
Name _DOG2: #REF!
Name _DOG22: #REF!
Name _DOG3: #REF!
Name _DOG33: #REF!
Name _DOG4: #REF!
Name _E7_E9_E11_E13_: #N/A
Name _FF1: #REF!
Name _H66766: #REF!
Name _IL1: #REF!
Name _l1: [4]내역서!#REF!
Name _LP1: #REF!
Name _LP2: #REF!
Name _LPB1: [5]부하계산서!#REF!
Name _LPK1: [5]부하계산서!#REF!
Name _LU1: '[6]부하(성남)'!#REF!
Name _LU2: '[6]부하(성남)'!#REF!
Name _LV01: '[6]부하(성남)'!#REF!
Name _MDL1: '[7]2월가격표-ESG-1월'!$B:$B
Name _MDL2: [7]SPEC!$A:$A
Name _OIU1: [8]!BlankMacro1
Name _OIU1: [8]!BlankMacro1
Name _OIU1: [8]!BlankMacro1
Name _OIU1: [8]!BlankMacro1
Name _PB1: [9]工완성공사율!$A$1:$J$45
Name _PB2: [9]工완성공사율!$K$1:$T$45
Name _PB3: [9]工완성공사율!$U$1:$AD$45
Name _PI48: #REF!
Name _PI60: #REF!
Name _Q1: #REF!
Name _Q2: #REF!
Name _Q3: #REF!
Name _RNG1: '[7]2월가격표-ESG-1월'!$A:$D
Name _RO110: #REF!
Name _RO22: #REF!
Name _RO35: #REF!
Name _RO45: #REF!
Name _RO60: #REF!
Name _RO80: #REF!
Name _SUB1: #REF!
Name _SUB2: #REF!
Name _SUB3: #REF!
Name _sub4: #REF!
Name _sub5: #REF!
Name _SUM1: [10]EP0618!#REF!
Name _SUM10: [10]EP0618!#REF!

Sheet 1.공통자재
A1: 단 가 대 비 표
A2: 2026년 상반기 충남교육청 건설공사 일위대가(전기, 통신, 전기소방)
A3: 품 명 | B3: 규 격 | C3: 단위 | D3: 재 료 비 | O3: 번 호 | P3: 비 고
D4: 조달청가격 | E4: PAGE | F4: 거래가격 | G4: PAGE | H4: 유통물가 | I4: PAGE | J4: 물가자료 | K4: PAGE | L4: 물가정보 | M4: PAGE | N4: 적용단가
A5: 사각맨홀(뚜껑별도) | B5: 800x800x800x150t | C5: 조 | D5: 0 | F5: 210000 | G5: 222 | H5: 320000 | I5: 197 | J5: 0 | L5: 170000 | M5: 207 | N5: =SMALL(D5:L5,COUNTIF(D5:L5,0)+1) -> 170000
A6: 사각맨홀(뚜껑별도) | B6: 1000x1000x1000x150t | C6: 조 | D6: 0 | F6: 0 | H6: 0 | J6: 0 | L6: 220000 | M6: 207 | N6: =SMALL(D6:L6,COUNTIF(D6:L6,0)+1) -> 220000
A7: 사각맨홀(뚜껑별도) | B7: 1200*1200*1200*200t | C7: 조 | D7: 0 | F7: 0 | H7: 0 | J7: 0 | L7: 290000 | M7: 207 | N7: =SMALL(D7:L7,COUNTIF(D7:L7,0)+1) -> 290000
A8: 사각맨홀(뚜껑별도) | B8: 1500x1500x1500x150t | C8: 조 | D8: 0 | F8: 0 | H8: 0 | J8: 0 | L8: 440000 | M8: 207 | N8: =SMALL(D8:L8,COUNTIF(D8:L8,0)+1) -> 440000
A9: 사각맨홀(뚜껑별도) | B9: 1800*1800*1800*200t | C9: 조 | D9: 0 | F9: 0 | H9: 0 | J9: 0 | L9: 1350000 | M9: 207 | N9: =SMALL(D9:L9,COUNTIF(D9:L9,0)+1) -> 1350000
A10: 사각맨홀(뚜껑별도) | B10: 2000x2000x1500x150t | C10: 조 | D10: 0 | F10: 0 | H10: 0 | J10: 0 | L10: 1600000 | M10: 207 | N10: =SMALL(D10:L10,COUNTIF(D10:L10,0)+1) -> 1600000
A11: 수공1호 (뚜껑별도) | B11: 950*450*700*150t | C11: 조 | D11: 0 | F11: 0 | H11: 0 | J11: 0 | L11: 110000 | M11: 207 | N11: =SMALL(D11:L11,COUNTIF(D11:L11,0)+1) -> 110000
A12: 수공2호 (뚜껑별도) | B12: 1700*800*1100*150t | C12: 조 | D12: 0 | F12: 0 | H12: 0 | J12: 0 | L12: 290000 | M12: 207 | N12: =SMALL(D12:L12,COUNTIF(D12:L12,0)+1) -> 290000
A13: 수공3호 (뚜껑별도) | B13: 2000*1000*1400*150t | C13: 조 | D13: 0 | F13: 0 | H13: 0 | J13: 0 | L13: 450000 | M13: 207 | N13: =SMALL(D13:L13,COUNTIF(D13:L13,0)+1) -> 450000
A14: 수공4호 (뚜껑별도) | B14: 2000*1500*1500*150t | C14: 조 | D14: 0 | F14: 0 | H14: 0 | J14: 0 | L14: 590000 | M14: 207 | N14: =SMALL(D14:L14,COUNTIF(D14:L14,0)+1) -> 590000
A15: 원형주철 뚜껑 (전기,통신) | B15: Φ648(KS) | C15: 조 | D15: 0 | F15: 0 | H15: 0 | J15: 0 | L15: 230000 | M15: 207 | N15: =SMALL(D15:L15,COUNTIF(D15:L15,0)+1) -> 230000
A16: 4각주철(수공) 뚜껑 (전기,통신) | B16: 1,120*620(KS) | C16: 조 | D16: 0 | F16: 540000 | G16: 222 | H16: 0 | J16: 0 | L16: 370000 | M16: 207 | N16: =SMALL(D16:L16,COUNTIF(D16:L16,0)+1) -> 370000
A17: 지중선로표시기 | B17: 전기,통신용 | C17: 개 | D17: 0 | F17: 5400 | G17: 1083 | H17: 5400 | I17: 905 | J17: 0 | L17: 0 | N17: =SMALL(D17:L17,COUNTIF(D17:L17,0)+1) -> 5400
A18: 경고테이프(케이블표시시트) | B18: 200㎜ | C18: M | D18: 0 | F18: 202 | G18: 1134 | H18: 180 | I18: 539 | J18: 0 | L18: 0 | N18: =SMALL(D18:L18,COUNTIF(D18:L18,0)+1) -> 180
A19: 경고테이프(케이블표시시트) | B19: 300㎜ | C19: M | D19: 0 | F19: 297 | G19: 1134 | H19: 200 | I19: 539 | J19: 0 | L19: 0 | N19: =SMALL(D19:L19,COUNTIF(D19:L19,0)+1) -> 200
A20: 스위치박스 | B20: 1개용, 44mm | C20: 개 | D20: 507 | F20: 600 | G20: 1028 | H20: 600 | I20: 873 | J20: 560 | K20: 1105 | L20: 600 | M20: 1206 | N20: =SMALL(D20:L20,COUNTIF(D20:L20,0)+1) -> 507
A21: 스위치박스 | B21: 1개용 54mm | C21: 개 | D21: 591 | F21: 650 | G21: 1028 | H21: 700 | I21: 873 | J21: 650 | K21: 1105 | L21: 700 | M21: 1206 | N21: =SMALL(D21:L21,COUNTIF(D21:L21,0)+1) -> 591
A22: 스위치박스 | B22: 1개용, 75mm | C22: 개 | D22: 1285 | F22: 1400 | G22: 1028 | H22: 1518 | I22: 873 | J22: 1360 | K22: 1105 | L22: 1518 | M22: 1206 | N22: =SMALL(D22:L22,COUNTIF(D22:L22,0)+1) -> 1285
A23: 스위치박스 | B23: 2개용, 44mm | C23: 개 | D23: 764 | F23: 900 | G23: 1028 | H23: 904 | I23: 873 | J23: 820 | K23: 1105 | L23: 904 | M23: 1206 | N23: =SMALL(D23:L23,COUNTIF(D23:L23,0)+1) -> 764
A24: 스위치박스 | B24: 2개용, 54mm | C24: 개 | D24: 823 | F24: 1000 | G24: 1028 | H24: 973 | I24: 873 | J24: 920 | K24: 1105 | L24: 973 | M24: 1206 | N24: =SMALL(D24:L24,COUNTIF(D24:L24,0)+1) -> 823
A25: 스위치박스 | B25: 2개용, 75mm | C25: 개 | D25: 1447 | F25: 1600 | G25: 1028 | H25: 1709 | I25: 873 | J25: 1540 | K25: 1105 | L25: 1709 | M25: 1206 | N25: =SMALL(D25:L25,COUNTIF(D25:L25,0)+1) -> 1447
A26: 콘센트박스 | B26: 1개용, 44mm | C26: 개 | D26: 507 | F26: 600 | G26: 1028 | H26: 600 | I26: 873 | J26: 0 | L26: 0 | N26: =SMALL(D26:L26,COUNTIF(D26:L26,0)+1) -> 507
A27: 콘센트박스 | B27: 1개용, 54mm | C27: 개 | D27: 591 | F27: 650 | G27: 1028 | H27: 700 | I27: 873 | J27: 740 | K27: 1105 | L27: 763 | M27: 1206 | N27: =SMALL(D27:L27,COUNTIF(D27:L27,0)+1) -> 591
A28: 콘센트박스 | B28: 1개용, 75mm | C28: 개 | D28: 1285 | F28: 1400 | G28: 1028 | H28: 1518 | I28: 873 | J28: 1450 | K28: 1105 | L28: 1526 | M28: 1206 | N28: =SMALL(D28:L28,COUNTIF(D28:L28,0)+1) -> 1285
A29: 콘센트박스 | B29: 2개용, 44mm | C29: 개 | D29: 764 | F29: 900 | G29: 1028 | H29: 904 | I29: 873 | J29: 0 | L29: 0 | N29: =SMALL(D29:L29,COUNTIF(D29:L29,0)+1) -> 764
A30: 콘센트박스 | B30: 2개용, 54mm | C30: 개 | D30: 823 | F30: 1000 | G30: 1028 | H30: 973 | I30: 873 | J30: 980 | K30: 1105 | L30: 1003 | M30: 1206 | N30: =SMALL(D30:L30,COUNTIF(D30:L30,0)+1) -> 823
A31: 콘센트박스 | B31: 2개용, 75mm | C31: 개 | D31: 1447 | F31: 1600 | G31: 1028 | H31: 1709 | I31: 873 | J31: 1600 | K31: 1105 | L31: 1660 | M31: 1206 | N31: =SMALL(D31:L31,COUNTIF(D31:L31,0)+1) -> 1447
A32: 아웃렛박스 | B32: 4각, 44mm | C32: 개 | D32: 0 | F32: 661 | G32: 1020 | H32: 0 | J32: 0 | L32: 0 | N32: =SMALL(D32:L32,COUNTIF(D32:L32,0)+1) -> 661
A33: 아웃렛박스 | B33: 4각, 54mm | C33: 개 | F33: 840 | G33: 1020 | H33: 0 | J33: 3100 | K33: 1105 | L33: 3480 | M33: 1206 | N33: =SMALL(D33:L33,COUNTIF(D33:L33,0)+1) -> 840
A34: 아웃렛박스 | B34: 4각, 75mm | C34: 개 | D34: 0 | F34: 1562 | G34: 1020 | H34: 0 | J34: 3330 | K34: 1105 | L34: 3960 | M34: 1206 | N34: =SMALL(D34:L34,COUNTIF(D34:L34,0)+1) -> 1562
A35: 아웃렛박스 | B35: 8각, 44mm | C35: 개 | D35: 562 | F35: 527 | G35: 1020 | H35: 752 | I35: 873 | J35: 690 | K35: 1105 | L35: 752 | M35: 1206 | N35: =SMALL(D35:L35,COUNTIF(D35:L35,0)+1) -> 527
A36: 아웃렛박스 | B36: 8각, 54mm | C36: 개 | D36: 626 | F36: 721 | G36: 1020 | H36: 845 | I36: 873 | J36: 790 | K36: 1105 | L36: 845 | M36: 1206 | N36: =SMALL(D36:L36,COUNTIF(D36:L36,0)+1) -> 626
A37: 아웃렛박스 | B37: 8각, 75mm | C37: 개 | D37: 1219 | F37: 1254 | G37: 1020 | H37: 1650 | I37: 873 | J37: 1450 | K37: 1105 | L37: 1650 | M37: 1206 | N37: =SMALL(D37:L37,COUNTIF(D37:L37,0)+1) -> 1219
A38: 평 커 바 | B38: 8각 | C38: 개 | F38: 240 | G38: 1020 | H38: 328 | I38: 905 | J38: 0 | L38: 0 | N38: =SMALL(D38:L38,COUNTIF(D38:L38,0)+1) -> 240
A39: 평 커 바 | B39: 4각 | C39: 개 | F39: 240 | G39: 1020 | H39: 0 | J39: 400 | K39: 1105 | L39: 0 | N39: =SMALL(D39:L39,COUNTIF(D39:L39,0)+1) -> 240
A40: 오 목 커버 | B40: 4각 | C40: 개 | F40: 240 | G40: 1020 | H40: 448 | I40: 905 | J40: 400 | K40: 1105 | L40: 0 | N40: =SMALL(D40:L40,COUNTIF(D40:L40,0)+1) -> 240
...

Sheet 2.전기자재
A1: 단 가 대 비 표
A2: 2026년 상반기 충남교육청 건설공사 일위대가(전기, 통신, 전기소방)
A3: 품 명 | B3: 규 격 | C3: 단위 | D3: 재 료 비 | O3: 번 호 | P3: 비 고
D4: 조달청가격 | E4: PAGE | F4: 거래가격 | G4: PAGE | H4: 유통물가 | I4: PAGE | J4: 물가자료 | K4: PAGE | L4: 물가정보 | M4: PAGE | N4: 적용단가
A5: 케이블단말처리재-25kV 3C옥내외 | B5: 자기수축형, 60~70SQ | C5: kit | D5: 212788 | F5: 264000 | G5: 1021 | H5: 264000 | I5: 855 | J5: 264000 | K5: 1096 | L5: 0 | N5: =SMALL(D5:L5,COUNTIF(D5:L5,0)+1) -> 212788
A6: 케이블 헤드지지금구 | B6: 상,하부용 | C6: 식 | D6: 0 | F6: 79715 | G6: 1134 | H6: 0 | J6: 0 | L6: 0 | N6: =SMALL(D6:L6,COUNTIF(D6:L6,0)+1) -> 79715
A7: 케이블 헤드 카바 | C7: 개 | D7: 0 | F7: 55186 | G7: 1134 | H7: 0 | J7: 0 | L7: 0 | N7: =SMALL(D7:L7,COUNTIF(D7:L7,0)+1) -> 55186
A8: 케이블 지지용강밴드 | B8: 40*1200mm | C8: 개 | D8: 0 | F8: 3500 | G8: 1134 | H8: 0 | J8: 0 | L8: 3500 | M8: 1298 | N8: =SMALL(D8:L8,COUNTIF(D8:L8,0)+1) -> 3500
A9: 위험표지판(특별고압) | B9: SUS,규격품 | C9: 개 | D9: 0 | F9: 0 | H9: 0 | J9: 0 | L9: 35000 | M9: 조사가 | N9: =SMALL(D9:L9,COUNTIF(D9:L9,0)+1) -> 35000
A10: 준공표지판 | B10: SUS,규격품 | C10: 개 | D10: 0 | F10: 0 | H10: 0 | J10: 0 | L10: 150000 | M10: 조사가 | N10: =SMALL(D10:L10,COUNTIF(D10:L10,0)+1) -> 150000
A11: 전주용입상관 | B11: 130Φx2m | C11: 개 | D11: 0 | F11: 39856 | G11: 1134 | H11: 0 | J11: 0 | L11: 0 | N11: =SMALL(D11:L11,COUNTIF(D11:L11,0)+1) -> 39856
A12: 조립식 반할강판 | B12: 130Φ | C12: 개 | D12: 0 | F12: 88911 | G12: 1134 | H12: 0 | J12: 0 | L12: 0 | N12: =SMALL(D12:L12,COUNTIF(D12:L12,0)+1) -> 88911
A13: 저압가선용랙크 | B13: 1선 | C13: 개 | D13: 0 | F13: 0 | H13: 0 | J13: 0 | L13: 1650 | M13: 1298 | N13: =SMALL(D13:L13,COUNTIF(D13:L13,0)+1) -> 1650
A14: 저압가선용랙크 | B14: 2선 | C14: 개 | D14: 0 | F14: 0 | H14: 0 | J14: 0 | L14: 6000 | M14: 1298 | N14: =SMALL(D14:L14,COUNTIF(D14:L14,0)+1) -> 6000
A15: 저압가선용랙크 | B15: 3선 | C15: 개 | D15: 0 | F15: 0 | H15: 0 | J15: 0 | L15: 8700 | M15: 1298 | N15: =SMALL(D15:L15,COUNTIF(D15:L15,0)+1) -> 8700
A16: 저압가선용랙크 | B16: 4선 | C16: 개 | D16: 0 | F16: 0 | H16: 0 | J16: 0 | L16: 11700 | M16: 1298 | N16: =SMALL(D16:L16,COUNTIF(D16:L16,0)+1) -> 11700
A17: 고장구간자동개폐기 | B17: ASS, 25.8KV | C17: 개 | D17: 0 | F17: 3026000 | G17: 1096 | H17: 0 | J17: 2507000 | K17: 1168 | L17: 2631000 | M17: 1241 | N17: =SMALL(D17:L17,COUNTIF(D17:L17,0)+1) -> 2507000
A18: 기중차단기 | B18: ACB, 1000AF | C18: 개 | D18: 0 | F18: 3773000 | G18: 1063 | H18: 0 | J18: 2222000 | K18: 1149 | L18: 3773000 | M18: 1240 | N18: =SMALL(D18:L18,COUNTIF(D18:L18,0)+1) -> 2222000
A19: 기중차단기 | B19: ACB, 1601AF | C19: 개 | D19: 0 | F19: 4740000 | G19: 1063 | H19: 0 | J19: 2495000 | K19: 1149 | L19: 4740000 | M19: 1240 | N19: =SMALL(D19:L19,COUNTIF(D19:L19,0)+1) -> 2495000
A20: 기중차단기 | B20: ACB, 2000AF | C20: 개 | D20: 0 | F20: 5022000 | G20: 1063 | H20: 0 | J20: 3310000 | K20: 1149 | L20: 5022000 | M20: 1240 | N20: =SMALL(D20:L20,COUNTIF(D20:L20,0)+1) -> 3310000
A21: 등기구보강대 | B21: 형광등기구용, 찬넬보강형 | C21: 조 | D21: 9246 | F21: 11800 | G21: 1104 | H21: 19000 | I21: 933 | J21: 0 | L21: 19000 | M21: 1289 | N21: =SMALL(D21:L21,COUNTIF(D21:L21,0)+1) -> 9246
A22: 등기구보강대 | B22: 형광등기구용, 행거스프링형 | C22: 조 | D22: 10329 | F22: 11200 | G22: 1104 | H22: 15600 | I22: 933 | J22: 0 | L22: 15600 | M22: 1289 | N22: =SMALL(D22:L22,COUNTIF(D22:L22,0)+1) -> 10329
A23: 등기구보강대 | B23: 형광등기구용, 장력형, 0.3m | C23: 조 | D23: 4560 | F23: 5900 | G23: 1104 | H23: 9000 | I23: 933 | J23: 0 | L23: 9000 | M23: 1289 | N23: =SMALL(D23:L23,COUNTIF(D23:L23,0)+1) -> 4560
A24: 등기구보강대 | B24: 형광등기구용, 장력형, 1.0m | C24: 조 | D24: 8199 | F24: 8400 | G24: 1104 | H24: 9600 | I24: 933 | J24: 0 | L24: 9600 | M24: 1289 | N24: =SMALL(D24:L24,COUNTIF(D24:L24,0)+1) -> 8199
A25: 등기구보강대 | B25: 형광등기구용, 장력형, 1.5m | C25: 조 | D25: 8544 | F25: 10000 | G25: 1104 | H25: 0 | J25: 0 | L25: 0 | N25: =SMALL(D25:L25,COUNTIF(D25:L25,0)+1) -> 8544
A26: 등기구보강대 | B26: 다운라이트용, 장력형, 1.0m | C26: 조 | D26: 5123 | F26: 5500 | G26: 1104 | H26: 6600 | I26: 933 | J26: 0 | L26: 6600 | M26: 1289 | N26: =SMALL(D26:L26,COUNTIF(D26:L26,0)+1) -> 5123
A27: 등기구보강대 | B27: 다운라이트용, 행거스프링형 | C27: 조 | D27: 6795 | F27: 6800 | G27: 1104 | H27: 9000 | I27: 933 | J27: 0 | L27: 9000 | M27: 1289 | N27: =SMALL(D27:L27,COUNTIF(D27:L27,0)+1) -> 6795
A28: 등기구보강대 | B28: 다운라이트용, 평형스프링형 | C28: 조 | D28: 7402 | F28: 9500 | G28: 1104 | H28: 14800 | I28: 933 | J28: 0 | L28: 14800 | M28: 1289 | N28: =SMALL(D28:L28,COUNTIF(D28:L28,0)+1) -> 7402
A29: 천정형 선풍기 보강대 | B29: 철판형 | C29: 조 | D29: 0 | F29: 5600 | G29: 1104 | H29: 10200 | I29: 933 | J29: 0 | L29: 0 | N29: =SMALL(D29:L29,COUNTIF(D29:L29,0)+1) -> 5600
A30: 천정형 선풍기 보강대 | B30: 표준형 | C30: 조 | D30: 0 | F30: 13600 | G30: 1104 | H30: 15600 | I30: 933 | J30: 0 | L30: 0 | N30: =SMALL(D30:L30,COUNTIF(D30:L30,0)+1) -> 13600
A31: 천정형 선풍기 보강대 | B31: 행가표준형 | C31: 조 | D31: 0 | F31: 15600 | G31: 1104 | H31: 18000 | I31: 933 | J31: 0 | L31: 0 | N31: =SMALL(D31:L31,COUNTIF(D31:L31,0)+1) -> 15600
A32: 덤블러스위치(와이드) | B32: 1로스위치, 15A250V1구 | C32: 개 | D32: 1323 | F32: 3920 | G32: 1098 | H32: 3967 | I32: 930 | J32: 0 | L32: 0 | N32: =SMALL(D32:L32,COUNTIF(D32:L32,0)+1) -> 1323
A33: 덤블러스위치(와이드) | B33: 1로스위치, 15A250V 2구 | C33: 개 | D33: 1851 | F33: 5500 | G33: 1098 | H33: 5934 | I33: 930 | J33: 0 | L33: 0 | N33: =SMALL(D33:L33,COUNTIF(D33:L33,0)+1) -> 1851
A34: 덤블러스위치(와이드) | B34: 1로스위치, 15A250V 3구 | C34: 개 | D34: 2393 | F34: 7070 | G34: 1098 | H34: 7900 | I34: 930 | J34: 0 | L34: 0 | N34: =SMALL(D34:L34,COUNTIF(D34:L34,0)+1) -> 2393
A35: 덤블러스위치(와이드) | B35: 1로스위치, 15A250V 4구 | C35: 개 | D35: 3350 | F35: 0 | H35: 11867 | I35: 930 | J35: 0 | L35: 0 | N35: =SMALL(D35:L35,COUNTIF(D35:L35,0)+1) -> 3350
A36: 덤블러스위치(와이드) | B36: 1로스위치, 15A250V 5구 | C36: 개 | D36: 4686 | F36: 0 | H36: 13834 | I36: 930 | J36: 0 | L36: 0 | N36: =SMALL(D36:L36,COUNTIF(D36:L36,0)+1) -> 4686
A37: 덤블러스위치(와이드) | B37: 1로스위치, 15A250V 6구 | C37: 개 | D37: 6233 | F37: 0 | H37: 15800 | I37: 930 | J37: 0 | L37: 0 | N37: =SMALL(D37:L37,COUNTIF(D37:L37,0)+1) -> 6233
A38: 덤블러스위치(와이드) | B38: 3로스위치, 15A250V1구 | C38: 개 | D38: 1725 | F38: 4210 | G38: 1098 | H38: 4434 | I38: 930 | J38: 0 | L38: 0 | N38: =SMALL(D38:L38,COUNTIF(D38:L38,0)+1) -> 1725
A39: 덤블러스위치(와이드) | B39: 3로스위치, 15A250V2구 | C39: 개 | D39: 2589 | F39: 6070 | G39: 1098 | H39: 6667 | I39: 930 | J39: 0 | L39: 0 | N39: =SMALL(D39:L39,COUNTIF(D39:L39,0)+1) -> 2589
A40: 덤블러스위치(와이드) | B40: 3로스위치, 15A250V3구 | C40: 개 | D40: 3544 | F40: 7920 | G40: 1098 | H40: 8450 | I40: 930 | J40: 0 | L40: 0 | N40: =SMALL(D40:L40,COUNTIF(D40:L40,0)+1) -> 3544
...

Sheet 3.통신자재
A1: 단 가 대 비 표
A2: 2026년 상반기 충남교육청 건설공사 일위대가(전기, 통신, 전기소방)
A3: 품 명 | B3: 규 격 | C3: 단위 | D3: 재 료 비 | O3: 번 호 | P3: 비 고
D4: 조달청가격 | E4: PAGE | F4: 거래가격 | G4: PAGE | H4: 유통물가 | I4: PAGE | J4: 물가자료 | K4: PAGE | L4: 물가정보 | M4: PAGE | N4: 적용단가
A5: 국선매입단자함(전면:스텐)보호기+110블럭포함 | B5: 국선10/사선25 | C5: Set | D5: 0 | F5: 0 | H5: 0 | J5: 74000 | K5: 1283 | L5: 0 | N5: =SMALL(D5:L5,COUNTIF(D5:L5,0)+1) -> 74000
A6: 국선매입단자함(전면:스텐)보호기+110블럭포함 | B6: 국선10/사선50 | C6: Set | D6: 0 | F6: 0 | H6: 0 | J6: 77000 | K6: 1283 | L6: 0 | N6: =SMALL(D6:L6,COUNTIF(D6:L6,0)+1) -> 77000
A7: 국선매입단자함(전면:스텐)보호기+110블럭포함 | B7: 국선20/사선50 | C7: Set | D7: 0 | F7: 0 | H7: 0 | J7: 101000 | K7: 1283 | L7: 0 | N7: =SMALL(D7:L7,COUNTIF(D7:L7,0)+1) -> 101000
A8: 국선매입단자함(전면:스텐)보호기+110블럭포함 | B8: 국선20/사선100 | C8: Set | D8: 0 | F8: 0 | H8: 0 | J8: 123000 | K8: 1283 | L8: 0 | N8: =SMALL(D8:L8,COUNTIF(D8:L8,0)+1) -> 123000
A9: 국선매입단자함(전면:스텐)보호기+110블럭포함 | B9: 국선30/사선100 | C9: Set | D9: 0 | F9: 0 | H9: 0 | J9: 136000 | K9: 1283 | L9: 0 | N9: =SMALL(D9:L9,COUNTIF(D9:L9,0)+1) -> 136000
A10: 국선매입단자함(전면:스텐)보호기+110블럭포함 | B10: 국선30/사선150 | C10: Set | D10: 0 | F10: 0 | H10: 0 | J10: 163000 | K10: 1283 | L10: 0 | N10: =SMALL(D10:L10,COUNTIF(D10:L10,0)+1) -> 163000
A11: 국선매입단자함(전면:스텐)보호기+110블럭포함 | B11: 국선40/사선100 | C11: Set | D11: 0 | F11: 0 | H11: 0 | J11: 170000 | K11: 1283 | L11: 0 | N11: =SMALL(D11:L11,COUNTIF(D11:L11,0)+1) -> 170000
A12: 국선매입단자함(전면:스텐)보호기+110블럭포함 | B12: 국선40/사선200 | C12: Set | D12: 0 | F12: 0 | H12: 0 | J12: 180000 | K12: 1283 | L12: 0 | N12: =SMALL(D12:L12,COUNTIF(D12:L12,0)+1) -> 180000
A13: 국선매입단자함(전면:스텐)보호기+110블럭포함 | B13: 국선50/사선100 | C13: Set | D13: 0 | F13: 0 | H13: 0 | J13: 183000 | K13: 1283 | N13: =SMALL(D13:L13,COUNTIF(D13:L13,0)+1) -> 183000
A14: 국선매입단자함(전면:스텐)보호기+110블럭포함 | B14: 국선50/사선200 | C14: Set | D14: 0 | F14: 0 | H14: 0 | J14: 197000 | K14: 1283 | L14: 0 | N14: =SMALL(D14:L14,COUNTIF(D14:L14,0)+1) -> 197000
A15: 국선매입단자함(전면:스텐)보호기+110블럭포함 | B15: 국선80/사선200 | C15: Set | D15: 0 | F15: 0 | H15: 0 | J15: 234000 | K15: 1283 | L15: 0 | N15: =SMALL(D15:L15,COUNTIF(D15:L15,0)+1) -> 234000
A16: 국선매입단자함(전면:스텐)보호기+110블럭포함 | B16: 국선80/사선300 | C16: Set | D16: 0 | F16: 0 | H16: 0 | J16: 290000 | K16: 1283 | L16: 0 | N16: =SMALL(D16:L16,COUNTIF(D16:L16,0)+1) -> 290000
A17: 국선매입단자함(전면:스텐)보호기+110블럭포함 | B17: 국선100/사선300 | C17: Set | D17: 0 | F17: 0 | H17: 0 | J17: 348000 | K17: 1283 | L17: 0 | N17: =SMALL(D17:L17,COUNTIF(D17:L17,0)+1) -> 348000
A18: 국선매입단자함(전면:스텐)보호기+110블럭포함 | B18: 국선100/사선600 | C18: Set | D18: 0 | F18: 0 | H18: 0 | J18: 378000 | K18: 1283 | L18: 0 | N18: =SMALL(D18:L18,COUNTIF(D18:L18,0)+1) -> 378000
A19: 국선매입단자함(전면:스텐)보호기+110블럭포함 | B19: 국선150/사선600 | C19: Set | D19: 0 | F19: 0 | H19: 0 | J19: 499000 | K19: 1283 | L19: 0 | N19: =SMALL(D19:L19,COUNTIF(D19:L19,0)+1) -> 499000
A20: 국선매입단자함(전면:스텐)보호기+110블럭포함 | B20: 국선200/사선800 | C20: Set | D20: 0 | F20: 0 | H20: 0 | J20: 617000 | K20: 1283 | L20: 0 | N20: =SMALL(D20:L20,COUNTIF(D20:L20,0)+1) -> 617000
A21: 국선단자함(노출:스텐)보호기+110블럭포함 | B21: 국선10/사선25 | C21: Set | D21: 0 | F21: 0 | H21: 0 | J21: 82000 | K21: 1283 | L21: 0 | N21: =SMALL(D21:L21,COUNTIF(D21:L21,0)+1) -> 82000
A22: 국선단자함(노출:스텐)보호기+110블럭포함 | B22: 국선10/사선50 | C22: Set | D22: 0 | F22: 0 | H22: 0 | J22: 85000 | K22: 1283 | L22: 0 | N22: =SMALL(D22:L22,COUNTIF(D22:L22,0)+1) -> 85000
A23: 국선단자함(노출:스텐)보호기+110블럭포함 | B23: 국선20/사선50 | C23: Set | D23: 0 | F23: 0 | H23: 0 | J23: 119000 | K23: 1283 | L23: 0 | N23: =SMALL(D23:L23,COUNTIF(D23:L23,0)+1) -> 119000
A24: 국선단자함(노출:스텐)보호기+110블럭포함 | B24: 국선20/사선100 | C24: Set | D24: 0 | F24: 0 | H24: 0 | J24: 137000 | K24: 1283 | L24: 0 | N24: =SMALL(D24:L24,COUNTIF(D24:L24,0)+1) -> 137000
A25: 국선단자함(노출:스텐)보호기+110블럭포함 | B25: 국선30/사선100 | C25: Set | D25: 0 | F25: 0 | H25: 0 | J25: 150000 | K25: 1283 | L25: 0 | N25: =SMALL(D25:L25,COUNTIF(D25:L25,0)+1) -> 150000
... A116: 방송단자함(노출:철재)단자대포함 | B116: 300회선 | C116: Set | D116: 0 | F116: 0 | H116: 0 | J116: 199500 | K116: 1283 | L116: 0 | N116: =SMALL(D116:L116,COUNTIF(D116:L116,0)+1) -> 199500
A117: TV매입증폭기함(전면:스텐) | B117: 300*400mm | C117: 개 | D117: 60264 | F117: 0 | H117: 0 | J117: 66000 | K117: 1283 | L117: 96940 | M117: 1336 | N117: =SMALL(D117:L117,COUNTIF(D117:L117,0)+1) -> 60264
A118: TV매입증폭기함(전면:스텐) | B118: 400*500mm | C118: 개 | D118: 72564 | F118: 0 | H118: 0 | J118: 98200 | K118: 1283 | L118: 141520 | M118: 1336 | N118: =SMALL(D118:L118,COUNTIF(D118:L118,0)+1) -> 72564
A119: TV매입증폭기함(전면:스텐) | B119: 500*600mm | C119: 개 | D119: 99863 | F119: 0 | H119: 0 | J119: 133300 | K119: 1283 | L119: 198020 | M119: 1336 | N119: =SMALL(D119:L119,COUNTIF(D119:L119,0)+1) -> 99863
A120: TV매입증폭기함(전면:스텐) | B120: 600*700mm | C120: 개 | D120: 127045 | F120: 0 | H120: 0 | J120: 170900 | K120: 1283 | L120: 266800 | M120: 1336 | N120: =SMALL(D120:L120,COUNTIF(D120:L120,0)+1) -> 127045
A121: TV매입증폭기함(전면:스텐) | B121: 700*800mm | C121: 개 | D121: 181528 | F121: 0 | H121: 0 | J121: 222400 | K121: 1283 | L121: 0 | N121: =SMALL(D121:L121,COUNTIF(D121:L121,0)+1) -> 181528
A122: TV매입증폭기함(전면:철재) | B122: 300*400mm | C122: Set | D122: 36281 | F122: 30000 | G122: 1177 | H122: 0 | J122: 43800 | K122: 1283 | L122: 62550 | M122: 1336 | N122: =SMALL(D122:L122,COUNTIF(D122:L122,0)+1) -> 30000
A123: TV매입증폭기함(전면:철재) | B123: 400*500mm | C123: Set | D123: 45380 | F123: 0 | H123: 0 | J123: 66000 | K123: 1283 | L123: 88810 | M123: 1336 | N123: =SMALL(D123:L123,COUNTIF(D123:L123,0)+1) -> 45380
A124: TV매입증폭기함(전면:철재) | B124: 500*600mm | C124: Set | D124: 54480 | F124: 70000 | G124: 1177 | H124: 0 | J124: 87800 | K124: 1283 | L124: 133400 | M124: 1336 | N124: =SMALL(D124:L124,COUNTIF(D124:L124,0)+1) -> 54480
A125: TV매입증폭기함(전면:철재) | B125: 600*700mm | C125: Set | D125: 90763 | F125: 0 | H125: 0 | J125: 125400 | K125: 1283 | L125: 185930 | M125: 1336 | N125: =SMALL(D125:L125,COUNTIF(D125:L125,0)+1) -> 90763
A126: TV매입증폭기함(전면:철재) | B126: 700*800mm | C126: Set | D126: 117946 | F126: 0 | H126: 0 | J126: 162400 | K126: 1283 | L126: 0 | N126: =SMALL(D126:L126,COUNTIF(D126:L126,0)+1) -> 117946
A127: TV증폭기함(노출:스텐) | B127: 300*400mm | C127: Set | D127: 0 | F127: 0 | H127: 0 | J127: 74100 | K127: 1283 | L127: 0 | N127: =SMALL(D127:L127,COUNTIF(D127:L127,0)+1) -> 74100
A128: TV증폭기함(노출:스텐) | B128: 400*500mm | C128: Set | D128: 0 | F128: 0 | H128: 0 | J128: 101900 | K128: 1283 | L128: 0 | N128: =SMALL(D128:L128,COUNTIF(D128:L128,0)+1) -> 101900
A129: TV증폭기함(노출:스텐) | B129: 500*600mm | C129: Set | D129: 0 | F129: 0 | H129: 0 | J129: 137200 | K129: 1283 | L129: 0 | N129: =SMALL(D129:L129,COUNTIF(D129:L129,0)+1) -> 137200
A130: TV증폭기함(노출:스텐) | B130: 600*700mm | C130: Set | D130: 0 | F130: 0 | H130: 0 | J130: 171500 | K130: 1283 | L130: 0 | N130: =SMALL(D130:L130,COUNTIF(D130:L130,0)+1) -> 171500
...

Sheet 4.소방자재
A1: 단 가 대 비 표 | U1: 만든이:나라기술 정진붕
A2: 2026년 상반기 충남교육청 건설공사 일위대가(전기, 통신, 전기소방)
A3: 품 명 | B3: 규 격 | C3: 단위 | D3: 재 료 비 | O3: 번 호 | P3: 비 고
D4: 조달청가격 | E4: PAGE | F4: 거래가격 | G4: PAGE | H4: 유통물가 | I4: PAGE | J4: 물가자료 | K4: PAGE | L4: 물가정보 | M4: PAGE | N4: 적용단가
A5: 화재수신기(복합형) | B5: 기본10회로-LCD | C5: 대 | D5: 0 | F5: 0 | H5: 0 | J5: 0 | L5: 800000 | M5: 1393 | N5: =SMALL(D5:L5,COUNTIF(D5:L5,0)+1) -> 800000
A6: 화재수신기(복합형) | B6: 기본20회로-LCD | C6: 대 | D6: 0 | F6: 0 | H6: 0 | J6: 0 | L6: 1300000 | M6: 1393 | N6: =SMALL(D6:L6,COUNTIF(D6:L6,0)+1) -> 1300000
A7: P형회로추가 | B7: 1회로당 | C7: 회로 | D7: 0 | F7: 0 | H7: 0 | J7: 0 | L7: 50000 | M7: 1393 | N7: =SMALL(D7:L7,COUNTIF(D7:L7,0)+1) -> 50000
A8: 화재감지기(열) | B8: 차동식 스포트형2종 | C8: 개 | D8: 4010 | F8: 5000 | G8: 1194 | H8: 5000 | I8: 758 | J8: 0 | L8: 0 | N8: =SMALL(D8:L8,COUNTIF(D8:L8,0)+1) -> 4010
A9: 화재감지기(열) | B9: 정온식 스포트형1종 | C9: 개 | D9: 3663 | F9: 5000 | G9: 1194 | H9: 5000 | I9: 758 | J9: 0 | L9: 0 | N9: =SMALL(D9:L9,COUNTIF(D9:L9,0)+1) -> 3663
A10: 화재감지기(연기) | B10: 광전식 스포트형2종-비축적 | C10: 개 | D10: 12631 | F10: 18000 | G10: 1194 | H10: 30000 | I10: 756 | J10: 0 | L10: 0 | N10: =SMALL(D10:L10,COUNTIF(D10:L10,0)+1) -> 12631
A11: 단독형감지기(연기) | B11: 광전식 | C11: 개 | D11: 0 | F11: 30000 | G11: 1194 | H11: 0 | J11: 0 | L11: 25000 | M11: 1393 | N11: =SMALL(D11:L11,COUNTIF(D11:L11,0)+1) -> 25000
A12: 불꽃감지기 | B12: 감시거리 30M, 옥내,외,방수,일반형 | C12: 개 | D12: 0 | F12: 2000000 | G12: 1194 | H12: 1100000 | I12: 757 | J12: 0 | L12: 1350000 | M12: 1387 | N12: =SMALL(D12:L12,COUNTIF(D12:L12,0)+1) -> 1100000
A13: 불꽃감지기 | B13: 감시거리 50M, 옥내,외,방수,일반형 | C13: 개 | D13: 0 | F13: 0 | H13: 1500000 | I13: 757 | J13: 0 | L13: 1800000 | M13: 1387 | N13: =SMALL(D13:L13,COUNTIF(D13:L13,0)+1) -> 1500000
A14: 불꽃감지기 전원공급기 | B14: AC220V/DC24V,3A | C14: 개 | D14: 0 | F14: 0 | H14: 0 | J14: 0 | L14: 300000 | M14: 1396 | N14: =SMALL(D14:L14,COUNTIF(D14:L14,0)+1) -> 300000
A15: 불꽃감지기 전원공급기 | B15: AC220V/DC24V,5A | C15: 개 | D15: 0 | F15: 0 | H15: 0 | J15: 0 | L15: 400000 | M15: 1396 | N15: =SMALL(D15:L15,COUNTIF(D15:L15,0)+1) -> 400000
A16: 불꽃감지기 전원공급기 | B16: AC220V/DC24V,15A | C16: 개 | D16: 0 | F16: 0 | H16: 0 | J16: 0 | L16: 600000 | M16: 1396 | N16: =SMALL(D16:L16,COUNTIF(D16:L16,0)+1) -> 600000
A17: 불꽃감지기 전원공급기 | B17: AC220V/DC24V,20A | C17: 개 | D17: 0 | F17: 0 | H17: 0 | J17: 0 | L17: 750000 | M17: 1396 | N17: =SMALL(D17:L17,COUNTIF(D17:L17,0)+1) -> 750000
A18: 발신기외함(노출) | B18: 문짝:철재, 박스:철재 | C18: 개 | D18: 19982 | F18: 70000 | G18: 1195 | H18: 50000 | I18: 757 | J18: 25000 | K18: 969 | L18: 0 | N18: =SMALL(D18:L18,COUNTIF(D18:L18,0)+1) -> 19982
A19: 발신기외함(노출) | B19: 문짝:스텐, 박스:스텐 | C19: 개 | D19: 40090 | F19: 155000 | G19: 1195 | H19: 110000 | I19: 757 | J19: 60000 | K19: 969 | L19: 0 | N19: =SMALL(D19:L19,COUNTIF(D19:L19,0)+1) -> 40090
A20: 발신기외함(매입) | B20: 문짝:스텐, 박스:철재 | C20: 개 | D20: 0 | F20: 0 | H20: 65000 | I20: 757 | J20: 0 | L20: 0 | N20: =SMALL(D20:L20,COUNTIF(D20:L20,0)+1) -> 65000
A21: 경종 | B21: DC 24V | C21: 개 | D21: 4138 | F21: 6000 | G21: 1194 | H21: 7500 | I21: 756 | J21: 0 | L21: 0 | N21: =SMALL(D21:L21,COUNTIF(D21:L21,0)+1) -> 4138
A22: 표시등(LED) | B22: DC 24V | C22: 개 | D22: 1364 | F22: 2000 | G22: 1194 | H22: 2000 | I22: 756 | J22: 0 | L22: 0 | N22: =SMALL(D22:L22,COUNTIF(D22:L22,0)+1) -> 1364
A23: 수동발신기 | B23: DC 24V | C23: 개 | D23: 2404 | F23: 5000 | G23: 1194 | H23: 5000 | I23: 756 | J23: 0 | L23: 0 | N23: =SMALL(D23:L23,COUNTIF(D23:L23,0)+1) -> 2404
A24: 가압표시등 | B24: 25mm, PILOT LAMP | C24: 개 | D24: 0 | F24: 3000 | G24: 1194 | H24: 0 | J24: 0 | L24: 0 | N24: =SMALL(D24:L24,COUNTIF(D24:L24,0)+1) -> 3000
A25: 접속단자대 | B25: TB, 10P 20A | C25: 개 | D25: 0 | F25: 0 | H25: 1900 | I25: 856 | J25: 0 | L25: 0 | N25: =SMALL(D25:L25,COUNTIF(D25:L25,0)+1) -> 1900
A26: 접속단자대 | B26: TB, 15P 20A | C26: 개 | D26: 0 | F26: 0 | H26: 2900 | I26: 856 | J26: 0 | L26: 0 | N26: =SMALL(D26:L26,COUNTIF(D26:L26,0)+1) -> 2900
A27: 접속단자대 | B27: TB, 20P 20A | C27: 개 | D27: 0 | F27: 0 | H27: 3770 | I27: 856 | J27: 0 | L27: 0 | N27: =SMALL(D27:L27,COUNTIF(D27:L27,0)+1) -> 3770
A28: 피난구 유도등(고효율,고휘도) | B28: LED, 소형(단면), 60분용 | C28: 개 | D28: 44806 | F28: 125000 | G28: 1194 | H28: 100000 | I28: 757 | J28: 100000 | K28: 969 | L28: 100000 | M28: 1396 | N28: =SMALL(D28:L28,COUNTIF(D28:L28,0)+1) -> 44806
A29: 피난구 유도등(고효율,고휘도) | B29: LED, 소형(양면), 60분용 | C29: 개 | D29: 48491 | F29: 150000 | G29: 1194 | H29: 150000 | I29: 757 | J29: 130000 | K29: 969 | L29: 110000 | M29: 1396 | N29: =SMALL(D29:L29,COUNTIF(D29:L29,0)+1) -> 48491
A30: 피난구 유도등(고효율,고휘도) | B30: LED, 중형(단면), 60분용 | C30: 개 | D30: 52282 | F30: 150000 | G30: 1194 | H30: 160000 | I30: 757 | J30: 130000 | K30: 969 | L30: 130000 | M30: 1396 | N30: =SMALL(D30:L30,COUNTIF(D30:L30,0)+1) -> 52282
A31: 피난구 유도등(고효율,고휘도) | B31: LED, 중형(양면), 60분용 | C31: 개 | D31: 56765 | F31: 180000 | G31: 1194 | H31: 200000 | I31: 757 | J31: 160000 | K31: 969 | L31: 150000 | M31: 1396 | N31: =SMALL(D31:L31,COUNTIF(D31:L31,0)+1) -> 56765
A32: 피난구 유도등(고효율,고휘도) | B32: LED, 대형(단면), 60분용 | C32: 개 | D32: 0 | F32: 180000 | G32: 1194 | H32: 200000 | I32: 756 | J32: 0 | L32: 150000 | M32: 1396 | N32: =SMALL(D32:L32,COUNTIF(D32:L32,0)+1) -> 150000
A33: 피난구 유도등(고효율,고휘도) | B33: LED, 대형(양면), 60분용 | C33: 개 | D33: 0 | F33: 220000 | G33: 1194 | H33: 0 | J33: 0 | L33: 170000 | M33: 1396 | N33: =SMALL(D33:L33,COUNTIF(D33:L33,0)+1) -> 170000
A34: 복도통로 유도등(고효율,고휘도) | B34: LED, 벽부, 60분용 | C34: 개 | D34: 0 | F34: 100000 | G34: 1194 | H34: 100000 | I34: 756 | J34: 100000 | K34: 969 | L34: 100000 | M34: 1396 | N34: =SMALL(D34:L34,COUNTIF(D34:L34,0)+1) -> 100000
A35: 계단통로 유도등(고효율,고휘도) | B35: LED, 벽부, 60분용 | C35: 개 | D35: 0 | F35: 120000 | G35: 1194 | H35: 220000 | I35: 756 | J35: 150000 | K35: 969 | L35: 150000 | M35: 1396 | N35: =SMALL(D35:L35,COUNTIF(D35:L35,0)+1) -> 120000
A36: 거실통로 유도등(고효율,고휘도) | B36: LED, 천정단면, 60분용 | C36: 개 | D36: 52282 | F36: 160000 | G36: 1194 | H36: 0 | J36: 130000 | K36: 969 | L36: 130000 | M36: 1396 | N36: =SMALL(D36:L36,COUNTIF(D36:L36,0)+1) -> 52282
A37: 거실통로 유도등(고효율,고휘도) | B37: LED, 천정양면, 60분용 | C37: 개 | D37: 56765 | F37: 190000 | G37: 1194 | H37: 160000 | I37: 756 | J37: 160000 | K37: 969 | L37: 160000 | M37: 1396 | N37: =SMALL(D37:L37,COUNTIF(D37:L37,0)+1) -> 56765
A38: 바닥통로 유도등(고효율,고휘도) | B38: LED, 소형, 60분용 | C38: 개 | D38: 170078 | F38: 300000 | G38: 1194 | H38: 0 | J38: 0 | L38: 0 | N38: =SMALL(D38:L38,COUNTIF(D38:L38,0)+1) -> 170078
A39: 바닥통로 유도등(고효율,고휘도) | B39: LED, 중형, 60분용 | C39: 개 | D39: 258163 | F39: 390000 | G39: 1194 | H39: 310000 | I39: 756 | J39: 310000 | K39: 969 | L39: 0 | N39: =SMALL(D39:L39,COUNTIF(D39:L39,0)+1) -> 258163
A40: 객석유도등 | B40: LED, DC24V | C40: 개 | F40: 100000 | G40: 1194 | H40: 0 | J40: 0 | L40: 0 | N40: =SMALL(D40:L40,COUNTIF(D40:L40,0)+1) -> 100000
...

Sheet 5.배선
A1: 단 가 대 비 표
A2: 2026년 상반기 충남교육청 건설공사 일위대가(전기, 통신, 전기소방)
A3: 품 명 | B3: 규 격 | C3: 단위 | D3: 재 료 비 | O3: 번 호 | P3: 비 고
D4: 조달청가격 | E4: PAGE | F4: 거래가격 | G4: PAGE | H4: 유통물가 | I4: PAGE | J4: 물가자료 | K4: PAGE | L4: 물가정보 | M4: PAGE | N4: 적용단가
A5: 강심알미늄전선 | B5: ACSR-OC, 58㎟, 22.9kV | C5: M | D5: 0 | F5: 1819 | G5: 1008 | H5: 3839 | I5: 839 | J5: 0 | L5: 3810 | M5: 1180 | N5: =SMALL(D5:L5,COUNTIF(D5:L5,0)+1) -> 1819
A6: 강심알미늄전선 | B6: ACSR, 58㎟ | C6: M | D6: 0 | F6: 1137 | G6: 1008 | H6: 2172 | I6: 839 | J6: 0 | L6: 2147 | M6: 1180 | N6: =SMALL(D6:L6,COUNTIF(D6:L6,0)+1) -> 1137
A7: 22.9KV동심중성선케이블 | B7: 22.9kv, FR-CN/CO-W, 수밀형무독성난연, 22.9kv, 1*60㎟ | C7: M | D7: 17959 | F7: 22679 | G7: 996 | H7: 25398 | I7: 835 | J7: 0 | L7: 26519 | M7: 1170 | N7: =SMALL(D7:L7,COUNTIF(D7:L7,0)+1) -> 17959 | P7: 대전,세종,충남
A8: 22.9kv동심중성선케이블 | B8: 22.9kv, CN/CV-W, 일반형, 1*60㎟ | C8: M | D8: 19159 | F8: 24425 | G8: 996 | H8: 27352 | I8: 835 | J8: 0 | L8: 28560 | M8: 1170 | N8: =SMALL(D8:L8,COUNTIF(D8:L8,0)+1) -> 19159 | P8: 대전,세종,충남
A9: 저독성난연케이블(단선) | B9: HFIX, 1.5㎣ (1.38㎜) | C9: M | D9: 342 | F9: 382 | G9: 993 | H9: 532 | I9: 833 | J9: 441 | K9: 1074 | L9: 596 | M9: 1165 | N9: =SMALL(D9:L9,COUNTIF(D9:L9,0)+1) -> 342 | P9: 대전,세종,충남
A10: 저독성난연케이블(단선) | B10: HFIX, 2.5㎣ (1.78㎜) | C10: M | D10: 513 | F10: 580 | G10: 993 | H10: 859 | I10: 833 | J10: 641 | K10: 1074 | L10: 981 | M10: 1165 | N10: =SMALL(D10:L10,COUNTIF(D10:L10,0)+1) -> 513 | P10: 대전,세종,충남
A11: 저독성난연케이블(단선) | B11: HFIX, 4㎣ (2.25㎜) | C11: M | D11: 781 | F11: 878 | G11: 993 | H11: 1349 | I11: 833 | J11: 980 | K11: 1074 | L11: 1528 | M11: 1165 | N11: =SMALL(D11:L11,COUNTIF(D11:L11,0)+1) -> 781 | P11: 대전,세종,충남
A12: 저독성난연케이블(연선) | B12: HFIX, 1.5㎟ | C12: M | D12: 0 | F12: 0 | H12: 0 | J12: 473 | K12: 1074 | L12: 0 | N12: =SMALL(D12:L12,COUNTIF(D12:L12,0)+1) -> 473 | P12: 대전,세종,충남
A13: 저독성난연케이블(연선) | B13: HFIX, 2.5㎟ | C13: M | D13: 551 | F13: 607 | G13: 993 | H13: 878 | I13: 833 | J13: 729 | K13: 1074 | L13: 999 | M13: 1165 | N13: =SMALL(D13:L13,COUNTIF(D13:L13,0)+1) -> 551 | P13: 대전,세종,충남
A14: 저독성난연케이블(연선) | B14: HFIX, 4㎟ | C14: M | D14: 817 | F14: 899 | G14: 993 | H14: 1446 | I14: 833 | J14: 1129 | K14: 1074 | L14: 1641 | M14: 1165 | N14: =SMALL(D14:L14,COUNTIF(D14:L14,0)+1) -> 817 | P14: 대전,세종,충남
A15: 저독성난연케이블 | B15: HFIX, 6㎟ | C15: M | D15: 1083 | F15: 1284 | G15: 993 | H15: 2069 | I15: 833 | J15: 1548 | K15: 1074 | L15: 2348 | M15: 1165 | N15: =SMALL(D15:L15,COUNTIF(D15:L15,0)+1) -> 1083 | P15: 대전,세종,충남
A16: 저독성난연케이블 | B16: HFIX, 10㎟ | C16: M | D16: 1896 | F16: 2087 | G16: 993 | H16: 3982 | I16: 833 | J16: 2700 | K16: 1074 | L16: 4521 | M16: 1165 | N16: =SMALL(D16:L16,COUNTIF(D16:L16,0)+1) -> 1896 | P16: 대전,세종,충남
A17: 저독성난연케이블 | B17: HFIX, 16㎟ | C17: M | D17: 2697 | F17: 3318 | G17: 993 | H17: 5413 | I17: 833 | J17: 4302 | K17: 1074 | L17: 6146 | M17: 1165 | N17: =SMALL(D17:L17,COUNTIF(D17:L17,0)+1) -> 2697 | P17: 대전,세종,충남
A18: 저독성난연케이블 | B18: HFIX, 25㎟ | C18: M | D18: 4295 | F18: 4983 | G18: 993 | H18: 8450 | I18: 833 | J18: 6664 | K18: 1074 | L18: 9660 | M18: 1165 | N18: =SMALL(D18:L18,COUNTIF(D18:L18,0)+1) -> 4295 | P18: 대전,세종,충남
A19: 저독성난연케이블 | B19: HFIX, 35㎟ | C19: M | D19: 5871 | F19: 6463 | G19: 993 | H19: 11225 | I19: 833 | J19: 9088 | K19: 1074 | L19: 12767 | M19: 1165 | N19: =SMALL(D19:L19,COUNTIF(D19:L19,0)+1) -> 5871 | P19: 대전,세종,충남
A20: 저독성난연케이블 | B20: HFIX, 50㎟ | C20: M | D20: 8150 | F20: 8971 | G20: 993 | H20: 15551 | I20: 833 | J20: 12970 | K20: 1074 | L20: 17746 | M20: 1165 | N20: =SMALL(D20:L20,COUNTIF(D20:L20,0)+1) -> 8150 | P20: 대전,세종,충남
A21: 저독성난연케이블 | B21: HFIX, 70㎟ | C21: M | D21: 11155 | F21: 12293 | G21: 993 | H21: 21095 | I21: 833 | J21: 17587 | K21: 1074 | L21: 23980 | M21: 1165 | N21: =SMALL(D21:L21,COUNTIF(D21:L21,0)+1) -> 11155 | P21: 대전,세종,충남
A22: 저독성난연케이블 | B22: HFIX, 95㎟ | C22: M | D22: 14462 | F22: 16803 | G22: 993 | H22: 28931 | I22: 833 | J22: 24008 | K22: 1074 | L22: 32908 | M22: 1165 | N22: =SMALL(D22:L22,COUNTIF(D22:L22,0)+1) -> 14462 | P22: 대전,세종,충남
A23: 저독성난연케이블 | B23: HFIX, 120㎟ | C23: M | D23: 18358 | F23: 21415 | G23: 993 | H23: 33637 | I23: 833 | J23: 30313 | K23: 1074 | L23: 38328 | M23: 1165 | N23: =SMALL(D23:L23,COUNTIF(D23:L23,0)+1) -> 18358 | P23: 대전,세종,충남
A24: 저독성난연케이블 | B24: HFIX, 150㎟ | C24: M | D24: 22386 | F24: 27811 | G24: 993 | H24: 41044 | I24: 833 | J24: 37180 | K24: 1074 | L24: 46739 | M24: 1165 | N24: =SMALL(D24:L24,COUNTIF(D24:L24,0)+1) -> 22386 | P24: 대전,세종,충남
... A27: 저독성난연케이블 | B27: HFIX, 300㎟ | C27: M | D27: 45457 | F27: 53075 | G27: 993 | H27: 86527 | I27: 833 | J27: 75609 | K27: 1074 | L27: 98750 | M27: 1165 | N27: =SMALL(D27:L27,COUNTIF(D27:L27,0)+1) -> 45457 | P27: 대전,세종,충남
A28: 저독성난연케이블 | B28: HFIX, 400㎟ | C28: M | D28: 56452 | F28: 68451 | G28: 993 | H28: 0 | J28: 0 | L28: 123013 | M28: 1165 | N28: =SMALL(D28:L28,COUNTIF(D28:L28,0)+1) -> 56452 | P28: 대전,세종,충남
A29: 600V폴리에틸렌케이블 | B29: F-CV, 1.5㎟ -1C | C29: M | D29: 442 | F29: 591 | G29: 993 | H29: 577 | I29: 834 | J29: 0 | L29: 586 | M29: 1168 | N29: =SMALL(D29:L29,COUNTIF(D29:L29,0)+1) -> 442 | P29: 대전,세종,충남
A30: 600V폴리에틸렌케이블 | B30: F-CV, 2.5㎟ -1C | C30: M | D30: 616 | F30: 965 | G30: 993 | H30: 798 | I30: 834 | J30: 1243 | K30: 1075 | L30: 816 | M30: 1168 | N30: =SMALL(D30:L30,COUNTIF(D30:L30,0)+1) -> 616 | P30: 대전,세종,충남
A31: 600V폴리에틸렌케이블 | B31: F-CV, 4㎟ -1C | C31: M | D31: 871 | F31: 1340 | G31: 993 | H31: 1127 | I31: 834 | J31: 1601 | K31: 1075 | L31: 1154 | M31: 1168 | N31: =SMALL(D31:L31,COUNTIF(D31:L31,0)+1) -> 871 | P31: 대전,세종,충남
A32: 600V폴리에틸렌케이블 | B32: F-CV, 6㎟ -1C | C32: M | D32: 1260 | F32: 1582 | G32: 993 | H32: 1650 | I32: 834 | J32: 2020 | K32: 1075 | L32: 1691 | M32: 1168 | N32: =SMALL(D32:L32,COUNTIF(D32:L32,0)+1) -> 1260 | P32: 대전,세종,충남
A33: 600V폴리에틸렌케이블 | B33: F-CV, 10㎟ -1C | C33: M | D33: 1983 | F33: 2643 | G33: 993 | H33: 2550 | I33: 834 | J33: 3169 | K33: 1075 | L33: 2625 | M33: 1168 | N33: =SMALL(D33:L33,COUNTIF(D33:L33,0)+1) -> 1983 | P33: 대전,세종,충남
A34: 600V폴리에틸렌케이블 | B34: F-CV, 16㎟ -1C | C34: M | D34: 3156 | F34: 4018 | G34: 993 | H34: 4002 | I34: 834 | J34: 4562 | K34: 1075 | L34: 4179 | M34: 1168 | N34: =SMALL(D34:L34,COUNTIF(D34:L34,0)+1) -> 3156 | P34: 대전,세종,충남
A35: 600V폴리에틸렌케이블 | B35: F-CV, 25㎟ -1C | C35: M | D35: 4767 | F35: 6068 | G35: 993 | H35: 6105 | I35: 834 | J35: 7259 | K35: 1075 | L35: 6311 | M35: 1168 | N35: =SMALL(D35:L35,COUNTIF(D35:L35,0)+1) -> 4767 | P35: 대전,세종,충남
A36: 600V폴리에틸렌케이블 | B36: F-CV, 35㎟ -1C | C36: M | D36: 6418 | F36: 8281 | G36: 993 | H36: 8608 | I36: 834 | J36: 9820 | K36: 1075 | L36: 8613 | M36: 1168 | N36: =SMALL(D36:L36,COUNTIF(D36:L36,0)+1) -> 6418 | P36: 대전,세종,충남
A37: 600V폴리에틸렌케이블 | B37: F-CV, 50㎟ -1C | C37: M | D37: 8697 | F37: 11069 | G37: 993 | H37: 11639 | I37: 834 | J37: 12871 | K37: 1075 | L37: 11513 | M37: 1168 | N37: =SMALL(D37:L37,COUNTIF(D37:L37,0)+1) -> 8697 | P37: 대전,세종,충남
A38: 600V폴리에틸렌케이블 | B38: F-CV, 70㎟ -1C | C38: M | D38: 12127 | F38: 15435 | G38: 993 | H38: 15657 | I38: 834 | J38: 18545 | K38: 1075 | L38: 16055 | M38: 1168 | N38: =SMALL(D38:L38,COUNTIF(D38:L38,0)+1) -> 12127 | P38: 대전,세종,충남
A39: 600V폴리에틸렌케이블 | B39: F-CV, 95㎟ -1C | C39: M | D39: 16587 | F39: 19426 | G39: 993 | H39: 22022 | I39: 834 | J39: 25149 | K39: 1075 | L39: 22209 | M39: 1168 | N39: =SMALL(D39:L39,COUNTIF(D39:L39,0)+1) -> 16587 | P39: 대전,세종,충남
A40: 600V폴리에틸렌케이블 | B40: F-CV, 120㎟ -1C | C40: M | D40: 20765 | F40: 24045 | G40: 993 | H40: 27005 | I40: 834 | J40: 31357 | K40: 1075 | L40: 27490 | M40: 1168 | N40: =SMALL(D40:L40,COUNTIF(D40:L40,0)+1) -> 20765 | P40: 대전,세종,충남
A41: 600V폴리에틸렌케이블 | B41: F-CV, 150㎟ -1C | C41: M | D41: 25591 | F41: 29633 | G41: 993 | H41: 32826 | I41: 834 | J41: 38748 | K41: 1075 | L41: 33878 | M41: 1168 | N41: =SMALL(D41:L41,COUNTIF(D41:L41,0)+1) -> 25591 | P41: 대전,세종,충남
... A45: 600V폴리에틸렌케이블 | B45: F-CV, 400㎟ -1C | C45: M | D45: 68894 | F45: 83974 | G45: 993 | H45: 93604 | I45: 834 | J45: 97651 | K45: 1075 | L45: 96002 | M45: 1168 | N45: =SMALL(D45:L45,COUNTIF(D45:L45,0)+1) -> 68894 | P45: 대전,세종,충남
...

Sheet 6.배관
A1: 단 가 대 비 표
A2: 2026년 상반기 충남교육청 건설공사 일위대가(전기, 통신, 전기소방)
A3: 품 명 | B3: 규 격 | C3: 단위 | D3: 재 료 비 | O3: 번 호 | P3: 비 고
D4: 조달청가격 | E4: PAGE | F4: 거래가격 | G4: PAGE | H4: 유통물가 | I4: PAGE | J4: 물가자료 | K4: PAGE | L4: 물가정보 | M4: PAGE | N4: 적용단가
A5: 강제전선관(아연도) | B5: ST, 16Φ | C5: M | D5: 2380 | F5: 2830 | G5: 1029 | H5: 3373 | I5: 864 | J5: 2930 | K5: 1101 | L5: 3340 | M5: 1201 | N5: =SMALL(D5:L5,COUNTIF(D5:L5,0)+1) -> 2380 | P5: 대전,세종,충남
A6: 강제전선관(아연도) | B6: ST, 22Φ | C6: M | D6: 3085 | F6: 3660 | G6: 1029 | H6: 4373 | I6: 864 | J6: 3810 | K6: 1101 | L6: 4330 | M6: 1201 | N6: =SMALL(D6:L6,COUNTIF(D6:L6,0)+1) -> 3085 | P6: 대전,세종,충남
A7: 강제전선관(아연도) | B7: ST, 28Φ | C7: M | D7: 4012 | F7: 4770 | G7: 1029 | H7: 5717 | I7: 864 | J7: 4970 | K7: 1101 | L7: 5660 | M7: 1201 | N7: =SMALL(D7:L7,COUNTIF(D7:L7,0)+1) -> 4012 | P7: 대전,세종,충남
A8: 강제전선관(아연도) | B8: ST, 36Φ | C8: M | D8: 5134 | F8: 6100 | G8: 1029 | H8: 7323 | I8: 864 | J8: 6290 | K8: 1101 | L8: 7250 | M8: 1201 | N8: =SMALL(D8:L8,COUNTIF(D8:L8,0)+1) -> 5134 | P8: 대전,세종,충남
A9: 강제전선관(아연도) | B9: ST, 42Φ | C9: M | D9: 5899 | F9: 7010 | G9: 1029 | H9: 8413 | I9: 864 | J9: 7190 | K9: 1101 | L9: 8330 | M9: 1201 | N9: =SMALL(D9:L9,COUNTIF(D9:L9,0)+1) -> 5899 | P9: 대전,세종,충남
A10: 강제전선관(아연도) | B10: ST, 54Φ | C10: M | D10: 8998 | F10: 9850 | G10: 1029 | H10: 11827 | I10: 864 | J10: 10200 | K10: 1101 | L10: 11710 | M10: 1201 | N10: =SMALL(D10:L10,COUNTIF(D10:L10,0)+1) -> 8998 | P10: 대전,세종,충남
A11: 강제전선관(아연도) | B11: ST, 70Φ | C11: M | D11: 10574 | F11: 12440 | G11: 1029 | H11: 15079 | I11: 864 | J11: 12880 | K11: 1101 | L11: 14930 | M11: 1201 | N11: =SMALL(D11:L11,COUNTIF(D11:L11,0)+1) -> 10574 | P11: 대전,세종,충남
A12: 강제전선관(아연도) | B12: ST, 82Φ | C12: M | D12: 12166 | F12: 14450 | G12: 1029 | H12: 17372 | I12: 864 | J12: 14850 | K12: 1101 | L12: 17200 | M12: 1201 | N12: =SMALL(D12:L12,COUNTIF(D12:L12,0)+1) -> 12166 | P12: 대전,세종,충남
A13: 강제전선관(아연도) | B13: ST, 104Φ | C13: M | D13: 19626 | F13: 23320 | G13: 1029 | H13: 28048 | I13: 864 | J13: 24310 | K13: 1101 | L13: 27770 | M13: 1201 | N13: =SMALL(D13:L13,COUNTIF(D13:L13,0)+1) -> 19626 | P13: 대전,세종,충남
A14: 경질비닐전선관 | B14: HI, 16Φ | C14: M | D14: 294 | F14: 332 | G14: 1024 | H14: 440 | I14: 861 | J14: 400 | K14: 1107 | L14: 440 | M14: 1203 | N14: =SMALL(D14:L14,COUNTIF(D14:L14,0)+1) -> 294 | P14: 대전,세종,충남
A15: 경질비닐전선관 | B15: HI, 22Φ | C15: M | D15: 350 | F15: 400 | G15: 1024 | H15: 528 | I15: 861 | J15: 480 | K15: 1107 | L15: 528 | M15: 1203 | N15: =SMALL(D15:L15,COUNTIF(D15:L15,0)+1) -> 350 | P15: 대전,세종,충남
A16: 경질비닐전선관 | B16: HI, 28Φ | C16: M | D16: 700 | F16: 774 | G16: 1024 | H16: 1021 | I16: 861 | J16: 930 | K16: 1107 | L16: 1021 | M16: 1203 | N16: =SMALL(D16:L16,COUNTIF(D16:L16,0)+1) -> 700 | P16: 대전,세종,충남
... A22: 경질비닐전선관 | B22: HI, 100Φ | C22: M | D22: 4108 | F22: 4834 | G22: 1024 | H22: 5912 | I22: 861 | J22: 6030 | K22: 1107 | L22: 5912 | M22: 1203 | N22: =SMALL(D22:L22,COUNTIF(D22:L22,0)+1) -> 4108 | P22: 대전,세종,충남
A23: 합성수지제가요전선관(일반) | B23: CD 하이렉스, 16Φ | C23: M | D23: 170 | F23: 267 | G23: 1025 | H23: 267 | I23: 860 | J23: 160 | K23: 1104 | L23: 0 | N23: =SMALL(D23:L23,COUNTIF(D23:L23,0)+1) -> 160 | P23: 콘크리트매입용
A24: 합성수지제가요전선관(일반) | B24: CD 하이렉스, 22Φ | C24: M | D24: 255 | F24: 373 | G24: 1025 | H24: 373 | I24: 860 | J24: 240 | K24: 1104 | L24: 0 | N24: =SMALL(D24:L24,COUNTIF(D24:L24,0)+1) -> 240 | P24: 콘크리트매입용
A25: 합성수지제가요전선관(일반) | B25: CD 하이렉스, 28Φ | C25: M | D25: 348 | F25: 549 | G25: 1025 | H25: 549 | I25: 860 | J25: 330 | K25: 1104 | L25: 0 | N25: =SMALL(D25:L25,COUNTIF(D25:L25,0)+1) -> 330 | P25: 콘크리트매입용
A26: 나사없는전선관(1본=3.6M) | B26: E19 (19.1Ø)(내경:16.7) | C26: M | D26: 1870 | F26: 7920 | G26: 1029 | H26: 2547 | I26: 863 | J26: 2547 | K26: 1102 | L26: 2547 | M26: 1201 | N26: =SMALL(D26:L26,COUNTIF(D26:L26,0)+1) -> 1870
A27: 나사없는전선관(1본=3.6M) | B27: E25 (25.4Ø)(내경:23.0) | C27: M | D27: 2725 | F27: 10330 | G27: 1029 | H27: 3354 | I27: 863 | J27: 3354 | K27: 1102 | L27: 3354 | M27: 1201 | N27: =SMALL(D27:L27,COUNTIF(D27:L27,0)+1) -> 2725
A28: 나사없는전선관(1본=3.6M) | B28: E31 (31.8Ø)(내경:29) | C28: M | D28: 3694 | F28: 14000 | G28: 1029 | H28: 4696 | I28: 863 | J28: 4696 | K28: 1102 | L28: 4696 | M28: 1201 | N28: =SMALL(D28:L28,COUNTIF(D28:L28,0)+1) -> 3694
A29: 나사없는전선관(1본=3.6M) | B29: E39 (38.1Ø)(내경:35.3) | C29: M | D29: 4390 | F29: 16640 | G29: 1029 | H29: 5840 | I29: 863 | J29: 5840 | K29: 1102 | L29: 5840 | M29: 1201 | N29: =SMALL(D29:L29,COUNTIF(D29:L29,0)+1) -> 4390
A30: 나사없는전선관(1본=3.6M) | B30: E51 (50.8Ø)(내경:48) | C30: M | D30: 5832 | F30: 22100 | G30: 1029 | H30: 7784 | I30: 863 | J30: 7784 | K30: 1102 | L30: 7784 | M30: 1201 | N30: =SMALL(D30:L30,COUNTIF(D30:L30,0)+1) -> 5832
A31: 나사없는전선관(1본=3.6M) | B31: E63 (63.5Ø)(내경:60.3) | C31: M | D31: 8082 | F31: 30630 | G31: 1029 | H31: 11138 | I31: 863 | J31: 11138 | K31: 1102 | L31: 11138 | M31: 1201 | N31: =SMALL(D31:L31,COUNTIF(D31:L31,0)+1) -> 8082
A32: 나사없는전선관(1본=3.6M) | B32: E75 (76.2Ø)(내경:72.6) | C32: M | D32: 10708 | F32: 40580 | G32: 1029 | H32: 14049 | I32: 863 | J32: 14049 | K32: 1102 | L32: 14049 | M32: 1201 | N32: =SMALL(D32:L32,COUNTIF(D32:L32,0)+1) -> 10708
A33: 파상형경질폴리에틸렌전선관 | B33: ELP, 30Φ | C33: M | D33: 342 | F33: 391 | G33: 1025 | H33: 480 | I33: 861 | J33: 360 | K33: 1106 | L33: 482 | M33: 1203 | N33: =SMALL(D33:L33,COUNTIF(D33:L33,0)+1) -> 342 | P33: 대전,세종,충남
A34: 파상형경질폴리에틸렌전선관 | B34: ELP, 40Φ | C34: M | D34: 522 | F34: 563 | G34: 1025 | H34: 607 | I34: 861 | J34: 550 | K34: 1106 | L34: 610 | M34: 1203 | N34: =SMALL(D34:L34,COUNTIF(D34:L34,0)+1) -> 522 | P34: 대전,세종,충남
A35: 파상형경질폴리에틸렌전선관 | B35: ELP, 50Φ | C35: M | D35: 680 | F35: 750 | G35: 1025 | H35: 860 | I35: 861 | J35: 730 | K35: 1106 | L35: 864 | M35: 1203 | N35: =SMALL(D35:L35,COUNTIF(D35:L35,0)+1) -> 680 | P35: 대전,세종,충남
A36: 파상형경질폴리에틸렌전선관 | B36: ELP, 65Φ | C36: M | D36: 990 | F36: 1250 | G36: 1025 | H36: 1239 | I36: 861 | J36: 1090 | K36: 1106 | L36: 1245 | M36: 1203 | N36: =SMALL(D36:L36,COUNTIF(D36:L36,0)+1) -> 990 | P36: 대전,세종,충남
A37: 파상형경질폴리에틸렌전선관 | B37: ELP, 80Φ | C37: M | D37: 1357 | F37: 1719 | G37: 1025 | H37: 1632 | I37: 861 | J37: 1450 | K37: 1106 | L37: 1640 | M37: 1203 | N37: =SMALL(D37:L37,COUNTIF(D37:L37,0)+1) -> 1357 | P37: 대전,세종,충남
A38: 파상형경질폴리에틸렌전선관 | B38: ELP,100Φ | C38: M | D38: 1784 | F38: 2188 | G38: 1025 | H38: 2214 | I38: 861 | J38: 1980 | K38: 1106 | L38: 2225 | M38: 1203 | N38: =SMALL(D38:L38,COUNTIF(D38:L38,0)+1) -> 1784 | P38: 대전,세종,충남
A39: 파상형경질폴리에틸렌전선관 | B39: ELP,125Φ | C39: M | D39: 2796 | F39: 3204 | G39: 1025 | H39: 3440 | I39: 861 | J39: 3040 | K39: 1106 | L39: 3457 | M39: 1203 | N39: =SMALL(D39:L39,COUNTIF(D39:L39,0)+1) -> 2796 | P39: 대전,세종,충남
A40: 파상형경질폴리에틸렌전선관 | B40: ELP,150Φ | C40: M | D40: 3699 | F40: 3906 | G40: 1025 | H40: 4491 | I40: 861 | J40: 3940 | K40: 1106 | L40: 4513 | M40: 1203 | N40: =SMALL(D40:L40,COUNTIF(D40:L40,0)+1) -> 3699 | P40: 대전,세종,충남
A41: 파상형경질폴리에틸렌전선관 | B41: ELP,175Φ | C41: M | D41: 6375 | F41: 7500 | G41: 1025 | H41: 7906 | I41: 861 | J41: 7510 | K41: 1106 | L41: 7946 | M41: 1203 | N41: =SMALL(D41:L41,COUNTIF(D41:L41,0)+1) -> 6375 | P41: 대전,세종,충남
A42: 파상형경질폴리에틸렌전선관 | B42: ELP,200Φ | C42: M | D42: 7081 | F42: 8594 | G42: 1025 | H42: 8829 | I42: 861 | J42: 8030 | K42: 1106 | L42: 8873 | M42: 1203 | N42: =SMALL(D42:L42,COUNTIF(D42:L42,0)+1) -> 7081 | P42: 대전,세종,충남
A43: 폴리에틸렌전선관 | B43: PE, 16Φ | C43: M | D43: 262 | F43: 344 | G43: 1026 | H43: 319 | I43: 861 | J43: 320 | K43: 1102 | L43: 320 | M43: 1204 | N43: =SMALL(D43:L43,COUNTIF(D43:L43,0)+1) -> 262 | P43: 대전,세종,충남
A44: 폴리에틸렌전선관 | B44: PE, 22Φ | C44: M | D44: 336 | F44: 454 | G44: 1026 | H44: 371 | I44: 861 | J44: 420 | K44: 1102 | L44: 408 | M44: 1204 | N44: =SMALL(D44:L44,COUNTIF(D44:L44,0)+1) -> 336 | P44: 대전,세종,충남
... A51: 폴리에틸렌전선관 | B51: PE, 100Φ | C51: M | D51: 4560 | F51: 5615 | G51: 1026 | H51: 4849 | I51: 861 | J51: 5290 | K51: 1102 | L51: 4861 | M51: 1204 | N51: =SMALL(D51:L51,COUNTIF(D51:L51,0)+1) -> 4560 | P51: 대전,세종,충남
...

Sheet 7.덕트,트레이
A1: 단 가 대 비 표
A2: 2026년 상반기 충남교육청 건설공사 일위대가(전기, 통신, 전기소방)
A3: 품 명 | B3: 규 격 | C3: 단위 | D3: 재 료 비 | O3: 번 호 | P3: 비 고
D4: 조달청가격 | E4: PAGE | F4: 거래가격 | G4: PAGE | H4: 유통물가 | I4: PAGE | J4: 물가자료 | K4: PAGE | L4: 물가정보 | M4: PAGE | N4: 적용단가
A5: 알루미늄몰드 | B5: 22*9mm | C5: M | D5: 0 | F5: 1100 | G5: 1031 | H5: 0 | J5: 0 | L5: 0 | N5: =SMALL(D5:L5,COUNTIF(D5:L5,0)+1) -> 1100
A6: 알루미늄몰드 | B6: 28*11mm | C6: M | D6: 1824 | F6: 3500 | G6: 1031 | H6: 3500 | I6: 871 | J6: 3150 | K6: 1099 | L6: 3500 | M6: 1205 | N6: =SMALL(D6:L6,COUNTIF(D6:L6,0)+1) -> 1824
A7: 알루미늄몰드 | B7: 36*14mm | C7: M | D7: 2561 | F7: 5000 | G7: 1031 | H7: 5000 | I7: 871 | J7: 4410 | K7: 1099 | L7: 5000 | M7: 1205 | N7: =SMALL(D7:L7,COUNTIF(D7:L7,0)+1) -> 2561
A8: 알루미늄몰드 | B8: 50*20mm | C8: M | D8: 4593 | F8: 9000 | G8: 1031 | H8: 9000 | I8: 871 | J8: 8190 | K8: 1099 | L8: 9000 | M8: 1205 | N8: =SMALL(D8:L8,COUNTIF(D8:L8,0)+1) -> 4593
A9: PVC고강도몰드(컬러) | B9: 25*9mm, 미니소 | C9: M | D9: 0 | F9: 1100 | G9: 1031 | H9: 1100 | I9: 871 | J9: 0 | L9: 1100 | M9: 1205 | N9: =SMALL(D9:L9,COUNTIF(D9:L9,0)+1) -> 1100
A10: PVC고강도몰드(컬러) | B10: 31*11mm, 소 | C10: M | D10: 0 | F10: 0 | H10: 1500 | I10: 871 | J10: 0 | L10: 1500 | M10: 1205 | N10: =SMALL(D10:L10,COUNTIF(D10:L10,0)+1) -> 1500
A11: PVC고강도몰드(컬러) | B11: 39*15mm, 중 | C11: M | D11: 0 | F11: 0 | H11: 2000 | I11: 871 | J11: 0 | L11: 2000 | M11: 1205 | N11: =SMALL(D11:L11,COUNTIF(D11:L11,0)+1) -> 2000
A12: PVC고강도몰드(컬러) | B12: 51*19mm, 대 | C12: M | D12: 0 | F12: 0 | H12: 3000 | I12: 871 | J12: 0 | L12: 3000 | M12: 1205 | N12: =SMALL(D12:L12,COUNTIF(D12:L12,0)+1) -> 3000
A13: PVC고강도몰드(컬러) | B13: 65*22mm, 특대 | C13: M | D13: 0 | F13: 0 | H13: 4000 | I13: 871 | J13: 0 | L13: 4000 | M13: 1205 | N13: =SMALL(D13:L13,COUNTIF(D13:L13,0)+1) -> 4000
A14: PVC 랜덕트 | B14: 40*30mm | C14: M | D14: 0 | F14: 4000 | G14: 1031 | H14: 4000 | I14: 870 | J14: 0 | L14: 4000 | M14: 1205 | N14: =SMALL(D14:L14,COUNTIF(D14:L14,0)+1) -> 4000
A15: PVC 랜덕트 | B15: 60*40mm | C15: M | D15: 0 | F15: 6000 | G15: 1031 | H15: 6000 | I15: 870 | J15: 0 | L15: 6000 | M15: 1205 | N15: =SMALL(D15:L15,COUNTIF(D15:L15,0)+1) -> 6000
A16: PVC 랜덕트 | B16: 80*60mm | C16: M | D16: 0 | F16: 8000 | G16: 1031 | H16: 8000 | I16: 870 | J16: 0 | L16: 8000 | M16: 1205 | N16: =SMALL(D16:L16,COUNTIF(D16:L16,0)+1) -> 8000
A17: PVC 랜덕트 | B17: 100*80mm | C17: M | D17: 0 | F17: 11000 | G17: 1031 | H17: 11000 | I17: 870 | J17: 0 | L17: 11000 | M17: 1205 | N17: =SMALL(D17:L17,COUNTIF(D17:L17,0)+1) -> 11000
A18: 알루미늄덕트 | B18: 50*35mm | C18: M | D18: 8827 | F18: 15000 | G18: 1031 | H18: 8000 | I18: 870 | J18: 0 | L18: 8000 | M18: 1205 | N18: =SMALL(D18:L18,COUNTIF(D18:L18,0)+1) -> 8000
A19: 알루미늄덕트 | B19: 60*60mm | C19: M | D19: 13241 | F19: 20000 | G19: 1031 | H19: 12000 | I19: 870 | J19: 0 | L19: 12000 | M19: 1205 | N19: =SMALL(D19:L19,COUNTIF(D19:L19,0)+1) -> 12000
A20: 알루미늄덕트 | B20: 70*40mm | C20: M | D20: 13241 | F20: 20000 | G20: 1031 | H20: 10000 | I20: 870 | J20: 0 | L20: 10000 | M20: 1205 | N20: =SMALL(D20:L20,COUNTIF(D20:L20,0)+1) -> 10000
A21: 알루미늄덕트 | B21: 100*50mm | C21: M | D21: 15890 | F21: 25000 | G21: 1031 | H21: 14000 | I21: 870 | J21: 0 | L21: 14000 | M21: 1205 | N21: =SMALL(D21:L21,COUNTIF(D21:L21,0)+1) -> 14000
A22: 알루미늄덕트 | B22: 120*60mm | C22: M | D22: 22069 | F22: 35000 | G22: 1031 | H22: 20000 | I22: 870 | J22: 0 | L22: 20000 | M22: 1205 | N22: =SMALL(D22:L22,COUNTIF(D22:L22,0)+1) -> 20000
A23: 알루미늄덕트 | B23: 150*100mm | C23: M | D23: 30898 | F23: 50000 | G23: 1031 | H23: 50000 | I23: 870 | J23: 0 | L23: 50000 | M23: 1205 | N23: =SMALL(D23:L23,COUNTIF(D23:L23,0)+1) -> 30898
A24: 알루미늄덕트 부속품 | B24: 엘보ㄱ/ㄴ/T형, 50mm | C24: 개 | D24: 5701 | F24: 12000 | G24: 1031 | H24: 12000 | I24: 870 | J24: 0 | L24: 12000 | M24: 1205 | N24: =SMALL(D24:L24,COUNTIF(D24:L24,0)+1) -> 5701
A25: 알루미늄덕트 부속품 | B25: 엘보ㄱ/ㄴ/T형, 70mm | C25: 개 | D25: 8449 | F25: 16000 | G25: 1031 | H25: 16000 | I25: 870 | J25: 0 | L25: 16000 | M25: 1205 | N25: =SMALL(D25:L25,COUNTIF(D25:L25,0)+1) -> 8449
... A27: 알루미늄덕트 부속품 | B27: 엘보ㄱ/ㄴ/T형, 120mm | C27: 개 | D27: 13228 | F27: 25000 | G27: 1031 | H27: 25000 | I27: 870 | J27: 0 | L27: 25000 | M27: 1205 | N27: =SMALL(D27:L27,COUNTIF(D27:L27,0)+1) -> 13228
A28: 알루미늄덕트 | B28: 벽면덕트80*47mm | C28: M | D28: 0 | F28: 80000 | G28: 1031 | H28: 0 | J28: 0 | L28: 80000 | M28: 1205 | N28: =SMALL(D28:L28,COUNTIF(D28:L28,0)+1) -> 80000
A29: 알루미늄덕트 | B29: 벽면덕트130*40mm | C29: M | D29: 0 | F29: 110000 | G29: 1031 | H29: 0 | J29: 0 | L29: 110000 | M29: 1205 | N29: =SMALL(D29:L29,COUNTIF(D29:L29,0)+1) -> 110000
A30: 알루미늄덕트 | B30: 플레이트, 마감 | C30: M | D30: 0 | F30: 3000 | G30: 1031 | H30: 0 | J30: 0 | L30: 3000 | M30: 1205 | N30: =SMALL(D30:L30,COUNTIF(D30:L30,0)+1) -> 3000
A31: 덕트형케이블트레이 | B31: ST, W150*100H*2.3t | C31: M | D31: 11498 | F31: 0 | H31: 0 | J31: 0 | L31: 0 | N31: =SMALL(D31:L31,COUNTIF(D31:L31,0)+1) -> 11498
A32: 덕트형케이블트레이 | B32: ST, W200*100H*2.3t | C32: M | D32: 13189 | F32: 0 | H32: 0 | J32: 0 | L32: 0 | N32: =SMALL(D32:L32,COUNTIF(D32:L32,0)+1) -> 13189
A33: 덕트형케이블트레이 | B33: ST, W300*100H*2.3t | C33: M | D33: 18265 | F33: 0 | H33: 0 | J33: 0 | L33: 0 | N33: =SMALL(D33:L33,COUNTIF(D33:L33,0)+1) -> 18265
A34: 덕트형케이블트레이 | B34: ST, W400*100H*2.3t | C34: M | D34: 21648 | F34: 0 | H34: 0 | J34: 0 | L34: 0 | N34: =SMALL(D34:L34,COUNTIF(D34:L34,0)+1) -> 21648
A35: 덕트형케이블트레이 | B35: ST, W500*100H*2.3t | C35: M | D35: 25905 | F35: 0 | H35: 0 | J35: 0 | L35: 0 | N35: =SMALL(D35:L35,COUNTIF(D35:L35,0)+1) -> 25905
A36: 덕트형케이블트레이 | B36: ST, W600*100H*2.3t | C36: M | D36: 29028 | F36: 0 | H36: 0 | J36: 0 | L36: 0 | N36: =SMALL(D36:L36,COUNTIF(D36:L36,0)+1) -> 29028
A37: 덕트형케이블트레이 | B37: ST, W700*100H*2.3t | C37: M | D37: 32403 | F37: 0 | H37: 0 | J37: 0 | L37: 0 | N37: =SMALL(D37:L37,COUNTIF(D37:L37,0)+1) -> 32403
A38: 덕트형케이블트레이 | B38: ST, W800*100H*2.3t | C38: M | D38: 36344 | F38: 0 | H38: 0 | J38: 0 | L38: 0 | N38: =SMALL(D38:L38,COUNTIF(D38:L38,0)+1) -> 36344
A39: 덕트형케이블트레이 | B39: ST, W900*100H*2.3t | C39: M | D39: 39132 | F39: 0 | H39: 0 | J39: 0 | L39: 0 | N39: =SMALL(D39:L39,COUNTIF(D39:L39,0)+1) -> 39132
A40: 덕트형케이블트레이 | B40: ST, W1000*100H*2.3t | C40: M | D40: 42999 | F40: 0 | H40: 0 | J40: 0 | L40: 0 | N40: =SMALL(D40:L40,COUNTIF(D40:L40,0)+1) -> 42999
A41: 덕트형케이블트레이부속품 | B41: ST, H. ELBOW, W150*100H*2.3t | C41: 개 | D41: 15095 | F41: 0 | H41: 0 | J41: 0 | L41: 0 | N41: =SMALL(D41:L41,COUNTIF(D41:L41,0)+1) -> 15095
...

Sheet 8.접지자재
A1: 단 가 대 비 표
A2: 2026년 상반기 충남교육청 건설공사 일위대가(전기, 통신, 전기소방)
A3: 품 명 | B3: 규 격 | C3: 단위 | D3: 재 료 비 | O3: 번 호 | P3: 비 고
D4: 조달청가격 | E4: PAGE | F4: 거래가격 | G4: PAGE | H4: 유통물가 | I4: PAGE | J4: 물가자료 | K4: PAGE | L4: 물가정보 | M4: PAGE | N4: 적용단가
A5: 이온방사형 광역 피뢰침 | B5: 보호반경 65m | C5: 개 | D5: 0 | F5: 4000000 | G5: 1074 | H5: 0 | J5: 0 | L5: 0 | N5: =SMALL(D5:L5,COUNTIF(D5:L5,0)+1) -> 4000000
A6: 이온방사형 광역 피뢰침 | B6: 보호반경 84m | C6: 개 | D6: 0 | F6: 4500000 | G6: 1074 | H6: 0 | J6: 0 | L6: 0 | N6: =SMALL(D6:L6,COUNTIF(D6:L6,0)+1) -> 4500000
A7: 이온방사형 광역 피뢰침 | B7: 보호반경 107m | C7: 개 | D7: 0 | F7: 6000000 | G7: 1074 | H7: 0 | J7: 0 | L7: 0 | N7: =SMALL(D7:L7,COUNTIF(D7:L7,0)+1) -> 6000000
A8: 피뢰침 | B8: 14Φx485(CU) | C8: 개 | D8: 0 | F8: 0 | H8: 27000 | I8: 925 | J8: 42000 | K8: 1198 | L8: 45000 | M8: 1274 | N8: =SMALL(D8:L8,COUNTIF(D8:L8,0)+1) -> 27000
A9: 피뢰침 | B9: 주 공 용 (CU) | C9: 개 | D9: 0 | F9: 0 | H9: 45000 | I9: 925 | J9: 63000 | K9: 1198 | L9: 65000 | M9: 1274 | N9: =SMALL(D9:L9,COUNTIF(D9:L9,0)+1) -> 45000
A10: 피뢰침 | B10: 일 자 용 (STS) | C10: 개 | D10: 0 | F10: 0 | H10: 0 | J10: 0 | L10: 120000 | M10: 1274 | N10: =SMALL(D10:L10,COUNTIF(D10:L10,0)+1) -> 120000
A11: 피뢰침지지대(STS 지선 기초포함) | B11: H:3.0M | C11: Set | D11: 184293 | F11: 360000 | G11: 1074 | H11: 225000 | I11: 925 | J11: 315000 | K11: 1198 | L11: 0 | N11: =SMALL(D11:L11,COUNTIF(D11:L11,0)+1) -> 184293
A12: 피뢰침지지대(STS 지선 기초포함) | B12: H:5.0M | C12: Set | D12: 294867 | F12: 580000 | G12: 1074 | H12: 360000 | I12: 925 | J12: 504000 | K12: 1198 | L12: 0 | N12: =SMALL(D12:L12,COUNTIF(D12:L12,0)+1) -> 294867
A13: 피뢰침지지대(STS 지선 기초포함) | B13: H:7.0M | C13: Set | D13: 368586 | F13: 0 | H13: 480000 | I13: 925 | J13: 672000 | K13: 1198 | L13: 0 | N13: =SMALL(D13:L13,COUNTIF(D13:L13,0)+1) -> 368586
A14: 접 지 봉 | B14: 14Φ*1000mm | C14: 개 | D14: 3316 | F14: 0 | H14: 3900 | I14: 925 | J14: 5780 | K14: 1198 | L14: 0 | N14: =SMALL(D14:L14,COUNTIF(D14:L14,0)+1) -> 3316
A15: 접 지 봉 | B15: 16Φ*1800mm | C15: 개 | D15: 5019 | F15: 0 | H15: 6900 | I15: 925 | J15: 10200 | K15: 1198 | L15: 0 | N15: =SMALL(D15:L15,COUNTIF(D15:L15,0)+1) -> 5019
A16: 접 지 봉 | B16: 18Φ*2400mm | C16: 개 | D16: 8544 | F16: 0 | H16: 11500 | I16: 961 | J16: 0 | L16: 0 | N16: =SMALL(D16:L16,COUNTIF(D16:L16,0)+1) -> 8544
A17: 접 지 봉 | B17: 19Φ*2400mm | C17: 개 | D17: 10054 | F17: 0 | H17: 16500 | I17: 925 | J17: 24360 | K17: 1198 | L17: 0 | N17: =SMALL(D17:L17,COUNTIF(D17:L17,0)+1) -> 10054
A18: 접 지 봉 | B18: 19Φ*3000mm | C18: 개 | D18: 14754 | F18: 0 | H18: 20250 | I18: 925 | J18: 0 | L18: 0 | N18: =SMALL(D18:L18,COUNTIF(D18:L18,0)+1) -> 14754
A19: 접지콘넥타 | B19: 볼트형, 일반형,16Φ | C19: 개 | D19: 827 | F19: 0 | H19: 1200 | I19: 925 | J19: 1800 | K19: 1198 | L19: 0 | N19: =SMALL(D19:L19,COUNTIF(D19:L19,0)+1) -> 827
A20: 접지콘넥타 | B20: 볼트형, 일반형,19Φ | C20: 개 | D20: 1173 | F20: 0 | H20: 1800 | I20: 925 | J20: 2700 | K20: 1198 | L20: 0 | N20: =SMALL(D20:L20,COUNTIF(D20:L20,0)+1) -> 1173
A21: 접지콘넥타 | B21: U볼트형, 16Φ | C21: 개 | D21: 3246 | F21: 0 | H21: 5250 | I21: 925 | J21: 6800 | K21: 1198 | L21: 0 | N21: =SMALL(D21:L21,COUNTIF(D21:L21,0)+1) -> 3246
A22: 접지콘넥타 | B22: U볼트형, 19Φ | C22: 개 | D22: 3798 | F22: 0 | H22: 5250 | I22: 925 | J22: 6800 | K22: 1198 | L22: 0 | N22: =SMALL(D22:L22,COUNTIF(D22:L22,0)+1) -> 3798
A23: 접지 저항 저감제 | B23: 아스론 10KG | C23: 포 | D23: 0 | F23: 0 | H23: 10500 | I23: 961 | J23: 10500 | K23: 1198 | L23: 0 | N23: =SMALL(D23:L23,COUNTIF(D23:L23,0)+1) -> 10500
A24: 피뢰도선 | B24: (CU) 8Φ | C24: M | D24: 0 | F24: 8000 | G24: 1074 | H24: 7410 | I24: 925 | J24: 9000 | K24: 1199 | L24: 9000 | M24: 1274 | N24: =SMALL(D24:L24,COUNTIF(D24:L24,0)+1) -> 7410
A25: 피뢰도선 | B25: (AL) 8Φ | C25: M | D25: 0 | F25: 4000 | G25: 1074 | H25: 1275 | I25: 925 | J25: 3500 | K25: 1199 | L25: 3500 | M25: 1274 | N25: =SMALL(D25:L25,COUNTIF(D25:L25,0)+1) -> 1275
A26: 피뢰도선 | B26: (STS) 8Φ | C26: M | D26: 0 | F26: 0 | H26: 3000 | I26: 925 | J26: 7000 | K26: 1199 | L26: 7000 | M26: 1274 | N26: =SMALL(D26:L26,COUNTIF(D26:L26,0)+1) -> 3000
A27: 피뢰도선 조인트 | B27: (CU) "-" 자형 | C27: 개 | D27: 0 | F27: 0 | H27: 2550 | I27: 925 | J27: 5000 | K27: 1199 | L27: 5000 | M27: 1274 | N27: =SMALL(D27:L27,COUNTIF(D27:L27,0)+1) -> 2550
A28: 피뢰도선 조인트 | B28: (CU) "T" 자형 | C28: 개 | D28: 0 | F28: 4000 | G28: 1074 | H28: 2550 | I28: 925 | J28: 6000 | K28: 1199 | L28: 6000 | M28: 1274 | N28: =SMALL(D28:L28,COUNTIF(D28:L28,0)+1) -> 2550
A29: 피뢰도선 조인트 | B29: (AL) "-" 자형 | C29: 개 | D29: 0 | F29: 0 | H29: 2100 | I29: 925 | J29: 3000 | K29: 1199 | L29: 3000 | M29: 1274 | N29: =SMALL(D29:L29,COUNTIF(D29:L29,0)+1) -> 2100
A30: 피뢰도선 조인트 | B30: (AL) "T" 자형 | C30: 개 | D30: 0 | F30: 3200 | G30: 1074 | H30: 2700 | I30: 925 | J30: 3500 | K30: 1199 | L30: 3500 | M30: 1274 | N30: =SMALL(D30:L30,COUNTIF(D30:L30,0)+1) -> 2700
A31: 피뢰도선 조인트 | B31: (STS) "-" 자형 | C31: 개 | D31: 0 | F31: 0 | H31: 2100 | I31: 925 | J31: 3500 | K31: 1199 | L31: 3500 | M31: 1274 | N31: =SMALL(D31:L31,COUNTIF(D31:L31,0)+1) -> 2100
A32: 피뢰도선 조인트 | B32: (STS) "T" 자형 | C32: 개 | D32: 0 | F32: 0 | H32: 2700 | I32: 925 | J32: 4500 | K32: 1199 | L32: 4500 | M32: 1274 | N32: =SMALL(D32:L32,COUNTIF(D32:L32,0)+1) -> 2700
A33: 이질크램프 | B33: AL+CU 이질스리브 / BOLT | C33: 개 | D33: 0 | F33: 0 | H33: 0 | J33: 7000 | K33: 1199 | L33: 7000 | M33: 1274 | N33: =SMALL(D33:L33,COUNTIF(D33:L33,0)+1) -> 7000
A34: 이질크램프 | B34: AL+CU 이질스리브 / 압착 | C34: 개 | D34: 0 | F34: 0 | H34: 0 | J34: 8000 | K34: 1199 | L34: 8000 | M34: 1274 | N34: =SMALL(D34:L34,COUNTIF(D34:L34,0)+1) -> 8000
A35: 이질크램프 | B35: STS+CU 이질스리브 / T자 | C35: 개 | D35: 0 | F35: 18000 | G35: 1074 | H35: 0 | J35: 10000 | K35: 1199 | L35: 10000 | M35: 1274 | N35: =SMALL(D35:L35,COUNTIF(D35:L35,0)+1) -> 10000
A36: 익스팬션 조인트 | B36: 38x200L (CU) | C36: Set | D36: 0 | F36: 0 | H36: 0 | J36: 10500 | K36: 1199 | L36: 10500 | M36: 1274 | N36: =SMALL(D36:L36,COUNTIF(D36:L36,0)+1) -> 10500
A37: 익스팬션 조인트 | B37: 38x200L (AL) | C37: Set | D37: 0 | F37: 0 | H37: 0 | J37: 8000 | K37: 1199 | L37: 8000 | M37: 1274 | N37: =SMALL(D37:L37,COUNTIF(D37:L37,0)+1) -> 8000
A38: 익스팬션 조인트 | B38: 38x200L (STS) | C38: Set | D38: 0 | F38: 0 | H38: 0 | J38: 13000 | K38: 1199 | L38: 13000 | M38: 1274 | N38: =SMALL(D38:L38,COUNTIF(D38:L38,0)+1) -> 13000
A39: 피뢰도선 지지금구 | B39: 엑폭시애자(동봉) | C39: 개 | D39: 0 | F39: 0 | H39: 0 | J39: 6000 | K39: 1199 | L39: 6000 | M39: 1274 | N39: =SMALL(D39:L39,COUNTIF(D39:L39,0)+1) -> 6000
A40: 피뢰도선 지지금구 | B40: 폴리카본(JSP-100) | C40: 개 | D40: 0 | F40: 0 | H40: 0 | J40: 4000 | K40: 1199 | L40: 4000 | M40: 1274 | N40: =SMALL(D40:L40,COUNTIF(D40:L40,0)+1) -> 4000
...

Sheet 9.전기(분전반)
A1: 단 가 대 비 표 | R1: 만든이:나라기술 정진붕
A2: 2026년 상반기 충남교육청 건설공사 일위대가(전기, 통신, 전기소방)
A3: 품 명 | B3: 규 격 | C3: 단위 | D3: 재 료 비 | O3: 번 호 | P3: 비 고
D4: 조달청가격 | E4: PAGE | F4: 거래가격 | G4: PAGE | H4: 유통물가 | I4: PAGE | J4: 물가자료 | K4: PAGE | L4: 물가정보 | M4: PAGE | N4: 적용단가
A5: 누전 차단기 | B5: 2P 30AF 2.5KA(미니) | C5: 개 | D5: 0 | F5: 15800 | G5: 1065 | H5: 15800 | I5: 901 | J5: 15600 | K5: 1162 | L5: 18000 | M5: 1236 | N5: =SMALL(D5:L5,COUNTIF(D5:L5,0)+1) -> 15600
A6: 누전 차단기 | B6: 2P 30AF 2.5KA(분전반용) | C6: 개 | D6: 0 | F6: 16100 | G6: 1065 | H6: 16100 | I6: 901 | J6: 16700 | K6: 1162 | L6: 16400 | M6: 1236 | N6: =SMALL(D6:L6,COUNTIF(D6:L6,0)+1) -> 16100
A7: 누전 차단기 | B7: 2P 30AF 5KA | C7: 개 | D7: 0 | F7: 43800 | G7: 1065 | H7: 47700 | I7: 901 | J7: 45500 | K7: 1161 | L7: 45500 | M7: 1236 | N7: =SMALL(D7:L7,COUNTIF(D7:L7,0)+1) -> 43800
A8: 누전 차단기 | B8: 2P 50AF 5KA | C8: 개 | D8: 0 | F8: 47200 | G8: 1065 | H8: 51400 | I8: 901 | J8: 48900 | K8: 1161 | L8: 48900 | M8: 1236 | N8: =SMALL(D8:L8,COUNTIF(D8:L8,0)+1) -> 47200
A9: 누전 차단기 | B9: 3P 30AF 14KA | C9: 개 | D9: 0 | F9: 95800 | G9: 1065 | H9: 94300 | I9: 901 | J9: 89800 | K9: 1162 | L9: 52600 | M9: 1236 | N9: =SMALL(D9:L9,COUNTIF(D9:L9,0)+1) -> 52600
A10: 누전 차단기 | B10: 3P 50AF 18KA | C10: 개 | D10: 0 | F10: 95800 | G10: 1065 | H10: 104300 | I10: 901 | J10: 86000 | K10: 1162 | L10: 99300 | M10: 1236 | N10: =SMALL(D10:L10,COUNTIF(D10:L10,0)+1) -> 86000
A11: 누전 차단기 | B11: 3P 60AF 18KA | C11: 개 | D11: 0 | F11: 101400 | G11: 1065 | H11: 110400 | I11: 901 | J11: 93000 | K11: 1162 | L11: 105200 | M11: 1236 | N11: =SMALL(D11:L11,COUNTIF(D11:L11,0)+1) -> 93000
A12: 누전 차단기 | B12: 3P 125AF 37KA | C12: 개 | D12: 0 | F12: 192300 | G12: 1065 | H12: 209400 | I12: 901 | J12: 199500 | K12: 1162 | L12: 0 | N12: =SMALL(D12:L12,COUNTIF(D12:L12,0)+1) -> 192300
A13: 누전 차단기 | B13: 3P 250AF 37KA | C13: 개 | D13: 0 | F13: 340100 | G13: 1065 | H13: 370300 | I13: 901 | J13: 352700 | K13: 1162 | L13: 352700 | M13: 1236 | N13: =SMALL(D13:L13,COUNTIF(D13:L13,0)+1) -> 340100
A14: 누전 차단기 | B14: 3P 400AF 50KA | C14: 개 | D14: 0 | F14: 614100 | G14: 1065 | H14: 668700 | I14: 901 | J14: 636800 | K14: 1162 | L14: 636800 | M14: 1236 | N14: =SMALL(D14:L14,COUNTIF(D14:L14,0)+1) -> 614100
A15: 누전 차단기 | B15: 3P 630AF 50KA | C15: 개 | D15: 0 | F15: 1185900 | G15: 1065 | H15: 1291400 | I15: 901 | J15: 1229900 | K15: 1162 | L15: 1229900 | M15: 1236 | N15: =SMALL(D15:L15,COUNTIF(D15:L15,0)+1) -> 1185900
A16: 누전 차단기 | B16: 4P 30AF 14KA | C16: 개 | D16: 0 | F16: 118900 | G16: 1065 | H16: 129500 | I16: 901 | J16: 123300 | K16: 1162 | L16: 123300 | M16: 1236 | N16: =SMALL(D16:L16,COUNTIF(D16:L16,0)+1) -> 118900
A17: 누전 차단기 | B17: 4P 50AF 18KA | C17: 개 | D17: 0 | F17: 154900 | G17: 1065 | H17: 168600 | I17: 901 | J17: 160660 | K17: 1162 | L17: 160600 | M17: 1236 | N17: =SMALL(D17:L17,COUNTIF(D17:L17,0)+1) -> 154900
A18: 누전 차단기 | B18: 4P 125AF 37KA | C18: 개 | D18: 0 | F18: 231000 | G18: 1065 | H18: 251500 | I18: 901 | J18: 239600 | K18: 1162 | L18: 239600 | M18: 1236 | N18: =SMALL(D18:L18,COUNTIF(D18:L18,0)+1) -> 231000
A19: 누전 차단기 | B19: 4P 250AF 37KA | C19: 개 | D19: 0 | F19: 479000 | G19: 1065 | H19: 521600 | I19: 901 | J19: 496700 | K19: 1162 | L19: 496700 | M19: 1236 | N19: =SMALL(D19:L19,COUNTIF(D19:L19,0)+1) -> 479000
A20: 누전 차단기 | B20: 4P 400AF 50KA | C20: 개 | D20: 0 | F20: 822200 | G20: 1065 | H20: 1007100 | I20: 901 | J20: 841200 | K20: 1162 | L20: 841200 | M20: 1236 | N20: =SMALL(D20:L20,COUNTIF(D20:L20,0)+1) -> 822200
