Workbook

Sheet 총공사비
A1: 화성 청원지구 — 총공사비 (도급액·간접비 포함)
A3: 【1. 내역서별 요약】
A4: ① 직접공사비 (재·노·경)
A5: 구분 | B5: No | C5: 내역서 | D5: 재료비 | E5: 노무비 | F5: 경비 | G5: 직접공사비 | H5: 비고
A6: 회전교차로 | B6: 05 | C6: 05 회전교차로 | D6: 115856514 | E6: 519405822 | F6: 35734886 | G6: 670997222
A7: 진입도로 | B7: 04 | C7: 04 진입도로 | D7: 84435224 | E7: 401743339 | F7: 46174874 | G7: 532353437
A8: 토목(조경) | B8: 01 | C8: 01 토목 | D8: 381224824 | E8: 1741229079 | F8: 347578180 | G8: 2470032083
A9: 토목(조경) | B9: 01 | C9: 01 조경 | D9: 600710000 | E9: 386951000 | F9: 30172000 | G9: 1017833000 | H9: 푸른조경 내역(순공사비)·토목요율
A10: 지구단위 | B10: 06 | C10: 06 개발행위 | D10: 341175859 | E10: 1079591249 | F10: 302642322 | G10: 1723409430
A11: 폐기물 | B11: 07 | C11: 07 건설폐기물 | D11: 0 | E11: 0 | F11: 31458312 | G11: 31458312
A12: 합계 | C12: ★ 01·04~07 | D12: 1523402421 | E12: 4128920489 | F12: 793760574 | G12: 6446083484 | H12: 구분 시트 ★소계 합
A14: ② 간접비·도급액
A15: 항목 | B15: 05 회전교차로 | C15: 04 진입도로 | D15: 01 토목 | E15: 01 조경 | F15: 06 개발행위 | G15: 07 건설폐기물 | H15: 합계
A16: 간접노무비 | B16: 102322947 | C16: 79143438 | D16: 343022129 | E16: 76229347 | F16: 212679476 | G16: 0 | H16: =B16+C16+D16+E16+F16+G16
A17: 순공사원가 | B17: 926519661 | C17: 730139087 | D17: 3321061676 | E17: 1264276727 | F17: 2264694918 | G17: 31867270 | H17: =B17+C17+D17+E17+F17+G17
A18: 일반관리비 | B18: 74121573 | C18: 58411127 | D18: 265684934 | E18: 101142138 | F18: 181175593 | G18: 2549382 | H18: =B18+C18+D18+E18+F18+G18
A19: 이윤 | B19: 132717708 | C19: 105617249 | D19: 480828268 | E19: 114706330 | F19: 315704198 | G19: 5162498 | H19: =B19+C19+D19+E19+F19+G19
A20: 부가세 | B20: 118315823 | C20: 93353978 | D20: 424856086 | E20: 155020931 | F20: 288602477 | G20: 4158539 | H20: =B20+C20+D20+E20+F20+G20
A21: 도급액 | B21: 1301474051 | C21: 1026893755 | D21: 4673416942 | E21: 1705230242 | F21: 3174627245 | G21: 45743924 | H21: =B21+C21+D21+E21+F21+G21
A22: 배율 | B22: =IF(G6=0,0,B21/G6) | C22: =IF(G7=0,0,C21/G7) | D22: =IF(G8=0,0,D21/G8) | E22: =IF(G9=0,0,E21/G9) | F22: =IF(G10=0,0,F21/G10) | G22: =IF(G11=0,0,G21/G11) | H22: =IF(G12=0,0,H21/G12)
A24: 【2. 간접비·원가계산 (내역서별 합산)】
A25: 단계 | B25: 항목 | C25: 금액(원) | D25: 산식 | F25: 비고
A26: ① | B26: 직접공사비 | C26: 6446083486 | D26: 재료비+직접노무비+직접경비 | F26: 01·04~07 내역서별 합산
B27: · 재료비 | C27: 1523402421
B28: · 직접노무비 | C28: 4128920489
B29: · 직접경비 | C29: 793760574
A30: ② | B30: 간접노무비 | C30: 813397337 | D30: 직접노무비 × 19.7% | F30: 01·04~07 내역서별 합산
B31: 노무비계(직접+간접) | C31: 4942317826 | F31: 01·04~07 내역서별 합산
A32: ③ | B32: 산재보험료 | C32: 175946514 | D32: 노무비계 × 3.56% | F32: 01·04~07 내역서별 합산
A33: ③ | B33: 고용보험료 | C33: 49917410 | D33: 노무비계 × 1.01% | F33: 01·04~07 내역서별 합산
A34: ③ | B34: 국민건강보험료 | C34: 148434690 | D34: 직접노무비 × 3.595% | F34: 01·04~07 내역서별 합산
A35: ③ | B35: 국민연금보험료 | C35: 196123723 | D35: 직접노무비 × 4.75% | F35: 01·04~07 내역서별 합산
A36: ③ | B36: 노인장기요양보험료 | C36: 19504319 | D36: 건강보험료 × 13.14% | F36: 01·04~07 내역서별 합산
A37: ③ | B37: 산업안전보건관리비 | C37: 159218077 | D37: (재료비+직접노무비) × 2.53% + 기초액 3,300,000원 | F37: 01·04~07 내역서별 합산
A38: ③ | B38: 기타경비 | C38: 446134697 | D38: (재료비+노무비계) × 6.9% | F38: 01·04~07 내역서별 합산
A39: ③ | B39: 건설기계대여대금 지급보증 | C39: 25784334 | D39: 직접공사비 × 0.4% (법정부담금) | F39: 01·04~07 내역서별 합산
A40: ③ | B40: 환경보전비 | C40: 58014752 | D40: 직접공사비 × 0.9% | F40: 01·04~07 내역서별 합산
B41: 경비계(직접경비+산출경비) | C41: 2072839091 | F41: 01·04~07 내역서별 합산
A42: ⑥ | B42: 순공사원가 | C42: 8538559339 | D42: 재료비+노무비계+경비계 | F42: 01·04~07 내역서별 합산
A43: ⑦ | B43: 일반관리비 | C43: 683084747 | D43: 순공사원가 × 8% (추정가격 구간) | F43: 01·04~07 내역서별 합산
...

Sheet 내역집계
A1: 화성 청원지구 — 내역 집계 (01·04~07, 02 전기 제외)
A3: 구분 | B3: No | C3: 내역서 | D3: 공종 | E3: 매칭 | F3: 전체 | G3: 매칭률 | H3: 재료비 | I3: 노무비 | J3: 경비 | K3: 합계 | L3: 합계(억)
A4: 회전교차로 | B4: 05 | C4: 05 회전교차로 | D4: 9. 산업안전보건관리비 | E4: 0 | F4: 1 | G4: 0 | H4: 0 | I4: 0 | J4: 0 | K4: 0 | L4: 0
A5: 회전교차로 | B5: 05 | C5: 05 회전교차로 | D5: 1. 토 공 | E5: 21 | F5: 21 | G5: 1 | H5: 10163806 | I5: 30847384 | J5: 12145548 | K5: 53156738 | L5: 0.53156738
A6: 회전교차로 | B6: 05 | C6: 05 회전교차로 | D6: 2. 우 수 공 | E6: 38 | F6: 42 | G6: 0.9047619 | H6: 10110092 | I6: 57050724 | J6: 5814386 | K6: 72975202 | L6: 0.72975202
A7: 회전교차로 | B7: 05 | C7: 05 회전교차로 | D7: 3. 포 장 공 | E7: 46 | F7: 53 | G7: 0.86792453 | H7: 25531309 | I7: 181022224 | J7: 14034229 | K7: 220587762 | L7: 2.2058776
A8: 회전교차로 | B8: 05 | C8: 05 회전교차로 | D8: 4. 구조물공 | E8: 21 | F8: 23 | G8: 0.91304348 | H8: 70040561 | I8: 2.4970535e+08 | J8: 3732883 | K8: 3.2347879e+08 | L8: 3.2347879
A9: 회전교차로 | B9: 05 | C9: 05 회전교차로 | D9: 5. 부 대 공 | E9: 3 | F9: 3 | G9: 1 | H9: 10747 | I9: 780140 | J9: 7840 | K9: 798727 | L9: 0.00798727
A10: 회전교차로 | B10: 05 | C10: 05 회전교차로 | D10: 가). 중기운반비 | E10: 0 | F10: 3 | G10: 0 | H10: 0 | I10: 0 | J10: 0 | K10: 0 | L10: 0
A11: 회전교차로 | B11: 05 | C11: 05 회전교차로 | D11: ▣ 품질관리비 | E11: 0 | F11: 1 | G11: 0 | H11: 0 | I11: 0 | J11: 0 | K11: 0 | L11: 0
A12: 회전교차로 | B12: 05 | C12: 05 회전교차로 | D12: ★ 05 회전교차로 소계 | E12: =회전교차로!D12 | F12: =회전교차로!E12 | G12: =회전교차로!F12 | H12: =회전교차로!G12 | I12: =회전교차로!H12 | J12: =회전교차로!I12 | K12: =회전교차로!J12 | L12: =회전교차로!K12
A13: 회전교차로 | C13: 회전교차로 | D13: ★ 회전교차로 소계 | E13: =회전교차로!D13 | F13: =회전교차로!E13 | G13: =회전교차로!F13 | H13: =회전교차로!G13 | I13: =회전교차로!H13 | J13: =회전교차로!I13 | K13: =회전교차로!J13 | L13: =회전교차로!K13
A14: 진입도로 | B14: 04 | C14: 04 진입도로 | D14: 9. 산업안전보건관리비 | E14: 0 | F14: 1 | G14: 0 | H14: 0 | I14: 0 | J14: 0 | K14: 0 | L14: 0
A15: 진입도로 | B15: 04 | C15: 04 진입도로 | D15: 1. 토 공 | E15: 19 | F15: 19 | G15: 1 | H15: 20465208 | I15: 65102573 | J15: 25173284 | K15: 110741065 | L15: 1.1074107
A16: 진입도로 | B16: 04 | C16: 04 진입도로 | D16: 2. 우 수 공 | E16: 26 | F16: 28 | G16: 0.92857143 | H16: 11851285 | I16: 79191767 | J16: 8862011 | K16: 99905063 | L16: 0.99905063
A17: 진입도로 | B17: 04 | C17: 04 진입도로 | D17: 3. 상 수 공 | E17: 17 | F17: 19 | G17: 0.89473684 | H17: 885328 | I17: 20516305 | J17: 467412 | K17: 21869045 | L17: 0.21869045
A18: 진입도로 | B18: 04 | C18: 04 진입도로 | D18: 4. 포 장 공 | E18: 50 | F18: 56 | G18: 0.89285714 | H18: 16880940 | I18: 108358542 | J18: 9375195 | K18: 134614677 | L18: 1.3461468
A19: 진입도로 | B19: 04 | C19: 04 진입도로 | D19: 5. 구조물공 | E19: 20 | F19: 22 | G19: 0.90909091 | H19: 34341716 | I19: 1.2779401e+08 | J19: 2289132 | K19: 1.6442486e+08 | L19: 1.6442486
A20: 진입도로 | B20: 04 | C20: 04 진입도로 | D20: 6. 부 대 공 | E20: 3 | F20: 3 | G20: 1 | H20: 10747 | I20: 780140 | J20: 7840 | K20: 798727 | L20: 0.00798727
A21: 진입도로 | B21: 04 | C21: 04 진입도로 | D21: 가). 중기운반비 | E21: 0 | F21: 3 | G21: 0 | H21: 0 | I21: 0 | J21: 0 | K21: 0 | L21: 0
A22: 진입도로 | B22: 04 | C22: 04 진입도로 | D22: ▣ 품질관리비 | E22: 0 | F22: 1 | G22: 0 | H22: 0 | I22: 0 | J22: 0 | K22: 0 | L22: 0
A23: 진입도로 | B23: 04 | C23: 04 진입도로 | D23: ★ 04 진입도로 소계 | E23: =진입도로!D13 | F23: =진입도로!E13 | G23: =진입도로!F13 | H23: =진입도로!G13 | I23: =진입도로!H13 | J23: =진입도로!I13 | K23: =진입도로!J13 | L23: =진입도로!K13
A24: 진입도로 | C24: 진입도로 | D24: ★ 진입도로 소계 | E24: =진입도로!D14 | F24: =진입도로!E14 | G24: =진입도로!F14 | H24: =진입도로!G14 | I24: =진입도로!H14 | J24: =진입도로!I14 | K24: =진입도로!J14 | L24: =진입도로!K14
A25: 토목(조경) | B25: 01 | C25: 01 토목 | D25: 1. 토 공 | E25: 41 | F25: 45 | G25: 0.91111111 | H25: 1.938648e+08 | I25: 3.7583083e+08 | J25: 248626066 | K25: 8.183217e+08 | L25: 8.183217
A26: 토목(조경) | B26: 01 | C26: 01 토목 | D26: 2. 우 수 공 | E26: 81 | F26: 99 | G26: 0.81818182 | H26: 45773360 | I26: 4.1265129e+08 | J26: 30187164 | K26: 4.8861181e+08 | L26: 4.8861181
A27: 토목(조경) | B27: 01 | C27: 01 토목 | D27: 3. 오 수 공 | E27: 36 | F27: 44 | G27: 0.81818182 | H27: 8139274.2 | I27: 91589702 | J27: 6281483 | K27: 1.0601046e+08 | L27: 1.0601046
A28: 토목(조경) | B28: 01 | C28: 01 토목 | D28: 4. 상 수 공 | E28: 62 | F28: 86 | G28: 0.72093023 | H28: 11736539 | I28: 84912162 | J28: 4722073 | K28: 101370774 | L28: 1.0137077
A29: 토목(조경) | B29: 01 | C29: 01 토목 | D29: 5. 포 장 공 | E29: 68 | F29: 76 | G29: 0.89473684 | H29: 55159585 | I29: 294369653 | J29: 23035558 | K29: 372564796 | L29: 3.725648
A30: 토목(조경) | B30: 01 | C30: 01 토목 | D30: 6. 구조물공 | E30: 39 | F30: 43 | G30: 0.90697674 | H30: 27584724 | I30: 2.1541458e+08 | J30: 17151782 | K30: 2.6015109e+08 | L30: 2.6015109
A31: 토목(조경) | B31: 01 | C31: 01 토목 | D31: 7. 부 대 공 | E31: 27 | F31: 36 | G31: 0.75 | H31: 15032685 | I31: 173478672 | J31: 7842946 | K31: 196354303 | L31: 1.963543
A32: 토목(조경) | B32: 01 | C32: 01 토목 | D32: 8. 하수처리장 | E32: 43 | F32: 53 | G32: 0.81132075 | H32: 14684153 | I32: 65843674 | J32: 1789336 | K32: 82317163 | L32: 0.82317163
A33: 토목(조경) | B33: 01 | C33: 01 토목 | D33: 9. 지하저류조 | E33: 7 | F33: 9 | G33: 0.77777778 | H33: 9249700 | I33: 27138515 | J33: 7941772 | K33: 44329987 | L33: 0.44329987
A34: 토목(조경) | B34: 01 | C34: 01 토목 | D34: ▣ 품질관리비 | E34: 0 | F34: 2 | G34: 0 | H34: 0 | I34: 0 | J34: 0 | K34: 0 | L34: 0
A35: 토목(조경) | B35: 01 | C35: 01 토목 | D35: ★ 01 토목 소계 | E35: ='토목(조경)'!D14 | F35: ='토목(조경)'!E14 | G35: ='토목(조경)'!F14 | H35: ='토목(조경)'!G14 | I35: ='토목(조경)'!H14 | J35: ='토목(조경)'!I14 | K35: ='토목(조경)'!J14 | L35: ='토목(조경)'!K14
A36: 토목(조경) | B36: 01 | C36: 01 조경 | D36: 10. 조 경 공 | E36: 80 | F36: 80 | G36: 1 | H36: 600710000 | I36: 386951000 | J36: 30172000 | K36: 1017833000 | L36: 10.17833
A37: 토목(조경) | B37: 01 | C37: 01 조경 | D37: ★ 01 조경 소계 | E37: ='토목(조경)'!D16 | F37: ='토목(조경)'!E16 | G37: ='토목(조경)'!F16 | H37: ='토목(조경)'!G16 | I37: ='토목(조경)'!H16 | J37: ='토목(조경)'!I16 | K37: ='토목(조경)'!J16 | L37: ='토목(조경)'!K16
A38: 토목(조경) | C38: 토목(조경) | D38: ★ 토목(조경) 소계 | E38: ='토목(조경)'!D17 | F38: ='토목(조경)'!E17 | G38: ='토목(조경)'!F17 | H38: ='토목(조경)'!G17 | I38: ='토목(조경)'!H17 | J38: ='토목(조경)'!I17 | K38: ='토목(조경)'!J17 | L38: ='토목(조경)'!K17
A39: 지구단위 | B39: 06 | C39: 06 개발행위 | D39: 1. 토 공 | E39: 9 | F39: 9 | G39: 1 | H39: 329303137 | I39: 633526312 | J39: 288990853 | K39: 1251820302 | L39: 12.518203
A40: 지구단위 | B40: 06 | C40: 06 개발행위 | D40: 2. A1 | E40: 14 | F40: 14 | G40: 1 | H40: 1322809 | I40: 36399255 | J40: 1512006 | K40: 39234070 | L40: 0.3923407
A41: 지구단위 | B41: 06 | C41: 06 개발행위 | D41: 3. A2 | E41: 17 | F41: 17 | G41: 1 | H41: 2352580 | I41: 88315220 | J41: 2468726 | K41: 93136526 | L41: 0.93136526
...

Sheet 회전교차로
A1: 화성 청원지구 — 회전교차로
A3: No | B3: 내역서 | C3: 공종 | D3: 매칭 | E3: 전체 | F3: 매칭률 | G3: 재료비 | H3: 노무비 | I3: 경비 | J3: 합계 | K3: 합계(억)
A4: 05 | B4: 05 회전교차로 | C4: 9. 산업안전보건관리비 | D4: 0 | E4: 1 | F4: 0 | G4: 0 | H4: 0 | I4: 0 | J4: 0 | K4: 0
A5: 05 | B5: 05 회전교차로 | C5: 1. 토 공 | D5: 21 | E5: 21 | F5: 1 | G5: 10163806 | H5: 30847384 | I5: 12145548 | J5: 53156738 | K5: 0.53156738
A6: 05 | B6: 05 회전교차로 | C6: 2. 우 수 공 | D6: 38 | E6: 42 | F6: 0.9047619 | G6: 10110092 | H6: 57050724 | I6: 5814386 | J6: 72975202 | K6: 0.72975202
A7: 05 | B7: 05 회전교차로 | C7: 3. 포 장 공 | D7: 46 | E7: 53 | F7: 0.86792453 | G7: 25531309 | H7: 181022224 | I7: 14034229 | J7: 220587762 | K7: 2.2058776
A8: 05 | B8: 05 회전교차로 | C8: 4. 구조물공 | D8: 21 | E8: 23 | F8: 0.91304348 | G8: 70040561 | H8: 2.4970535e+08 | I8: 3732883 | J8: 3.2347879e+08 | K8: 3.2347879
A9: 05 | B9: 05 회전교차로 | C9: 5. 부 대 공 | D9: 3 | E9: 3 | F9: 1 | G9: 10747 | H9: 780140 | I9: 7840 | J9: 798727 | K9: 0.00798727
A10: 05 | B10: 05 회전교차로 | C10: 가). 중기운반비 | D10: 0 | E10: 3 | F10: 0 | G10: 0 | H10: 0 | I10: 0 | J10: 0 | K10: 0
A11: 05 | B11: 05 회전교차로 | C11: ▣ 품질관리비 | D11: 0 | E11: 1 | F11: 0 | G11: 0 | H11: 0 | I11: 0 | J11: 0 | K11: 0
A12: 05 | B12: 05 회전교차로 | C12: ★ 05 회전교차로 소계 | D12: 129 | E12: 147 | F12: 0.87755102 | G12: 1.1585651e+08 | H12: 5.1940582e+08 | I12: 35734886 | J12: 6.7099722e+08 | K12: 6.7099722
B13: 회전교차로 | C13: ★ 회전교차로 합계 | D13: 129 | E13: 147 | F13: 0.87755102 | G13: 1.1585651e+08 | H13: 5.1940582e+08 | I13: 35734886 | J13: 6.7099722e+08 | K13: 6.7099722
A15: ◆ 회전교차로 — 내역 일괄
A17: 내역서 | B17: 공종 | C17: No | D17: 공종명 | E17: 규격 | F17: 수량 | G17: 단위 | H17: 재료단가 | I17: 재료금액 | J17: 노무단가 | K17: 노무금액 | L17: 경비단가 | M17: 경비금액 | N17: 합계단가 | O17: 합계금액 | P17: 상태 | Q17: 비고
A18: 05 회전교차로 | B18: 9. 산업안전보건관리비 | C18: 1 | D18: 10. 안전관리비 | F18: 1 | G18: P.S | I18: =F18*H18 | K18: =F18*J18 | M18: =F18*L18 | N18: =H18+J18+L18 | O18: =I18+K18+M18 | P18: 미매칭 | Q18: 안전관리비
A19: 05 회전교차로 | B19: 9. 산업안전보건관리비 | D19: ★ 9. 산업안전보건관리비 소계 | I19: =SUM(I18:I18) | K19: =SUM(K18:K18) | M19: =SUM(M18:M18) | O19: =SUM(O18:O18) | Q19: 1건
A20: 05 회전교차로 | B20: 1. 토 공 | C20: 1 | D20: 1). 노상준비공 | E20: 깍기부 | F20: 3022 | G20: m2 | H20: 193 | I20: =F20*H20 | J20: 445 | K20: =F20*J20 | L20: 216 | M20: =F20*L20 | N20: =H20+J20+L20 | O20: =I20+K20+M20 | Q20: 1). 노상준비공
A21: 05 회전교차로 | B21: 1. 토 공 | C21: 2 | D21: 1). 법면보호공 | E21: 잔디붙임(줄떼) | F21: 245 | G21: ㎡ | H21: 0 | I21: =F21*H21 | J21: 4699 | K21: =F21*J21 | L21: 0 | M21: =F21*L21 | N21: =H21+J21+L21 | O21: =I21+K21+M21 | Q21: 잔디붙임(줄떼)
A22: 05 회전교차로 | B22: 1. 토 공 | C22: 3 | D22: 나). 흙깍기(토사) | E22: 굴삭기1.0㎥ | F22: 578 | G22: ㎥ | H22: 912 | I22: =F22*H22 | J22: 1951 | K22: =F22*J22 | L22: 685 | M22: =F22*L22 | N22: =H22+J22+L22 | O22: =I22+K22+M22 | Q22: 토사
A23: 05 회전교차로 | B23: 1. 토 공 | C23: 4 | D23: 1). 터파기(토사) | E23: TYPE-1, 굴착기1.0, 기계100% | F23: 2132 | G23: ㎥ | H23: 447 | I23: =F23*H23 | J23: 955 | K23: =F23*J23 | L23: 336 | M23: =F23*L23 | N23: =H23+J23+L23 | O23: =I23+K23+M23 | Q23: 토사
A24: 05 회전교차로 | B24: 1. 토 공 | C24: 5 | D24: 가). 흙쌓기 | E24: 노상, 두께20cm, 다짐도95%이상 | F24: 1216 | G24: ㎥ | H24: 887 | I24: =F24*H24 | J24: 2394 | K24: =F24*J24 | L24: 1107 | M24: =F24*L24 | N24: =H24+J24+L24 | O24: =I24+K24+M24 | Q24: 가). 흙쌓기
A25: 05 회전교차로 | B25: 1. 토 공 | C25: 6 | D25: 가). 흙쌓기 | E25: 노체, 두께30cm, 다짐도90%이상 | F25: 1406 | G25: ㎥ | H25: 594 | I25: =F25*H25 | J25: 1602 | K25: =F25*J25 | L25: 741 | M25: =F25*L25 | N25: =H25+J25+L25 | O25: =I25+K25+M25 | Q25: 가). 흙쌓기
A26: 05 회전교차로 | B26: 1. 토 공 | C26: 7 | D26: 가). 흙쌓기 | E26: 노체, 두께30cm, 다짐도90%이상 | F26: 1787 | G26: ㎥ | H26: 594 | I26: =F26*H26 | J26: 1602 | K26: =F26*J26 | L26: 741 | M26: =F26*L26 | N26: =H26+J26+L26 | O26: =I26+K26+M26 | Q26: 가). 흙쌓기
A27: 05 회전교차로 | B27: 1. 토 공 | C27: 8 | D27: 1). 층따기 | F27: 161 | G27: m3 | H27: 438 | I27: =F27*H27 | J27: 728 | K27: =F27*J27 | L27: 427 | M27: =F27*L27 | N27: =H27+J27+L27 | O27: =I27+K27+M27 | Q27: 1). 층따기
A28: 05 회전교차로 | B28: 1. 토 공 | C28: 9 | D28: 가). 토사 | F28: 2720 | G28: ㎥ | H28: 678 | I28: =F28*H28 | J28: 1818 | K28: =F28*J28 | L28: 909 | M28: =F28*L28 | N28: =H28+J28+L28 | O28: =I28+K28+M28 | Q28: 하천 CUA31704000S 치환토(되메우기·교체) — 현재 후보 유지·현장 흙질 확인
A29: 05 회전교차로 | B29: 1. 토 공 | C29: 10 | D29: 가). 흙운반(토사) | E29: 불도저 32톤, L=44.9m | F29: 206 | G29: ㎥ | H29: 906 | I29: =F29*H29 | J29: 1736 | K29: =F29*J29 | L29: 515 | M29: =F29*L29 | N29: =H29+J29+L29 | O29: =I29+K29+M29 | Q29: 토사
A30: 05 회전교차로 | B30: 1. 토 공 | C30: 11 | D30: 가). 흙 운반(토사)(지구내) | E30: 굴삭기1.0㎥+덤프24톤, L=0.076Km | F30: 136 | G30: ㎥ | H30: 873 | I30: =F30*H30 | J30: 1719 | K30: =F30*J30 | L30: 653 | M30: =F30*L30 | N30: =H30+J30+L30 | O30: =I30+K30+M30 | Q30: 토사
A31: 05 회전교차로 | B31: 1. 토 공 | C31: 12 | D31: 1). 목재규준틀 | E31: 비탈규준틀 | F31: 44 | G31: 개 | H31: 0 | I31: =F31*H31 | J31: 68074 | K31: =F31*J31 | L31: 0 | M31: =F31*L31 | N31: =H31+J31+L31 | O31: =I31+K31+M31 | Q31: 하천 CUA31301000S · 품셈 목재규준틀(비탈)
A32: 05 회전교차로 | B32: 1. 토 공 | C32: 13 | D32: 2). 목재규준틀 | E32: 수평규준틀 | F32: 4 | G32: 개 | H32: 0 | I32: =F32*H32 | J32: 90391 | K32: =F32*J32 | L32: 0 | M32: =F32*L32 | N32: =H32+J32+L32 | O32: =I32+K32+M32 | Q32: 하천 CUA31302000S · 품셈 목재규준틀(수평)
A33: 05 회전교차로 | B33: 1. 토 공 | C33: 14 | D33: 가). 구조물헐기(철근) | E33: 대형30CM미만 | F33: 13 | G33: ㎥ | H33: 18511 | I33: =F33*H33 | J33: 70869 | K33: =F33*J33 | L33: 33531 | M33: =F33*L33 | N33: =H33+J33+L33 | O33: =I33+K33+M33 | Q33: 철근
A34: 05 회전교차로 | B34: 1. 토 공 | C34: 15 | D34: 나). 구조물헐기(무근) | E34: 대형30CM미만 | F34: 72 | G34: ㎥ | H34: 5125 | I34: =F34*H34 | J34: 19126 | K34: =F34*J34 | L34: 8630 | M34: =F34*L34 | N34: =H34+J34+L34 | O34: =I34+K34+M34 | Q34: 무근
A35: 05 회전교차로 | B35: 1. 토 공 | C35: 16 | D35: 다). 포장절단/아스팔트 | F35: 30 | G35: m | H35: 1266 | I35: =F35*H35 | J35: 1229 | K35: =F35*J35 | L35: 122 | M35: =F35*L35 | N35: =H35+J35+L35 | O35: =I35+K35+M35 | Q35: 다). 포장절단/아스팔트
A36: 05 회전교차로 | B36: 1. 토 공 | C36: 17 | D36: 라). 포장절단/콘크리트 | F36: 17 | G36: m | H36: 1379 | I36: =F36*H36 | J36: 1386 | K36: =F36*J36 | L36: 124 | M36: =F36*L36 | N36: =H36+J36+L36 | O36: =I36+K36+M36 | Q36: 라). 포장절단/콘크리트
A37: 05 회전교차로 | B37: 1. 토 공 | C37: 18 | D37: 마). 아스팔트포장깨기 | E37: T=30cm 미만 | F37: 631 | G37: m3 | H37: 2730 | I37: =F37*H37 | J37: 7242 | K37: =F37*J37 | L37: 3955 | M37: =F37*L37 | N37: =H37+J37+L37 | O37: =I37+K37+M37 | Q37: 마). 아스팔트포장깨기
A38: 05 회전교차로 | B38: 1. 토 공 | C38: 19 | D38: 바). 콘크리트포장깨기 | E38: T=30cm 미만 | F38: 11 | G38: m3 | H38: 6259 | I38: =F38*H38 | J38: 18737 | K38: =F38*J38 | L38: 9072 | M38: =F38*L38 | N38: =H38+J38+L38 | O38: =I38+K38+M38 | Q38: 바). 콘크리트포장깨기
A39: 05 회전교차로 | B39: 1. 토 공 | C39: 20 | D39: 사). 가드레일철거 | E39: 설치품의 30% | F39: 249 | G39: m | H39: 111 | I39: =F39*H39 | J39: 1345 | K39: =F39*J39 | L39: 132 | M39: =F39*L39 | N39: =H39+J39+L39 | O39: =I39+K39+M39 | Q39: 내역 규격「설치품의 30%」· CTH80401010S 설치 5,292원/m × 30% = 1,588원/m · 설치 단가 대비 철거 관행
A40: 05 회전교차로 | B40: 1. 토 공 | C40: 21 | D40: 가). 폐기물상차 | E40: 굴삭기 0.7㎥ | F40: 728 | G40: ㎥ | H40: 570 | I40: =F40*H40 | J40: 936 | K40: =F40*J40 | L40: 331 | M40: =F40*L40 | N40: =H40+J40+L40 | O40: =I40+K40+M40 | Q40: 오매칭 CUS30201010S(가물막이 / 굴착,적사,운반) 제외 · 표준시장단가 CDS101201500 흙운반 직상차(덤프15t) — 굴삭기0.7㎥ 상차 공정 대용 · 운반·처리비 별도
A41: 05 회전교차로 | B41: 1. 토 공 | D41: ★ 1. 토 공 소계 | I41: =SUM(I20:I40) | K41: =SUM(K20:K40) | M41: =SUM(M20:M40) | O41: =SUM(O20:O40) | Q41: 21건
A42: 05 회전교차로 | B42: 2. 우 수 공 | C42: 1 | D42: (1). 터파기(토사) | E42: TYPE-1, 백호1.0, 기계100% | F42: 1711 | G42: ㎥ | H42: 301 | I42: =F42*H42 | J42: 4367 | K42: =F42*J42 | L42: 417 | M42: =F42*L42 | N42: =H42+J42+L42 | O42: =I42+K42+M42 | Q42: 1
A43: 05 회전교차로 | B43: 2. 우 수 공 | C43: 2 | D43: 가). 되메우기및다짐(토사) | E43: 백호0.7+플레이트콤펙터1.5ton | F43: 1504 | G43: ㎥ | H43: 1652 | I43: =F43*H43 | J43: 3924 | K43: =F43*J43 | L43: 1432 | M43: =F43*L43 | N43: =H43+J43+L43 | O43: =I43+K43+M43 | Q43: 가). 되메우기및다짐
...

Sheet 진입도로
A1: 화성 청원지구 — 진입도로
A3: No | B3: 내역서 | C3: 공종 | D3: 매칭 | E3: 전체 | F3: 매칭률 | G3: 재료비 | H3: 노무비 | I3: 경비 | J3: 합계 | K3: 합계(억)
A4: 04 | B4: 04 진입도로 | C4: 9. 산업안전보건관리비 | D4: 0 | E4: 1 | F4: 0 | G4: 0 | H4: 0 | I4: 0 | J4: 0 | K4: 0
A5: 04 | B5: 04 진입도로 | C5: 1. 토 공 | D5: 19 | E5: 19 | F5: 1 | G5: 20465208 | H5: 65102573 | I5: 25173284 | J5: 110741065 | K5: 1.1074107
A6: 04 | B6: 04 진입도로 | C6: 2. 우 수 공 | D6: 26 | E6: 28 | F6: 0.92857143 | G6: 11851285 | H6: 79191767 | I6: 8862011 | J6: 99905063 | K6: 0.99905063
A7: 04 | B7: 04 진입도로 | C7: 3. 상 수 공 | D7: 17 | E7: 19 | F7: 0.89473684 | G7: 885328 | H7: 20516305 | I7: 467412 | J7: 21869045 | K7: 0.21869045
A8: 04 | B8: 04 진입도로 | C8: 4. 포 장 공 | D8: 50 | E8: 56 | F8: 0.89285714 | G8: 16880940 | H8: 108358542 | I8: 9375195 | J8: 134614677 | K8: 1.3461468
A9: 04 | B9: 04 진입도로 | C9: 5. 구조물공 | D9: 20 | E9: 22 | F9: 0.90909091 | G9: 34341716 | H9: 1.2779401e+08 | I9: 2289132 | J9: 1.6442486e+08 | K9: 1.6442486
A10: 04 | B10: 04 진입도로 | C10: 6. 부 대 공 | D10: 3 | E10: 3 | F10: 1 | G10: 10747 | H10: 780140 | I10: 7840 | J10: 798727 | K10: 0.00798727
A11: 04 | B11: 04 진입도로 | C11: 가). 중기운반비 | D11: 0 | E11: 3 | F11: 0 | G11: 0 | H11: 0 | I11: 0 | J11: 0 | K11: 0
A12: 04 | B12: 04 진입도로 | C12: ▣ 품질관리비 | D12: 0 | E12: 1 | F12: 0 | G12: 0 | H12: 0 | I12: 0 | J12: 0 | K12: 0
A13: 04 | B13: 04 진입도로 | C13: ★ 04 진입도로 소계 | D13: 135 | E13: 152 | F13: 0.88815789 | G13: 84435224 | H13: 4.0174334e+08 | I13: 46174874 | J13: 5.3235344e+08 | K13: 5.3235344
B14: 진입도로 | C14: ★ 진입도로 합계 | D14: 135 | E14: 152 | F14: 0.88815789 | G14: 84435224 | H14: 4.0174334e+08 | I14: 46174874 | J14: 5.3235344e+08 | K14: 5.3235344
A16: ◆ 진입도로 — 내역 일괄
A18: 내역서 | B18: 공종 | C18: No | D18: 공종명 | E18: 규격 | F18: 수량 | G18: 단위 | H18: 재료단가 | I18: 재료금액 | J18: 노무단가 | K18: 노무금액 | L18: 경비단가 | M18: 경비금액 | N18: 합계단가 | O18: 합계금액 | P18: 상태 | Q18: 비고
A19: 04 진입도로 | B19: 9. 산업안전보건관리비 | C19: 1 | D19: 10. 안전관리비 | F19: 1 | G19: P.S | I19: =F19*H19 | K19: =F19*J19 | M19: =F19*L19 | N19: =H19+J19+L19 | O19: =I19+K19+M19 | P19: 미매칭 | Q19: 안전관리비
A20: 04 진입도로 | B20: 9. 산업안전보건관리비 | D20: ★ 9. 산업안전보건관리비 소계 | I20: =SUM(I19:I19) | K20: =SUM(K19:K19) | M20: =SUM(M19:M19) | O20: =SUM(O19:O19) | Q20: 1건
A21: 04 진입도로 | B21: 1. 토 공 | C21: 1 | D21: 1). 노상준비공 | E21: 깍기부 | F21: 1418 | G21: m2 | H21: 193 | I21: =F21*H21 | J21: 445 | K21: =F21*J21 | L21: 216 | M21: =F21*L21 | N21: =H21+J21+L21 | O21: =I21+K21+M21 | Q21: 1). 노상준비공
A22: 04 진입도로 | B22: 1. 토 공 | C22: 2 | D22: 1). 법면보호공 | E22: 잔디붙임(줄떼) | F22: 1640 | G22: ㎡ | H22: 0 | I22: =F22*H22 | J22: 4699 | K22: =F22*J22 | L22: 0 | M22: =F22*L22 | N22: =H22+J22+L22 | O22: =I22+K22+M22 | Q22: 잔디붙임(줄떼)
A23: 04 진입도로 | B23: 1. 토 공 | C23: 3 | D23: 나). 흙깍기(토사) | E23: 굴삭기1.0㎥ | F23: 725 | G23: ㎥ | H23: 912 | I23: =F23*H23 | J23: 1951 | K23: =F23*J23 | L23: 685 | M23: =F23*L23 | N23: =H23+J23+L23 | O23: =I23+K23+M23 | Q23: 토사
A24: 04 진입도로 | B24: 1. 토 공 | C24: 4 | D24: 1). 터파기(토사) | E24: TYPE-1, 굴착기1.0, 기계100% | F24: 142 | G24: ㎥ | H24: 447 | I24: =F24*H24 | J24: 955 | K24: =F24*J24 | L24: 336 | M24: =F24*L24 | N24: =H24+J24+L24 | O24: =I24+K24+M24 | Q24: 토사
A25: 04 진입도로 | B25: 1. 토 공 | C25: 5 | D25: 가). 흙쌓기 | E25: 노상, 두께20cm, 다짐도95%이상 | F25: 1710 | G25: ㎥ | H25: 887 | I25: =F25*H25 | J25: 2394 | K25: =F25*J25 | L25: 1107 | M25: =F25*L25 | N25: =H25+J25+L25 | O25: =I25+K25+M25 | Q25: 가). 흙쌓기
A26: 04 진입도로 | B26: 1. 토 공 | C26: 6 | D26: 가). 흙쌓기 | E26: 노체, 두께30cm, 다짐도90%이상 | F26: 25732 | G26: ㎥ | H26: 594 | I26: =F26*H26 | J26: 1602 | K26: =F26*J26 | L26: 741 | M26: =F26*L26 | N26: =H26+J26+L26 | O26: =I26+K26+M26 | Q26: 가). 흙쌓기
A27: 04 진입도로 | B27: 1. 토 공 | C27: 7 | D27: 가). 흙쌓기 | E27: 노체, 두께30cm, 다짐도90%이상 | F27: 34 | G27: ㎥ | H27: 594 | I27: =F27*H27 | J27: 1602 | K27: =F27*J27 | L27: 741 | M27: =F27*L27 | N27: =H27+J27+L27 | O27: =I27+K27+M27 | Q27: 가). 흙쌓기
A28: 04 진입도로 | B28: 1. 토 공 | C28: 8 | D28: 1). 층따기 | F28: 774 | G28: m3 | H28: 438 | I28: =F28*H28 | J28: 728 | K28: =F28*J28 | L28: 427 | M28: =F28*L28 | N28: =H28+J28+L28 | O28: =I28+K28+M28 | Q28: 1). 층따기
A29: 04 진입도로 | B29: 1. 토 공 | C29: 9 | D29: 가). 토사 | F29: 1266 | G29: ㎥ | H29: 678 | I29: =F29*H29 | J29: 1818 | K29: =F29*J29 | L29: 909 | M29: =F29*L29 | N29: =H29+J29+L29 | O29: =I29+K29+M29 | Q29: 하천 CUA31704000S 치환토(되메우기·교체) — 현재 후보 유지·현장 흙질 확인
A30: 04 진입도로 | B30: 1. 토 공 | C30: 10 | D30: 가). 흙운반(토사) | E30: 불도저 32톤, L=39.8m | F30: 185 | G30: ㎥ | H30: 906 | I30: =F30*H30 | J30: 1736 | K30: =F30*J30 | L30: 515 | M30: =F30*L30 | N30: =H30+J30+L30 | O30: =I30+K30+M30 | Q30: 토사
A31: 04 진입도로 | B31: 1. 토 공 | C31: 11 | D31: 가). 흙 운반(토사)(지구내) | E31: 굴삭기1.0㎥+덤프24톤, L=0.090Km | F31: 136 | G31: ㎥ | H31: 873 | I31: =F31*H31 | J31: 1719 | K31: =F31*J31 | L31: 653 | M31: =F31*L31 | N31: =H31+J31+L31 | O31: =I31+K31+M31 | Q31: 토사
A32: 04 진입도로 | B32: 1. 토 공 | C32: 12 | D32: 1). 목재규준틀 | E32: 비탈규준틀 | F32: 36 | G32: 개 | H32: 0 | I32: =F32*H32 | J32: 68074 | K32: =F32*J32 | L32: 0 | M32: =F32*L32 | N32: =H32+J32+L32 | O32: =I32+K32+M32 | Q32: 하천 CUA31301000S · 품셈 목재규준틀(비탈)
A33: 04 진입도로 | B33: 1. 토 공 | C33: 13 | D33: 2). 목재규준틀 | E33: 수평규준틀 | F33: 6 | G33: 개 | H33: 0 | I33: =F33*H33 | J33: 90391 | K33: =F33*J33 | L33: 0 | M33: =F33*L33 | N33: =H33+J33+L33 | O33: =I33+K33+M33 | Q33: 하천 CUA31302000S · 품셈 목재규준틀(수평)
A34: 04 진입도로 | B34: 1. 토 공 | C34: 14 | D34: 가). 구조물헐기(철근) | E34: 대형30CM미만 | F34: 20 | G34: ㎥ | H34: 18511 | I34: =F34*H34 | J34: 70869 | K34: =F34*J34 | L34: 33531 | M34: =F34*L34 | N34: =H34+J34+L34 | O34: =I34+K34+M34 | Q34: 철근
A35: 04 진입도로 | B35: 1. 토 공 | C35: 15 | D35: 나). 구조물헐기(무근) | E35: 대형30CM미만 | F35: 10 | G35: ㎥ | H35: 5125 | I35: =F35*H35 | J35: 19126 | K35: =F35*J35 | L35: 8630 | M35: =F35*L35 | N35: =H35+J35+L35 | O35: =I35+K35+M35 | Q35: 무근
A36: 04 진입도로 | B36: 1. 토 공 | C36: 16 | D36: 다). 포장절단/아스팔트 | F36: 30 | G36: m | H36: 1266 | I36: =F36*H36 | J36: 1229 | K36: =F36*J36 | L36: 122 | M36: =F36*L36 | N36: =H36+J36+L36 | O36: =I36+K36+M36 | Q36: 다). 포장절단/아스팔트
A37: 04 진입도로 | B37: 1. 토 공 | C37: 17 | D37: 라). 아스팔트포장깨기 | E37: T=30cm 미만 | F37: 162 | G37: m3 | H37: 2730 | I37: =F37*H37 | J37: 7242 | K37: =F37*J37 | L37: 3955 | M37: =F37*L37 | N37: =H37+J37+L37 | O37: =I37+K37+M37 | Q37: 라). 아스팔트포장깨기
A38: 04 진입도로 | B38: 1. 토 공 | C38: 18 | D38: 마). 콘크리트포장깨기 | E38: T=30cm 미만 | F38: 22 | G38: m3 | H38: 6259 | I38: =F38*H38 | J38: 18737 | K38: =F38*J38 | L38: 9072 | M38: =F38*L38 | N38: =H38+J38+L38 | O38: =I38+K38+M38 | Q38: 마). 콘크리트포장깨기
A39: 04 진입도로 | B39: 1. 토 공 | C39: 19 | D39: 가). 폐기물상차 | E39: 굴삭기 0.7㎥ | F39: 214 | G39: ㎥ | H39: 570 | I39: =F39*H39 | J39: 936 | K39: =F39*J39 | L39: 331 | M39: =F39*L39 | N39: =H39+J39+L39 | O39: =I39+K39+M39 | Q39: 오매칭 CUS30201010S(가물막이 / 굴착,적사,운반) 제외 · 표준시장단가 CDS101201500 흙운반 직상차(덤프15t) — 굴삭기0.7㎥ 상차 공정 대용 · 운반·처리비 별도
A40: 04 진입도로 | B40: 1. 토 공 | D40: ★ 1. 토 공 소계 | I40: =SUM(I21:I39) | K40: =SUM(K21:K39) | M40: =SUM(M21:M39) | O40: =SUM(O21:O39) | Q40: 19건
A41: 04 진입도로 | B41: 2. 우 수 공 | C41: 1 | D41: (1). 터파기(토사) | E41: TYPE-1, 백호1.0, 기계100% | F41: 2694 | G41: ㎥ | H41: 301 | I41: =F41*H41 | J41: 4367 | K41: =F41*J41 | L41: 417 | M41: =F41*L41 | N41: =H41+J41+L41 | O41: =I41+K41+M41 | Q41: 1
A42: 04 진입도로 | B42: 2. 우 수 공 | C42: 2 | D42: 가). 되메우기및다짐(토사) | E42: 백호0.7+플레이트콤펙터1.5ton | F42: 2103 | G42: ㎥ | H42: 1652 | I42: =F42*H42 | J42: 3924 | K42: =F42*J42 | L42: 1432 | M42: =F42*L42 | N42: =H42+J42+L42 | O42: =I42+K42+M42 | Q42: 가). 되메우기및다짐
A43: 04 진입도로 | B43: 2. 우 수 공 | C43: 3 | D43: 가). 잔토처리(토사) | E43: 기계 | F43: 591 | G43: ㎥ | H43: 447 | I43: =F43*H43 | J43: 955 | K43: =F43*J43 | L43: 336 | M43: =F43*L43 | N43: =H43+J43+L43 | O43: =I43+K43+M43 | Q43: 기계
...

Sheet 토목(조경)
A1: 화성 청원지구 — 토목(조경)
A3: No | B3: 내역서 | C3: 공종 | D3: 매칭 | E3: 전체 | F3: 매칭률 | G3: 재료비 | H3: 노무비 | I3: 경비 | J3: 합계 | K3: 합계(억)
A4: 01 | B4: 01 토목 | C4: 1. 토 공 | D4: 41 | E4: 45 | F4: 0.91111111 | G4: 1.938648e+08 | H4: 3.7583083e+08 | I4: 248626066 | J4: 8.183217e+08 | K4: 8.183217
A5: 01 | B5: 01 토목 | C5: 2. 우 수 공 | D5: 81 | E5: 99 | F5: 0.81818182 | G5: 45773360 | H5: 4.1265129e+08 | I5: 30187164 | J5: 4.8861181e+08 | K5: 4.8861181
A6: 01 | B6: 01 토목 | C6: 3. 오 수 공 | D6: 36 | E6: 44 | F6: 0.81818182 | G6: 8139274.2 | H6: 91589702 | I6: 6281483 | J6: 1.0601046e+08 | K6: 1.0601046
A7: 01 | B7: 01 토목 | C7: 4. 상 수 공 | D7: 62 | E7: 86 | F7: 0.72093023 | G7: 11736539 | H7: 84912162 | I7: 4722073 | J7: 101370774 | K7: 1.0137077
A8: 01 | B8: 01 토목 | C8: 5. 포 장 공 | D8: 68 | E8: 76 | F8: 0.89473684 | G8: 55159585 | H8: 294369653 | I8: 23035558 | J8: 372564796 | K8: 3.725648
A9: 01 | B9: 01 토목 | C9: 6. 구조물공 | D9: 39 | E9: 43 | F9: 0.90697674 | G9: 27584724 | H9: 2.1541458e+08 | I9: 17151782 | J9: 2.6015109e+08 | K9: 2.6015109
A10: 01 | B10: 01 토목 | C10: 7. 부 대 공 | D10: 27 | E10: 36 | F10: 0.75 | G10: 15032685 | H10: 173478672 | I10: 7842946 | J10: 196354303 | K10: 1.963543
A11: 01 | B11: 01 토목 | C11: 8. 하수처리장 | D11: 43 | E11: 53 | F11: 0.81132075 | G11: 14684153 | H11: 65843674 | I11: 1789336 | J11: 82317163 | K11: 0.82317163
A12: 01 | B12: 01 토목 | C12: 9. 지하저류조 | D12: 7 | E12: 9 | F12: 0.77777778 | G12: 9249700 | H12: 27138515 | I12: 7941772 | J12: 44329987 | K12: 0.44329987
A13: 01 | B13: 01 토목 | C13: ▣ 품질관리비 | D13: 0 | E13: 2 | F13: 0 | G13: 0 | H13: 0 | I13: 0 | J13: 0 | K13: 0
A14: 01 | B14: 01 토목 | C14: ★ 01 토목 소계 | D14: 404 | E14: 493 | F14: 0.81947262 | G14: 3.8122482e+08 | H14: 1.7412291e+09 | I14: 3.4757818e+08 | J14: 2.4700321e+09 | K14: 24.700321
A15: 01 | B15: 01 조경 | C15: 10. 조 경 공 | D15: 80 | E15: 80 | F15: 1 | G15: 600710000 | H15: 386951000 | I15: 30172000 | J15: 1017833000 | K15: 10.17833
A16: 01 | B16: 01 조경 | C16: ★ 01 조경 소계 | D16: 80 | E16: 80 | F16: 1 | G16: 600710000 | H16: 386951000 | I16: 30172000 | J16: 1017833000 | K16: 10.17833
B17: 토목(조경) | C17: ★ 토목(조경) 합계 | D17: 484 | E17: 573 | F17: 0.84467714 | G17: 9.8193482e+08 | H17: 2.1281801e+09 | I17: 3.7775018e+08 | J17: 3.4878651e+09 | K17: 34.878651
A19: ◆ 토목(조경) — 내역 일괄
A21: 내역서 | B21: 공종 | C21: No | D21: 공종명 | E21: 규격 | F21: 수량 | G21: 단위 | H21: 재료단가 | I21: 재료금액 | J21: 노무단가 | K21: 노무금액 | L21: 경비단가 | M21: 경비금액 | N21: 합계단가 | O21: 합계금액 | P21: 상태 | Q21: 비고
A22: 01 토목 | B22: 1. 토 공 | C22: 1 | D22: 가). 벌목 | F22: 22891 | G22: ㎡ | H22: 116 | I22: =F22*H22 | J22: 619 | K22: =F22*J22 | L22: 59 | M22: =F22*L22 | N22: =H22+J22+L22 | O22: =I22+K22+M22 | P22: 가영현 | Q22: 벌목
A23: 01 토목 | B23: 1. 토 공 | C23: 2 | D23: 나). 벌개제근 | F23: 22891 | G23: ㎡ | H23: 450 | I23: =F23*H23 | J23: 1800 | K23: =F23*J23 | L23: 650 | M23: =F23*L23 | N23: =H23+J23+L23 | O23: =I23+K23+M23 | P23: 가영현 | Q23: 벌개제근
A24: 01 토목 | B24: 1. 토 공 | C24: 3 | D24: 가). 임목 운반 | E24: 운반거리 L=83m(현장--->임목파쇄장) | F24: 1917 | G24: ㎥ | H24: 0 | I24: =F24*H24 | J24: 0 | K24: =F24*J24 | L24: 8000 | M24: =F24*L24 | N24: =H24+J24+L24 | O24: =I24+K24+M24 | Q24: 수동위탁
A25: 01 토목 | B25: 1. 토 공 | C25: 4 | D25: 나). 임목파쇄 | E25: 가지, 잡목류, 354.35kW | F25: 1906 | G25: ㎥ | H25: 0 | I25: =F25*H25 | J25: 0 | K25: =F25*J25 | L25: 41000 | M25: =F25*L25 | N25: =H25+J25+L25 | O25: =I25+K25+M25 | Q25: 수동위탁
A26: 01 토목 | B26: 1. 토 공 | C26: 5 | D26: 다). 임목파쇄 | E26: 뿌리류, 354.35kW | F26: 11 | G26: ㎥ | H26: 0 | I26: =F26*H26 | J26: 0 | K26: =F26*J26 | L26: 46000 | M26: =F26*L26 | N26: =H26+J26+L26 | O26: =I26+K26+M26 | Q26: 수동위탁
A27: 01 토목 | B27: 1. 토 공 | C27: 6 | D27: 가). PE천막지 | F27: 1082 | G27: ㎡ | H27: 1200 | I27: =F27*H27 | J27: 800 | K27: =F27*J27 | L27: 350 | M27: =F27*L27 | N27: =H27+J27+L27 | O27: =I27+K27+M27 | P27: 가영현 | Q27: PE천막지
A28: 01 토목 | B28: 1. 토 공 | C28: 7 | D28: 나). 터파기(토사) | E28: TYPE-1, 백호1.0, 기계100% | F28: 67 | G28: ㎥ | H28: 447 | I28: =F28*H28 | J28: 955 | K28: =F28*J28 | L28: 336 | M28: =F28*L28 | N28: =H28+J28+L28 | O28: =I28+K28+M28 | Q28: 토사
A29: 01 토목 | B29: 1. 토 공 | C29: 8 | D29: 다). 되메우기(토사) | E29: 백호0.7, 기계100% | F29: 67 | G29: ㎥ | H29: 547 | I29: =F29*H29 | J29: 8585 | K29: =F29*J29 | L29: 492 | M29: =F29*L29 | N29: =H29+J29+L29 | O29: =I29+K29+M29 | Q29: 되메우기
A30: 01 토목 | B30: 1. 토 공 | C30: 9 | D30: 1). 법면보호공 | E30: 잔디붙임(줄떼) | F30: 1246 | G30: ㎡ | H30: 0 | I30: =F30*H30 | J30: 4699 | K30: =F30*J30 | L30: 0 | M30: =F30*L30 | N30: =H30+J30+L30 | O30: =I30+K30+M30 | Q30: 잔디붙임(줄떼)
A31: 01 토목 | B31: 1. 토 공 | C31: 10 | D31: 2). 법면보호공 | E31: 잔디붙임(평떼) | F31: 1172 | G31: ㎡ | H31: 0 | I31: =F31*H31 | J31: 5538 | K31: =F31*J31 | L31: 0 | M31: =F31*L31 | N31: =H31+J31+L31 | O31: =I31+K31+M31 | Q31: 잔디붙임(평떼)
A32: 01 토목 | B32: 1. 토 공 | C32: 11 | D32: 가).흙깍기(기계,토사) | E32: 중규모, 보통토사, 불도져 19ton | F32: 10527 | G32: ㎥ | H32: 570 | I32: =F32*H32 | J32: 843 | K32: =F32*J32 | L32: 513 | M32: =F32*L32 | N32: =H32+J32+L32 | O32: =I32+K32+M32 | Q32: 흙깎기
A33: 01 토목 | B33: 1. 토 공 | C33: 12 | D33: 나). 흙깍기(토사) | E33: 굴삭기1.0㎥ | F33: 72445 | G33: ㎥ | H33: 991 | I33: =F33*H33 | J33: 893 | K33: =F33*J33 | L33: 732 | M33: =F33*L33 | N33: =H33+J33+L33 | O33: =I33+K33+M33 | Q33: 흙깎기
A34: 01 토목 | B34: 1. 토 공 | C34: 13 | D34: 가). 흙깍기(리핑암) | E34: 불도저 32ton + 리퍼 | F34: 5167 | G34: ㎥ | H34: 991 | I34: =F34*H34 | J34: 893 | K34: =F34*J34 | L34: 732 | M34: =F34*L34 | N34: =H34+J34+L34 | O34: =I34+K34+M34 | Q34: 흙깎기
A35: 01 토목 | B35: 1. 토 공 | C35: 14 | D35: 가). 땅깍기(암석절취) | E35: 중규모진동제어발파, 연암 | F35: 921 | G35: ㎥ | H35: 3359 | I35: =F35*H35 | J35: 5469 | K35: =F35*J35 | L35: 1896 | M35: =F35*L35 | N35: =H35+J35+L35 | O35: =I35+K35+M35 | Q35: 흙깎기
A36: 01 토목 | B36: 1. 토 공 | C36: 15 | D36: 가). 땅깍기(암석절취) | E36: 일반발파, 보통암 | F36: 27 | G36: ㎥ | H36: 5916 | I36: =F36*H36 | J36: 19069 | K36: =F36*J36 | L36: 9487 | M36: =F36*L36 | N36: =H36+J36+L36 | O36: =I36+K36+M36 | Q36: 흙깎기
A37: 01 토목 | B37: 1. 토 공 | C37: 16 | D37: 가). 발파암 소할 | E37: 30CM이상 | F37: 142 | G37: ㎥ | H37: 850 | I37: =F37*H37 | J37: 957 | K37: =F37*J37 | L37: 473 | M37: =F37*L37 | N37: =H37+J37+L37 | O37: =I37+K37+M37 | Q37: 발파암 소할
A38: 01 토목 | B38: 1. 토 공 | C38: 17 | D38: 1). 터파기(토사) | E38: TYPE-1, 굴착기1.0, 기계100% | F38: 1325 | G38: ㎥ | H38: 447 | I38: =F38*H38 | J38: 955 | K38: =F38*J38 | L38: 336 | M38: =F38*L38 | N38: =H38+J38+L38 | O38: =I38+K38+M38 | Q38: 토사
A39: 01 토목 | B39: 1. 토 공 | C39: 18 | D39: 가). 흙쌓기(토사) | E39: 비다짐, 불도저 32톤 | F39: 6499 | G39: ㎥ | H39: 582 | I39: =F39*H39 | J39: 1162 | K39: =F39*J39 | L39: 501 | M39: =F39*L39 | N39: =H39+J39+L39 | O39: =I39+K39+M39 | Q39: 흙쌓기
... A43: 01 토목 | B43: 1. 토 공 | C43: 22 | D43: 가). 흙쌓기 | E43: 노체, 두께30cm, 다짐도90%이상 | F43: 1174 | G43: ㎥ | H43: 594 | I43: =F43*H43 | J43: 1602 | K43: =F43*J43 | L43: 741 | M43: =F43*L43 | N43: =H43+J43+L43 | O43: =I43+K43+M43 | Q43: 흙쌓기
A44: 01 토목 | B44: 1. 토 공 | C44: 23 | D44: 가). 토사 | F44: 5363 | G44: ㎥ | H44: 912 | I44: =F44*H44 | J44: 1951 | K44: =F44*J44 | L44: 685 | M44: =F44*L44 | N44: =H44+J44+L44 | O44: =I44+K44+M44 | P44: 가영현 | Q44: 토사
A45: 01 토목 | B45: 1. 토 공 | C45: 24 | D45: 가). 흙운반(토사) | E45: 불도저 32톤, L=15.2m | F45: 10527 | G45: ㎥ | H45: 906 | I45: =F45*H45 | J45: 1736 | K45: =F45*J45 | L45: 515 | M45: =F45*L45 | N45: =H45+J45+L45 | O45: =I45+K45+M45 | Q45: 토사
A46: 01 토목 | B46: 1. 토 공 | C46: 25 | D46: 나). 흙운반(풍화암) | E46: 불도저 32톤, L=19.7m | F46: 26 | G46: ㎥ | H46: 906 | I46: =F46*H46 | J46: 1736 | K46: =F46*J46 | L46: 515 | M46: =F46*L46 | N46: =H46+J46+L46 | O46: =I46+K46+M46 | Q46: 흙운반
...

Sheet 지구단위
A1: 화성 청원지구 — 지구단위
A3: No | B3: 내역서 | C3: 공종 | D3: 매칭 | E3: 전체 | F3: 매칭률 | G3: 재료비 | H3: 노무비 | I3: 경비 | J3: 합계 | K3: 합계(억)
A4: 06 | B4: 06 개발행위 | C4: 1. 토 공 | D4: 9 | E4: 9 | F4: 1 | G4: 329303137 | H4: 633526312 | I4: 288990853 | J4: 1251820302 | K4: 12.518203
A5: 06 | B5: 06 개발행위 | C5: 2. A1 | D5: 14 | E5: 14 | F5: 1 | G5: 1322809 | H5: 36399255 | I5: 1512006 | J5: 39234070 | K5: 0.3923407
A6: 06 | B6: 06 개발행위 | C6: 3. A2 | D6: 17 | E6: 17 | F6: 1 | G6: 2352580 | H6: 88315220 | I6: 2468726 | J6: 93136526 | K6: 0.93136526
A7: 06 | B7: 06 개발행위 | C7: 4. A3 | D7: 16 | E7: 17 | F7: 0.94117647 | G7: 1709156 | H7: 77274394 | I7: 2194560 | J7: 81178110 | K7: 0.8117811
A8: 06 | B8: 06 개발행위 | C8: 5. A4 | D8: 14 | E8: 15 | F8: 0.93333333 | G8: 1677855 | H8: 59383425 | I8: 2123566 | J8: 63184846 | K8: 0.63184846
A9: 06 | B9: 06 개발행위 | C9: 6. A5 | D9: 14 | E9: 15 | F9: 0.93333333 | G9: 1149785 | H9: 45609407 | I9: 1591411 | J9: 48350603 | K9: 0.48350603
A10: 06 | B10: 06 개발행위 | C10: 7. B1 | D10: 13 | E10: 14 | F10: 0.92857143 | G10: 1161816 | H10: 62903235 | I10: 1273047 | J10: 65338098 | K10: 0.65338098
A11: 06 | B11: 06 개발행위 | C11: 8. B2 | D11: 13 | E11: 14 | F11: 0.92857143 | G11: 1365630 | H11: 58315326 | I11: 1427499 | J11: 61108455 | K11: 0.61108455
A12: 06 | B12: 06 개발행위 | C12: 9. 지원시설 | D12: 11 | E12: 12 | F12: 0.91666667 | G12: 656770 | H12: 13039376 | I12: 460290 | J12: 14156436 | K12: 0.14156436
A13: 06 | B13: 06 개발행위 | C13: 10. 주차장 | D13: 9 | E13: 10 | F13: 0.9 | G13: 476321 | H13: 4825299 | I13: 600364 | J13: 5901984 | K13: 0.05901984
A14: 06 | B14: 06 개발행위 | C14: ★ 06 개발행위 소계 | D14: 130 | E14: 137 | F14: 0.94890511 | G14: 341175859 | H14: 1079591249 | I14: 302642322 | J14: 1723409430 | K14: 17.234094
B15: 지구단위 | C15: ★ 지구단위 합계 | D15: 130 | E15: 137 | F15: 0.94890511 | G15: 341175859 | H15: 1079591249 | I15: 302642322 | J15: 1723409430 | K15: 17.234094
A17: ◆ 지구단위 — 내역 일괄
A19: 내역서 | B19: 공종 | C19: No | D19: 공종명 | E19: 규격 | F19: 수량 | G19: 단위 | H19: 재료단가 | I19: 재료금액 | J19: 노무단가 | K19: 노무금액 | L19: 경비단가 | M19: 경비금액 | N19: 합계단가 | O19: 합계금액 | P19: 상태 | Q19: 비고
A20: 06 개발행위 | B20: 1. 토 공 | C20: 1 | D20: 가).흙깍기(기계,토사) | E20: 중규모, 보통토사, 불도져 19ton | F20: 140244 | G20: ㎥ | H20: 570 | I20: =F20*H20 | J20: 843 | K20: =F20*J20 | L20: 513 | M20: =F20*L20 | N20: =H20+J20+L20 | O20: =I20+K20+M20 | Q20: 기계
A21: 06 개발행위 | B21: 1. 토 공 | C21: 2 | D21: 가). 흙깍기(리핑암) | E21: 불도저 32ton + 리퍼 | F21: 20870 | G21: ㎥ | H21: 991 | I21: =F21*H21 | J21: 893 | K21: =F21*J21 | L21: 732 | M21: =F21*L21 | N21: =H21+J21+L21 | O21: =I21+K21+M21 | Q21: 가). 흙깎기
A22: 06 개발행위 | B22: 1. 토 공 | C22: 3 | D22: 가). 땅깍기(암석절취) | E22: 중규모진동제어발파, 연암 | F22: 11485 | G22: ㎥ | H22: 3359 | I22: =F22*H22 | J22: 5469 | K22: =F22*J22 | L22: 1896 | M22: =F22*L22 | N22: =H22+J22+L22 | O22: =I22+K22+M22 | Q22: 중규모진동제어발파
A23: 06 개발행위 | B23: 1. 토 공 | C23: 4 | D23: 가). 땅깍기(암석절취) | E23: 일반발파, 보통암 | F23: 8203 | G23: ㎥ | H23: 5916 | I23: =F23*H23 | J23: 19069 | K23: =F23*J23 | L23: 9487 | M23: =F23*L23 | N23: =H23+J23+L23 | O23: =I23+K23+M23 | Q23: 가). 흙깎기
A24: 06 개발행위 | B24: 1. 토 공 | C24: 5 | D24: 가). 흙쌓기(토사) | E24: 비다짐, 불도저 32톤 | F24: 72163 | G24: ㎥ | H24: 582 | I24: =F24*H24 | J24: 1162 | K24: =F24*J24 | L24: 501 | M24: =F24*L24 | N24: =H24+J24+L24 | O24: =I24+K24+M24 | Q24: 가). 흙쌓기
A25: 06 개발행위 | B25: 1. 토 공 | C25: 6 | D25: 가). 흙 운반(토사)(야적장) | E25: 굴삭기1.0㎥+덤프24톤, L=0.238Km | F25: 60064 | G25: ㎥ | H25: 873 | I25: =F25*H25 | J25: 1719 | K25: =F25*J25 | L25: 653 | M25: =F25*L25 | N25: =H25+J25+L25 | O25: =I25+K25+M25 | Q25: 토사
A26: 06 개발행위 | B26: 1. 토 공 | C26: 7 | D26: 나). 흙운반(풍화암)(야적장) | E26: 로우더1.72㎥+덤프24톤, L=0.212Km | F26: 25508 | G26: ㎥ | H26: 906 | I26: =F26*H26 | J26: 1736 | K26: =F26*J26 | L26: 515 | M26: =F26*L26 | N26: =H26+J26+L26 | O26: =I26+K26+M26 | Q26: 나). 흙운반
A27: 06 개발행위 | B27: 1. 토 공 | C27: 8 | D27: 다). 흙운반(연암)(야적장) | E27: 굴삭기1.0㎥+덤프24톤, L=0.216Km | F27: 14675 | G27: ㎥ | H27: 906 | I27: =F27*H27 | J27: 1736 | K27: =F27*J27 | L27: 515 | M27: =F27*L27 | N27: =H27+J27+L27 | O27: =I27+K27+M27 | Q27: 다). 흙운반
A28: 06 개발행위 | B28: 1. 토 공 | C28: 9 | D28: 라). 흙운반(보통암)(야적장) | E28: 굴삭기1.0㎥+덤프24톤, L=0.226Km | F28: 11848 | G28: ㎥ | H28: 906 | I28: =F28*H28 | J28: 1736 | K28: =F28*J28 | L28: 515 | M28: =F28*L28 | N28: =H28+J28+L28 | O28: =I28+K28+M28 | Q28: 라). 흙운반
A29: 06 개발행위 | B29: 1. 토 공 | D29: ★ 1. 토 공 소계 | I29: =SUM(I20:I28) | K29: =SUM(K20:K28) | M29: =SUM(M20:M28) | O29: =SUM(O20:O28) | Q29: 9건
A30: 06 개발행위 | B30: 2. A1 | C30: 1 | D30: 1). 우수 원형1호 맨홀 | E30: D900 | F30: 1 | G30: 개소 | H30: 0 | I30: =F30*H30 | J30: 71377 | K30: =F30*J30 | L30: 0 | M30: =F30*L30 | N30: =H30+J30+L30 | O30: =I30+K30+M30 | Q30: D900
A31: 06 개발행위 | B31: 2. A1 | C31: 2 | D31: 2). 집수정 | E31: 0.6x0.6,스틸그레이팅 | F31: 7 | G31: 개소 | H31: 5775 | I31: =F31*H31 | J31: 258574 | K31: =F31*J31 | L31: 3583 | M31: =F31*L31 | N31: =H31+J31+L31 | O31: =I31+K31+M31 | Q31: 표준DB CTC30702040S (점수0.55) / 대안: 스틸레자방음문(0.51) · 깍기부집수정(흄관)(0.51)
A32: 06 개발행위 | B32: 2. A1 | C32: 3 | D32: 3). 오수받이 | F32: 1 | G32: 개소 | H32: 340000 | I32: =F32*H32 | J32: 75000 | K32: =F32*J32 | L32: 75000 | M32: =F32*L32 | N32: =H32+J32+L32 | O32: =I32+K32+M32 | P32: 가영현 | Q32: 3). 오수받이
A33: 06 개발행위 | B33: 2. A1 | C33: 4 | D33: 4). 고강성 PVC 이중벽관 접합 및 부설 | E33: D150mm, 시공조건B | F33: 15 | G33: m | H33: 230 | I33: =F33*H33 | J33: 4360 | K33: =F33*J33 | L33: 0 | M33: =F33*L33 | N33: =H33+J33+L33 | O33: =I33+K33+M33 | Q33: D150mm
A34: 06 개발행위 | B34: 2. A1 | C34: 5 | D34: 5). 고강성 PVC 이중벽관 접합 및 부설 | E34: D450mm, 시공조건B | F34: 154 | G34: m | H34: 230 | I34: =F34*H34 | J34: 4360 | K34: =F34*J34 | L34: 0 | M34: =F34*L34 | N34: =H34+J34+L34 | O34: =I34+K34+M34 | Q34: 부설
A35: 06 개발행위 | B35: 2. A1 | C35: 6 | D35: 6). 고강성PVC이중벽관 | E35: D150mm, 직관 | F35: 3 | G35: 본 | H35: 505 | I35: =F35*H35 | J35: 25263 | K35: =F35*J35 | L35: 0 | M35: =F35*L35 | N35: =H35+J35+L35 | O35: =I35+K35+M35 | Q35: 표준DB CGR10100500S (점수0.55) / 대안: 내충격PVC수도관 부설 및 접(0.55) · 내충격PVC수도관 부설 및 접(0.55)
A36: 06 개발행위 | B36: 2. A1 | C36: 7 | D36: 7). 고강성PVC이중벽관 | E36: D450mm, 직관 | F36: 26 | G36: 본 | H36: 180000 | I36: =F36*H36 | J36: 25263 | K36: =F36*J36 | M36: =F36*L36 | N36: =H36+J36+L36 | O36: =I36+K36+M36 | P36: 가영현 | Q36: 7). 고강성PVC이중벽관
A37: 06 개발행위 | B37: 2. A1 | C37: 8 | D37: 8). 원심력철근콘크리트관 접합및부설(소켓식) | E37: Ø 600mm, 시공조건 B | F37: 11 | G37: m | H37: 2339 | I37: =F37*H37 | J37: 19375 | K37: =F37*J37 | L37: 2505 | M37: =F37*L37 | N37: =H37+J37+L37 | O37: =I37+K37+M37 | Q37: 소켓식
A38: 06 개발행위 | B38: 2. A1 | C38: 9 | D38: 9). 사각수로관 | E38: Ø 300mm | F38: 15 | G38: m | H38: 32611 | I38: =F38*H38 | J38: 106288 | K38: =F38*J38 | L38: 62900 | M38: =F38*L38 | N38: =H38+J38+L38 | O38: =I38+K38+M38 | Q38: Ø 300mm
A39: 06 개발행위 | B39: 2. A1 | C39: 10 | D39: 10). CEP옹벽 | E39: 1.5m~5.0m | F39: 35 | G39: M2 | H39: 150000 | I39: =F39*H39 | J39: 150000 | K39: =F39*J39 | L39: 50000 | M39: =F39*L39 | N39: =H39+J39+L39 | O39: =I39+K39+M39 | P39: 가영현 | Q39: 1.5m~5.0m
A40: 06 개발행위 | B40: 2. A1 | C40: 11 | D40: 11). 메쉬휀스 | E40: H=1.5m | F40: 74 | G40: m | H40: 2290 | I40: =F40*H40 | J40: 40880 | K40: =F40*J40 | L40: 2681 | M40: =F40*L40 | N40: =H40+J40+L40 | O40: =I40+K40+M40 | Q40: H=1.5m
A41: 06 개발행위 | B41: 2. A1 | C41: 12 | D41: 12). 콘크리트포장 | E41: T=20Cm | F41: 2284 | G41: ㎡ | H41: 185 | I41: =F41*H41 | J41: 197 | K41: =F41*J41 | L41: 139 | M41: =F41*L41 | N41: =H41+J41+L41 | O41: =I41+K41+M41 | Q41: T=20Cm
A42: 06 개발행위 | B42: 2. A1 | C42: 13 | D42: 13). 관목 | E42: H0.3xW0.3 | F42: 6750 | G42: 주 | I42: =F42*H42 | J42: 3797 | K42: =F42*J42 | M42: =F42*L42 | N42: =H42+J42+L42 | O42: =I42+K42+M42 | P42: 가영현 | Q42: 13). 관목
A43: 06 개발행위 | B43: 2. A1 | C43: 14 | D43: 14). 법면보호공 | E43: 잔디붙임(줄떼) | F43: 83 | G43: ㎡ | H43: 0 | I43: =F43*H43 | J43: 4699 | K43: =F43*J43 | L43: 0 | M43: =F43*L43 | N43: =H43+J43+L43 | O43: =I43+K43+M43 | Q43: 잔디붙임(줄떼)
...

Sheet 폐기물
A1: 화성 청원지구 — 폐기물
A3: No | B3: 내역서 | C3: 공종 | D3: 매칭 | E3: 전체 | F3: 매칭률 | G3: 재료비 | H3: 노무비 | I3: 경비 | J3: 합계 | K3: 합계(억)
A4: 07 | B4: 07 건설폐기물 | C4: 1). 폐기물운반 | G4: 0 | H4: 0 | I4: 10873450 | J4: 10873450 | K4: 0.1087345
A5: 07 | B5: 07 건설폐기물 | C5: 1). 폐콘크리트 처리비 | G5: 0 | H5: 0 | I5: 20584862 | J5: 20584862 | K5: 0.20584862
A6: 07 | B6: 07 건설폐기물 | C6: ★ 07 건설폐기물 소계 | D6: 0 | E6: 0 | F6: 0 | G6: 0 | H6: 0 | I6: 31458312 | J6: 31458312 | K6: 0.31458312
B7: 폐기물 | C7: ★ 폐기물 합계 | D7: 0 | E7: 0 | F7: 0 | G7: 0 | H7: 0 | I7: 31458312 | J7: 31458312 | K7: 0.31458312
A9: ◆ 폐기물 — 내역 일괄
A11: 내역서 | B11: 공종 | C11: No | D11: 공종명 | E11: 규격 | F11: 수량 | G11: 단위 | H11: 재료단가 | I11: 재료금액 | J11: 노무단가 | K11: 노무금액 | L11: 경비단가 | M11: 경비금액 | N11: 합계단가 | O11: 합계금액 | P11: 상태 | Q11: 비고
A12: 07 건설폐기물 | B12: 건설폐기물처리 | C12: 1 | D12: 1). 폐기물운반 | E12: 24톤, 30Km 이내 | F12: 661 | G12: Ton | H12: 0 | I12: =F12*H12 | J12: 0 | K12: =F12*J12 | L12: 16450 | M12: =F12*L12 | N12: =H12+J12+L12 | O12: =I12+K12+M12 | Q12: 26. 협회단가
A13: 07 건설폐기물 | B13: 건설폐기물처리 | C13: 2 | D13: 1). 폐콘크리트 처리비 | F13: 661 | G13: Ton | H13: 0 | I13: =F13*H13 | J13: 0 | K13: =F13*J13 | L13: 31142 | M13: =F13*L13 | N13: =H13+J13+L13 | O13: =I13+K13+M13 | Q13: 26. 협회단가
A14: 07 건설폐기물 | B14: 건설폐기물처리 | D14: ★ 건설폐기물처리 소계 | I14: =SUM(I12:I13) | K14: =SUM(K12:K13) | M14: =SUM(M12:M13) | O14: =SUM(O12:O13) | Q14: 2건
D15: ★ 폐기물 내역 합계 | I15: =SUMIF(C12:C14,"<>",I12:I14) | K15: =SUMIF(C12:C14,"<>",K12:K14) | M15: =SUMIF(C12:C14,"<>",M12:M14) | O15: =SUMIF(C12:C14,"<>",O12:O14) | Q15: No<>인 행 합산
