Workbook

Sheet 표지
B4: 견 적 서
B11: 공사명 : 화성 청원지구 산업유통형 지구단위계획
B15: 2026년 06월 30일
B24: 삼아건설주식회사

Sheet 견적서
A1: 견 적 서
A3: 2026년 06월 30일 | G3: 삼아건설주식회사
A4: 진명개발 귀하 | G4: 인천광역시 연수구 센트럴로 313, 씨동 2123호 (송도동, 송도씨워크인테라스한라)
A5: 공사명 : 화성 청원지구 산업유통형 지구단위계획 | G5: TEL : 032 - 818 - 2581
A6: 공사금액 : 일금 일백이십삼억칠천팔백이십이만일천일백육십팔원정 (₩12,378,221,168) | G6: FAX : 032 - 822 - 0887
A7: 상기 공사 견적서를 아래와 같이 제출합니다. | G7: 대표자 가 영 현 (인)
A9: 공 종 | B9: 규 격 | C9: 수량 | D9: 단위 | E9: 재 료 비 | G9: 노 무 비 | I9: 경 비 | K9: 합 계 | M9: 비고
E10: 단가 | F10: 금액 | G10: 단가 | H10: 금액 | I10: 단가 | J10: 금액 | K10: 단가 | L10: 금액
A11: Ⅰ. 직접공사비 계 | F11: =원가계산서!D3 -> 3511003009 | H11: =원가계산서!D4 -> 1849055312 | J11: =원가계산서!D5 -> 4525588656 | L11: =원가계산서!D6 -> 9885646977
A12: Ⅱ. 간접공사비 계 | C12: 1 | D12: 식 | F12: =0 -> 0 | H12: =0 -> 0 | J12: =원가계산서!D23-원가계산서!D6 -> 2.4925742e+09 | L12: =원가계산서!D23-원가계산서!D6 -> 2.4925742e+09
A13: 합 계 | F13: =원가계산서!D3 -> 3511003009 | H13: =원가계산서!D4 -> 1849055312 | J13: =J11+J12 -> 7.0181628e+09 | L13: =원가계산서!D23 -> 1.2378221e+10
A14: 부 가 가 치 세 | C14: 1 | D14: 식 | F14: =0 -> 0 | H14: =0 -> 0 | J14: =원가계산서!D24 -> 1.2378221e+09 | L14: =원가계산서!D24 -> 1.2378221e+09
A15: 공 사 비 계 | F15: =원가계산서!D3 -> 3511003009 | H15: =원가계산서!D4 -> 1849055312 | J15: =J13+J14 -> 8.255985e+09 | L15: =원가계산서!D25 -> 1.3616043e+10

Sheet 원가계산서
A1: 구분 | B1: 항목 | C1: 산식 | D1: 금액 | E1: 비고
A3: 직접공사비 | B3: 재료비 | C3: Σ 섹션 재료비 | D3: =내역서!F828+내역서!F1082+내역서!F1307+내역서!F1468+내역서!F1474 -> 3511003009
B4: 직접노무비 | C4: Σ 섹션 노무비 | D4: =내역서!H828+내역서!H1082+내역서!H1307+내역서!H1468+내역서!H1474 -> 1849055312
B5: 직접경비 | C5: Σ 섹션 경비 | D5: =내역서!J828+내역서!J1082+내역서!J1307+내역서!J1468+내역서!J1474 -> 4525588656
B6: 【 직접공사비 계 】 | C6: 재+직노+직경 | D6: =D3+D4+D5 -> 9885646977
A7: 간접비 | B7: 간접노무비 | C7: 직접노무비×19.7% | D7: =D4*0.197 -> 3.642639e+08 | E7: 조달청 원가계산 제비율(토목 50~300억·13~36개월)
B8: 산재보험료 | C8: 노무비계×3.56% | D8: =(D4+D7)*0.0356 -> 78794164 | E8: 2026년 산재보험료율 고시(건설업 3.5%)+임금채권보장부담금 0.06%
B9: 고용보험료 | C9: 노무비계×1.15% | D9: =(D4+D7)*0.0115 -> 25453171 | E9: 고용보험료율 사업주 부담(실업급여 0.9%+고용안정·직업능력개발 0.25%)
B10: 국민건강보험료 | C10: 직접노무비×3.595% | D10: =D4*0.03595 -> 66473538 | E10: 2026년 법정요율(건강보험 7.19%의 1/2)
B11: 국민연금보험료 | C11: 직접노무비×4.75% | D11: =D4*0.0475 -> 87830127 | E11: 2026년 법정요율(국민연금 9.5%의 1/2)
B12: 노인장기요양보험료 | C12: 건강보험료×13.14% | D12: =D10*0.1314 -> 8734623 | E12: 2026년 법정요율(건강보험료의 13.14%)
B13: 산업안전보건관리비 | C13: (재+직노)×2.60% | D13: =(D3+D4)*0.026 -> 1.3936152e+08 | E13: 건설업 산업안전보건관리비 계상기준 고시(고용노동부 제2025-11호, 토목 50억 이상)
B14: 기타경비(공과잡비) | C14: (재+노무비계)×6.2% | D14: =(D3+D4+D7)*0.062 -> 3.5490798e+08 | E14: 조달청 원가계산 제비율(세금과공과 등)
B15: 건설기계대여대금지급보증 | C15: 직접공사비×0.40% | D15: =D6*0.004 -> 39542588 | E15: 건설기계 대여대금 지급보증 수수료
B16: 환경보전비 | C16: 직접공사비×0.60% | D16: =D6*0.006 -> 59313882 | E16: 건설기술 진흥법 환경관리비 기준
B17: 【 산출경비 계 】 | C17: 간접경비 합 | D17: =D8+D9+D10+D11+D12+D13+D14+D15+D16 -> 8.6041159e+08
A18: 원가 | B18: 【 경비계(직접+산출) 】 | C18: 직접경비+산출경비 | D18: =D5+D17 -> 5.3860002e+09
B19: 【 순공사원가 】 | C19: 재+노무비계+경비계 | D19: =D3+D4+D7+D18 -> 1.1110322e+10
A20: 간접비 | B20: 일반관리비 | C20: 순공사원가×5.5% | D20: =D19*0.055 -> 6.1106774e+08
B21: 이윤 | C21: (노무비계+경비계+일반관리비)×8% | D21: =(D4+D7+D18+D20)*0.08 -> 6.5683097e+08
B22: 이행(준공)보증보험료 | C22: 미적용 | D22: 0
A23: 합계 | B23: 【 공급가액 】 | C23: 순공사원가+일반관리비+이윤 | D23: =D19+D20+D21+D22 -> 1.2378221e+10
B24: 부가가치세 | C24: 공급가액×10% | D24: =D23*0.1 -> 1.2378221e+09
B25: ★ 도급액(공사비 계) | C25: 공급가액+부가세 | D25: =D23+D24 -> 1.3616043e+10
B27: ※ 직접공사비=첨부 내역서, 간접노무비·기타경비·일반관리비·이윤 등 제비율 및 사회보험료·산업안전보건관리비·건설기계대여대금지급보증·환경보전비는 관계 법령·기준요율 적용.

Sheet 내역서
A1: 공종명 / 품명· | B1: 규격 | C1: 수량 | D1: 단위 | E1: 재료비 | G1: 노무비 | I1: 경비 | K1: 합계 | M1: 비고
E2: 단가 | F2: 금액 | G2: 단가 | H2: 금액 | I2: 단가 | J2: 금액 | K2: 단가 | L2: 금액
A3: 【 01. 토목·조경 】
A4: 1. 토 공 | F4: =SUM(F7:F82) -> 119051717 | H4: =SUM(H7:H82) -> 149906705 | J4: =SUM(J7:J82) -> 454175418 | L4: =F4+H4+J4 -> 723133840
A5: 가. 벌목 및 벌개제근
A6: 1). 벌목 및 벌개제근
A7: 가). 벌목 | C7: 22891 | D7: ㎡ | E7: 313 | F7: =ROUND(E7*C7,0) -> 7164883 | G7: 101 | H7: =ROUND(G7*C7,0) -> 2311991 | I7: 33 | J7: =ROUND(I7*C7,0) -> 755403 | K7: =E7+G7+I7 -> 447 | L7: =F7+H7+J7 -> 10232277
A8: 나). 벌개제근 | C8: 22891 | D8: ㎡ | E8: 313 | F8: =ROUND(E8*C8,0) -> 7164883 | G8: 61 | H8: =ROUND(G8*C8,0) -> 1396351 | I8: 33 | J8: =ROUND(I8*C8,0) -> 755403 | K8: =E8+G8+I8 -> 407 | L8: =F8+H8+J8 -> 9316637
A9: 나. 임목폐기물
A10: 1). 임목파쇄
A11: 가). 임목 운반 | B11: 운반거리 L=83m(현장--->임목파쇄장) | C11: 1917 | D11: ㎥ | E11: 1273 | F11: =ROUND(E11*C11,0) -> 2440341 | G11: 0 | H11: =ROUND(G11*C11,0) -> 0 | I11: 0 | J11: =ROUND(I11*C11,0) -> 0 | K11: =E11+G11+I11 -> 1273 | L11: =F11+H11+J11 -> 2440341
A12: 나). 임목파쇄 | B12: 가지, 잡목류, 354.35kW | C12: 1906 | D12: ㎥ | E12: 5303 | F12: =ROUND(E12*C12,0) -> 10107518 | G12: 0 | H12: =ROUND(G12*C12,0) -> 0 | I12: 0 | J12: =ROUND(I12*C12,0) -> 0 | K12: =E12+G12+I12 -> 5303 | L12: =F12+H12+J12 -> 10107518
A13: 다). 임목파쇄 | B13: 뿌리류, 354.35kW | C13: 11 | D13: ㎥ | E13: 404000 | F13: =ROUND(E13*C13,0) -> 4444000 | G13: 0 | H13: =ROUND(G13*C13,0) -> 0 | I13: 0 | J13: =ROUND(I13*C13,0) -> 0 | K13: =E13+G13+I13 -> 404000 | L13: =F13+H13+J13 -> 4444000
A14: 2). 임목폐기물 적치장
A15: 가). PE천막지 | C15: 1082 | D15: ㎡ | E15: 565 | F15: =ROUND(E15*C15,0) -> 611330 | G15: 493 | H15: =ROUND(G15*C15,0) -> 533426 | I15: 0 | J15: =ROUND(I15*C15,0) -> 0 | K15: =E15+G15+I15 -> 1058 | L15: =F15+H15+J15 -> 1144756
A16: 나). 터파기(토사) | B16: TYPE-1, 백호1.0, 기계100% | C16: 67 | D16: ㎥ | E16: 0 | F16: =ROUND(E16*C16,0) -> 0 | G16: 331 | H16: =ROUND(G16*C16,0) -> 22177 | I16: 1857 | J16: =ROUND(I16*C16,0) -> 124419 | K16: =E16+G16+I16 -> 2188 | L16: =F16+H16+J16 -> 146596
A17: 다). 되메우기(토사) | B17: 백호0.7, 기계100% | C17: 67 | D17: ㎥ | E17: 0 | F17: =ROUND(E17*C17,0) -> 0 | G17: 664 | H17: =ROUND(G17*C17,0) -> 44488 | I17: 2636 | J17: =ROUND(I17*C17,0) -> 176612 | K17: =E17+G17+I17 -> 3300 | L17: =F17+H17+J17 -> 221100
A18: 다. 법면보호공
A19: 1). 법면보호공 | B19: 잔디붙임(줄떼) | C19: 1246 | D19: ㎡ | E19: 6262 | F19: =ROUND(E19*C19,0) -> 7802452 | G19: 1313 | H19: =ROUND(G19*C19,0) -> 1635998 | I19: 0 | J19: =ROUND(I19*C19,0) -> 0 | K19: =E19+G19+I19 -> 7575 | L19: =F19+H19+J19 -> 9438450
A20: 2). 법면보호공 | B20: 잔디붙임(평떼) | C20: 1172 | D20: ㎡ | E20: 12524 | F20: =ROUND(E20*C20,0) -> 14678128 | G20: 2626 | H20: =ROUND(G20*C20,0) -> 3077672 | I20: 0 | J20: =ROUND(I20*C20,0) -> 0 | K20: =E20+G20+I20 -> 15150 | L20: =F20+H20+J20 -> 17755800
A21: 라. 흙깎기
A22: 1). 토사
A23: 가).흙깍기(기계,토사) | B23: 중규모, 보통토사, 불도져 19ton | C23: 10527 | D23: ㎥ | E23: 0 | F23: =ROUND(E23*C23,0) -> 0 | G23: 254 | H23: =ROUND(G23*C23,0) -> 2673858 | I23: 1239 | J23: =ROUND(I23*C23,0) -> 13042953 | K23: =E23+G23+I23 -> 1493 | L23: =F23+H23+J23 -> 15716811
A24: 나). 흙깍기(토사) | B24: 굴삭기1.0㎥ | C24: 72445 | D24: ㎥ | E24: 0 | F24: =ROUND(E24*C24,0) -> 0 | G24: 253 | H24: =ROUND(G24*C24,0) -> 18328585 | I24: 1373 | J24: =ROUND(I24*C24,0) -> 99466985 | K24: =E24+G24+I24 -> 1626 | L24: =F24+H24+J24 -> 117795570
A25: 2). 풍화암
A26: 가). 흙깍기(리핑암) | B26: 불도저 32ton + 리퍼 | C26: 5167 | D26: ㎥ | E26: 0 | F26: =ROUND(E26*C26,0) -> 0 | G26: 258 | H26: =ROUND(G26*C26,0) -> 1333086 | I26: 1755 | J26: =ROUND(I26*C26,0) -> 9068085 | K26: =E26+G26+I26 -> 2013 | L26: =F26+H26+J26 -> 10401171
A27: 3). 연암
A28: 가). 땅깍기(암석절취) | B28: 중규모진동제어발파, 연암 | C28: 921 | D28: ㎥ | E28: 0 | F28: =ROUND(E28*C28,0) -> 0 | G28: 384 | H28: =ROUND(G28*C28,0) -> 353664 | I28: 11167 | J28: =ROUND(I28*C28,0) -> 10284807 | K28: =E28+G28+I28 -> 11551 | L28: =F28+H28+J28 -> 10638471
A29: 나). 땅깍기(암석절취) | B29: 일반발파, 연암 | C29: 0 | D29: ㎥ | E29: 0 | F29: =ROUND(E29*C29,0) -> 0 | G29: 0 | H29: =ROUND(G29*C29,0) -> 0 | I29: 0 | J29: =ROUND(I29*C29,0) -> 0 | K29: =E29+G29+I29 -> 0 | L29: =F29+H29+J29 -> 0
A30: 4). 보통암
A31: 가). 땅깍기(암석절취) | B31: 일반발파, 보통암 | C31: 27 | D31: ㎥ | E31: 0 | F31: =ROUND(E31*C31,0) -> 0 | G31: 384 | H31: =ROUND(G31*C31,0) -> 10368 | I31: 6758 | J31: =ROUND(I31*C31,0) -> 182466 | K31: =E31+G31+I31 -> 7142 | L31: =F31+H31+J31 -> 192834
A32: 5). 발파암 소할
A33: 가). 발파암 소할 | B33: 30CM이상 | C33: 142 | D33: ㎥ | E33: 0 | F33: =ROUND(E33*C33,0) -> 0 | G33: 1313 | H33: =ROUND(G33*C33,0) -> 186446 | I33: 2977 | J33: =ROUND(I33*C33,0) -> 422734 | K33: =E33+G33+I33 -> 4290 | L33: =F33+H33+J33 -> 609180
A34: 마. 터파기
A35: 1). 터파기(토사) | B35: TYPE-1, 굴착기1.0, 기계100% | C35: 1325 | D35: ㎥ | E35: 0 | F35: =ROUND(E35*C35,0) -> 0 | G35: 269 | H35: =ROUND(G35*C35,0) -> 356425 | I35: 1503 | J35: =ROUND(I35*C35,0) -> 1991475 | K35: =E35+G35+I35 -> 1772 | L35: =F35+H35+J35 -> 2347900
A36: 바. 흙쌓기
A37: 1). 비다짐
A38: 가). 흙쌓기(토사) | B38: 비다짐, 불도저 32톤 | C38: 6499 | D38: ㎥ | E38: 0 | F38: =ROUND(E38*C38,0) -> 0 | G38: 141 | H38: =ROUND(G38*C38,0) -> 916359 | I38: 838 | J38: =ROUND(I38*C38,0) -> 5446162 | K38: =E38+G38+I38 -> 979 | L38: =F38+H38+J38 -> 6362521
A39: 나). 흙쌓기(풍화암) | B39: 비다짐, 불도저 32톤 | C39: 26 | D39: ㎥ | E39: 0 | F39: =ROUND(E39*C39,0) -> 0 | G39: 141 | H39: =ROUND(G39*C39,0) -> 3666 | I39: 838 | J39: =ROUND(I39*C39,0) -> 21788 | K39: =E39+G39+I39 -> 979 | L39: =F39+H39+J39 -> 25454
A40: 2). 노상
...

Sheet 02.전기(참고)
A1: 공종명 / 품명 | B1: 규격 | C1: 수량 | D1: 단위 | E1: 재료비 | G1: 노무비 | I1: 경비 | K1: 합계 | M1: 비고
E2: 단가 | F2: 금액 | G2: 단가 | H2: 금액 | I2: 단가 | J2: 금액 | K2: 단가 | L2: 금액
A3: 1.전기공사 (지구내) ▸ 1-1.가로등설비공사 | F3: =SUM(F4:F42) -> 160349230 | H3: =SUM(H4:H42) -> 71200210 | J3: =SUM(J4:J42) -> 2773431 | L3: =F3+H3+J3 -> 234322871
A4: 파상형 폴리에틸렌 전선관 | B4: 40㎜(가로등,신호,구내) | C4: 2061 | D4: m | E4: 945 | F4: =ROUND(E4*C4,0) -> 1947645 | G4: 9002 | H4: =ROUND(G4*C4,0) -> 18553122 | I4: 0 | J4: =ROUND(I4*C4,0) -> 0 | K4: =E4+G4+I4 -> 9947 | L4: =F4+H4+J4 -> 20500767 | M4: 제 11호
A5: 파상형 폴리에틸렌 전선관 | B5: 50㎜(가로등,신호,구내) | C5: 105 | D5: m | E5: 1170 | F5: =ROUND(E5*C5,0) -> 122850 | G5: 9002 | H5: =ROUND(G5*C5,0) -> 945210 | I5: 0 | J5: =ROUND(I5*C5,0) -> 0 | K5: =E5+G5+I5 -> 10172 | L5: =F5+H5+J5 -> 1068060 | M5: 제 12호
A6: 접지용비닐절연전선(F-GV)_지중 | B6: 6㎟ | C6: 35 | D6: m | E6: 1879 | F6: =ROUND(E6*C6,0) -> 65765 | G6: 2463 | H6: =ROUND(G6*C6,0) -> 86205 | I6: 0 | J6: =ROUND(I6*C6,0) -> 0 | K6: =E6+G6+I6 -> 4342 | L6: =F6+H6+J6 -> 151970 | M6: 제 19호
A7: 접지용비닐절연전선(F-GV) | B7: 10㎟ | C7: 2157 | D7: m | E7: 3116 | F7: =ROUND(E7*C7,0) -> 6721212 | G7: 2463 | H7: =ROUND(G7*C7,0) -> 5312691 | I7: 0 | J7: =ROUND(I7*C7,0) -> 0 | K7: =E7+G7+I7 -> 5579 | L7: =F7+H7+J7 -> 12033903 | M7: 제 20호
A8: 접지용비닐절연전선(F-GV) | B8: 16㎟ | C8: 39 | D8: m | E8: 4094 | F8: =ROUND(E8*C8,0) -> 159666 | G8: 2873 | H8: =ROUND(G8*C8,0) -> 112047 | I8: 0 | J8: =ROUND(I8*C8,0) -> 0 | K8: =E8+G8+I8 -> 6967 | L8: =F8+H8+J8 -> 271713 | M8: 제 21호
A9: 폴리에틸렌 난연케이블 | B9: 0.6/1kv F-CV 2C×2.5㎟ | C9: 780 | D9: m | E9: 2116 | F9: =ROUND(E9*C9,0) -> 1650480 | G9: 4258 | H9: =ROUND(G9*C9,0) -> 3321240 | I9: 0 | J9: =ROUND(I9*C9,0) -> 0 | K9: =E9+G9+I9 -> 6374 | L9: =F9+H9+J9 -> 4971720 | M9: 제 22호
A10: 폴리에틸렌 난연케이블(옥외) | B10: 0.6/1kv F-CV 2C×10㎟ | C10: 487 | D10: m | E10: 4423 | F10: =ROUND(E10*C10,0) -> 2154001 | G10: 0 | H10: =ROUND(G10*C10,0) -> 0 | I10: 0 | J10: =ROUND(I10*C10,0) -> 0 | K10: =E10+G10+I10 -> 4423 | L10: =F10+H10+J10 -> 2154001
A11: 폴리에틸렌 난연케이블(옥외) | B11: 0.6/1kv F-CV 2C×25㎟ | C11: 105 | D11: m | E11: 10580 | F11: =ROUND(E11*C11,0) -> 1110900 | G11: 0 | H11: =ROUND(G11*C11,0) -> 0 | I11: 0 | J11: =ROUND(I11*C11,0) -> 0 | K11: =E11+G11+I11 -> 10580 | L11: =F11+H11+J11 -> 1110900
A12: 폴리에틸렌 난연케이블(옥외) | B12: 0.6/1kv F-CV 4C×10㎟ | C12: 1565 | D12: m | E12: 8027 | F12: =ROUND(E12*C12,0) -> 12562255 | G12: 0 | H12: =ROUND(G12*C12,0) -> 0 | I12: 0 | J12: =ROUND(I12*C12,0) -> 0 | K12: =E12+G12+I12 -> 8027 | L12: =F12+H12+J12 -> 12562255
A13: 폴리에틸렌 난연케이블(옥외) | B13: 0.6/1kv F-CV 4C×25㎟ | C13: 105 | D13: m | E13: 19933 | F13: =ROUND(E13*C13,0) -> 2092965 | G13: 0 | H13: =ROUND(G13*C13,0) -> 0 | I13: 0 | J13: =ROUND(I13*C13,0) -> 0 | K13: =E13+G13+I13 -> 19933 | L13: =F13+H13+J13 -> 2092965
A14: 접지봉 | B14: 14Φ×1000 mm | C14: 14 | D14: 개 | E14: 7096 | F14: =ROUND(E14*C14,0) -> 99344 | G14: 43869 | H14: =ROUND(G14*C14,0) -> 614166 | I14: 0 | J14: =ROUND(I14*C14,0) -> 0 | K14: =E14+G14+I14 -> 50965 | L14: =F14+H14+J14 -> 713510 | M14: 제 27호
A15: 접지크램프(IEC 90) | B15: 16sq | C15: 16 | D15: 개 | E15: 721 | F15: =ROUND(E15*C15,0) -> 11536 | G15: 7389 | H15: =ROUND(G15*C15,0) -> 118224 | I15: 0 | J15: =ROUND(I15*C15,0) -> 0 | K15: =E15+G15+I15 -> 8110 | L15: =F15+H15+J15 -> 129760 | M15: 제 28호
A16: 케이블표지시트 | B16: 0.23x400 | C16: 2005 | D16: m | E16: 187 | F16: =ROUND(E16*C16,0) -> 374935 | G16: 237 | H16: =ROUND(G16*C16,0) -> 475185 | I16: 0 | J16: =ROUND(I16*C16,0) -> 0 | K16: =E16+G16+I16 -> 424 | L16: =F16+H16+J16 -> 850120 | M16: 제 29호
A17: 압착단자 | B17: R형동선 나압착 25 ㎟ | C17: 24 | D17: 개 | E17: 1343 | F17: =ROUND(E17*C17,0) -> 32232 | G17: 36133 | H17: =ROUND(G17*C17,0) -> 867192 | I17: 0 | J17: =ROUND(I17*C17,0) -> 0 | K17: =E17+G17+I17 -> 37476 | L17: =F17+H17+J17 -> 899424 | M17: 제 31호
A18: 가로등 건주 기계화 시공 | B18: 일반 5m-7m | C18: 2 | D18: 식 | E18: 11653 | F18: =ROUND(E18*C18,0) -> 23306 | G18: 117311 | H18: =ROUND(G18*C18,0) -> 234622 | I18: 31713 | J18: =ROUND(I18*C18,0) -> 63426 | K18: =E18+G18+I18 -> 160677 | L18: =F18+H18+J18 -> 321354 | M18: 제 6호
A19: 가로등 건주 기계화 시공 | B19: 일반 10m-12m | C19: 43 | D19: 식 | E19: 14212 | F19: =ROUND(E19*C19,0) -> 611116 | G19: 153319 | H19: =ROUND(G19*C19,0) -> 6592717 | I19: 37479 | J19: =ROUND(I19*C19,0) -> 1611597 | K19: =E19+G19+I19 -> 205010 | L19: =F19+H19+J19 -> 8815430 | M19: 제 7호
A20: 터파기(기계90%,인력10%) | B20: 보통토사 | C20: 794.591 | D20: ㎥ | E20: 501 | F20: =ROUND(E20*C20,0) -> 398090 | G20: 4659 | H20: =ROUND(G20*C20,0) -> 3701999 | I20: 483 | J20: =ROUND(I20*C20,0) -> 383787 | K20: =E20+G20+I20 -> 5643 | L20: =F20+H20+J20 -> 4483876 | M20: 제 1호
A21: 되메우기(기계90%,인력10%) | B21: 보통토사 | C21: 767.46 | D21: ㎥ | E21: 449 | F21: =ROUND(E21*C21,0) -> 344590 | G21: 2939 | H21: =ROUND(G21*C21,0) -> 2255565 | I21: 483 | J21: =ROUND(I21*C21,0) -> 370683 | K21: =E21+G21+I21 -> 3871 | L21: =F21+H21+J21 -> 2970838 | M21: 제 2호
A22: 인력잔토처리 | B22: 현장처리 | C22: 27.131 | D22: ㎥ | E22: 1032 | F22: =ROUND(E22*C22,0) -> 27999 | G22: 34413 | H22: =ROUND(G22*C22,0) -> 933659 | I22: 0 | J22: =ROUND(I22*C22,0) -> 0 | K22: =E22+G22+I22 -> 35445 | L22: =F22+H22+J22 -> 961658 | M22: 제 3호
A23: 전주용입상관 | B23: Φ130*2t*2m | C23: 4 | D23: EA | E23: 38396 | F23: =ROUND(E23*C23,0) -> 153584 | G23: 110220 | H23: =ROUND(G23*C23,0) -> 440880 | I23: 0 | J23: =ROUND(I23*C23,0) -> 0 | K23: =E23+G23+I23 -> 148616 | L23: =F23+H23+J23 -> 594464 | M23: 제 35호
A24: 반경관취부밴드 | C24: 12 | D24: EA | E24: 2424 | F24: =ROUND(E24*C24,0) -> 29088 | G24: 0 | H24: =ROUND(G24*C24,0) -> 0 | I24: 0 | J24: =ROUND(I24*C24,0) -> 0 | K24: =E24+G24+I24 -> 2424 | L24: =F24+H24+J24 -> 29088
A25: 케이블 포설(가로등) | B25: 10㎟/2C*1열 | C25: 473 | D25: m | E25: 131 | F25: =ROUND(E25*C25,0) -> 61963 | G25: 4381 | H25: =ROUND(G25*C25,0) -> 2072213 | I25: 0 | J25: =ROUND(I25*C25,0) -> 0 | K25: =E25+G25+I25 -> 4512 | L25: =F25+H25+J25 -> 2134176 | M25: 제 40호
A26: 케이블 포설(가로등) | B26: 25㎟/2C*1열 | C26: 114 | D26: m | E26: 165 | F26: =ROUND(E26*C26,0) -> 18810 | G26: 5509 | H26: =ROUND(G26*C26,0) -> 628026 | I26: 0 | J26: =ROUND(I26*C26,0) -> 0 | K26: =E26+G26+I26 -> 5674 | L26: =F26+H26+J26 -> 646836 | M26: 제 42호
A27: 케이블 포설(가로등) | B27: 10㎟/4C*1열 | C27: 1520 | D27: m | E27: 214 | F27: =ROUND(E27*C27,0) -> 325280 | G27: 7143 | H27: =ROUND(G27*C27,0) -> 10857360 | I27: 0 | J27: =ROUND(I27*C27,0) -> 0 | K27: =E27+G27+I27 -> 7357 | L27: =F27+H27+J27 -> 11182640 | M27: 제 45호
A28: 케이블 포설(가로등) | B28: 25㎟/4C*1열 | C28: 102 | D28: m | E28: 269 | F28: =ROUND(E28*C28,0) -> 27438 | G28: 8991 | H28: =ROUND(G28*C28,0) -> 917082 | I28: 0 | J28: =ROUND(I28*C28,0) -> 0 | K28: =E28+G28+I28 -> 9260 | L28: =F28+H28+J28 -> 944520 | M28: 제 46호
A29: LED 가로등기구 | B29: 100W급 | C29: 43 | D29: 개 | E29: 622655 | F29: =ROUND(E29*C29,0) -> 26774165 | G29: 88522 | H29: =ROUND(G29*C29,0) -> 3806446 | I29: 0 | J29: =ROUND(I29*C29,0) -> 0 | K29: =E29+G29+I29 -> 711177 | L29: =F29+H29+J29 -> 30580611 | M29: 제 47호
A30: LED 공원등기구 | B30: 50W급(A타입) | C30: 2 | D30: 개 | E30: 501502 | F30: =ROUND(E30*C30,0) -> 1003004 | G30: 50082 | H30: =ROUND(G30*C30,0) -> 100164 | I30: 0 | J30: =ROUND(I30*C30,0) -> 0 | K30: =E30+G30+I30 -> 551584 | L30: =F30+H30+J30 -> 1103168 | M30: 제 48호
A31: 가로등기초(직각)기성품 | B31: 500X850X675X700 | C31: 2 | D31: 개 | E31: 105637 | F31: =ROUND(E31*C31,0) -> 211274 | G31: 54586 | H31: =ROUND(G31*C31,0) -> 109172 | I31: 0 | J31: =ROUND(I31*C31,0) -> 0 | K31: =E31+G31+I31 -> 160223 | L31: =F31+H31+J31 -> 320446 | M31: 제 50호
A32: 가로등기초 | B32: 500x775x1050x1100(E) | C32: 43 | D32: 개 | E32: 309437 | F32: =ROUND(E32*C32,0) -> 13305791 | G32: 54586 | H32: =ROUND(G32*C32,0) -> 2347198 | I32: 0 | J32: =ROUND(I32*C32,0) -> 0 | K32: =E32+G32+I32 -> 364023 | L32: =F32+H32+J32 -> 15652989 | M32: 제 51호
A33: 가로등 제어반 | B33: 6회로 | C33: 2 | D33: 개 | E33: 6294374 | F33: =ROUND(E33*C33,0) -> 12588748 | G33: 279149 | H33: =ROUND(G33*C33,0) -> 558298 | I33: 0 | J33: =ROUND(I33*C33,0) -> 0 | K33: =E33+G33+I33 -> 6573523 | L33: =F33+H33+J33 -> 13147046 | M33: 제 52호
A34: 가로등주 | B34: 원형테퍼 강관주 10m -1등용 | C34: 43 | D34: 개 | E34: 1500000 | F34: =ROUND(E34*C34,0) -> 64500000 | G34: 0 | H34: =ROUND(G34*C34,0) -> 0 | I34: 0 | J34: =ROUND(I34*C34,0) -> 0 | K34: =E34+G34+I34 -> 1500000 | L34: =F34+H34+J34 -> 64500000
A35: 가로등 표찰 | B35: STS | C35: 45 | D35: 개 | E35: 10351 | F35: =ROUND(E35*C35,0) -> 465795 | G35: 11700 | H35: =ROUND(G35*C35,0) -> 526500 | I35: 0 | J35: =ROUND(I35*C35,0) -> 0 | K35: =E35+G35+I35 -> 22051 | L35: =F35+H35+J35 -> 992295 | M35: 제 54호
A36: 공원등주 | B36: 5m-1.0m 1등용(A타입) | C36: 2 | D36: 개 | E36: 1194545 | F36: =ROUND(E36*C36,0) -> 2389090 | G36: 84839 | H36: =ROUND(G36*C36,0) -> 169678 | I36: 0 | J36: =ROUND(I36*C36,0) -> 0 | K36: =E36+G36+I36 -> 1279384 | L36: =F36+H36+J36 -> 2558768 | M36: 제 55호
A37: 방수형 접속함 | B37: 1등용,ELB부 | C37: 45 | D37: 개 | E37: 56559 | F37: =ROUND(E37*C37,0) -> 2545155 | G37: 51998 | H37: =ROUND(G37*C37,0) -> 2339910 | I37: 0 | J37: =ROUND(I37*C37,0) -> 0 | K37: =E37+G37+I37 -> 108557 | L37: =F37+H37+J37 -> 4885065 | M37: 제 58호
A38: 방수형 접속함 | B38: 격등용 | C38: 34 | D38: 개 | E38: 15000 | F38: =ROUND(E38*C38,0) -> 510000 | G38: 0 | H38: =ROUND(G38*C38,0) -> 0 | I38: 0 | J38: =ROUND(I38*C38,0) -> 0 | K38: =E38+G38+I38 -> 15000 | L38: =F38+H38+J38 -> 510000
A39: 백호우 | B39: 0.4㎥ | C39: 21 | D39: hr | E39: 14230 | F39: =ROUND(E39*C39,0) -> 298830 | G39: 56783 | H39: =ROUND(G39*C39,0) -> 1192443 | I39: 16378 | J39: =ROUND(I39*C39,0) -> 343938 | K39: =E39+G39+I39 -> 87391 | L39: =F39+H39+J39 -> 1835211
A40: 제어반기초(기성품) | B40: 500x500x800 | C40: 2 | D40: 개 | E40: 141637 | F40: =ROUND(E40*C40,0) -> 283274 | G40: 54586 | H40: =ROUND(G40*C40,0) -> 109172 | I40: 0 | J40: =ROUND(I40*C40,0) -> 0 | K40: =E40+G40+I40 -> 196223 | L40: =F40+H40+J40 -> 392446 | M40: 제 66호
...
