Workbook

Sheet 표지
B4: 견 적 서
B11: 공사명 : 화성 청원지구 산업유통형 지구단위계획(토목,조경,전기)
B15: 46210
B23: 에이치앤케이산업개발주식회사

Sheet 견적서
A1: 견 적 서
A4: 46210 | G4: 에이치앤케이산업개발주식회사
A5: 진명개발 귀하 | G5: 인천광역시 연수구 센트럴로 313, 씨동 2123호 (송도동, 송도씨워크인테라스한라)
A7: 공사명 : 화성 청원지구 산업유통형 지구단위계획 | J7: TEL : 032 - 818 - 2581
A8: 공사금액 : 일금 일백이십삼억칠천팔백이십이만일천일백육십팔원정 (₩12,378,221,168) | J8: FAX : 032 - 822 - 0887
A9: 상기 공사 견적서를 아래와 같이 제출합니다. | J9: 대표자 가 영 현 (인)
A11: 공 종 | B11: 규 격 | C11: 수량 | D11: 단위 | E11: 재 료 비 | G11: 노 무 비 | I11: 경 비 | K11: 합 계 | M11: 비고
E12: 단가 | F12: 금액 | G12: 단가 | H12: 금액 | I12: 단가 | J12: 금액 | K12: 단가 | L12: 금액
A13: Ⅰ. 직접공사비 계 | F13: =+원가계산!D4 -> 4245357794 | H13: =+원가계산!D5 -> 2147353595 | J13: =+원가계산!D6 -> 4811196564 | L13: =+원가계산!D7 -> 11203907953
A14: Ⅱ. 간접공사비 계 | C14: 1 | D14: 식 | F14: =0 -> 0 | H14: =0 -> 0 | J14: =+원가계산!D24-원가계산!D7 -> 2.6978981e+09 | L14: =+J14 -> 2.6978981e+09
A15: 합 계 | F15: =SUM(F13:F14) -> 4245357794 | G15: =SUM(G13:G14) -> 0 | H15: =SUM(H13:H14) -> 2147353595 | I15: =SUM(I13:I14) -> 0 | J15: =SUM(J13:J14) -> 7.5090947e+09 | K15: =SUM(K13:K14) -> 0 | L15: =SUM(L13:L14) -> 1.3901806e+10
A16: 부 가 가 치 세 | C16: 1 | D16: 식 | F16: =0 -> 0 | H16: =0 -> 0 | J16: =원가계산!D25 -> 1.3901806e+09 | L16: =J16 -> 1.3901806e+09
A17: 공 사 비 계 | F17: =+F15 -> 4245357794 | H17: =+H15 -> 2147353595 | J17: =+J16+J15 -> 8.8992753e+09 | L17: =+L16+L15 -> 1.5291987e+10

Sheet 원가계산
A1: 원 가 계 산 서
A2: 구분 | B2: 항목 | C2: 산식 | D2: 금액 | E2: 비고
A4: 직접비 | B4: 재료비 | C4: Σ 섹션 재료비 | D4: =집계표!F3 -> 4245357794
B5: 직접노무비 | C5: Σ 섹션 노무비 | D5: =집계표!H3 -> 2147353595
B6: 직접경비 | C6: Σ 섹션 경비 | D6: =집계표!J3 -> 4811196564
B7: 【 직접공사비 계 】 | C7: 재+직노+직경 | D7: =D4+D5+D6 -> 11203907953
A8: 간접비 | B8: 간접노무비 | C8: 직접노무비×19.7% | D8: =D5*0.197 -> 4.2302866e+08 | E8: 조달청 원가계산 제비율(토목 50~300억·13~36개월)
B9: 산재보험료 | C9: 노무비계×3.56% | D9: =(D5+D8)*0.0356 -> 91505608 | E9: 2026년 산재보험료율 고시(건설업 3.5%)+임금채권보장부담금 0.06%
B10: 고용보험료 | C10: 노무비계×1.15% | D10: =(D5+D8)*0.0115 -> 29559396 | E10: 고용보험료율 사업주 부담(실업급여 0.9%+고용안정·직업능력개발 0.25%) | J10: =SUM(D8:D17)+D21+D22 -> 2.6978981e+09
B11: 국민건강보험료 | C11: 직접노무비×3.595% | D11: =D5*0.03595 -> 77197362 | E11: 2026년 법정요율(건강보험 7.19%의 1/2)
B12: 국민연금보험료 | C12: 직접노무비×4.75% | D12: =D5*0.0475 -> 1.019993e+08 | E12: 2026년 법정요율(국민연금 9.5%의 1/2)
B13: 노인장기요양보험료 | C13: 건강보험료×13.14% | D13: =D11*0.1314 -> 10143733
B14: 산업안전보건관리비 | C14: (재+직노)×2.60% | D14: =(D4+D5)*0.026 -> 1.662105e+08 | E14: 건설업 산업안전보건관리비 계상기준 고시(고용노동부 제2025-11호, 토목 50억 이상)
B15: 기타경비(공과잡비) | C15: (재+노무비계)×6.2% | D15: =(D4+D5+D8)*0.062 -> 4.2257588e+08 | E15: 조달청 원가계산 제비율(세금과공과 등)
B16: 건설기계대여대금지급보증 | C16: 직접공사비×0.40% | D16: =D7*0.004 -> 44815632 | E16: 건설기계 대여대금 지급보증 수수료
B17: 환경보전비 | C17: 직접공사비×0.60% | D17: =D7*0.006 -> 67223448 | E17: 건설기술 진흥법 환경관리비 기준
A18: 원가 | B18: 【 산출경비 계 】 | C18: 간접경비 합 | D18: =D9+D10+D11+D12+D13+D14+D15+D16+D17 -> 1.0112309e+09
B19: 【 경비계(직접+산출) 】 | C19: 직접경비+산출경비 | D19: =D6+D18 -> 5.8224274e+09
B20: 【 순공사원가 】 | C20: 재+노무비계+경비계 | D20: =D4+D5+D8+D19 -> 1.2638167e+10
A21: 간접비 | B21: 일반관리비 | C21: 순공사원가×5% | D21: =D20*0.05 -> 6.3190837e+08 | E21: 0.05
B22: 이윤 | C22: (노무비계+경비계+일반관리비)×7% | D22: =(D5+D8+D19+D21)*0.07 -> 6.3173026e+08 | E22: 0.07
A24: 합계 | B24: 【 공급가액 】 | C24: 순공사원가+일반관리비+이윤 | D24: =D20+D21+D22+D23 -> 1.3901806e+10
B25: 부가가치세 | C25: 공급가액×10% | D25: =D24*0.1 -> 1.3901806e+09
B26: ★ 도급액(공사비 계) | C26: 공급가액+부가세 | D26: =D24+D25 -> 1.5291987e+10
B28: ※ 직접공사비=첨부 내역서, 간접노무비·기타경비·일반관리비·이윤 등 제비율 및 사회보험료·산업안전보건관리비·건설기계대여대금지급보증·환경보전비는 관계 법령·기준요율 적용.

Sheet 집계표
A1: 공종명 / 품명 | B1: 규격 | C1: 수량 | D1: 단위 | E1: 재료비 | G1: 노무비 | I1: 경비 | K1: 합계 | M1: 비고
E2: 단가 | F2: 금액 | G2: 단가 | H2: 금액 | I2: 단가 | J2: 금액 | K2: 단가 | L2: 금액
A3: 【 토목,조경,전기 직접공사비 계 】 | F3: =SUM(F4:F5) -> 4245357794 | G3: =SUM(G4:G5) -> 0 | H3: =SUM(H4:H5) -> 2147353595 | I3: =SUM(I4:I5) -> 0 | J3: =SUM(J4:J5) -> 4811196564 | K3: =SUM(K4:K5) -> 0 | L3: =SUM(L4:L5) -> 11203907953
A4: ='토목,조경 내역서'!A3 -> 【 01. 토목·조경 직접공사비 계 】 | F4: ='토목,조경 내역서'!F3 -> 3724120909 | G4: ='토목,조경 내역서'!G3 -> 0 | H4: ='토목,조경 내역서'!H3 -> 1954126620 | I4: ='토목,조경 내역서'!I3 -> 0 | J4: ='토목,조경 내역서'!J3 -> 4800291901 | K4: ='토목,조경 내역서'!K3 -> 0 | L4: ='토목,조경 내역서'!L3 -> 10478539430
A5: =전기!A3 -> 【 02. 전기설비 】 | F5: =전기!F3 -> 521236885 | G5: =전기!G3 -> 0 | H5: =전기!H3 -> 193226975 | I5: =전기!I3 -> 0 | J5: =전기!J3 -> 10904663 | K5: =전기!K3 -> 0 | L5: =전기!L3 -> 725368523

Sheet 토목,조경 내역서
A1: 공종명 / 품명 | B1: 규격 | C1: 수량 | D1: 단위 | E1: 재료비 | G1: 노무비 | I1: 경비 | K1: 합계 | M1: 비고
E2: 단가 | F2: 금액 | G2: 단가 | H2: 금액 | I2: 단가 | J2: 금액 | K2: 단가 | L2: 금액
A3: 【 01. 토목·조경 직접공사비 계 】 | F3: =+F4+F20+F28+F34+F45 -> 3724120909 | H3: =+H4+H20+H28+H34+H45 -> 1954126620 | J3: =+J4+J20+J28+J34+J45 -> 4800291901 | L3: =+L4+L20+L28+L34+L45 -> 10478539430
A4: 【 01. 토목·조경 】 | F4: =SUM(F5:F19) -> 2041994590 | H4: =SUM(H5:H19) -> 1021115015 | J4: =SUM(J5:J19) -> 2384977654 | L4: =SUM(L5:L19) -> 5448087259
A5: =+A65 -> 1. 토 공 | F5: =+F65 -> 126278155 | H5: =+H65 -> 156169881 | J5: =+J65 -> 481743868 | L5: =+L65 -> 764191904 | M5: =+M65 -> 0
A6: =+A145 -> 2. 우 수 공 | F6: =+F145 -> 446797776 | H6: =+H145 -> 164585918 | J6: =+J145 -> 232324824 | L6: =+L145 -> 843708518
A7: =+A283 -> 3. 오 수 공 | F7: =+F283 -> 47625602 | H7: =+H283 -> 34125578 | J7: =+J283 -> 37402210 | L7: =+L283 -> 119153390
A8: =+A352 -> 4. 상 수 공 | F8: =+F352 -> 130597022 | H8: =+H352 -> 84470417 | J8: =+J352 -> 21214664 | L8: =+L352 -> 236282103
A9: =+A482 -> 5. 포 장 공 | F9: =+F482 -> 579476922 | H9: =+H482 -> 135390547 | J9: =+J482 -> 121868378 | L9: =+L482 -> 836735847
A10: =+A580 -> 6. 구조물공 | F10: =+F580 -> 55404947 | H10: =+H580 -> 32846006 | J10: =+J580 -> 20683982 | L10: =+L580 -> 108934935
A11: =+A634 -> 7. 부 대 공 | F11: =+F634 -> 137267397 | H11: =+H634 -> 172060870 | J11: =+J634 -> 331559738 | L11: =+L634 -> 640888005
A12: =+A692 -> 8. 하수처리장 | F12: =+F692 -> 44205670 | H12: =+H692 -> 37212134 | J12: =+J692 -> 334836442 | L12: =+L692 -> 416254246
A13: =+A773 -> 9. 지하저류조 | F13: =+F773 -> 396840609 | H13: =+H773 -> 147234419 | J13: =+J773 -> 112134434 | L13: =+L773 -> 656209462
A14: =+A790 -> 10. 조 경 공 | F14: =+F790 -> 77500490 | H14: =+H790 -> 57019245 | J14: =+J790 -> 691209114 | L14: =+L790 -> 825728849
A15: =+A893 -> 1. GIS DB 구축
A16: =+A894 -> 2. 구조검토비
A17: =+A895 -> 1. GIS DB 구축
A18: =+A895 -> 1. GIS DB 구축
A19: =+A897 -> 2. 구조검토비
A20: =+A900 -> 【 04. 진입도로 】 | F20: =SUM(F21:F26) -> 498233494 | H20: =SUM(H21:H26) -> 220907755 | J20: =SUM(J21:J26) -> 202406558 | L20: =SUM(L21:L26) -> 921547807
A21: =+A901 -> 1. 토 공 | F21: =+F901 -> 11833096 | H21: =+H901 -> 22879517 | J21: =+J901 -> 66029706 | L21: =+L901 -> 100742319
A22: =+A941 -> 2. 우 수 공 | F22: =+F941 -> 113891806 | H22: =+H941 -> 56125531 | J22: =+J941 -> 58790980 | L22: =+L941 -> 228808317
A23: =+A997 -> 3. 상 수 공 | F23: =+F997 -> 19471303 | H23: =+H997 -> 14525613 | J23: =+J997 -> 3648976 | L23: =+L997 -> 37645892
A24: =+A1040 -> 4. 포 장 공 | F24: =+F1040 -> 264616882 | H24: =+H1040 -> 56155091 | J24: =+J1040 -> 62747940 | L24: =+L1040 -> 383519913
A25: =+A1115 -> 5. 구조물공 | F25: =+F1115 -> 88420407 | H25: =+H1115 -> 69676086 | J25: =+J1115 -> 10657102 | L25: =+L1115 -> 168753595
A26: =+A1145 -> 6. 부 대 공 | F26: =+F1145 -> 0 | H26: =+H1145 -> 1545917 | J26: =+J1145 -> 531854 | L26: =+L1145 -> 2077771
A28: 【 05. 회전교차로 】 | F28: =SUM(F29:F33) -> 703408420 | H28: =SUM(H29:H33) -> 298567599 | J28: =SUM(J29:J33) -> 214132368 | L28: =SUM(L29:L33) -> 1216108387
A29: =+A1160 -> 1. 토 공 | F29: =+F1160 -> 2610721 | H29: =+H1160 -> 14497621 | J29: =+J1160 -> 40205248 | L29: =+L1160 -> 57313590
A30: =+A1201 -> 2. 우 수 공 | F30: =+F1201 -> 40232512 | H30: =+H1201 -> 35096610 | J30: =+J1201 -> 38472298 | L30: =+L1201 -> 113801420
A31: =+A1272 -> 3. 포 장 공 | F31: =+F1272 -> 484968879 | H31: =+H1272 -> 109114579 | J31: =+J1272 -> 112940694 | L31: =+L1272 -> 707024152
A32: =+A1344 -> 4. 구조물공 | F32: =+F1344 -> 175596308 | H32: =+H1344 -> 138024451 | J32: =+J1344 -> 22452767 | L32: =+L1344 -> 336073526
A33: =+A1374 -> 5. 부 대 공 | F33: =+F1374 -> 0 | H33: =+H1374 -> 1834338 | J33: =+J1374 -> 61361 | L33: =+L1374 -> 1895699
A34: 【 06. 개발행위 】 | F34: =SUM(F35:F44) -> 480484405 | H34: =SUM(H35:H44) -> 413536251 | J34: =SUM(J35:J44) -> 1962353399 | L34: =SUM(L35:L44) -> 2856374055
A35: =+A1389 -> 1. 토 공 | F35: =+F1389 -> 0 | H35: =+H1389 -> 103878160 | J35: =+J1389 -> 888816168 | L35: =+L1389 -> 992694328
A36: =+A1411 -> 2. A1 | F36: =+F1411 -> 38435289 | H36: =+H1411 -> 28552687 | J36: =+J1411 -> 88297375 | L36: =+L1411 -> 155285351
A37: =+A1427 -> 3. A2 | F37: =+F1427 -> 72135060 | H37: =+H1427 -> 51913040 | J37: =+J1427 -> 457514727 | L37: =+L1427 -> 581562827
A38: =+A1446 -> 4. A3 | F38: =+F1446 -> 71854705 | H38: =+H1446 -> 49167943 | J38: =+J1446 -> 119857181 | L38: =+L1446 -> 240879829
A39: =+A1465 -> 5. A4 | F39: =+F1465 -> 64850156 | H39: =+H1465 -> 43131547 | J39: =+J1465 -> 87335066 | L39: =+L1465 -> 195316769
A40: =+A1482 -> 6. A5 | F40: =+F1482 -> 55462553 | H40: =+H1482 -> 33708290 | J40: =+J1482 -> 74800007 | L40: =+L1482 -> 163970850
A41: =+A1499 -> 7. B1 | F41: =+F1499 -> 72570279 | H41: =+H1499 -> 43028478 | J41: =+J1499 -> 112058050 | L41: =+L1499 -> 227656807
...

Sheet 전기
A1: 공종명 / 품명 | B1: 규격 | C1: 수량 | D1: 단위 | E1: 재료비 | G1: 노무비 | I1: 경비 | K1: 합계 | M1: 비고
E2: 단가 | F2: 금액 | G2: 단가 | H2: 금액 | I2: 단가 | J2: 금액 | K2: 단가 | L2: 금액
A3: 【 02. 전기설비 】 | F3: =SUM(F4:F11) -> 521236885 | G3: =SUM(G4:G11) -> 0 | H3: =SUM(H4:H11) -> 193226975 | I3: =SUM(I4:I11) -> 0 | J3: =SUM(J4:J11) -> 10904663 | K3: =SUM(K4:K11) -> 0 | L3: =SUM(L4:L11) -> 725368523
A4: =+A34 -> 1.전기공사 (지구내) ▸ 1-1.가로등설비공사 | F4: =+F34 -> 168366694 | G4: =+G34 -> 0 | H4: =+H34 -> 74760221 | I4: =+I34 -> 0 | J4: =+J34 -> 2912103 | K4: =+K34 -> 0 | L4: =+L34 -> 246039018
A5: =+A74 -> 1.전기공사 (지구내) ▸ 1-2.공원등설비공사 | F5: =+F74 -> 62703135 | G5: =+G74 -> 0 | H5: =+H74 -> 24119403 | I5: =+I74 -> 0 | J5: =+J74 -> 1032510 | K5: =+K74 -> 0 | L5: =+L74 -> 87855048
A6: =+A107 -> 1.전기공사 (지구내) ▸ 1-3.신호등설비공사 | F6: =+F107 -> 18575525 | G6: =+G107 -> 0 | H6: =+H107 -> 11313170 | I6: =+I107 -> 0 | J6: =+J107 -> 362824 | K6: =+K107 -> 0 | L6: =+L107 -> 30251519
A7: =+A132 -> 1.전기공사 (지구내) ▸ 1-4.공원 통신설비 공사 | F7: =+F132 -> 72948061 | G7: =+G132 -> 0 | H7: =+H132 -> 18973472 | I7: =+I132 -> 0 | J7: =+J132 -> 4264900 | K7: =+K132 -> 0 | L7: =+L132 -> 96186433
A8: =+A176 -> 1.전기공사 (지구내) ▸ 1-5.불법주정차단속시스템 | F8: =+F176 -> 24853500 | G8: =+G176 -> 0 | H8: =+H176 -> 0 | I8: =+I176 -> 0 | J8: =+J176 -> 0 | K8: =+K176 -> 0 | L8: =+L176 -> 24853500
A9: =+A178 -> 2.전기공사 (지구외) ▸ 2-1.가로등설비공사 | F9: =+F178 -> 112592176 | G9: =+G178 -> 0 | H9: =+H178 -> 47591777 | I9: =+I178 -> 0 | J9: =+J178 -> 2041425 | K9: =+K178 -> 0 | L9: =+L178 -> 162225378
A10: =+A211 -> 2.전기공사 (지구외) ▸ 2-2.신호등설비공사 | F10: =F211 -> 36344294 | G10: =G211 -> 0 | H10: =H211 -> 16468932 | I10: =I211 -> 0 | J10: =J211 -> 290901 | K10: =K211 -> 0 | L10: =L211 -> 53104127
A11: =+A249 -> 2.전기공사 (지구외) ▸ 2-3.불법주정차단속시스템 | F11: =+F249 -> 24853500 | G11: =+G249 -> 0 | H11: =+H249 -> 0 | I11: =+I249 -> 0 | J11: =+J249 -> 0 | K11: =+K249 -> 0 | L11: =+L249 -> 24853500
A34: 1.전기공사 (지구내) ▸ 1-1.가로등설비공사 | F34: =SUM(F35:F73) -> 168366694 | H34: =SUM(H35:H73) -> 74760221 | J34: =SUM(J35:J73) -> 2912103 | L34: =F34+H34+J34 -> 246039018
A35: 파상형 폴리에틸렌 전선관 | B35: 40㎜(가로등,신호,구내) | C35: 2061 | D35: m | E35: 992.25 | F35: =ROUND(E35*C35,0) -> 2045027 | G35: 9452.1 | H35: =ROUND(G35*C35,0) -> 19480778 | I35: 0 | J35: =ROUND(I35*C35,0) -> 0 | K35: =E35+G35+I35 -> 10444.35 | L35: =F35+H35+J35 -> 21525805
A36: 파상형 폴리에틸렌 전선관 | B36: 50㎜(가로등,신호,구내) | C36: 105 | D36: m | E36: 1228.5 | F36: =ROUND(E36*C36,0) -> 128993 | G36: 9452.1 | H36: =ROUND(G36*C36,0) -> 992471 | I36: 0 | J36: =ROUND(I36*C36,0) -> 0 | K36: =E36+G36+I36 -> 10680.6 | L36: =F36+H36+J36 -> 1121464
A37: 접지용비닐절연전선(F-GV)_지중 | B37: 6㎟ | C37: 35 | D37: m | E37: 1972.95 | F37: =ROUND(E37*C37,0) -> 69053 | G37: 2586.15 | H37: =ROUND(G37*C37,0) -> 90515 | I37: 0 | J37: =ROUND(I37*C37,0) -> 0 | K37: =E37+G37+I37 -> 4559.1 | L37: =F37+H37+J37 -> 159568
A38: 접지용비닐절연전선(F-GV) | B38: 10㎟ | C38: 2157 | D38: m | E38: 3271.8 | F38: =ROUND(E38*C38,0) -> 7057273 | G38: 2586.15 | H38: =ROUND(G38*C38,0) -> 5578326 | I38: 0 | J38: =ROUND(I38*C38,0) -> 0 | K38: =E38+G38+I38 -> 5857.95 | L38: =F38+H38+J38 -> 12635599
A39: 접지용비닐절연전선(F-GV) | B39: 16㎟ | C39: 39 | D39: m | E39: 4298.7 | F39: =ROUND(E39*C39,0) -> 167649 | G39: 3016.65 | H39: =ROUND(G39*C39,0) -> 117649 | I39: 0 | J39: =ROUND(I39*C39,0) -> 0 | K39: =E39+G39+I39 -> 7315.35 | L39: =F39+H39+J39 -> 285298
A40: 폴리에틸렌 난연케이블 | B40: 0.6/1kv F-CV 2C×2.5㎟ | C40: 780 | D40: m | E40: 2221.8 | F40: =ROUND(E40*C40,0) -> 1733004 | G40: 4470.9 | H40: =ROUND(G40*C40,0) -> 3487302 | I40: 0 | J40: =ROUND(I40*C40,0) -> 0 | K40: =E40+G40+I40 -> 6692.7 | L40: =F40+H40+J40 -> 5220306
A41: 폴리에틸렌 난연케이블(옥외) | B41: 0.6/1kv F-CV 2C×10㎟ | C41: 487 | D41: m | E41: 4644.15 | F41: =ROUND(E41*C41,0) -> 2261701 | G41: 0 | H41: =ROUND(G41*C41,0) -> 0 | I41: 0 | J41: =ROUND(I41*C41,0) -> 0 | K41: =E41+G41+I41 -> 4644.15 | L41: =F41+H41+J41 -> 2261701
A42: 폴리에틸렌 난연케이블(옥외) | B42: 0.6/1kv F-CV 2C×25㎟ | C42: 105 | D42: m | E42: 11109 | F42: =ROUND(E42*C42,0) -> 1166445 | G42: 0 | H42: =ROUND(G42*C42,0) -> 0 | I42: 0 | J42: =ROUND(I42*C42,0) -> 0 | K42: =E42+G42+I42 -> 11109 | L42: =F42+H42+J42 -> 1166445
A43: 폴리에틸렌 난연케이블(옥외) | B43: 0.6/1kv F-CV 4C×10㎟ | C43: 1565 | D43: m | E43: 8428.35 | F43: =ROUND(E43*C43,0) -> 13190368 | G43: 0 | H43: =ROUND(G43*C43,0) -> 0 | I43: 0 | J43: =ROUND(I43*C43,0) -> 0 | K43: =E43+G43+I43 -> 8428.35 | L43: =F43+H43+J43 -> 13190368
A44: 폴리에틸렌 난연케이블(옥외) | B44: 0.6/1kv F-CV 4C×25㎟ | C44: 105 | D44: m | E44: 20929.65 | F44: =ROUND(E44*C44,0) -> 2197613 | G44: 0 | H44: =ROUND(G44*C44,0) -> 0 | I44: 0 | J44: =ROUND(I44*C44,0) -> 0 | K44: =E44+G44+I44 -> 20929.65 | L44: =F44+H44+J44 -> 2197613
A45: 접지봉 | B45: 14Φ×1000 mm | C45: 14 | D45: 개 | E45: 7450.8 | F45: =ROUND(E45*C45,0) -> 104311 | G45: 46062.45 | H45: =ROUND(G45*C45,0) -> 644874 | I45: 0 | J45: =ROUND(I45*C45,0) -> 0 | K45: =E45+G45+I45 -> 53513.25 | L45: =F45+H45+J45 -> 749185
A46: 접지크램프(IEC 90) | B46: 16sq | C46: 16 | D46: 개 | E46: 757.05 | F46: =ROUND(E46*C46,0) -> 12113 | G46: 7758.45 | H46: =ROUND(G46*C46,0) -> 124135 | I46: 0 | J46: =ROUND(I46*C46,0) -> 0 | K46: =E46+G46+I46 -> 8515.5 | L46: =F46+H46+J46 -> 136248
... A54: 전주용입상관 | B54: Φ130*2t*2m | C54: 4 | D54: EA | E54: 40315.8 | F54: =ROUND(E54*C54,0) -> 161263 | G54: 115731 | H54: =ROUND(G54*C54,0) -> 462924 | I54: 0 | J54: =ROUND(I54*C54,0) -> 0 | K54: =E54+G54+I54 -> 156046.8 | L54: =F54+H54+J54 -> 624187
A55: 반경관취부밴드 | C55: 12 | D55: EA | E55: 2545.2 | F55: =ROUND(E55*C55,0) -> 30542 | G55: 0 | H55: =ROUND(G55*C55,0) -> 0 | I55: 0 | J55: =ROUND(I55*C55,0) -> 0 | K55: =E55+G55+I55 -> 2545.2 | L55: =F55+H55+J55 -> 30542
A56: 케이블 포설(가로등) | B56: 10㎟/2C*1열 | C56: 473 | D56: m | E56: 137.55 | F56: =ROUND(E56*C56,0) -> 65061 | G56: 4600.05 | H56: =ROUND(G56*C56,0) -> 2175824 | I56: 0 | J56: =ROUND(I56*C56,0) -> 0 | K56: =E56+G56+I56 -> 4737.6 | L56: =F56+H56+J56 -> 2240885
A57: 케이블 포설(가로등) | B57: 25㎟/2C*1열 | C57: 114 | D57: m | E57: 173.25 | F57: =ROUND(E57*C57,0) -> 19751 | G57: 5784.45 | H57: =ROUND(G57*C57,0) -> 659427 | I57: 0 | J57: =ROUND(I57*C57,0) -> 0 | K57: =E57+G57+I57 -> 5957.7 | L57: =F57+H57+J57 -> 679178
A58: 케이블 포설(가로등) | B58: 10㎟/4C*1열 | C58: 1520 | D58: m | E58: 224.7 | F58: =ROUND(E58*C58,0) -> 341544 | G58: 7500.15 | H58: =ROUND(G58*C58,0) -> 11400228 | I58: 0 | J58: =ROUND(I58*C58,0) -> 0 | K58: =E58+G58+I58 -> 7724.85 | L58: =F58+H58+J58 -> 11741772
A59: 케이블 포설(가로등) | B59: 25㎟/4C*1열 | C59: 102 | D59: m | E59: 282.45 | F59: =ROUND(E59*C59,0) -> 28810 | G59: 9440.55 | H59: =ROUND(G59*C59,0) -> 962936 | I59: 0 | J59: =ROUND(I59*C59,0) -> 0 | K59: =E59+G59+I59 -> 9723 | L59: =F59+H59+J59 -> 991746
A60: LED 가로등기구 | B60: 100W급 | C60: 43 | D60: 개 | E60: 653787.75 | F60: =ROUND(E60*C60,0) -> 28112873 | G60: 92948.1 | H60: =ROUND(G60*C60,0) -> 3996768 | I60: 0 | J60: =ROUND(I60*C60,0) -> 0 | K60: =E60+G60+I60 -> 746735.85 | L60: =F60+H60+J60 -> 32109641
A61: LED 공원등기구 | B61: 50W급(A타입) | C61: 2 | D61: 개 | E61: 526577.1 | F61: =ROUND(E61*C61,0) -> 1053154 | G61: 52586.1 | H61: =ROUND(G61*C61,0) -> 105172 | I61: 0 | J61: =ROUND(I61*C61,0) -> 0 | K61: =E61+G61+I61 -> 579163.2 | L61: =F61+H61+J61 -> 1158326
A62: 가로등기초(직각)기성품 | B62: 500X850X675X700 | C62: 2 | D62: 개 | E62: 110918.85 | F62: =ROUND(E62*C62,0) -> 221838 | G62: 57315.3 | H62: =ROUND(G62*C62,0) -> 114631 | I62: 0 | J62: =ROUND(I62*C62,0) -> 0 | K62: =E62+G62+I62 -> 168234.15 | L62: =F62+H62+J62 -> 336469
A63: 가로등기초 | B63: 500x775x1050x1100(E) | C63: 43 | D63: 개 | E63: 324908.85 | F63: =ROUND(E63*C63,0) -> 13971081 | G63: 57315.3 | H63: =ROUND(G63*C63,0) -> 2464558 | I63: 0 | J63: =ROUND(I63*C63,0) -> 0 | K63: =E63+G63+I63 -> 382224.15 | L63: =F63+H63+J63 -> 16435639
A64: 가로등 제어반 | B64: 6회로 | C64: 2 | D64: 개 | E64: 6609092.7 | F64: =ROUND(E64*C64,0) -> 13218185 | G64: 293106.45 | H64: =ROUND(G64*C64,0) -> 586213 | I64: 0 | J64: =ROUND(I64*C64,0) -> 0 | K64: =E64+G64+I64 -> 6902199.2 | L64: =F64+H64+J64 -> 13804398
A65: 가로등주 | B65: 원형테퍼 강관주 10m -1등용 | C65: 43 | D65: 개 | E65: 1575000 | F65: =ROUND(E65*C65,0) -> 67725000 | G65: 0 | H65: =ROUND(G65*C65,0) -> 0 | I65: 0 | J65: =ROUND(I65*C65,0) -> 0 | K65: =E65+G65+I65 -> 1575000 | L65: =F65+H65+J65 -> 67725000
A66: 가로등 표찰 | B66: STS | C66: 45 | D66: 개 | E66: 10868.55 | F66: =ROUND(E66*C66,0) -> 489085 | G66: 12285 | H66: =ROUND(G66*C66,0) -> 552825 | I66: 0 | J66: =ROUND(I66*C66,0) -> 0 | K66: =E66+G66+I66 -> 23153.55 | L66: =F66+H66+J66 -> 1041910
A67: 공원등주 | B67: 5m-1.0m 1등용(A타입) | C67: 2 | D67: 개 | E67: 1254272.2 | F67: =ROUND(E67*C67,0) -> 2508545 | G67: 89080.95 | H67: =ROUND(G67*C67,0) -> 178162 | I67: 0 | J67: =ROUND(I67*C67,0) -> 0 | K67: =E67+G67+I67 -> 1343353.2 | L67: =F67+H67+J67 -> 2686707
... A73: 핸드홀뚜껑 | B73: 700x700xt32 | C73: 6 | D73: 개 | E73: 294000 | F73: =ROUND(E73*C73,0) -> 1764000 | G73: 0 | H73: =ROUND(G73*C73,0) -> 0 | I73: 0 | J73: =ROUND(I73*C73,0) -> 0 | K73: =E73+G73+I73 -> 294000 | L73: =F73+H73+J73 -> 1764000
A74: 1.전기공사 (지구내) ▸ 1-2.공원등설비공사 | F74: =SUM(F75:F106) -> 62703135 | H74: =SUM(H75:H106) -> 24119403 | J74: =SUM(J75:J106) -> 1032510 | L74: =F74+H74+J74 -> 87855048
...
